I0501 08:21:08.402618       1 round_trippers.go:466] curl -v -XGET  -H "Accept: application/vnd.kubernetes.protobuf, */*" -H "User-Agent: kube-scheduler/v1.24.7 (linux/amd64) kubernetes/e6f3597/leader-election" 'https://172.18.0.2:6443/apis/coordination.k8s.io/v1/namespaces/kube-system/leases/kube-scheduler?timeout=5s'
I0501 08:21:08.406247       1 round_trippers.go:553] GET https://172.18.0.2:6443/apis/coordination.k8s.io/v1/namespaces/kube-system/leases/kube-scheduler?timeout=5s 200 OK in 3 milliseconds
I0501 08:21:08.406299       1 round_trippers.go:570] HTTP Statistics: GetConnection 0 ms ServerProcessing 3 ms Duration 3 ms
I0501 08:21:08.406316       1 round_trippers.go:577] Response Headers:
I0501 08:21:08.406344       1 round_trippers.go:580]     Audit-Id: c96cde4e-d056-4e91-a730-46d04cf1e803
I0501 08:21:08.406360       1 round_trippers.go:580]     Cache-Control: no-cache, private
I0501 08:21:08.406375       1 round_trippers.go:580]     Content-Type: application/vnd.kubernetes.protobuf
I0501 08:21:08.406390       1 round_trippers.go:580]     X-Kubernetes-Pf-Flowschema-Uid: 493426e8-0f6d-4ea6-bc2c-2d926c7e3221
I0501 08:21:08.406405       1 round_trippers.go:580]     X-Kubernetes-Pf-Prioritylevel-Uid: afabb116-6975-46b8-863b-3258bec9e1ea
I0501 08:21:08.406420       1 round_trippers.go:580]     Content-Length: 432
I0501 08:21:08.406435       1 round_trippers.go:580]     Date: Mon, 01 May 2023 08:21:08 GMT
I0501 08:21:08.406503       1 request.go:1152] Response Body:
00000000  6b 38 73 00 0a 1f 0a 16  63 6f 6f 72 64 69 6e 61  |k8s.....coordina|
00000010  74 69 6f 6e 2e 6b 38 73  2e 69 6f 2f 76 31 12 05  |tion.k8s.io/v1..|
00000020  4c 65 61 73 65 12 84 03  0a a6 02 0a 0e 6b 75 62  |Lease........kub|
00000030  65 2d 73 63 68 65 64 75  6c 65 72 12 00 1a 0b 6b  |e-scheduler....k|
00000040  75 62 65 2d 73 79 73 74  65 6d 22 00 2a 24 36 61  |ube-system".*$6a|
00000050  30 65 32 30 33 66 2d 65  32 38 30 2d 34 36 61 30  |0e203f-e280-46a0|
00000060  2d 39 35 33 62 2d 35 66  62 64 63 37 38 61 63 38  |-953b-5fbdc78ac8|
00000070  36 65 32 07 32 32 36 38  35 32 32 38 00 42 08 08  |6e2.22685228.B..|
00000080  b1 b2 e2 a1 06 10 00 7a  00 8a 01 c4 01 0a 0e 6b  |.......z.......k|
00000090  75 62 65 2d 73 63 68 65  64 75 6c 65 72 12 06 55  |ube-scheduler..U|
000000a0  70 64 61 74 65 1a 16 63  6f 6f 72 64 69 6e 61 74  |pdate..coordinat|
000000b0  69 6f 6e 2e 6b 38 73 2e  69 6f 2f 76 31 22 08 08  |ion.k8s.io/v1"..|
000000c0  b1 b2 e2 a1 06 10 00 32  08 46 69 65 6c 64 73 56  |.......2.FieldsV|
000000d0  31 3a 7c 0a 7a 7b 22 66  3a 73 70 65 63 22 3a 7b  |1:|.z{"f:spec":{|
000000e0  22 66 3a 61 63 71 75 69  72 65 54 69 6d 65 22 3a  |"f:acquireTime":|
000000f0  7b 7d 2c 22 66 3a 68 6f  6c 64 65 72 49 64 65 6e  |{},"f:holderIden|
00000100  74 69 74 79 22 3a 7b 7d  2c 22 66 3a 6c 65 61 73  |tity":{},"f:leas|
00000110  65 44 75 72 61 74 69 6f  6e 53 65 63 6f 6e 64 73  |eDurationSeconds|
00000120  22 3a 7b 7d 2c 22 66 3a  6c 65 61 73 65 54 72 61  |":{},"f:leaseTra|
00000130  6e 73 69 74 69 6f 6e 73  22 3a 7b 7d 2c 22 66 3a  |nsitions":{},"f:|
00000140  72 65 6e 65 77 54 69 6d  65 22 3a 7b 7d 7d 7d 42  |renewTime":{}}}B|
00000150  00 12 59 0a 37 6b 69 6e  64 2d 63 6f 6e 74 72 6f  |..Y.7kind-contro|
00000160  6c 2d 70 6c 61 6e 65 5f  30 64 32 66 61 66 39 33  |l-plane_0d2faf93|
00000170  2d 34 61 30 62 2d 34 66  32 38 2d 38 33 64 33 2d  |-4a0b-4f28-83d3-|
00000180  35 62 35 62 62 66 61 31  65 36 31 30 10 0f 1a 0c  |5b5bbfa1e610....|
00000190  08 f7 a5 86 a2 06 10 b9  84 b7 94 03 22 0c 08 f2  |............"...|
000001a0  ec bd a2 06 10 b1 93 dd  b9 01 28 0a 1a 00 22 00  |..........(...".|
I0501 08:21:08.406728       1 request.go:1152] Request Body:
00000000  6b 38 73 00 0a 1f 0a 16  63 6f 6f 72 64 69 6e 61  |k8s.....coordina|
00000010  74 69 6f 6e 2e 6b 38 73  2e 69 6f 2f 76 31 12 05  |tion.k8s.io/v1..|
00000020  4c 65 61 73 65 12 84 03  0a a6 02 0a 0e 6b 75 62  |Lease........kub|
00000030  65 2d 73 63 68 65 64 75  6c 65 72 12 00 1a 0b 6b  |e-scheduler....k|
00000040  75 62 65 2d 73 79 73 74  65 6d 22 00 2a 24 36 61  |ube-system".*$6a|
00000050  30 65 32 30 33 66 2d 65  32 38 30 2d 34 36 61 30  |0e203f-e280-46a0|
00000060  2d 39 35 33 62 2d 35 66  62 64 63 37 38 61 63 38  |-953b-5fbdc78ac8|
00000070  36 65 32 07 32 32 36 38  35 32 32 38 00 42 08 08  |6e2.22685228.B..|
00000080  b1 b2 e2 a1 06 10 00 7a  00 8a 01 c4 01 0a 0e 6b  |.......z.......k|
00000090  75 62 65 2d 73 63 68 65  64 75 6c 65 72 12 06 55  |ube-scheduler..U|
000000a0  70 64 61 74 65 1a 16 63  6f 6f 72 64 69 6e 61 74  |pdate..coordinat|
000000b0  69 6f 6e 2e 6b 38 73 2e  69 6f 2f 76 31 22 08 08  |ion.k8s.io/v1"..|
000000c0  b1 b2 e2 a1 06 10 00 32  08 46 69 65 6c 64 73 56  |.......2.FieldsV|
000000d0  31 3a 7c 0a 7a 7b 22 66  3a 73 70 65 63 22 3a 7b  |1:|.z{"f:spec":{|
000000e0  22 66 3a 61 63 71 75 69  72 65 54 69 6d 65 22 3a  |"f:acquireTime":|
000000f0  7b 7d 2c 22 66 3a 68 6f  6c 64 65 72 49 64 65 6e  |{},"f:holderIden|
00000100  74 69 74 79 22 3a 7b 7d  2c 22 66 3a 6c 65 61 73  |tity":{},"f:leas|
00000110  65 44 75 72 61 74 69 6f  6e 53 65 63 6f 6e 64 73  |eDurationSeconds|
00000120  22 3a 7b 7d 2c 22 66 3a  6c 65 61 73 65 54 72 61  |":{},"f:leaseTra|
00000130  6e 73 69 74 69 6f 6e 73  22 3a 7b 7d 2c 22 66 3a  |nsitions":{},"f:|
00000140  72 65 6e 65 77 54 69 6d  65 22 3a 7b 7d 7d 7d 42  |renewTime":{}}}B|
00000150  00 12 59 0a 37 6b 69 6e  64 2d 63 6f 6e 74 72 6f  |..Y.7kind-contro|
00000160  6c 2d 70 6c 61 6e 65 5f  30 64 32 66 61 66 39 33  |l-plane_0d2faf93|
00000170  2d 34 61 30 62 2d 34 66  32 38 2d 38 33 64 33 2d  |-4a0b-4f28-83d3-|
00000180  35 62 35 62 62 66 61 31  65 36 31 30 10 0f 1a 0c  |5b5bbfa1e610....|
00000190  08 f7 a5 86 a2 06 10 b9  84 b7 94 03 22 0c 08 f4  |............"...|
000001a0  ec bd a2 06 10 84 f8 f1  bf 01 28 0a 1a 00 22 00  |..........(...".|
I0501 08:21:08.406846       1 round_trippers.go:466] curl -v -XPUT  -H "Accept: application/vnd.kubernetes.protobuf, */*" -H "Content-Type: application/vnd.kubernetes.protobuf" -H "User-Agent: kube-scheduler/v1.24.7 (linux/amd64) kubernetes/e6f3597/leader-election" 'https://172.18.0.2:6443/apis/coordination.k8s.io/v1/namespaces/kube-system/leases/kube-scheduler?timeout=5s'
I0501 08:21:08.414232       1 round_trippers.go:553] PUT https://172.18.0.2:6443/apis/coordination.k8s.io/v1/namespaces/kube-system/leases/kube-scheduler?timeout=5s 200 OK in 7 milliseconds
I0501 08:21:08.414367       1 round_trippers.go:570] HTTP Statistics: GetConnection 0 ms ServerProcessing 6 ms Duration 7 ms
I0501 08:21:08.414448       1 round_trippers.go:577] Response Headers:
I0501 08:21:08.414547       1 round_trippers.go:580]     Audit-Id: 4e19cbe0-907f-4eef-b826-69dc754985dd
I0501 08:21:08.414665       1 round_trippers.go:580]     Cache-Control: no-cache, private
I0501 08:21:08.414770       1 round_trippers.go:580]     Content-Type: application/vnd.kubernetes.protobuf
I0501 08:21:08.414902       1 round_trippers.go:580]     X-Kubernetes-Pf-Flowschema-Uid: 493426e8-0f6d-4ea6-bc2c-2d926c7e3221
I0501 08:21:08.415020       1 round_trippers.go:580]     X-Kubernetes-Pf-Prioritylevel-Uid: afabb116-6975-46b8-863b-3258bec9e1ea
I0501 08:21:08.415114       1 round_trippers.go:580]     Content-Length: 432
I0501 08:21:08.415252       1 round_trippers.go:580]     Date: Mon, 01 May 2023 08:21:08 GMT
I0501 08:21:08.415422       1 request.go:1152] Response Body:
00000000  6b 38 73 00 0a 1f 0a 16  63 6f 6f 72 64 69 6e 61  |k8s.....coordina|
00000010  74 69 6f 6e 2e 6b 38 73  2e 69 6f 2f 76 31 12 05  |tion.k8s.io/v1..|
00000020  4c 65 61 73 65 12 84 03  0a a6 02 0a 0e 6b 75 62  |Lease........kub|
00000030  65 2d 73 63 68 65 64 75  6c 65 72 12 00 1a 0b 6b  |e-scheduler....k|
00000040  75 62 65 2d 73 79 73 74  65 6d 22 00 2a 24 36 61  |ube-system".*$6a|
00000050  30 65 32 30 33 66 2d 65  32 38 30 2d 34 36 61 30  |0e203f-e280-46a0|
00000060  2d 39 35 33 62 2d 35 66  62 64 63 37 38 61 63 38  |-953b-5fbdc78ac8|
00000070  36 65 32 07 32 32 36 38  35 32 35 38 00 42 08 08  |6e2.22685258.B..|
00000080  b1 b2 e2 a1 06 10 00 7a  00 8a 01 c4 01 0a 0e 6b  |.......z.......k|
00000090  75 62 65 2d 73 63 68 65  64 75 6c 65 72 12 06 55  |ube-scheduler..U|
000000a0  70 64 61 74 65 1a 16 63  6f 6f 72 64 69 6e 61 74  |pdate..coordinat|
000000b0  69 6f 6e 2e 6b 38 73 2e  69 6f 2f 76 31 22 08 08  |ion.k8s.io/v1"..|
000000c0  b1 b2 e2 a1 06 10 00 32  08 46 69 65 6c 64 73 56  |.......2.FieldsV|
000000d0  31 3a 7c 0a 7a 7b 22 66  3a 73 70 65 63 22 3a 7b  |1:|.z{"f:spec":{|
000000e0  22 66 3a 61 63 71 75 69  72 65 54 69 6d 65 22 3a  |"f:acquireTime":|
000000f0  7b 7d 2c 22 66 3a 68 6f  6c 64 65 72 49 64 65 6e  |{},"f:holderIden|
00000100  74 69 74 79 22 3a 7b 7d  2c 22 66 3a 6c 65 61 73  |tity":{},"f:leas|
00000110  65 44 75 72 61 74 69 6f  6e 53 65 63 6f 6e 64 73  |eDurationSeconds|
00000120  22 3a 7b 7d 2c 22 66 3a  6c 65 61 73 65 54 72 61  |":{},"f:leaseTra|
00000130  6e 73 69 74 69 6f 6e 73  22 3a 7b 7d 2c 22 66 3a  |nsitions":{},"f:|
00000140  72 65 6e 65 77 54 69 6d  65 22 3a 7b 7d 7d 7d 42  |renewTime":{}}}B|
00000150  00 12 59 0a 37 6b 69 6e  64 2d 63 6f 6e 74 72 6f  |..Y.7kind-contro|
00000160  6c 2d 70 6c 61 6e 65 5f  30 64 32 66 61 66 39 33  |l-plane_0d2faf93|
00000170  2d 34 61 30 62 2d 34 66  32 38 2d 38 33 64 33 2d  |-4a0b-4f28-83d3-|
00000180  35 62 35 62 62 66 61 31  65 36 31 30 10 0f 1a 0c  |5b5bbfa1e610....|
00000190  08 f7 a5 86 a2 06 10 b9  84 b7 94 03 22 0c 08 f4  |............"...|
000001a0  ec bd a2 06 10 84 f8 f1  bf 01 28 0a 1a 00 22 00  |..........(...".|
I0501 08:21:08.415628       1 leaderelection.go:278] successfully renewed lease kube-system/kube-scheduler
I0501 08:21:09.666867       1 pathrecorder.go:241] kube-scheduler: "/healthz" satisfied by exact match
I0501 08:21:09.666976       1 httplog.go:131] "HTTP" verb="GET" URI="/healthz" latency="172.343µs" userAgent="kube-probe/1.24" audit-ID="" srcIP="127.0.0.1:57376" resp=200
I0501 08:21:10.416156       1 round_trippers.go:466] curl -v -XGET  -H "Accept: application/vnd.kubernetes.protobuf, */*" -H "User-Agent: kube-scheduler/v1.24.7 (linux/amd64) kubernetes/e6f3597/leader-election" 'https://172.18.0.2:6443/apis/coordination.k8s.io/v1/namespaces/kube-system/leases/kube-scheduler?timeout=5s'
I0501 08:21:10.419469       1 round_trippers.go:553] GET https://172.18.0.2:6443/apis/coordination.k8s.io/v1/namespaces/kube-system/leases/kube-scheduler?timeout=5s 200 OK in 3 milliseconds
I0501 08:21:10.419504       1 round_trippers.go:570] HTTP Statistics: GetConnection 0 ms ServerProcessing 2 ms Duration 3 ms
I0501 08:21:10.419521       1 round_trippers.go:577] Response Headers:
I0501 08:21:10.419538       1 round_trippers.go:580]     Date: Mon, 01 May 2023 08:21:10 GMT
I0501 08:21:10.419565       1 round_trippers.go:580]     Audit-Id: 6f02fa32-fc37-4394-ba49-892772e4b1df
I0501 08:21:10.419580       1 round_trippers.go:580]     Cache-Control: no-cache, private
I0501 08:21:10.419596       1 round_trippers.go:580]     Content-Type: application/vnd.kubernetes.protobuf
I0501 08:21:10.419619       1 round_trippers.go:580]     X-Kubernetes-Pf-Flowschema-Uid: 493426e8-0f6d-4ea6-bc2c-2d926c7e3221
I0501 08:21:10.419634       1 round_trippers.go:580]     X-Kubernetes-Pf-Prioritylevel-Uid: afabb116-6975-46b8-863b-3258bec9e1ea
I0501 08:21:10.419669       1 round_trippers.go:580]     Content-Length: 432
I0501 08:21:10.419741       1 request.go:1152] Response Body:
00000000  6b 38 73 00 0a 1f 0a 16  63 6f 6f 72 64 69 6e 61  |k8s.....coordina|
00000010  74 69 6f 6e 2e 6b 38 73  2e 69 6f 2f 76 31 12 05  |tion.k8s.io/v1..|
00000020  4c 65 61 73 65 12 84 03  0a a6 02 0a 0e 6b 75 62  |Lease........kub|
00000030  65 2d 73 63 68 65 64 75  6c 65 72 12 00 1a 0b 6b  |e-scheduler....k|
00000040  75 62 65 2d 73 79 73 74  65 6d 22 00 2a 24 36 61  |ube-system".*$6a|
00000050  30 65 32 30 33 66 2d 65  32 38 30 2d 34 36 61 30  |0e203f-e280-46a0|
00000060  2d 39 35 33 62 2d 35 66  62 64 63 37 38 61 63 38  |-953b-5fbdc78ac8|
00000070  36 65 32 07 32 32 36 38  35 32 35 38 00 42 08 08  |6e2.22685258.B..|
00000080  b1 b2 e2 a1 06 10 00 7a  00 8a 01 c4 01 0a 0e 6b  |.......z.......k|
00000090  75 62 65 2d 73 63 68 65  64 75 6c 65 72 12 06 55  |ube-scheduler..U|
000000a0  70 64 61 74 65 1a 16 63  6f 6f 72 64 69 6e 61 74  |pdate..coordinat|
000000b0  69 6f 6e 2e 6b 38 73 2e  69 6f 2f 76 31 22 08 08  |ion.k8s.io/v1"..|
000000c0  b1 b2 e2 a1 06 10 00 32  08 46 69 65 6c 64 73 56  |.......2.FieldsV|
000000d0  31 3a 7c 0a 7a 7b 22 66  3a 73 70 65 63 22 3a 7b  |1:|.z{"f:spec":{|
000000e0  22 66 3a 61 63 71 75 69  72 65 54 69 6d 65 22 3a  |"f:acquireTime":|
000000f0  7b 7d 2c 22 66 3a 68 6f  6c 64 65 72 49 64 65 6e  |{},"f:holderIden|
00000100  74 69 74 79 22 3a 7b 7d  2c 22 66 3a 6c 65 61 73  |tity":{},"f:leas|
00000110  65 44 75 72 61 74 69 6f  6e 53 65 63 6f 6e 64 73  |eDurationSeconds|
00000120  22 3a 7b 7d 2c 22 66 3a  6c 65 61 73 65 54 72 61  |":{},"f:leaseTra|
00000130  6e 73 69 74 69 6f 6e 73  22 3a 7b 7d 2c 22 66 3a  |nsitions":{},"f:|
00000140  72 65 6e 65 77 54 69 6d  65 22 3a 7b 7d 7d 7d 42  |renewTime":{}}}B|
00000150  00 12 59 0a 37 6b 69 6e  64 2d 63 6f 6e 74 72 6f  |..Y.7kind-contro|
00000160  6c 2d 70 6c 61 6e 65 5f  30 64 32 66 61 66 39 33  |l-plane_0d2faf93|
00000170  2d 34 61 30 62 2d 34 66  32 38 2d 38 33 64 33 2d  |-4a0b-4f28-83d3-|
00000180  35 62 35 62 62 66 61 31  65 36 31 30 10 0f 1a 0c  |5b5bbfa1e610....|
00000190  08 f7 a5 86 a2 06 10 b9  84 b7 94 03 22 0c 08 f4  |............"...|
000001a0  ec bd a2 06 10 84 f8 f1  bf 01 28 0a 1a 00 22 00  |..........(...".|
I0501 08:21:10.419925       1 request.go:1152] Request Body:
00000000  6b 38 73 00 0a 1f 0a 16  63 6f 6f 72 64 69 6e 61  |k8s.....coordina|
00000010  74 69 6f 6e 2e 6b 38 73  2e 69 6f 2f 76 31 12 05  |tion.k8s.io/v1..|
00000020  4c 65 61 73 65 12 84 03  0a a6 02 0a 0e 6b 75 62  |Lease........kub|
00000030  65 2d 73 63 68 65 64 75  6c 65 72 12 00 1a 0b 6b  |e-scheduler....k|
00000040  75 62 65 2d 73 79 73 74  65 6d 22 00 2a 24 36 61  |ube-system".*$6a|
00000050  30 65 32 30 33 66 2d 65  32 38 30 2d 34 36 61 30  |0e203f-e280-46a0|
00000060  2d 39 35 33 62 2d 35 66  62 64 63 37 38 61 63 38  |-953b-5fbdc78ac8|
00000070  36 65 32 07 32 32 36 38  35 32 35 38 00 42 08 08  |6e2.22685258.B..|
00000080  b1 b2 e2 a1 06 10 00 7a  00 8a 01 c4 01 0a 0e 6b  |.......z.......k|
00000090  75 62 65 2d 73 63 68 65  64 75 6c 65 72 12 06 55  |ube-scheduler..U|
000000a0  70 64 61 74 65 1a 16 63  6f 6f 72 64 69 6e 61 74  |pdate..coordinat|
000000b0  69 6f 6e 2e 6b 38 73 2e  69 6f 2f 76 31 22 08 08  |ion.k8s.io/v1"..|
000000c0  b1 b2 e2 a1 06 10 00 32  08 46 69 65 6c 64 73 56  |.......2.FieldsV|
000000d0  31 3a 7c 0a 7a 7b 22 66  3a 73 70 65 63 22 3a 7b  |1:|.z{"f:spec":{|
000000e0  22 66 3a 61 63 71 75 69  72 65 54 69 6d 65 22 3a  |"f:acquireTime":|
000000f0  7b 7d 2c 22 66 3a 68 6f  6c 64 65 72 49 64 65 6e  |{},"f:holderIden|
00000100  74 69 74 79 22 3a 7b 7d  2c 22 66 3a 6c 65 61 73  |tity":{},"f:leas|
00000110  65 44 75 72 61 74 69 6f  6e 53 65 63 6f 6e 64 73  |eDurationSeconds|
00000120  22 3a 7b 7d 2c 22 66 3a  6c 65 61 73 65 54 72 61  |":{},"f:leaseTra|
00000130  6e 73 69 74 69 6f 6e 73  22 3a 7b 7d 2c 22 66 3a  |nsitions":{},"f:|
00000140  72 65 6e 65 77 54 69 6d  65 22 3a 7b 7d 7d 7d 42  |renewTime":{}}}B|
00000150  00 12 59 0a 37 6b 69 6e  64 2d 63 6f 6e 74 72 6f  |..Y.7kind-contro|
00000160  6c 2d 70 6c 61 6e 65 5f  30 64 32 66 61 66 39 33  |l-plane_0d2faf93|
00000170  2d 34 61 30 62 2d 34 66  32 38 2d 38 33 64 33 2d  |-4a0b-4f28-83d3-|
00000180  35 62 35 62 62 66 61 31  65 36 31 30 10 0f 1a 0c  |5b5bbfa1e610....|
00000190  08 f7 a5 86 a2 06 10 b9  84 b7 94 03 22 0c 08 f6  |............"...|
000001a0  ec bd a2 06 10 9f 9d ad  c6 01 28 0a 1a 00 22 00  |..........(...".|
I0501 08:21:10.420048       1 round_trippers.go:466] curl -v -XPUT  -H "Content-Type: application/vnd.kubernetes.protobuf" -H "Accept: application/vnd.kubernetes.protobuf, */*" -H "User-Agent: kube-scheduler/v1.24.7 (linux/amd64) kubernetes/e6f3597/leader-election" 'https://172.18.0.2:6443/apis/coordination.k8s.io/v1/namespaces/kube-system/leases/kube-scheduler?timeout=5s'
I0501 08:21:10.425858       1 round_trippers.go:553] PUT https://172.18.0.2:6443/apis/coordination.k8s.io/v1/namespaces/kube-system/leases/kube-scheduler?timeout=5s 200 OK in 5 milliseconds
I0501 08:21:10.425920       1 round_trippers.go:570] HTTP Statistics: GetConnection 0 ms ServerProcessing 5 ms Duration 5 ms
I0501 08:21:10.425938       1 round_trippers.go:577] Response Headers:
I0501 08:21:10.425957       1 round_trippers.go:580]     Audit-Id: 66aeda6c-e617-4fd3-9d80-8213169a0fc9
I0501 08:21:10.425973       1 round_trippers.go:580]     Cache-Control: no-cache, private
I0501 08:21:10.425988       1 round_trippers.go:580]     Content-Type: application/vnd.kubernetes.protobuf
I0501 08:21:10.426003       1 round_trippers.go:580]     X-Kubernetes-Pf-Flowschema-Uid: 493426e8-0f6d-4ea6-bc2c-2d926c7e3221
I0501 08:21:10.426018       1 round_trippers.go:580]     X-Kubernetes-Pf-Prioritylevel-Uid: afabb116-6975-46b8-863b-3258bec9e1ea
I0501 08:21:10.426033       1 round_trippers.go:580]     Content-Length: 432
I0501 08:21:10.426050       1 round_trippers.go:580]     Date: Mon, 01 May 2023 08:21:10 GMT
I0501 08:21:10.426131       1 request.go:1152] Response Body:
00000000  6b 38 73 00 0a 1f 0a 16  63 6f 6f 72 64 69 6e 61  |k8s.....coordina|
00000010  74 69 6f 6e 2e 6b 38 73  2e 69 6f 2f 76 31 12 05  |tion.k8s.io/v1..|
00000020  4c 65 61 73 65 12 84 03  0a a6 02 0a 0e 6b 75 62  |Lease........kub|
00000030  65 2d 73 63 68 65 64 75  6c 65 72 12 00 1a 0b 6b  |e-scheduler....k|
00000040  75 62 65 2d 73 79 73 74  65 6d 22 00 2a 24 36 61  |ube-system".*$6a|
00000050  30 65 32 30 33 66 2d 65  32 38 30 2d 34 36 61 30  |0e203f-e280-46a0|
00000060  2d 39 35 33 62 2d 35 66  62 64 63 37 38 61 63 38  |-953b-5fbdc78ac8|
00000070  36 65 32 07 32 32 36 38  35 32 37 38 00 42 08 08  |6e2.22685278.B..|
00000080  b1 b2 e2 a1 06 10 00 7a  00 8a 01 c4 01 0a 0e 6b  |.......z.......k|
00000090  75 62 65 2d 73 63 68 65  64 75 6c 65 72 12 06 55  |ube-scheduler..U|
000000a0  70 64 61 74 65 1a 16 63  6f 6f 72 64 69 6e 61 74  |pdate..coordinat|
000000b0  69 6f 6e 2e 6b 38 73 2e  69 6f 2f 76 31 22 08 08  |ion.k8s.io/v1"..|
000000c0  b1 b2 e2 a1 06 10 00 32  08 46 69 65 6c 64 73 56  |.......2.FieldsV|
000000d0  31 3a 7c 0a 7a 7b 22 66  3a 73 70 65 63 22 3a 7b  |1:|.z{"f:spec":{|
000000e0  22 66 3a 61 63 71 75 69  72 65 54 69 6d 65 22 3a  |"f:acquireTime":|
000000f0  7b 7d 2c 22 66 3a 68 6f  6c 64 65 72 49 64 65 6e  |{},"f:holderIden|
00000100  74 69 74 79 22 3a 7b 7d  2c 22 66 3a 6c 65 61 73  |tity":{},"f:leas|
00000110  65 44 75 72 61 74 69 6f  6e 53 65 63 6f 6e 64 73  |eDurationSeconds|
00000120  22 3a 7b 7d 2c 22 66 3a  6c 65 61 73 65 54 72 61  |":{},"f:leaseTra|
00000130  6e 73 69 74 69 6f 6e 73  22 3a 7b 7d 2c 22 66 3a  |nsitions":{},"f:|
00000140  72 65 6e 65 77 54 69 6d  65 22 3a 7b 7d 7d 7d 42  |renewTime":{}}}B|
00000150  00 12 59 0a 37 6b 69 6e  64 2d 63 6f 6e 74 72 6f  |..Y.7kind-contro|
00000160  6c 2d 70 6c 61 6e 65 5f  30 64 32 66 61 66 39 33  |l-plane_0d2faf93|
00000170  2d 34 61 30 62 2d 34 66  32 38 2d 38 33 64 33 2d  |-4a0b-4f28-83d3-|
00000180  35 62 35 62 62 66 61 31  65 36 31 30 10 0f 1a 0c  |5b5bbfa1e610....|
00000190  08 f7 a5 86 a2 06 10 b9  84 b7 94 03 22 0c 08 f6  |............"...|
000001a0  ec bd a2 06 10 9f 9d ad  c6 01 28 0a 1a 00 22 00  |..........(...".|
I0501 08:21:10.426302       1 leaderelection.go:278] successfully renewed lease kube-system/kube-scheduler
I0501 08:21:12.427573       1 round_trippers.go:466] curl -v -XGET  -H "Accept: application/vnd.kubernetes.protobuf, */*" -H "User-Agent: kube-scheduler/v1.24.7 (linux/amd64) kubernetes/e6f3597/leader-election" 'https://172.18.0.2:6443/apis/coordination.k8s.io/v1/namespaces/kube-system/leases/kube-scheduler?timeout=5s'
I0501 08:21:12.432614       1 round_trippers.go:553] GET https://172.18.0.2:6443/apis/coordination.k8s.io/v1/namespaces/kube-system/leases/kube-scheduler?timeout=5s 200 OK in 4 milliseconds
I0501 08:21:12.432665       1 round_trippers.go:570] HTTP Statistics: GetConnection 0 ms ServerProcessing 4 ms Duration 4 ms
I0501 08:21:12.432754       1 round_trippers.go:577] Response Headers:
I0501 08:21:12.432845       1 round_trippers.go:580]     Audit-Id: af7d5337-3957-45d8-8549-9c840a4d4d29
I0501 08:21:12.432871       1 round_trippers.go:580]     Cache-Control: no-cache, private
I0501 08:21:12.432950       1 round_trippers.go:580]     Content-Type: application/vnd.kubernetes.protobuf
I0501 08:21:12.432983       1 round_trippers.go:580]     X-Kubernetes-Pf-Flowschema-Uid: 493426e8-0f6d-4ea6-bc2c-2d926c7e3221
I0501 08:21:12.433065       1 round_trippers.go:580]     X-Kubernetes-Pf-Prioritylevel-Uid: afabb116-6975-46b8-863b-3258bec9e1ea
I0501 08:21:12.433139       1 round_trippers.go:580]     Content-Length: 432
I0501 08:21:12.433221       1 round_trippers.go:580]     Date: Mon, 01 May 2023 08:21:12 GMT
I0501 08:21:12.433360       1 request.go:1152] Response Body:
00000000  6b 38 73 00 0a 1f 0a 16  63 6f 6f 72 64 69 6e 61  |k8s.....coordina|
00000010  74 69 6f 6e 2e 6b 38 73  2e 69 6f 2f 76 31 12 05  |tion.k8s.io/v1..|
00000020  4c 65 61 73 65 12 84 03  0a a6 02 0a 0e 6b 75 62  |Lease........kub|
00000030  65 2d 73 63 68 65 64 75  6c 65 72 12 00 1a 0b 6b  |e-scheduler....k|
00000040  75 62 65 2d 73 79 73 74  65 6d 22 00 2a 24 36 61  |ube-system".*$6a|
00000050  30 65 32 30 33 66 2d 65  32 38 30 2d 34 36 61 30  |0e203f-e280-46a0|
00000060  2d 39 35 33 62 2d 35 66  62 64 63 37 38 61 63 38  |-953b-5fbdc78ac8|
00000070  36 65 32 07 32 32 36 38  35 32 37 38 00 42 08 08  |6e2.22685278.B..|
00000080  b1 b2 e2 a1 06 10 00 7a  00 8a 01 c4 01 0a 0e 6b  |.......z.......k|
00000090  75 62 65 2d 73 63 68 65  64 75 6c 65 72 12 06 55  |ube-scheduler..U|
000000a0  70 64 61 74 65 1a 16 63  6f 6f 72 64 69 6e 61 74  |pdate..coordinat|
000000b0  69 6f 6e 2e 6b 38 73 2e  69 6f 2f 76 31 22 08 08  |ion.k8s.io/v1"..|
000000c0  b1 b2 e2 a1 06 10 00 32  08 46 69 65 6c 64 73 56  |.......2.FieldsV|
000000d0  31 3a 7c 0a 7a 7b 22 66  3a 73 70 65 63 22 3a 7b  |1:|.z{"f:spec":{|
000000e0  22 66 3a 61 63 71 75 69  72 65 54 69 6d 65 22 3a  |"f:acquireTime":|
000000f0  7b 7d 2c 22 66 3a 68 6f  6c 64 65 72 49 64 65 6e  |{},"f:holderIden|
00000100  74 69 74 79 22 3a 7b 7d  2c 22 66 3a 6c 65 61 73  |tity":{},"f:leas|
00000110  65 44 75 72 61 74 69 6f  6e 53 65 63 6f 6e 64 73  |eDurationSeconds|
00000120  22 3a 7b 7d 2c 22 66 3a  6c 65 61 73 65 54 72 61  |":{},"f:leaseTra|
00000130  6e 73 69 74 69 6f 6e 73  22 3a 7b 7d 2c 22 66 3a  |nsitions":{},"f:|
00000140  72 65 6e 65 77 54 69 6d  65 22 3a 7b 7d 7d 7d 42  |renewTime":{}}}B|
00000150  00 12 59 0a 37 6b 69 6e  64 2d 63 6f 6e 74 72 6f  |..Y.7kind-contro|
00000160  6c 2d 70 6c 61 6e 65 5f  30 64 32 66 61 66 39 33  |l-plane_0d2faf93|
00000170  2d 34 61 30 62 2d 34 66  32 38 2d 38 33 64 33 2d  |-4a0b-4f28-83d3-|
00000180  35 62 35 62 62 66 61 31  65 36 31 30 10 0f 1a 0c  |5b5bbfa1e610....|
00000190  08 f7 a5 86 a2 06 10 b9  84 b7 94 03 22 0c 08 f6  |............"...|
000001a0  ec bd a2 06 10 9f 9d ad  c6 01 28 0a 1a 00 22 00  |..........(...".|
I0501 08:21:12.433737       1 request.go:1152] Request Body:
00000000  6b 38 73 00 0a 1f 0a 16  63 6f 6f 72 64 69 6e 61  |k8s.....coordina|
00000010  74 69 6f 6e 2e 6b 38 73  2e 69 6f 2f 76 31 12 05  |tion.k8s.io/v1..|
00000020  4c 65 61 73 65 12 84 03  0a a6 02 0a 0e 6b 75 62  |Lease........kub|
00000030  65 2d 73 63 68 65 64 75  6c 65 72 12 00 1a 0b 6b  |e-scheduler....k|
00000040  75 62 65 2d 73 79 73 74  65 6d 22 00 2a 24 36 61  |ube-system".*$6a|
00000050  30 65 32 30 33 66 2d 65  32 38 30 2d 34 36 61 30  |0e203f-e280-46a0|
00000060  2d 39 35 33 62 2d 35 66  62 64 63 37 38 61 63 38  |-953b-5fbdc78ac8|
00000070  36 65 32 07 32 32 36 38  35 32 37 38 00 42 08 08  |6e2.22685278.B..|
00000080  b1 b2 e2 a1 06 10 00 7a  00 8a 01 c4 01 0a 0e 6b  |.......z.......k|
00000090  75 62 65 2d 73 63 68 65  64 75 6c 65 72 12 06 55  |ube-scheduler..U|
000000a0  70 64 61 74 65 1a 16 63  6f 6f 72 64 69 6e 61 74  |pdate..coordinat|
000000b0  69 6f 6e 2e 6b 38 73 2e  69 6f 2f 76 31 22 08 08  |ion.k8s.io/v1"..|
000000c0  b1 b2 e2 a1 06 10 00 32  08 46 69 65 6c 64 73 56  |.......2.FieldsV|
000000d0  31 3a 7c 0a 7a 7b 22 66  3a 73 70 65 63 22 3a 7b  |1:|.z{"f:spec":{|
000000e0  22 66 3a 61 63 71 75 69  72 65 54 69 6d 65 22 3a  |"f:acquireTime":|
000000f0  7b 7d 2c 22 66 3a 68 6f  6c 64 65 72 49 64 65 6e  |{},"f:holderIden|
00000100  74 69 74 79 22 3a 7b 7d  2c 22 66 3a 6c 65 61 73  |tity":{},"f:leas|
00000110  65 44 75 72 61 74 69 6f  6e 53 65 63 6f 6e 64 73  |eDurationSeconds|
00000120  22 3a 7b 7d 2c 22 66 3a  6c 65 61 73 65 54 72 61  |":{},"f:leaseTra|
00000130  6e 73 69 74 69 6f 6e 73  22 3a 7b 7d 2c 22 66 3a  |nsitions":{},"f:|
00000140  72 65 6e 65 77 54 69 6d  65 22 3a 7b 7d 7d 7d 42  |renewTime":{}}}B|
00000150  00 12 59 0a 37 6b 69 6e  64 2d 63 6f 6e 74 72 6f  |..Y.7kind-contro|
00000160  6c 2d 70 6c 61 6e 65 5f  30 64 32 66 61 66 39 33  |l-plane_0d2faf93|
00000170  2d 34 61 30 62 2d 34 66  32 38 2d 38 33 64 33 2d  |-4a0b-4f28-83d3-|
00000180  35 62 35 62 62 66 61 31  65 36 31 30 10 0f 1a 0c  |5b5bbfa1e610....|
00000190  08 f7 a5 86 a2 06 10 b9  84 b7 94 03 22 0c 08 f8  |............"...|
000001a0  ec bd a2 06 10 c1 d1 e4  cb 01 28 0a 1a 00 22 00  |..........(...".|
I0501 08:21:12.434039       1 round_trippers.go:466] curl -v -XPUT  -H "Accept: application/vnd.kubernetes.protobuf, */*" -H "Content-Type: application/vnd.kubernetes.protobuf" -H "User-Agent: kube-scheduler/v1.24.7 (linux/amd64) kubernetes/e6f3597/leader-election" 'https://172.18.0.2:6443/apis/coordination.k8s.io/v1/namespaces/kube-system/leases/kube-scheduler?timeout=5s'
I0501 08:21:12.439684       1 round_trippers.go:553] PUT https://172.18.0.2:6443/apis/coordination.k8s.io/v1/namespaces/kube-system/leases/kube-scheduler?timeout=5s 200 OK in 5 milliseconds
I0501 08:21:12.439732       1 round_trippers.go:570] HTTP Statistics: GetConnection 0 ms ServerProcessing 5 ms Duration 5 ms
I0501 08:21:12.439752       1 round_trippers.go:577] Response Headers:
I0501 08:21:12.439773       1 round_trippers.go:580]     Audit-Id: 7889f23a-b3f3-4c4b-8e25-a6fae50fc9f8
I0501 08:21:12.439799       1 round_trippers.go:580]     Cache-Control: no-cache, private
I0501 08:21:12.439830       1 round_trippers.go:580]     Content-Type: application/vnd.kubernetes.protobuf
I0501 08:21:12.439849       1 round_trippers.go:580]     X-Kubernetes-Pf-Flowschema-Uid: 493426e8-0f6d-4ea6-bc2c-2d926c7e3221
I0501 08:21:12.439867       1 round_trippers.go:580]     X-Kubernetes-Pf-Prioritylevel-Uid: afabb116-6975-46b8-863b-3258bec9e1ea
I0501 08:21:12.439895       1 round_trippers.go:580]     Content-Length: 432
I0501 08:21:12.439914       1 round_trippers.go:580]     Date: Mon, 01 May 2023 08:21:12 GMT
I0501 08:21:12.439985       1 request.go:1152] Response Body:
00000000  6b 38 73 00 0a 1f 0a 16  63 6f 6f 72 64 69 6e 61  |k8s.....coordina|
00000010  74 69 6f 6e 2e 6b 38 73  2e 69 6f 2f 76 31 12 05  |tion.k8s.io/v1..|
00000020  4c 65 61 73 65 12 84 03  0a a6 02 0a 0e 6b 75 62  |Lease........kub|
00000030  65 2d 73 63 68 65 64 75  6c 65 72 12 00 1a 0b 6b  |e-scheduler....k|
00000040  75 62 65 2d 73 79 73 74  65 6d 22 00 2a 24 36 61  |ube-system".*$6a|
00000050  30 65 32 30 33 66 2d 65  32 38 30 2d 34 36 61 30  |0e203f-e280-46a0|
00000060  2d 39 35 33 62 2d 35 66  62 64 63 37 38 61 63 38  |-953b-5fbdc78ac8|
00000070  36 65 32 07 32 32 36 38  35 33 31 38 00 42 08 08  |6e2.22685318.B..|
00000080  b1 b2 e2 a1 06 10 00 7a  00 8a 01 c4 01 0a 0e 6b  |.......z.......k|
00000090  75 62 65 2d 73 63 68 65  64 75 6c 65 72 12 06 55  |ube-scheduler..U|
000000a0  70 64 61 74 65 1a 16 63  6f 6f 72 64 69 6e 61 74  |pdate..coordinat|
000000b0  69 6f 6e 2e 6b 38 73 2e  69 6f 2f 76 31 22 08 08  |ion.k8s.io/v1"..|
000000c0  b1 b2 e2 a1 06 10 00 32  08 46 69 65 6c 64 73 56  |.......2.FieldsV|
000000d0  31 3a 7c 0a 7a 7b 22 66  3a 73 70 65 63 22 3a 7b  |1:|.z{"f:spec":{|
000000e0  22 66 3a 61 63 71 75 69  72 65 54 69 6d 65 22 3a  |"f:acquireTime":|
000000f0  7b 7d 2c 22 66 3a 68 6f  6c 64 65 72 49 64 65 6e  |{},"f:holderIden|
00000100  74 69 74 79 22 3a 7b 7d  2c 22 66 3a 6c 65 61 73  |tity":{},"f:leas|
00000110  65 44 75 72 61 74 69 6f  6e 53 65 63 6f 6e 64 73  |eDurationSeconds|
00000120  22 3a 7b 7d 2c 22 66 3a  6c 65 61 73 65 54 72 61  |":{},"f:leaseTra|
00000130  6e 73 69 74 69 6f 6e 73  22 3a 7b 7d 2c 22 66 3a  |nsitions":{},"f:|
00000140  72 65 6e 65 77 54 69 6d  65 22 3a 7b 7d 7d 7d 42  |renewTime":{}}}B|
00000150  00 12 59 0a 37 6b 69 6e  64 2d 63 6f 6e 74 72 6f  |..Y.7kind-contro|
00000160  6c 2d 70 6c 61 6e 65 5f  30 64 32 66 61 66 39 33  |l-plane_0d2faf93|
00000170  2d 34 61 30 62 2d 34 66  32 38 2d 38 33 64 33 2d  |-4a0b-4f28-83d3-|
00000180  35 62 35 62 62 66 61 31  65 36 31 30 10 0f 1a 0c  |5b5bbfa1e610....|
00000190  08 f7 a5 86 a2 06 10 b9  84 b7 94 03 22 0c 08 f8  |............"...|
000001a0  ec bd a2 06 10 c1 d1 e4  cb 01 28 0a 1a 00 22 00  |..........(...".|
I0501 08:21:12.440106       1 leaderelection.go:278] successfully renewed lease kube-system/kube-scheduler
I0501 08:21:14.441485       1 round_trippers.go:466] curl -v -XGET  -H "Accept: application/vnd.kubernetes.protobuf, */*" -H "User-Agent: kube-scheduler/v1.24.7 (linux/amd64) kubernetes/e6f3597/leader-election" 'https://172.18.0.2:6443/apis/coordination.k8s.io/v1/namespaces/kube-system/leases/kube-scheduler?timeout=5s'
I0501 08:21:14.447680       1 round_trippers.go:553] GET https://172.18.0.2:6443/apis/coordination.k8s.io/v1/namespaces/kube-system/leases/kube-scheduler?timeout=5s 200 OK in 6 milliseconds
I0501 08:21:14.447742       1 round_trippers.go:570] HTTP Statistics: GetConnection 0 ms ServerProcessing 5 ms Duration 6 ms
I0501 08:21:14.447764       1 round_trippers.go:577] Response Headers:
I0501 08:21:14.447789       1 round_trippers.go:580]     Audit-Id: 9f807c71-c38b-4d5c-a399-0add2f228574
I0501 08:21:14.447814       1 round_trippers.go:580]     Cache-Control: no-cache, private
I0501 08:21:14.447833       1 round_trippers.go:580]     Content-Type: application/vnd.kubernetes.protobuf
I0501 08:21:14.447856       1 round_trippers.go:580]     X-Kubernetes-Pf-Flowschema-Uid: 493426e8-0f6d-4ea6-bc2c-2d926c7e3221
I0501 08:21:14.447878       1 round_trippers.go:580]     X-Kubernetes-Pf-Prioritylevel-Uid: afabb116-6975-46b8-863b-3258bec9e1ea
I0501 08:21:14.447895       1 round_trippers.go:580]     Content-Length: 432
I0501 08:21:14.447918       1 round_trippers.go:580]     Date: Mon, 01 May 2023 08:21:14 GMT
I0501 08:21:14.448024       1 request.go:1152] Response Body:
00000000  6b 38 73 00 0a 1f 0a 16  63 6f 6f 72 64 69 6e 61  |k8s.....coordina|
00000010  74 69 6f 6e 2e 6b 38 73  2e 69 6f 2f 76 31 12 05  |tion.k8s.io/v1..|
00000020  4c 65 61 73 65 12 84 03  0a a6 02 0a 0e 6b 75 62  |Lease........kub|
00000030  65 2d 73 63 68 65 64 75  6c 65 72 12 00 1a 0b 6b  |e-scheduler....k|
00000040  75 62 65 2d 73 79 73 74  65 6d 22 00 2a 24 36 61  |ube-system".*$6a|
00000050  30 65 32 30 33 66 2d 65  32 38 30 2d 34 36 61 30  |0e203f-e280-46a0|
00000060  2d 39 35 33 62 2d 35 66  62 64 63 37 38 61 63 38  |-953b-5fbdc78ac8|
00000070  36 65 32 07 32 32 36 38  35 33 31 38 00 42 08 08  |6e2.22685318.B..|
00000080  b1 b2 e2 a1 06 10 00 7a  00 8a 01 c4 01 0a 0e 6b  |.......z.......k|
00000090  75 62 65 2d 73 63 68 65  64 75 6c 65 72 12 06 55  |ube-scheduler..U|
000000a0  70 64 61 74 65 1a 16 63  6f 6f 72 64 69 6e 61 74  |pdate..coordinat|
000000b0  69 6f 6e 2e 6b 38 73 2e  69 6f 2f 76 31 22 08 08  |ion.k8s.io/v1"..|
000000c0  b1 b2 e2 a1 06 10 00 32  08 46 69 65 6c 64 73 56  |.......2.FieldsV|
000000d0  31 3a 7c 0a 7a 7b 22 66  3a 73 70 65 63 22 3a 7b  |1:|.z{"f:spec":{|
000000e0  22 66 3a 61 63 71 75 69  72 65 54 69 6d 65 22 3a  |"f:acquireTime":|
000000f0  7b 7d 2c 22 66 3a 68 6f  6c 64 65 72 49 64 65 6e  |{},"f:holderIden|
00000100  74 69 74 79 22 3a 7b 7d  2c 22 66 3a 6c 65 61 73  |tity":{},"f:leas|
00000110  65 44 75 72 61 74 69 6f  6e 53 65 63 6f 6e 64 73  |eDurationSeconds|
00000120  22 3a 7b 7d 2c 22 66 3a  6c 65 61 73 65 54 72 61  |":{},"f:leaseTra|
00000130  6e 73 69 74 69 6f 6e 73  22 3a 7b 7d 2c 22 66 3a  |nsitions":{},"f:|
00000140  72 65 6e 65 77 54 69 6d  65 22 3a 7b 7d 7d 7d 42  |renewTime":{}}}B|
00000150  00 12 59 0a 37 6b 69 6e  64 2d 63 6f 6e 74 72 6f  |..Y.7kind-contro|
00000160  6c 2d 70 6c 61 6e 65 5f  30 64 32 66 61 66 39 33  |l-plane_0d2faf93|
00000170  2d 34 61 30 62 2d 34 66  32 38 2d 38 33 64 33 2d  |-4a0b-4f28-83d3-|
00000180  35 62 35 62 62 66 61 31  65 36 31 30 10 0f 1a 0c  |5b5bbfa1e610....|
00000190  08 f7 a5 86 a2 06 10 b9  84 b7 94 03 22 0c 08 f8  |............"...|
000001a0  ec bd a2 06 10 c1 d1 e4  cb 01 28 0a 1a 00 22 00  |..........(...".|
I0501 08:21:14.448493       1 request.go:1152] Request Body:
00000000  6b 38 73 00 0a 1f 0a 16  63 6f 6f 72 64 69 6e 61  |k8s.....coordina|
00000010  74 69 6f 6e 2e 6b 38 73  2e 69 6f 2f 76 31 12 05  |tion.k8s.io/v1..|
00000020  4c 65 61 73 65 12 84 03  0a a6 02 0a 0e 6b 75 62  |Lease........kub|
00000030  65 2d 73 63 68 65 64 75  6c 65 72 12 00 1a 0b 6b  |e-scheduler....k|
00000040  75 62 65 2d 73 79 73 74  65 6d 22 00 2a 24 36 61  |ube-system".*$6a|
00000050  30 65 32 30 33 66 2d 65  32 38 30 2d 34 36 61 30  |0e203f-e280-46a0|
00000060  2d 39 35 33 62 2d 35 66  62 64 63 37 38 61 63 38  |-953b-5fbdc78ac8|
00000070  36 65 32 07 32 32 36 38  35 33 31 38 00 42 08 08  |6e2.22685318.B..|
00000080  b1 b2 e2 a1 06 10 00 7a  00 8a 01 c4 01 0a 0e 6b  |.......z.......k|
00000090  75 62 65 2d 73 63 68 65  64 75 6c 65 72 12 06 55  |ube-scheduler..U|
000000a0  70 64 61 74 65 1a 16 63  6f 6f 72 64 69 6e 61 74  |pdate..coordinat|
000000b0  69 6f 6e 2e 6b 38 73 2e  69 6f 2f 76 31 22 08 08  |ion.k8s.io/v1"..|
000000c0  b1 b2 e2 a1 06 10 00 32  08 46 69 65 6c 64 73 56  |.......2.FieldsV|
000000d0  31 3a 7c 0a 7a 7b 22 66  3a 73 70 65 63 22 3a 7b  |1:|.z{"f:spec":{|
000000e0  22 66 3a 61 63 71 75 69  72 65 54 69 6d 65 22 3a  |"f:acquireTime":|
000000f0  7b 7d 2c 22 66 3a 68 6f  6c 64 65 72 49 64 65 6e  |{},"f:holderIden|
00000100  74 69 74 79 22 3a 7b 7d  2c 22 66 3a 6c 65 61 73  |tity":{},"f:leas|
00000110  65 44 75 72 61 74 69 6f  6e 53 65 63 6f 6e 64 73  |eDurationSeconds|
00000120  22 3a 7b 7d 2c 22 66 3a  6c 65 61 73 65 54 72 61  |":{},"f:leaseTra|
00000130  6e 73 69 74 69 6f 6e 73  22 3a 7b 7d 2c 22 66 3a  |nsitions":{},"f:|
00000140  72 65 6e 65 77 54 69 6d  65 22 3a 7b 7d 7d 7d 42  |renewTime":{}}}B|
00000150  00 12 59 0a 37 6b 69 6e  64 2d 63 6f 6e 74 72 6f  |..Y.7kind-contro|
00000160  6c 2d 70 6c 61 6e 65 5f  30 64 32 66 61 66 39 33  |l-plane_0d2faf93|
00000170  2d 34 61 30 62 2d 34 66  32 38 2d 38 33 64 33 2d  |-4a0b-4f28-83d3-|
00000180  35 62 35 62 62 66 61 31  65 36 31 30 10 0f 1a 0c  |5b5bbfa1e610....|
00000190  08 f7 a5 86 a2 06 10 b9  84 b7 94 03 22 0c 08 fa  |............"...|
000001a0  ec bd a2 06 10 ee 98 ad  d2 01 28 0a 1a 00 22 00  |..........(...".|
I0501 08:21:14.448685       1 round_trippers.go:466] curl -v -XPUT  -H "Content-Type: application/vnd.kubernetes.protobuf" -H "Accept: application/vnd.kubernetes.protobuf, */*" -H "User-Agent: kube-scheduler/v1.24.7 (linux/amd64) kubernetes/e6f3597/leader-election" 'https://172.18.0.2:6443/apis/coordination.k8s.io/v1/namespaces/kube-system/leases/kube-scheduler?timeout=5s'
I0501 08:21:14.454181       1 round_trippers.go:553] PUT https://172.18.0.2:6443/apis/coordination.k8s.io/v1/namespaces/kube-system/leases/kube-scheduler?timeout=5s 200 OK in 5 milliseconds
I0501 08:21:14.454228       1 round_trippers.go:570] HTTP Statistics: GetConnection 0 ms ServerProcessing 4 ms Duration 5 ms
I0501 08:21:14.454247       1 round_trippers.go:577] Response Headers:
I0501 08:21:14.454265       1 round_trippers.go:580]     Audit-Id: b06a8ecb-6c6a-4664-b9be-5734d53d3b89
I0501 08:21:14.454283       1 round_trippers.go:580]     Cache-Control: no-cache, private
I0501 08:21:14.454300       1 round_trippers.go:580]     Content-Type: application/vnd.kubernetes.protobuf
I0501 08:21:14.454317       1 round_trippers.go:580]     X-Kubernetes-Pf-Flowschema-Uid: 493426e8-0f6d-4ea6-bc2c-2d926c7e3221
I0501 08:21:14.454334       1 round_trippers.go:580]     X-Kubernetes-Pf-Prioritylevel-Uid: afabb116-6975-46b8-863b-3258bec9e1ea
I0501 08:21:14.454351       1 round_trippers.go:580]     Content-Length: 432
I0501 08:21:14.454368       1 round_trippers.go:580]     Date: Mon, 01 May 2023 08:21:14 GMT
I0501 08:21:14.454436       1 request.go:1152] Response Body:
00000000  6b 38 73 00 0a 1f 0a 16  63 6f 6f 72 64 69 6e 61  |k8s.....coordina|
00000010  74 69 6f 6e 2e 6b 38 73  2e 69 6f 2f 76 31 12 05  |tion.k8s.io/v1..|
00000020  4c 65 61 73 65 12 84 03  0a a6 02 0a 0e 6b 75 62  |Lease........kub|
00000030  65 2d 73 63 68 65 64 75  6c 65 72 12 00 1a 0b 6b  |e-scheduler....k|
00000040  75 62 65 2d 73 79 73 74  65 6d 22 00 2a 24 36 61  |ube-system".*$6a|
00000050  30 65 32 30 33 66 2d 65  32 38 30 2d 34 36 61 30  |0e203f-e280-46a0|
00000060  2d 39 35 33 62 2d 35 66  62 64 63 37 38 61 63 38  |-953b-5fbdc78ac8|
00000070  36 65 32 07 32 32 36 38  35 33 34 38 00 42 08 08  |6e2.22685348.B..|
00000080  b1 b2 e2 a1 06 10 00 7a  00 8a 01 c4 01 0a 0e 6b  |.......z.......k|
00000090  75 62 65 2d 73 63 68 65  64 75 6c 65 72 12 06 55  |ube-scheduler..U|
000000a0  70 64 61 74 65 1a 16 63  6f 6f 72 64 69 6e 61 74  |pdate..coordinat|
000000b0  69 6f 6e 2e 6b 38 73 2e  69 6f 2f 76 31 22 08 08  |ion.k8s.io/v1"..|
000000c0  b1 b2 e2 a1 06 10 00 32  08 46 69 65 6c 64 73 56  |.......2.FieldsV|
000000d0  31 3a 7c 0a 7a 7b 22 66  3a 73 70 65 63 22 3a 7b  |1:|.z{"f:spec":{|
000000e0  22 66 3a 61 63 71 75 69  72 65 54 69 6d 65 22 3a  |"f:acquireTime":|
000000f0  7b 7d 2c 22 66 3a 68 6f  6c 64 65 72 49 64 65 6e  |{},"f:holderIden|
00000100  74 69 74 79 22 3a 7b 7d  2c 22 66 3a 6c 65 61 73  |tity":{},"f:leas|
00000110  65 44 75 72 61 74 69 6f  6e 53 65 63 6f 6e 64 73  |eDurationSeconds|
00000120  22 3a 7b 7d 2c 22 66 3a  6c 65 61 73 65 54 72 61  |":{},"f:leaseTra|
00000130  6e 73 69 74 69 6f 6e 73  22 3a 7b 7d 2c 22 66 3a  |nsitions":{},"f:|
00000140  72 65 6e 65 77 54 69 6d  65 22 3a 7b 7d 7d 7d 42  |renewTime":{}}}B|
00000150  00 12 59 0a 37 6b 69 6e  64 2d 63 6f 6e 74 72 6f  |..Y.7kind-contro|
00000160  6c 2d 70 6c 61 6e 65 5f  30 64 32 66 61 66 39 33  |l-plane_0d2faf93|
00000170  2d 34 61 30 62 2d 34 66  32 38 2d 38 33 64 33 2d  |-4a0b-4f28-83d3-|
00000180  35 62 35 62 62 66 61 31  65 36 31 30 10 0f 1a 0c  |5b5bbfa1e610....|
00000190  08 f7 a5 86 a2 06 10 b9  84 b7 94 03 22 0c 08 fa  |............"...|
000001a0  ec bd a2 06 10 ee 98 ad  d2 01 28 0a 1a 00 22 00  |..........(...".|
I0501 08:21:14.454558       1 leaderelection.go:278] successfully renewed lease kube-system/kube-scheduler
I0501 08:21:16.413509       1 eventhandlers.go:116] "Add event for unscheduled pod" pod="default/nginx-deployment-66f58bff7c-x8rw9"
I0501 08:21:16.413705       1 scheduling_queue.go:956] "About to try and schedule pod" pod="default/nginx-deployment-66f58bff7c-x8rw9"
I0501 08:21:16.413743       1 schedule_one.go:84] "Attempting to schedule pod" pod="default/nginx-deployment-66f58bff7c-x8rw9"
I0501 08:21:16.414586       1 resource_allocation.go:70] "Listing internal info for allocatable resources, requested resources and score" pod="default/nginx-deployment-66f58bff7c-x8rw9" node="kind-worker" resourceAllocationScorer="LeastAllocated" allocatableResource=map[cpu:8000 memory:8362762240] requestedResource=map[cpu:600 memory:681574400] resourceScore=91
I0501 08:21:16.414685       1 resource_allocation.go:70] "Listing internal info for allocatable resources, requested resources and score" pod="default/nginx-deployment-66f58bff7c-x8rw9" node="kind-worker" resourceAllocationScorer="NodeResourcesBalancedAllocation" allocatableResource=map[cpu:8000 memory:8362762240] requestedResource=map[cpu:500 memory:52428800] resourceScore=97
I0501 08:21:16.414742       1 resource_allocation.go:70] "Listing internal info for allocatable resources, requested resources and score" pod="default/nginx-deployment-66f58bff7c-x8rw9" node="kind-worker3" resourceAllocationScorer="LeastAllocated" allocatableResource=map[cpu:8000 memory:8362762240] requestedResource=map[cpu:400 memory:471859200] resourceScore=94
I0501 08:21:16.414794       1 resource_allocation.go:70] "Listing internal info for allocatable resources, requested resources and score" pod="default/nginx-deployment-66f58bff7c-x8rw9" node="kind-worker3" resourceAllocationScorer="NodeResourcesBalancedAllocation" allocatableResource=map[cpu:8000 memory:8362762240] requestedResource=map[cpu:300 memory:52428800] resourceScore=98
I0501 08:21:16.419271       1 resource_allocation.go:70] "Listing internal info for allocatable resources, requested resources and score" pod="default/nginx-deployment-66f58bff7c-x8rw9" node="kind-worker2" resourceAllocationScorer="LeastAllocated" allocatableResource=map[cpu:8000 memory:8362762240] requestedResource=map[cpu:500 memory:681574400] resourceScore=92
I0501 08:21:16.419344       1 resource_allocation.go:70] "Listing internal info for allocatable resources, requested resources and score" pod="default/nginx-deployment-66f58bff7c-x8rw9" node="kind-worker2" resourceAllocationScorer="NodeResourcesBalancedAllocation" allocatableResource=map[cpu:8000 memory:8362762240] requestedResource=map[cpu:400 memory:262144000] resourceScore=99
I0501 08:21:16.419657       1 schedule_one.go:645] "Plugin scored node for pod" pod="default/nginx-deployment-66f58bff7c-x8rw9" plugin="NodeAffinity" node="kind-worker" score=0
I0501 08:21:16.419718       1 schedule_one.go:645] "Plugin scored node for pod" pod="default/nginx-deployment-66f58bff7c-x8rw9" plugin="NodeAffinity" node="kind-worker3" score=0
I0501 08:21:16.419750       1 schedule_one.go:645] "Plugin scored node for pod" pod="default/nginx-deployment-66f58bff7c-x8rw9" plugin="NodeAffinity" node="kind-worker2" score=0
I0501 08:21:16.419772       1 schedule_one.go:645] "Plugin scored node for pod" pod="default/nginx-deployment-66f58bff7c-x8rw9" plugin="NodeResourcesFit" node="kind-worker" score=91
I0501 08:21:16.419854       1 schedule_one.go:645] "Plugin scored node for pod" pod="default/nginx-deployment-66f58bff7c-x8rw9" plugin="NodeResourcesFit" node="kind-worker3" score=94
I0501 08:21:16.419945       1 schedule_one.go:645] "Plugin scored node for pod" pod="default/nginx-deployment-66f58bff7c-x8rw9" plugin="NodeResourcesFit" node="kind-worker2" score=92
I0501 08:21:16.419972       1 schedule_one.go:645] "Plugin scored node for pod" pod="default/nginx-deployment-66f58bff7c-x8rw9" plugin="VolumeBinding" node="kind-worker" score=0
I0501 08:21:16.420038       1 schedule_one.go:645] "Plugin scored node for pod" pod="default/nginx-deployment-66f58bff7c-x8rw9" plugin="VolumeBinding" node="kind-worker3" score=0
I0501 08:21:16.420063       1 schedule_one.go:645] "Plugin scored node for pod" pod="default/nginx-deployment-66f58bff7c-x8rw9" plugin="VolumeBinding" node="kind-worker2" score=0
I0501 08:21:16.420131       1 schedule_one.go:645] "Plugin scored node for pod" pod="default/nginx-deployment-66f58bff7c-x8rw9" plugin="PodTopologySpread" node="kind-worker" score=100
I0501 08:21:16.420166       1 schedule_one.go:645] "Plugin scored node for pod" pod="default/nginx-deployment-66f58bff7c-x8rw9" plugin="PodTopologySpread" node="kind-worker3" score=200
I0501 08:21:16.420277       1 schedule_one.go:645] "Plugin scored node for pod" pod="default/nginx-deployment-66f58bff7c-x8rw9" plugin="PodTopologySpread" node="kind-worker2" score=200
I0501 08:21:16.420306       1 schedule_one.go:645] "Plugin scored node for pod" pod="default/nginx-deployment-66f58bff7c-x8rw9" plugin="InterPodAffinity" node="kind-worker" score=0
I0501 08:21:16.420380       1 schedule_one.go:645] "Plugin scored node for pod" pod="default/nginx-deployment-66f58bff7c-x8rw9" plugin="InterPodAffinity" node="kind-worker3" score=0
I0501 08:21:16.420445       1 schedule_one.go:645] "Plugin scored node for pod" pod="default/nginx-deployment-66f58bff7c-x8rw9" plugin="InterPodAffinity" node="kind-worker2" score=0
I0501 08:21:16.420486       1 schedule_one.go:645] "Plugin scored node for pod" pod="default/nginx-deployment-66f58bff7c-x8rw9" plugin="NodeResourcesBalancedAllocation" node="kind-worker" score=97
I0501 08:21:16.420553       1 schedule_one.go:645] "Plugin scored node for pod" pod="default/nginx-deployment-66f58bff7c-x8rw9" plugin="NodeResourcesBalancedAllocation" node="kind-worker3" score=98
I0501 08:21:16.420625       1 schedule_one.go:645] "Plugin scored node for pod" pod="default/nginx-deployment-66f58bff7c-x8rw9" plugin="NodeResourcesBalancedAllocation" node="kind-worker2" score=99
I0501 08:21:16.420663       1 schedule_one.go:645] "Plugin scored node for pod" pod="default/nginx-deployment-66f58bff7c-x8rw9" plugin="ImageLocality" node="kind-worker" score=0
I0501 08:21:16.420762       1 schedule_one.go:645] "Plugin scored node for pod" pod="default/nginx-deployment-66f58bff7c-x8rw9" plugin="ImageLocality" node="kind-worker3" score=0
I0501 08:21:16.420796       1 schedule_one.go:645] "Plugin scored node for pod" pod="default/nginx-deployment-66f58bff7c-x8rw9" plugin="ImageLocality" node="kind-worker2" score=0
I0501 08:21:16.420867       1 schedule_one.go:645] "Plugin scored node for pod" pod="default/nginx-deployment-66f58bff7c-x8rw9" plugin="TaintToleration" node="kind-worker" score=300
I0501 08:21:16.420892       1 schedule_one.go:645] "Plugin scored node for pod" pod="default/nginx-deployment-66f58bff7c-x8rw9" plugin="TaintToleration" node="kind-worker3" score=300
I0501 08:21:16.420973       1 schedule_one.go:645] "Plugin scored node for pod" pod="default/nginx-deployment-66f58bff7c-x8rw9" plugin="TaintToleration" node="kind-worker2" score=300
I0501 08:21:16.421160       1 schedule_one.go:703] "Calculated node's final score for pod" pod="default/nginx-deployment-66f58bff7c-x8rw9" node="kind-worker" score=588
I0501 08:21:16.421188       1 schedule_one.go:703] "Calculated node's final score for pod" pod="default/nginx-deployment-66f58bff7c-x8rw9" node="kind-worker3" score=692
I0501 08:21:16.421210       1 schedule_one.go:703] "Calculated node's final score for pod" pod="default/nginx-deployment-66f58bff7c-x8rw9" node="kind-worker2" score=691
I0501 08:21:16.421368       1 default_binder.go:52] "Attempting to bind pod to node" pod="default/nginx-deployment-66f58bff7c-x8rw9" node="kind-worker3"
I0501 08:21:16.421420       1 eventhandlers.go:116] "Add event for unscheduled pod" pod="default/nginx-deployment-66f58bff7c-l7r5r"
I0501 08:21:16.421491       1 request.go:1152] Request Body:
00000000  6b 38 73 00 0a 0d 0a 02  76 31 12 07 42 69 6e 64  |k8s.....v1..Bind|
00000010  69 6e 67 12 80 01 0a 5e  0a 21 6e 67 69 6e 78 2d  |ing....^.!nginx-|
00000020  64 65 70 6c 6f 79 6d 65  6e 74 2d 36 36 66 35 38  |deployment-66f58|
00000030  62 66 66 37 63 2d 78 38  72 77 39 12 00 1a 07 64  |bff7c-x8rw9....d|
00000040  65 66 61 75 6c 74 22 00  2a 24 34 62 38 35 30 38  |efault".*$4b8508|
00000050  65 33 2d 33 61 66 62 2d  34 64 32 65 2d 61 34 66  |e3-3afb-4d2e-a4f|
00000060  63 2d 37 61 65 36 31 65  38 37 38 33 65 61 32 00  |c-7ae61e8783ea2.|
00000070  38 00 42 00 7a 00 12 1e  0a 04 4e 6f 64 65 12 00  |8.B.z.....Node..|
00000080  1a 0c 6b 69 6e 64 2d 77  6f 72 6b 65 72 33 22 00  |..kind-worker3".|
00000090  2a 00 32 00 3a 00 1a 00  22 00                    |*.2.:...".|
I0501 08:21:16.421629       1 round_trippers.go:466] curl -v -XPOST  -H "Content-Type: application/vnd.kubernetes.protobuf" -H "Accept: application/vnd.kubernetes.protobuf, */*" -H "User-Agent: kube-scheduler/v1.24.7 (linux/amd64) kubernetes/e6f3597/scheduler" 'https://172.18.0.2:6443/api/v1/namespaces/default/pods/nginx-deployment-66f58bff7c-x8rw9/binding'
I0501 08:21:16.421498       1 scheduling_queue.go:956] "About to try and schedule pod" pod="default/nginx-deployment-66f58bff7c-l7r5r"
I0501 08:21:16.421687       1 schedule_one.go:84] "Attempting to schedule pod" pod="default/nginx-deployment-66f58bff7c-l7r5r"
I0501 08:21:16.422121       1 resource_allocation.go:70] "Listing internal info for allocatable resources, requested resources and score" pod="default/nginx-deployment-66f58bff7c-l7r5r" node="kind-worker" resourceAllocationScorer="LeastAllocated" allocatableResource=map[cpu:8000 memory:8362762240] requestedResource=map[cpu:600 memory:681574400] resourceScore=91
I0501 08:21:16.422178       1 resource_allocation.go:70] "Listing internal info for allocatable resources, requested resources and score" pod="default/nginx-deployment-66f58bff7c-l7r5r" node="kind-worker" resourceAllocationScorer="NodeResourcesBalancedAllocation" allocatableResource=map[cpu:8000 memory:8362762240] requestedResource=map[cpu:500 memory:52428800] resourceScore=97
I0501 08:21:16.422222       1 resource_allocation.go:70] "Listing internal info for allocatable resources, requested resources and score" pod="default/nginx-deployment-66f58bff7c-l7r5r" node="kind-worker3" resourceAllocationScorer="LeastAllocated" allocatableResource=map[cpu:8000 memory:8362762240] requestedResource=map[cpu:600 memory:681574400] resourceScore=91
I0501 08:21:16.422263       1 resource_allocation.go:70] "Listing internal info for allocatable resources, requested resources and score" pod="default/nginx-deployment-66f58bff7c-l7r5r" node="kind-worker3" resourceAllocationScorer="NodeResourcesBalancedAllocation" allocatableResource=map[cpu:8000 memory:8362762240] requestedResource=map[cpu:500 memory:52428800] resourceScore=97
I0501 08:21:16.422316       1 resource_allocation.go:70] "Listing internal info for allocatable resources, requested resources and score" pod="default/nginx-deployment-66f58bff7c-l7r5r" node="kind-worker2" resourceAllocationScorer="LeastAllocated" allocatableResource=map[cpu:8000 memory:8362762240] requestedResource=map[cpu:500 memory:681574400] resourceScore=92
I0501 08:21:16.422367       1 resource_allocation.go:70] "Listing internal info for allocatable resources, requested resources and score" pod="default/nginx-deployment-66f58bff7c-l7r5r" node="kind-worker2" resourceAllocationScorer="NodeResourcesBalancedAllocation" allocatableResource=map[cpu:8000 memory:8362762240] requestedResource=map[cpu:400 memory:262144000] resourceScore=99
I0501 08:21:16.422470       1 schedule_one.go:645] "Plugin scored node for pod" pod="default/nginx-deployment-66f58bff7c-l7r5r" plugin="VolumeBinding" node="kind-worker" score=0
I0501 08:21:16.422497       1 schedule_one.go:645] "Plugin scored node for pod" pod="default/nginx-deployment-66f58bff7c-l7r5r" plugin="VolumeBinding" node="kind-worker3" score=0
I0501 08:21:16.422516       1 schedule_one.go:645] "Plugin scored node for pod" pod="default/nginx-deployment-66f58bff7c-l7r5r" plugin="VolumeBinding" node="kind-worker2" score=0
I0501 08:21:16.422535       1 schedule_one.go:645] "Plugin scored node for pod" pod="default/nginx-deployment-66f58bff7c-l7r5r" plugin="PodTopologySpread" node="kind-worker" score=100
I0501 08:21:16.422554       1 schedule_one.go:645] "Plugin scored node for pod" pod="default/nginx-deployment-66f58bff7c-l7r5r" plugin="PodTopologySpread" node="kind-worker3" score=100
I0501 08:21:16.422572       1 schedule_one.go:645] "Plugin scored node for pod" pod="default/nginx-deployment-66f58bff7c-l7r5r" plugin="PodTopologySpread" node="kind-worker2" score=200
I0501 08:21:16.422590       1 schedule_one.go:645] "Plugin scored node for pod" pod="default/nginx-deployment-66f58bff7c-l7r5r" plugin="InterPodAffinity" node="kind-worker" score=0
I0501 08:21:16.422608       1 schedule_one.go:645] "Plugin scored node for pod" pod="default/nginx-deployment-66f58bff7c-l7r5r" plugin="InterPodAffinity" node="kind-worker3" score=0
I0501 08:21:16.422641       1 schedule_one.go:645] "Plugin scored node for pod" pod="default/nginx-deployment-66f58bff7c-l7r5r" plugin="InterPodAffinity" node="kind-worker2" score=0
I0501 08:21:16.422662       1 schedule_one.go:645] "Plugin scored node for pod" pod="default/nginx-deployment-66f58bff7c-l7r5r" plugin="NodeResourcesBalancedAllocation" node="kind-worker" score=97
I0501 08:21:16.422682       1 schedule_one.go:645] "Plugin scored node for pod" pod="default/nginx-deployment-66f58bff7c-l7r5r" plugin="NodeResourcesBalancedAllocation" node="kind-worker3" score=97
I0501 08:21:16.422702       1 schedule_one.go:645] "Plugin scored node for pod" pod="default/nginx-deployment-66f58bff7c-l7r5r" plugin="NodeResourcesBalancedAllocation" node="kind-worker2" score=99
I0501 08:21:16.422723       1 schedule_one.go:645] "Plugin scored node for pod" pod="default/nginx-deployment-66f58bff7c-l7r5r" plugin="ImageLocality" node="kind-worker" score=0
I0501 08:21:16.422744       1 schedule_one.go:645] "Plugin scored node for pod" pod="default/nginx-deployment-66f58bff7c-l7r5r" plugin="ImageLocality" node="kind-worker3" score=0
I0501 08:21:16.422763       1 schedule_one.go:645] "Plugin scored node for pod" pod="default/nginx-deployment-66f58bff7c-l7r5r" plugin="ImageLocality" node="kind-worker2" score=0
I0501 08:21:16.422782       1 schedule_one.go:645] "Plugin scored node for pod" pod="default/nginx-deployment-66f58bff7c-l7r5r" plugin="TaintToleration" node="kind-worker" score=300
I0501 08:21:16.422803       1 schedule_one.go:645] "Plugin scored node for pod" pod="default/nginx-deployment-66f58bff7c-l7r5r" plugin="TaintToleration" node="kind-worker3" score=300
I0501 08:21:16.422825       1 schedule_one.go:645] "Plugin scored node for pod" pod="default/nginx-deployment-66f58bff7c-l7r5r" plugin="TaintToleration" node="kind-worker2" score=300
I0501 08:21:16.422845       1 schedule_one.go:645] "Plugin scored node for pod" pod="default/nginx-deployment-66f58bff7c-l7r5r" plugin="NodeAffinity" node="kind-worker" score=0
I0501 08:21:16.422868       1 schedule_one.go:645] "Plugin scored node for pod" pod="default/nginx-deployment-66f58bff7c-l7r5r" plugin="NodeAffinity" node="kind-worker3" score=0
I0501 08:21:16.422889       1 schedule_one.go:645] "Plugin scored node for pod" pod="default/nginx-deployment-66f58bff7c-l7r5r" plugin="NodeAffinity" node="kind-worker2" score=0
I0501 08:21:16.422908       1 schedule_one.go:645] "Plugin scored node for pod" pod="default/nginx-deployment-66f58bff7c-l7r5r" plugin="NodeResourcesFit" node="kind-worker" score=91
I0501 08:21:16.422927       1 schedule_one.go:645] "Plugin scored node for pod" pod="default/nginx-deployment-66f58bff7c-l7r5r" plugin="NodeResourcesFit" node="kind-worker3" score=91
I0501 08:21:16.422946       1 schedule_one.go:645] "Plugin scored node for pod" pod="default/nginx-deployment-66f58bff7c-l7r5r" plugin="NodeResourcesFit" node="kind-worker2" score=92
I0501 08:21:16.422969       1 schedule_one.go:703] "Calculated node's final score for pod" pod="default/nginx-deployment-66f58bff7c-l7r5r" node="kind-worker" score=588
I0501 08:21:16.422989       1 schedule_one.go:703] "Calculated node's final score for pod" pod="default/nginx-deployment-66f58bff7c-l7r5r" node="kind-worker3" score=588
I0501 08:21:16.423009       1 schedule_one.go:703] "Calculated node's final score for pod" pod="default/nginx-deployment-66f58bff7c-l7r5r" node="kind-worker2" score=691
I0501 08:21:16.423211       1 default_binder.go:52] "Attempting to bind pod to node" pod="default/nginx-deployment-66f58bff7c-l7r5r" node="kind-worker2"
I0501 08:21:16.423319       1 request.go:1152] Request Body:
00000000  6b 38 73 00 0a 0d 0a 02  76 31 12 07 42 69 6e 64  |k8s.....v1..Bind|
00000010  69 6e 67 12 80 01 0a 5e  0a 21 6e 67 69 6e 78 2d  |ing....^.!nginx-|
00000020  64 65 70 6c 6f 79 6d 65  6e 74 2d 36 36 66 35 38  |deployment-66f58|
00000030  62 66 66 37 63 2d 6c 37  72 35 72 12 00 1a 07 64  |bff7c-l7r5r....d|
00000040  65 66 61 75 6c 74 22 00  2a 24 33 63 65 38 35 62  |efault".*$3ce85b|
00000050  64 61 2d 39 34 62 37 2d  34 63 33 37 2d 39 36 33  |da-94b7-4c37-963|
00000060  39 2d 62 62 66 31 31 34  30 37 30 66 61 33 32 00  |9-bbf114070fa32.|
00000070  38 00 42 00 7a 00 12 1e  0a 04 4e 6f 64 65 12 00  |8.B.z.....Node..|
00000080  1a 0c 6b 69 6e 64 2d 77  6f 72 6b 65 72 32 22 00  |..kind-worker2".|
00000090  2a 00 32 00 3a 00 1a 00  22 00                    |*.2.:...".|
I0501 08:21:16.423427       1 round_trippers.go:466] curl -v -XPOST  -H "Accept: application/vnd.kubernetes.protobuf, */*" -H "Content-Type: application/vnd.kubernetes.protobuf" -H "User-Agent: kube-scheduler/v1.24.7 (linux/amd64) kubernetes/e6f3597/scheduler" 'https://172.18.0.2:6443/api/v1/namespaces/default/pods/nginx-deployment-66f58bff7c-l7r5r/binding'
I0501 08:21:16.432792       1 eventhandlers.go:116] "Add event for unscheduled pod" pod="default/nginx-deployment-66f58bff7c-zr9m5"
I0501 08:21:16.432922       1 scheduling_queue.go:956] "About to try and schedule pod" pod="default/nginx-deployment-66f58bff7c-zr9m5"
I0501 08:21:16.432957       1 schedule_one.go:84] "Attempting to schedule pod" pod="default/nginx-deployment-66f58bff7c-zr9m5"
I0501 08:21:16.433724       1 resource_allocation.go:70] "Listing internal info for allocatable resources, requested resources and score" pod="default/nginx-deployment-66f58bff7c-zr9m5" node="kind-worker" resourceAllocationScorer="LeastAllocated" allocatableResource=map[cpu:8000 memory:8362762240] requestedResource=map[cpu:600 memory:681574400] resourceScore=91
I0501 08:21:16.433810       1 resource_allocation.go:70] "Listing internal info for allocatable resources, requested resources and score" pod="default/nginx-deployment-66f58bff7c-zr9m5" node="kind-worker" resourceAllocationScorer="NodeResourcesBalancedAllocation" allocatableResource=map[cpu:8000 memory:8362762240] requestedResource=map[cpu:500 memory:52428800] resourceScore=97
I0501 08:21:16.433859       1 resource_allocation.go:70] "Listing internal info for allocatable resources, requested resources and score" pod="default/nginx-deployment-66f58bff7c-zr9m5" node="kind-worker3" resourceAllocationScorer="LeastAllocated" allocatableResource=map[cpu:8000 memory:8362762240] requestedResource=map[cpu:600 memory:681574400] resourceScore=91
I0501 08:21:16.433912       1 resource_allocation.go:70] "Listing internal info for allocatable resources, requested resources and score" pod="default/nginx-deployment-66f58bff7c-zr9m5" node="kind-worker3" resourceAllocationScorer="NodeResourcesBalancedAllocation" allocatableResource=map[cpu:8000 memory:8362762240] requestedResource=map[cpu:500 memory:52428800] resourceScore=97
I0501 08:21:16.434025       1 resource_allocation.go:70] "Listing internal info for allocatable resources, requested resources and score" pod="default/nginx-deployment-66f58bff7c-zr9m5" node="kind-worker2" resourceAllocationScorer="LeastAllocated" allocatableResource=map[cpu:8000 memory:8362762240] requestedResource=map[cpu:700 memory:891289600] resourceScore=90
I0501 08:21:16.434081       1 resource_allocation.go:70] "Listing internal info for allocatable resources, requested resources and score" pod="default/nginx-deployment-66f58bff7c-zr9m5" node="kind-worker2" resourceAllocationScorer="NodeResourcesBalancedAllocation" allocatableResource=map[cpu:8000 memory:8362762240] requestedResource=map[cpu:600 memory:262144000] resourceScore=97
I0501 08:21:16.435419       1 schedule_one.go:645] "Plugin scored node for pod" pod="default/nginx-deployment-66f58bff7c-zr9m5" plugin="TaintToleration" node="kind-worker" score=300
I0501 08:21:16.435593       1 schedule_one.go:645] "Plugin scored node for pod" pod="default/nginx-deployment-66f58bff7c-zr9m5" plugin="TaintToleration" node="kind-worker3" score=300
I0501 08:21:16.435635       1 schedule_one.go:645] "Plugin scored node for pod" pod="default/nginx-deployment-66f58bff7c-zr9m5" plugin="TaintToleration" node="kind-worker2" score=300
I0501 08:21:16.436724       1 schedule_one.go:645] "Plugin scored node for pod" pod="default/nginx-deployment-66f58bff7c-zr9m5" plugin="NodeAffinity" node="kind-worker" score=0
I0501 08:21:16.436765       1 schedule_one.go:645] "Plugin scored node for pod" pod="default/nginx-deployment-66f58bff7c-zr9m5" plugin="NodeAffinity" node="kind-worker3" score=0
I0501 08:21:16.436964       1 schedule_one.go:645] "Plugin scored node for pod" pod="default/nginx-deployment-66f58bff7c-zr9m5" plugin="NodeAffinity" node="kind-worker2" score=0
I0501 08:21:16.437004       1 schedule_one.go:645] "Plugin scored node for pod" pod="default/nginx-deployment-66f58bff7c-zr9m5" plugin="NodeResourcesFit" node="kind-worker" score=91
I0501 08:21:16.437087       1 schedule_one.go:645] "Plugin scored node for pod" pod="default/nginx-deployment-66f58bff7c-zr9m5" plugin="NodeResourcesFit" node="kind-worker3" score=91
I0501 08:21:16.437110       1 schedule_one.go:645] "Plugin scored node for pod" pod="default/nginx-deployment-66f58bff7c-zr9m5" plugin="NodeResourcesFit" node="kind-worker2" score=90
I0501 08:21:16.437216       1 schedule_one.go:645] "Plugin scored node for pod" pod="default/nginx-deployment-66f58bff7c-zr9m5" plugin="VolumeBinding" node="kind-worker" score=0
I0501 08:21:16.437248       1 schedule_one.go:645] "Plugin scored node for pod" pod="default/nginx-deployment-66f58bff7c-zr9m5" plugin="VolumeBinding" node="kind-worker3" score=0
I0501 08:21:16.437308       1 schedule_one.go:645] "Plugin scored node for pod" pod="default/nginx-deployment-66f58bff7c-zr9m5" plugin="VolumeBinding" node="kind-worker2" score=0
I0501 08:21:16.437380       1 schedule_one.go:645] "Plugin scored node for pod" pod="default/nginx-deployment-66f58bff7c-zr9m5" plugin="PodTopologySpread" node="kind-worker" score=200
I0501 08:21:16.437412       1 schedule_one.go:645] "Plugin scored node for pod" pod="default/nginx-deployment-66f58bff7c-zr9m5" plugin="PodTopologySpread" node="kind-worker3" score=200
I0501 08:21:16.437475       1 schedule_one.go:645] "Plugin scored node for pod" pod="default/nginx-deployment-66f58bff7c-zr9m5" plugin="PodTopologySpread" node="kind-worker2" score=200
I0501 08:21:16.437546       1 schedule_one.go:645] "Plugin scored node for pod" pod="default/nginx-deployment-66f58bff7c-zr9m5" plugin="InterPodAffinity" node="kind-worker" score=0
I0501 08:21:16.437572       1 schedule_one.go:645] "Plugin scored node for pod" pod="default/nginx-deployment-66f58bff7c-zr9m5" plugin="InterPodAffinity" node="kind-worker3" score=0
I0501 08:21:16.437649       1 schedule_one.go:645] "Plugin scored node for pod" pod="default/nginx-deployment-66f58bff7c-zr9m5" plugin="InterPodAffinity" node="kind-worker2" score=0
I0501 08:21:16.437683       1 schedule_one.go:645] "Plugin scored node for pod" pod="default/nginx-deployment-66f58bff7c-zr9m5" plugin="NodeResourcesBalancedAllocation" node="kind-worker" score=97
I0501 08:21:16.437757       1 schedule_one.go:645] "Plugin scored node for pod" pod="default/nginx-deployment-66f58bff7c-zr9m5" plugin="NodeResourcesBalancedAllocation" node="kind-worker3" score=97
I0501 08:21:16.437852       1 schedule_one.go:645] "Plugin scored node for pod" pod="default/nginx-deployment-66f58bff7c-zr9m5" plugin="NodeResourcesBalancedAllocation" node="kind-worker2" score=97
I0501 08:21:16.437886       1 schedule_one.go:645] "Plugin scored node for pod" pod="default/nginx-deployment-66f58bff7c-zr9m5" plugin="ImageLocality" node="kind-worker" score=0
I0501 08:21:16.437955       1 schedule_one.go:645] "Plugin scored node for pod" pod="default/nginx-deployment-66f58bff7c-zr9m5" plugin="ImageLocality" node="kind-worker3" score=0
I0501 08:21:16.438021       1 schedule_one.go:645] "Plugin scored node for pod" pod="default/nginx-deployment-66f58bff7c-zr9m5" plugin="ImageLocality" node="kind-worker2" score=0
I0501 08:21:16.438099       1 schedule_one.go:703] "Calculated node's final score for pod" pod="default/nginx-deployment-66f58bff7c-zr9m5" node="kind-worker" score=688
I0501 08:21:16.438130       1 schedule_one.go:703] "Calculated node's final score for pod" pod="default/nginx-deployment-66f58bff7c-zr9m5" node="kind-worker3" score=688
I0501 08:21:16.438233       1 schedule_one.go:703] "Calculated node's final score for pod" pod="default/nginx-deployment-66f58bff7c-zr9m5" node="kind-worker2" score=687
I0501 08:21:16.435643       1 round_trippers.go:553] POST https://172.18.0.2:6443/api/v1/namespaces/default/pods/nginx-deployment-66f58bff7c-l7r5r/binding 201 Created in 12 milliseconds
I0501 08:21:16.439982       1 round_trippers.go:570] HTTP Statistics: GetConnection 0 ms ServerProcessing 11 ms Duration 12 ms
I0501 08:21:16.440005       1 round_trippers.go:577] Response Headers:
I0501 08:21:16.440066       1 round_trippers.go:580]     X-Kubernetes-Pf-Flowschema-Uid: 8a935dea-6b5d-4402-a842-ba69f911704f
I0501 08:21:16.440097       1 round_trippers.go:580]     X-Kubernetes-Pf-Prioritylevel-Uid: 4ccc4fdb-4419-4777-8b6f-3ed0d4949e5d
I0501 08:21:16.440162       1 round_trippers.go:580]     Content-Length: 48
I0501 08:21:16.440192       1 round_trippers.go:580]     Date: Mon, 01 May 2023 08:21:16 GMT
I0501 08:21:16.440247       1 round_trippers.go:580]     Audit-Id: 8a793cf1-40fd-4acb-bb52-9118a71c31bd
I0501 08:21:16.440276       1 round_trippers.go:580]     Cache-Control: no-cache, private
I0501 08:21:16.440292       1 round_trippers.go:580]     Content-Type: application/vnd.kubernetes.protobuf
I0501 08:21:16.440442       1 request.go:1152] Response Body:
00000000  6b 38 73 00 0a 0c 0a 02  76 31 12 06 53 74 61 74  |k8s.....v1..Stat|
00000010  75 73 12 18 0a 06 0a 00  12 00 1a 00 12 07 53 75  |us............Su|
00000020  63 63 65 73 73 1a 00 22  00 30 c9 01 1a 00 22 00  |ccess..".0....".|
I0501 08:21:16.440544       1 cache.go:379] "Finished binding for pod, can be expired" pod="default/nginx-deployment-66f58bff7c-l7r5r"
I0501 08:21:16.440606       1 schedule_one.go:265] "Successfully bound pod to node" pod="default/nginx-deployment-66f58bff7c-l7r5r" node="kind-worker2" evaluatedNodes=4 feasibleNodes=3
I0501 08:21:16.440873       1 request.go:1152] Request Body:
00000000  6b 38 73 00 0a 19 0a 10  65 76 65 6e 74 73 2e 6b  |k8s.....events.k|
00000010  38 73 2e 69 6f 2f 76 31  12 05 45 76 65 6e 74 12  |8s.io/v1..Event.|
00000020  f5 02 0a 4b 0a 32 6e 67  69 6e 78 2d 64 65 70 6c  |...K.2nginx-depl|
00000030  6f 79 6d 65 6e 74 2d 36  36 66 35 38 62 66 66 37  |oyment-66f58bff7|
00000040  63 2d 6c 37 72 35 72 2e  31 37 35 61 66 37 34 32  |c-l7r5r.175af742|
00000050  61 38 35 38 39 63 36 33  12 00 1a 07 64 65 66 61  |a8589c63....defa|
00000060  75 6c 74 22 00 2a 00 32  00 38 00 42 00 7a 00 12  |ult".*.2.8.B.z..|
00000070  0c 08 fc ec bd a2 06 10  9c bb 8a d2 01 22 11 64  |.............".d|
00000080  65 66 61 75 6c 74 2d 73  63 68 65 64 75 6c 65 72  |efault-scheduler|
00000090  2a 24 64 65 66 61 75 6c  74 2d 73 63 68 65 64 75  |*$default-schedu|
000000a0  6c 65 72 2d 6b 69 6e 64  2d 63 6f 6e 74 72 6f 6c  |ler-kind-control|
000000b0  2d 70 6c 61 6e 65 32 07  42 69 6e 64 69 6e 67 3a  |-plane2.Binding:|
000000c0  09 53 63 68 65 64 75 6c  65 64 42 66 0a 03 50 6f  |.ScheduledBf..Po|
000000d0  64 12 07 64 65 66 61 75  6c 74 1a 21 6e 67 69 6e  |d..default.!ngin|
000000e0  78 2d 64 65 70 6c 6f 79  6d 65 6e 74 2d 36 36 66  |x-deployment-66f|
000000f0  35 38 62 66 66 37 63 2d  6c 37 72 35 72 22 24 33  |58bff7c-l7r5r"$3|
00000100  63 65 38 35 62 64 61 2d  39 34 62 37 2d 34 63 33  |ce85bda-94b7-4c3|
00000110  37 2d 39 36 33 39 2d 62  62 66 31 31 34 30 37 30  |7-9639-bbf114070|
00000120  66 61 33 2a 02 76 31 32  07 32 32 36 38 35 34 35  |fa3*.v12.2268545|
00000130  3a 00 52 4f 53 75 63 63  65 73 73 66 75 6c 6c 79  |:.ROSuccessfully|
00000140  20 61 73 73 69 67 6e 65  64 20 64 65 66 61 75 6c  | assigned defaul|
00000150  74 2f 6e 67 69 6e 78 2d  64 65 70 6c 6f 79 6d 65  |t/nginx-deployme|
00000160  6e 74 2d 36 36 66 35 38  62 66 66 37 63 2d 6c 37  |nt-66f58bff7c-l7|
00000170  72 35 72 20 74 6f 20 6b  69 6e 64 2d 77 6f 72 6b  |r5r to kind-work|
00000180  65 72 32 5a 06 4e 6f 72  6d 61 6c 62 04 0a 00 12  |er2Z.Normalb....|
00000190  00 6a 00 72 00 78 00 1a  00 22 00                 |.j.r.x...".|
I0501 08:21:16.441138       1 round_trippers.go:466] curl -v -XPOST  -H "Content-Type: application/vnd.kubernetes.protobuf" -H "User-Agent: kube-scheduler/v1.24.7 (linux/amd64) kubernetes/e6f3597/scheduler" -H "Accept: application/vnd.kubernetes.protobuf, */*" 'https://172.18.0.2:6443/apis/events.k8s.io/v1/namespaces/default/events'
I0501 08:21:16.435672       1 round_trippers.go:553] POST https://172.18.0.2:6443/api/v1/namespaces/default/pods/nginx-deployment-66f58bff7c-x8rw9/binding 201 Created in 14 milliseconds
I0501 08:21:16.441820       1 round_trippers.go:570] HTTP Statistics: GetConnection 0 ms ServerProcessing 13 ms Duration 14 ms
I0501 08:21:16.441896       1 round_trippers.go:577] Response Headers:
I0501 08:21:16.441925       1 round_trippers.go:580]     Cache-Control: no-cache, private
I0501 08:21:16.441989       1 round_trippers.go:580]     Content-Type: application/vnd.kubernetes.protobuf
I0501 08:21:16.442017       1 round_trippers.go:580]     X-Kubernetes-Pf-Flowschema-Uid: 8a935dea-6b5d-4402-a842-ba69f911704f
I0501 08:21:16.442083       1 round_trippers.go:580]     X-Kubernetes-Pf-Prioritylevel-Uid: 4ccc4fdb-4419-4777-8b6f-3ed0d4949e5d
I0501 08:21:16.442112       1 round_trippers.go:580]     Content-Length: 48
I0501 08:21:16.442175       1 round_trippers.go:580]     Date: Mon, 01 May 2023 08:21:16 GMT
I0501 08:21:16.442203       1 round_trippers.go:580]     Audit-Id: b9ff8103-8a7c-4d77-af77-5bfd03aeaca6
I0501 08:21:16.442290       1 request.go:1152] Response Body:
00000000  6b 38 73 00 0a 0c 0a 02  76 31 12 06 53 74 61 74  |k8s.....v1..Stat|
00000010  75 73 12 18 0a 06 0a 00  12 00 1a 00 12 07 53 75  |us............Su|
00000020  63 63 65 73 73 1a 00 22  00 30 c9 01 1a 00 22 00  |ccess..".0....".|
I0501 08:21:16.442402       1 cache.go:379] "Finished binding for pod, can be expired" pod="default/nginx-deployment-66f58bff7c-x8rw9"
I0501 08:21:16.442560       1 schedule_one.go:265] "Successfully bound pod to node" pod="default/nginx-deployment-66f58bff7c-x8rw9" node="kind-worker3" evaluatedNodes=4 feasibleNodes=3
I0501 08:21:16.442783       1 request.go:1152] Request Body:
00000000  6b 38 73 00 0a 19 0a 10  65 76 65 6e 74 73 2e 6b  |k8s.....events.k|
00000010  38 73 2e 69 6f 2f 76 31  12 05 45 76 65 6e 74 12  |8s.io/v1..Event.|
00000020  f5 02 0a 4b 0a 32 6e 67  69 6e 78 2d 64 65 70 6c  |...K.2nginx-depl|
00000030  6f 79 6d 65 6e 74 2d 36  36 66 35 38 62 66 66 37  |oyment-66f58bff7|
00000040  63 2d 78 38 72 77 39 2e  31 37 35 61 66 37 34 32  |c-x8rw9.175af742|
00000050  61 38 37 35 62 32 31 39  12 00 1a 07 64 65 66 61  |a875b219....defa|
00000060  75 6c 74 22 00 2a 00 32  00 38 00 42 00 7a 00 12  |ult".*.2.8.B.z..|
00000070  0c 08 fc ec bd a2 06 10  96 82 ff d2 01 22 11 64  |.............".d|
00000080  65 66 61 75 6c 74 2d 73  63 68 65 64 75 6c 65 72  |efault-scheduler|
00000090  2a 24 64 65 66 61 75 6c  74 2d 73 63 68 65 64 75  |*$default-schedu|
000000a0  6c 65 72 2d 6b 69 6e 64  2d 63 6f 6e 74 72 6f 6c  |ler-kind-control|
000000b0  2d 70 6c 61 6e 65 32 07  42 69 6e 64 69 6e 67 3a  |-plane2.Binding:|
000000c0  09 53 63 68 65 64 75 6c  65 64 42 66 0a 03 50 6f  |.ScheduledBf..Po|
000000d0  64 12 07 64 65 66 61 75  6c 74 1a 21 6e 67 69 6e  |d..default.!ngin|
000000e0  78 2d 64 65 70 6c 6f 79  6d 65 6e 74 2d 36 36 66  |x-deployment-66f|
000000f0  35 38 62 66 66 37 63 2d  78 38 72 77 39 22 24 34  |58bff7c-x8rw9"$4|
00000100  62 38 35 30 38 65 33 2d  33 61 66 62 2d 34 64 32  |b8508e3-3afb-4d2|
00000110  65 2d 61 34 66 63 2d 37  61 65 36 31 65 38 37 38  |e-a4fc-7ae61e878|
00000120  33 65 61 2a 02 76 31 32  07 32 32 36 38 35 34 31  |3ea*.v12.2268541|
00000130  3a 00 52 4f 53 75 63 63  65 73 73 66 75 6c 6c 79  |:.ROSuccessfully|
00000140  20 61 73 73 69 67 6e 65  64 20 64 65 66 61 75 6c  | assigned defaul|
00000150  74 2f 6e 67 69 6e 78 2d  64 65 70 6c 6f 79 6d 65  |t/nginx-deployme|
00000160  6e 74 2d 36 36 66 35 38  62 66 66 37 63 2d 78 38  |nt-66f58bff7c-x8|
00000170  72 77 39 20 74 6f 20 6b  69 6e 64 2d 77 6f 72 6b  |rw9 to kind-work|
00000180  65 72 33 5a 06 4e 6f 72  6d 61 6c 62 04 0a 00 12  |er3Z.Normalb....|
00000190  00 6a 00 72 00 78 00 1a  00 22 00                 |.j.r.x...".|
I0501 08:21:16.443067       1 round_trippers.go:466] curl -v -XPOST  -H "Content-Type: application/vnd.kubernetes.protobuf" -H "User-Agent: kube-scheduler/v1.24.7 (linux/amd64) kubernetes/e6f3597/scheduler" -H "Accept: application/vnd.kubernetes.protobuf, */*" 'https://172.18.0.2:6443/apis/events.k8s.io/v1/namespaces/default/events'
I0501 08:21:16.436419       1 eventhandlers.go:159] "Delete event for unscheduled pod" pod="default/nginx-deployment-66f58bff7c-x8rw9"
I0501 08:21:16.443555       1 eventhandlers.go:159] "Delete event for unscheduled pod" pod="default/nginx-deployment-66f58bff7c-l7r5r"
I0501 08:21:16.444073       1 default_binder.go:52] "Attempting to bind pod to node" pod="default/nginx-deployment-66f58bff7c-zr9m5" node="kind-worker3"
I0501 08:21:16.444195       1 request.go:1152] Request Body:
00000000  6b 38 73 00 0a 0d 0a 02  76 31 12 07 42 69 6e 64  |k8s.....v1..Bind|
00000010  69 6e 67 12 80 01 0a 5e  0a 21 6e 67 69 6e 78 2d  |ing....^.!nginx-|
00000020  64 65 70 6c 6f 79 6d 65  6e 74 2d 36 36 66 35 38  |deployment-66f58|
00000030  62 66 66 37 63 2d 7a 72  39 6d 35 12 00 1a 07 64  |bff7c-zr9m5....d|
00000040  65 66 61 75 6c 74 22 00  2a 24 62 38 61 62 63 66  |efault".*$b8abcf|
00000050  34 64 2d 66 30 39 65 2d  34 38 62 64 2d 62 31 61  |4d-f09e-48bd-b1a|
00000060  33 2d 64 61 31 33 30 35  62 36 62 64 38 63 32 00  |3-da1305b6bd8c2.|
00000070  38 00 42 00 7a 00 12 1e  0a 04 4e 6f 64 65 12 00  |8.B.z.....Node..|
00000080  1a 0c 6b 69 6e 64 2d 77  6f 72 6b 65 72 33 22 00  |..kind-worker3".|
00000090  2a 00 32 00 3a 00 1a 00  22 00                    |*.2.:...".|
I0501 08:21:16.444393       1 round_trippers.go:466] curl -v -XPOST  -H "Content-Type: application/vnd.kubernetes.protobuf" -H "Accept: application/vnd.kubernetes.protobuf, */*" -H "User-Agent: kube-scheduler/v1.24.7 (linux/amd64) kubernetes/e6f3597/scheduler" 'https://172.18.0.2:6443/api/v1/namespaces/default/pods/nginx-deployment-66f58bff7c-zr9m5/binding'
I0501 08:21:16.436458       1 eventhandlers.go:184] "Add event for scheduled pod" pod="default/nginx-deployment-66f58bff7c-x8rw9"
I0501 08:21:16.447389       1 eventhandlers.go:184] "Add event for scheduled pod" pod="default/nginx-deployment-66f58bff7c-l7r5r"
I0501 08:21:16.455501       1 round_trippers.go:466] curl -v -XGET  -H "Accept: application/vnd.kubernetes.protobuf, */*" -H "User-Agent: kube-scheduler/v1.24.7 (linux/amd64) kubernetes/e6f3597/leader-election" 'https://172.18.0.2:6443/apis/coordination.k8s.io/v1/namespaces/kube-system/leases/kube-scheduler?timeout=5s'
I0501 08:21:16.469331       1 round_trippers.go:553] POST https://172.18.0.2:6443/api/v1/namespaces/default/pods/nginx-deployment-66f58bff7c-zr9m5/binding 201 Created in 24 milliseconds
I0501 08:21:16.469388       1 round_trippers.go:570] HTTP Statistics: GetConnection 0 ms ServerProcessing 24 ms Duration 24 ms
I0501 08:21:16.469404       1 round_trippers.go:577] Response Headers:
I0501 08:21:16.469421       1 round_trippers.go:580]     X-Kubernetes-Pf-Prioritylevel-Uid: 4ccc4fdb-4419-4777-8b6f-3ed0d4949e5d
I0501 08:21:16.469436       1 round_trippers.go:580]     Content-Length: 48
I0501 08:21:16.469453       1 round_trippers.go:580]     Date: Mon, 01 May 2023 08:21:16 GMT
I0501 08:21:16.469452       1 round_trippers.go:553] POST https://172.18.0.2:6443/apis/events.k8s.io/v1/namespaces/default/events 201 Created in 28 milliseconds
I0501 08:21:16.469490       1 round_trippers.go:570] HTTP Statistics: GetConnection 0 ms ServerProcessing 27 ms Duration 28 ms
I0501 08:21:16.469514       1 round_trippers.go:577] Response Headers:
I0501 08:21:16.469534       1 round_trippers.go:580]     X-Kubernetes-Pf-Flowschema-Uid: 8a935dea-6b5d-4402-a842-ba69f911704f
I0501 08:21:16.469562       1 round_trippers.go:580]     X-Kubernetes-Pf-Prioritylevel-Uid: 4ccc4fdb-4419-4777-8b6f-3ed0d4949e5d
I0501 08:21:16.469578       1 round_trippers.go:580]     Content-Length: 676
I0501 08:21:16.469626       1 round_trippers.go:580]     Date: Mon, 01 May 2023 08:21:16 GMT
I0501 08:21:16.469653       1 round_trippers.go:580]     Audit-Id: 5750ebb3-92c0-4a8d-9617-e28d90e25bdf
I0501 08:21:16.469668       1 round_trippers.go:580]     Cache-Control: no-cache, private
I0501 08:21:16.469683       1 round_trippers.go:580]     Content-Type: application/vnd.kubernetes.protobuf
I0501 08:21:16.469469       1 round_trippers.go:580]     Audit-Id: 1407fbb8-abba-4830-8287-0e01140fd1dd
I0501 08:21:16.469809       1 round_trippers.go:580]     Cache-Control: no-cache, private
I0501 08:21:16.469827       1 round_trippers.go:580]     Content-Type: application/vnd.kubernetes.protobuf
I0501 08:21:16.469842       1 round_trippers.go:580]     X-Kubernetes-Pf-Flowschema-Uid: 8a935dea-6b5d-4402-a842-ba69f911704f
I0501 08:21:16.470117       1 eventhandlers.go:116] "Add event for unscheduled pod" pod="default/nginx-deployment-66f58bff7c-m9fqn"
I0501 08:21:16.470252       1 scheduling_queue.go:956] "About to try and schedule pod" pod="default/nginx-deployment-66f58bff7c-m9fqn"
I0501 08:21:16.471566       1 schedule_one.go:84] "Attempting to schedule pod" pod="default/nginx-deployment-66f58bff7c-m9fqn"
I0501 08:21:16.471826       1 eventhandlers.go:116] "Add event for unscheduled pod" pod="default/nginx-deployment-66f58bff7c-dmm7c"
I0501 08:21:16.471904       1 eventhandlers.go:159] "Delete event for unscheduled pod" pod="default/nginx-deployment-66f58bff7c-zr9m5"
I0501 08:21:16.471947       1 round_trippers.go:553] POST https://172.18.0.2:6443/apis/events.k8s.io/v1/namespaces/default/events 201 Created in 27 milliseconds
I0501 08:21:16.471970       1 round_trippers.go:570] HTTP Statistics: GetConnection 0 ms ServerProcessing 27 ms Duration 27 ms
I0501 08:21:16.472372       1 resource_allocation.go:70] "Listing internal info for allocatable resources, requested resources and score" pod="default/nginx-deployment-66f58bff7c-m9fqn" node="kind-worker" resourceAllocationScorer="LeastAllocated" allocatableResource=map[cpu:8000 memory:8362762240] requestedResource=map[cpu:600 memory:681574400] resourceScore=91
I0501 08:21:16.472493       1 resource_allocation.go:70] "Listing internal info for allocatable resources, requested resources and score" pod="default/nginx-deployment-66f58bff7c-m9fqn" node="kind-worker" resourceAllocationScorer="NodeResourcesBalancedAllocation" allocatableResource=map[cpu:8000 memory:8362762240] requestedResource=map[cpu:500 memory:52428800] resourceScore=97
I0501 08:21:16.472574       1 eventhandlers.go:184] "Add event for scheduled pod" pod="default/nginx-deployment-66f58bff7c-zr9m5"
I0501 08:21:16.472654       1 request.go:1152] Response Body:
00000000  6b 38 73 00 0a 19 0a 10  65 76 65 6e 74 73 2e 6b  |k8s.....events.k|
00000010  38 73 2e 69 6f 2f 76 31  12 05 45 76 65 6e 74 12  |8s.io/v1..Event.|
00000020  fe 04 0a d3 02 0a 32 6e  67 69 6e 78 2d 64 65 70  |......2nginx-dep|
00000030  6c 6f 79 6d 65 6e 74 2d  36 36 66 35 38 62 66 66  |loyment-66f58bff|
00000040  37 63 2d 6c 37 72 35 72  2e 31 37 35 61 66 37 34  |7c-l7r5r.175af74|
00000050  32 61 38 35 38 39 63 36  33 12 00 1a 07 64 65 66  |2a8589c63....def|
00000060  61 75 6c 74 22 00 2a 24  37 36 35 64 30 31 65 66  |ault".*$765d01ef|
00000070  2d 39 32 36 62 2d 34 35  65 66 2d 39 30 38 35 2d  |-926b-45ef-9085-|
00000080  37 35 37 37 64 65 36 66  31 38 39 32 32 07 32 32  |7577de6f18922.22|
00000090  36 38 35 35 33 38 00 42  08 08 fc ec bd a2 06 10  |685538.B........|
000000a0  00 7a 00 8a 01 d1 01 0a  0e 6b 75 62 65 2d 73 63  |.z.......kube-sc|
000000b0  68 65 64 75 6c 65 72 12  06 55 70 64 61 74 65 1a  |heduler..Update.|
000000c0  10 65 76 65 6e 74 73 2e  6b 38 73 2e 69 6f 2f 76  |.events.k8s.io/v|
000000d0  31 22 08 08 fc ec bd a2  06 10 00 32 08 46 69 65  |1".........2.Fie|
000000e0  6c 64 73 56 31 3a 8e 01  0a 8b 01 7b 22 66 3a 61  |ldsV1:.....{"f:a|
000000f0  63 74 69 6f 6e 22 3a 7b  7d 2c 22 66 3a 65 76 65  |ction":{},"f:eve|
00000100  6e 74 54 69 6d 65 22 3a  7b 7d 2c 22 66 3a 6e 6f  |ntTime":{},"f:no|
00000110  74 65 22 3a 7b 7d 2c 22  66 3a 72 65 61 73 6f 6e  |te":{},"f:reason|
00000120  22 3a 7b 7d 2c 22 66 3a  72 65 67 61 72 64 69 6e  |":{},"f:regardin|
00000130  67 22 3a 7b 7d 2c 22 66  3a 72 65 70 6f 72 74 69  |g":{},"f:reporti|
00000140  6e 67 43 6f 6e 74 72 6f  6c 6c 65 72 22 3a 7b 7d  |ngController":{}|
00000150  2c 22 66 3a 72 65 70 6f  72 74 69 6e 67 49 6e 73  |,"f:reportingIns|
00000160  74 61 6e 63 65 22 3a 7b  7d 2c 22 66 3a 74 79 70  |tance":{},"f:typ|
00000170  65 22 3a 7b 7d 7d 42 00  12 0c 08 fc ec bd a2 06  |e":{}}B.........|
00000180  10 9c bb 8a d2 01 22 11  64 65 66 61 75 6c 74 2d  |......".default-|
00000190  73 63 68 65 64 75 6c 65  72 2a 24 64 65 66 61 75  |scheduler*$defau|
000001a0  6c 74 2d 73 63 68 65 64  75 6c 65 72 2d 6b 69 6e  |lt-scheduler-kin|
000001b0  64 2d 63 6f 6e 74 72 6f  6c 2d 70 6c 61 6e 65 32  |d-control-plane2|
000001c0  07 42 69 6e 64 69 6e 67  3a 09 53 63 68 65 64 75  |.Binding:.Schedu|
000001d0  6c 65 64 42 66 0a 03 50  6f 64 12 07 64 65 66 61  |ledBf..Pod..defa|
000001e0  75 6c 74 1a 21 6e 67 69  6e 78 2d 64 65 70 6c 6f  |ult.!nginx-deplo|
000001f0  79 6d 65 6e 74 2d 36 36  66 35 38 62 66 66 37 63  |yment-66f58bff7c|
00000200  2d 6c 37 72 35 72 22 24  33 63 65 38 35 62 64 61  |-l7r5r"$3ce85bda|
00000210  2d 39 34 62 37 2d 34 63  33 37 2d 39 36 33 39 2d  |-94b7-4c37-9639-|
00000220  62 62 66 31 31 34 30 37  30 66 61 33 2a 02 76 31  |bbf114070fa3*.v1|
00000230  32 07 32 32 36 38 35 34  35 3a 00 52 4f 53 75 63  |2.2268545:.ROSuc|
00000240  63 65 73 73 66 75 6c 6c  79 20 61 73 73 69 67 6e  |cessfully assign|
00000250  65 64 20 64 65 66 61 75  6c 74 2f 6e 67 69 6e 78  |ed default/nginx|
00000260  2d 64 65 70 6c 6f 79 6d  65 6e 74 2d 36 36 66 35  |-deployment-66f5|
00000270  38 62 66 66 37 63 2d 6c  37 72 35 72 20 74 6f 20  |8bff7c-l7r5r to |
00000280  6b 69 6e 64 2d 77 6f 72  6b 65 72 32 5a 06 4e 6f  |kind-worker2Z.No|
00000290  72 6d 61 6c 62 04 0a 00  12 00 6a 00 72 00 78 00  |rmalb.....j.r.x.|
000002a0  1a 00 22 00                                       |..".|
I0501 08:21:16.472700       1 round_trippers.go:577] Response Headers:
I0501 08:21:16.472740       1 round_trippers.go:580]     Audit-Id: 0e726f49-e3f5-4bbe-853d-c165b98ccd08
I0501 08:21:16.472768       1 round_trippers.go:580]     Cache-Control: no-cache, private
I0501 08:21:16.472785       1 round_trippers.go:580]     Content-Type: application/vnd.kubernetes.protobuf
I0501 08:21:16.472801       1 round_trippers.go:580]     X-Kubernetes-Pf-Flowschema-Uid: 8a935dea-6b5d-4402-a842-ba69f911704f
I0501 08:21:16.472816       1 round_trippers.go:580]     X-Kubernetes-Pf-Prioritylevel-Uid: 4ccc4fdb-4419-4777-8b6f-3ed0d4949e5d
I0501 08:21:16.472831       1 round_trippers.go:580]     Content-Length: 676
I0501 08:21:16.472847       1 round_trippers.go:580]     Date: Mon, 01 May 2023 08:21:16 GMT
I0501 08:21:16.473245       1 request.go:1152] Response Body:
00000000  6b 38 73 00 0a 19 0a 10  65 76 65 6e 74 73 2e 6b  |k8s.....events.k|
00000010  38 73 2e 69 6f 2f 76 31  12 05 45 76 65 6e 74 12  |8s.io/v1..Event.|
00000020  fe 04 0a d3 02 0a 32 6e  67 69 6e 78 2d 64 65 70  |......2nginx-dep|
00000030  6c 6f 79 6d 65 6e 74 2d  36 36 66 35 38 62 66 66  |loyment-66f58bff|
00000040  37 63 2d 78 38 72 77 39  2e 31 37 35 61 66 37 34  |7c-x8rw9.175af74|
00000050  32 61 38 37 35 62 32 31  39 12 00 1a 07 64 65 66  |2a875b219....def|
00000060  61 75 6c 74 22 00 2a 24  64 65 62 38 61 63 34 63  |ault".*$deb8ac4c|
00000070  2d 61 66 30 38 2d 34 64  31 30 2d 61 63 38 65 2d  |-af08-4d10-ac8e-|
00000080  36 66 65 30 34 39 38 63  34 31 37 65 32 07 32 32  |6fe0498c417e2.22|
00000090  36 38 35 35 35 38 00 42  08 08 fc ec bd a2 06 10  |685558.B........|
000000a0  00 7a 00 8a 01 d1 01 0a  0e 6b 75 62 65 2d 73 63  |.z.......kube-sc|
000000b0  68 65 64 75 6c 65 72 12  06 55 70 64 61 74 65 1a  |heduler..Update.|
000000c0  10 65 76 65 6e 74 73 2e  6b 38 73 2e 69 6f 2f 76  |.events.k8s.io/v|
000000d0  31 22 08 08 fc ec bd a2  06 10 00 32 08 46 69 65  |1".........2.Fie|
000000e0  6c 64 73 56 31 3a 8e 01  0a 8b 01 7b 22 66 3a 61  |ldsV1:.....{"f:a|
000000f0  63 74 69 6f 6e 22 3a 7b  7d 2c 22 66 3a 65 76 65  |ction":{},"f:eve|
00000100  6e 74 54 69 6d 65 22 3a  7b 7d 2c 22 66 3a 6e 6f  |ntTime":{},"f:no|
00000110  74 65 22 3a 7b 7d 2c 22  66 3a 72 65 61 73 6f 6e  |te":{},"f:reason|
00000120  22 3a 7b 7d 2c 22 66 3a  72 65 67 61 72 64 69 6e  |":{},"f:regardin|
00000130  67 22 3a 7b 7d 2c 22 66  3a 72 65 70 6f 72 74 69  |g":{},"f:reporti|
00000140  6e 67 43 6f 6e 74 72 6f  6c 6c 65 72 22 3a 7b 7d  |ngController":{}|
00000150  2c 22 66 3a 72 65 70 6f  72 74 69 6e 67 49 6e 73  |,"f:reportingIns|
00000160  74 61 6e 63 65 22 3a 7b  7d 2c 22 66 3a 74 79 70  |tance":{},"f:typ|
00000170  65 22 3a 7b 7d 7d 42 00  12 0c 08 fc ec bd a2 06  |e":{}}B.........|
00000180  10 96 82 ff d2 01 22 11  64 65 66 61 75 6c 74 2d  |......".default-|
00000190  73 63 68 65 64 75 6c 65  72 2a 24 64 65 66 61 75  |scheduler*$defau|
000001a0  6c 74 2d 73 63 68 65 64  75 6c 65 72 2d 6b 69 6e  |lt-scheduler-kin|
000001b0  64 2d 63 6f 6e 74 72 6f  6c 2d 70 6c 61 6e 65 32  |d-control-plane2|
000001c0  07 42 69 6e 64 69 6e 67  3a 09 53 63 68 65 64 75  |.Binding:.Schedu|
000001d0  6c 65 64 42 66 0a 03 50  6f 64 12 07 64 65 66 61  |ledBf..Pod..defa|
000001e0  75 6c 74 1a 21 6e 67 69  6e 78 2d 64 65 70 6c 6f  |ult.!nginx-deplo|
000001f0  79 6d 65 6e 74 2d 36 36  66 35 38 62 66 66 37 63  |yment-66f58bff7c|
00000200  2d 78 38 72 77 39 22 24  34 62 38 35 30 38 65 33  |-x8rw9"$4b8508e3|
00000210  2d 33 61 66 62 2d 34 64  32 65 2d 61 34 66 63 2d  |-3afb-4d2e-a4fc-|
00000220  37 61 65 36 31 65 38 37  38 33 65 61 2a 02 76 31  |7ae61e8783ea*.v1|
00000230  32 07 32 32 36 38 35 34  31 3a 00 52 4f 53 75 63  |2.2268541:.ROSuc|
00000240  63 65 73 73 66 75 6c 6c  79 20 61 73 73 69 67 6e  |cessfully assign|
00000250  65 64 20 64 65 66 61 75  6c 74 2f 6e 67 69 6e 78  |ed default/nginx|
00000260  2d 64 65 70 6c 6f 79 6d  65 6e 74 2d 36 36 66 35  |-deployment-66f5|
00000270  38 62 66 66 37 63 2d 78  38 72 77 39 20 74 6f 20  |8bff7c-x8rw9 to |
00000280  6b 69 6e 64 2d 77 6f 72  6b 65 72 33 5a 06 4e 6f  |kind-worker3Z.No|
00000290  72 6d 61 6c 62 04 0a 00  12 00 6a 00 72 00 78 00  |rmalb.....j.r.x.|
000002a0  1a 00 22 00                                       |..".|
I0501 08:21:16.472668       1 resource_allocation.go:70] "Listing internal info for allocatable resources, requested resources and score" pod="default/nginx-deployment-66f58bff7c-m9fqn" node="kind-worker3" resourceAllocationScorer="LeastAllocated" allocatableResource=map[cpu:8000 memory:8362762240] requestedResource=map[cpu:800 memory:891289600] resourceScore=89
I0501 08:21:16.473504       1 resource_allocation.go:70] "Listing internal info for allocatable resources, requested resources and score" pod="default/nginx-deployment-66f58bff7c-m9fqn" node="kind-worker3" resourceAllocationScorer="NodeResourcesBalancedAllocation" allocatableResource=map[cpu:8000 memory:8362762240] requestedResource=map[cpu:700 memory:52428800] resourceScore=95
I0501 08:21:16.474951       1 resource_allocation.go:70] "Listing internal info for allocatable resources, requested resources and score" pod="default/nginx-deployment-66f58bff7c-m9fqn" node="kind-worker2" resourceAllocationScorer="LeastAllocated" allocatableResource=map[cpu:8000 memory:8362762240] requestedResource=map[cpu:700 memory:891289600] resourceScore=90
I0501 08:21:16.475467       1 request.go:1152] Response Body:
00000000  6b 38 73 00 0a 0c 0a 02  76 31 12 06 53 74 61 74  |k8s.....v1..Stat|
00000010  75 73 12 18 0a 06 0a 00  12 00 1a 00 12 07 53 75  |us............Su|
00000020  63 63 65 73 73 1a 00 22  00 30 c9 01 1a 00 22 00  |ccess..".0....".|
I0501 08:21:16.475662       1 cache.go:379] "Finished binding for pod, can be expired" pod="default/nginx-deployment-66f58bff7c-zr9m5"
I0501 08:21:16.475752       1 schedule_one.go:265] "Successfully bound pod to node" pod="default/nginx-deployment-66f58bff7c-zr9m5" node="kind-worker3" evaluatedNodes=4 feasibleNodes=3
I0501 08:21:16.475984       1 request.go:1152] Request Body:
00000000  6b 38 73 00 0a 19 0a 10  65 76 65 6e 74 73 2e 6b  |k8s.....events.k|
00000010  38 73 2e 69 6f 2f 76 31  12 05 45 76 65 6e 74 12  |8s.io/v1..Event.|
00000020  f5 02 0a 4b 0a 32 6e 67  69 6e 78 2d 64 65 70 6c  |...K.2nginx-depl|
00000030  6f 79 6d 65 6e 74 2d 36  36 66 35 38 62 66 66 37  |oyment-66f58bff7|
00000040  63 2d 7a 72 39 6d 35 2e  31 37 35 61 66 37 34 32  |c-zr9m5.175af742|
00000050  61 61 37 30 39 66 63 32  12 00 1a 07 64 65 66 61  |aa709fc2....defa|
00000060  75 6c 74 22 00 2a 00 32  00 38 00 42 00 7a 00 12  |ult".*.2.8.B.z..|
00000070  0c 08 fc ec bd a2 06 10  96 96 ea e2 01 22 11 64  |.............".d|
00000080  65 66 61 75 6c 74 2d 73  63 68 65 64 75 6c 65 72  |efault-scheduler|
00000090  2a 24 64 65 66 61 75 6c  74 2d 73 63 68 65 64 75  |*$default-schedu|
000000a0  6c 65 72 2d 6b 69 6e 64  2d 63 6f 6e 74 72 6f 6c  |ler-kind-control|
000000b0  2d 70 6c 61 6e 65 32 07  42 69 6e 64 69 6e 67 3a  |-plane2.Binding:|
000000c0  09 53 63 68 65 64 75 6c  65 64 42 66 0a 03 50 6f  |.ScheduledBf..Po|
000000d0  64 12 07 64 65 66 61 75  6c 74 1a 21 6e 67 69 6e  |d..default.!ngin|
000000e0  78 2d 64 65 70 6c 6f 79  6d 65 6e 74 2d 36 36 66  |x-deployment-66f|
000000f0  35 38 62 66 66 37 63 2d  7a 72 39 6d 35 22 24 62  |58bff7c-zr9m5"$b|
00000100  38 61 62 63 66 34 64 2d  66 30 39 65 2d 34 38 62  |8abcf4d-f09e-48b|
00000110  64 2d 62 31 61 33 2d 64  61 31 33 30 35 62 36 62  |d-b1a3-da1305b6b|
00000120  64 38 63 2a 02 76 31 32  07 32 32 36 38 35 34 36  |d8c*.v12.2268546|
00000130  3a 00 52 4f 53 75 63 63  65 73 73 66 75 6c 6c 79  |:.ROSuccessfully|
00000140  20 61 73 73 69 67 6e 65  64 20 64 65 66 61 75 6c  | assigned defaul|
00000150  74 2f 6e 67 69 6e 78 2d  64 65 70 6c 6f 79 6d 65  |t/nginx-deployme|
00000160  6e 74 2d 36 36 66 35 38  62 66 66 37 63 2d 7a 72  |nt-66f58bff7c-zr|
00000170  39 6d 35 20 74 6f 20 6b  69 6e 64 2d 77 6f 72 6b  |9m5 to kind-work|
00000180  65 72 33 5a 06 4e 6f 72  6d 61 6c 62 04 0a 00 12  |er3Z.Normalb....|
00000190  00 6a 00 72 00 78 00 1a  00 22 00                 |.j.r.x...".|
I0501 08:21:16.476116       1 round_trippers.go:466] curl -v -XPOST  -H "Accept: application/vnd.kubernetes.protobuf, */*" -H "Content-Type: application/vnd.kubernetes.protobuf" -H "User-Agent: kube-scheduler/v1.24.7 (linux/amd64) kubernetes/e6f3597/scheduler" 'https://172.18.0.2:6443/apis/events.k8s.io/v1/namespaces/default/events'
I0501 08:21:16.476498       1 resource_allocation.go:70] "Listing internal info for allocatable resources, requested resources and score" pod="default/nginx-deployment-66f58bff7c-m9fqn" node="kind-worker2" resourceAllocationScorer="NodeResourcesBalancedAllocation" allocatableResource=map[cpu:8000 memory:8362762240] requestedResource=map[cpu:600 memory:262144000] resourceScore=97
I0501 08:21:16.477285       1 schedule_one.go:645] "Plugin scored node for pod" pod="default/nginx-deployment-66f58bff7c-m9fqn" plugin="TaintToleration" node="kind-worker" score=300
I0501 08:21:16.477353       1 schedule_one.go:645] "Plugin scored node for pod" pod="default/nginx-deployment-66f58bff7c-m9fqn" plugin="TaintToleration" node="kind-worker3" score=300
I0501 08:21:16.477873       1 schedule_one.go:645] "Plugin scored node for pod" pod="default/nginx-deployment-66f58bff7c-m9fqn" plugin="TaintToleration" node="kind-worker2" score=300
I0501 08:21:16.478075       1 schedule_one.go:645] "Plugin scored node for pod" pod="default/nginx-deployment-66f58bff7c-m9fqn" plugin="NodeAffinity" node="kind-worker" score=0
I0501 08:21:16.478184       1 schedule_one.go:645] "Plugin scored node for pod" pod="default/nginx-deployment-66f58bff7c-m9fqn" plugin="NodeAffinity" node="kind-worker3" score=0
I0501 08:21:16.478351       1 schedule_one.go:645] "Plugin scored node for pod" pod="default/nginx-deployment-66f58bff7c-m9fqn" plugin="NodeAffinity" node="kind-worker2" score=0
I0501 08:21:16.478645       1 schedule_one.go:645] "Plugin scored node for pod" pod="default/nginx-deployment-66f58bff7c-m9fqn" plugin="NodeResourcesFit" node="kind-worker" score=91
I0501 08:21:16.478972       1 schedule_one.go:645] "Plugin scored node for pod" pod="default/nginx-deployment-66f58bff7c-m9fqn" plugin="NodeResourcesFit" node="kind-worker3" score=89
I0501 08:21:16.479016       1 schedule_one.go:645] "Plugin scored node for pod" pod="default/nginx-deployment-66f58bff7c-m9fqn" plugin="NodeResourcesFit" node="kind-worker2" score=90
I0501 08:21:16.479704       1 schedule_one.go:645] "Plugin scored node for pod" pod="default/nginx-deployment-66f58bff7c-m9fqn" plugin="VolumeBinding" node="kind-worker" score=0
I0501 08:21:16.480011       1 schedule_one.go:645] "Plugin scored node for pod" pod="default/nginx-deployment-66f58bff7c-m9fqn" plugin="VolumeBinding" node="kind-worker3" score=0
I0501 08:21:16.480141       1 schedule_one.go:645] "Plugin scored node for pod" pod="default/nginx-deployment-66f58bff7c-m9fqn" plugin="VolumeBinding" node="kind-worker2" score=0
I0501 08:21:16.480234       1 schedule_one.go:645] "Plugin scored node for pod" pod="default/nginx-deployment-66f58bff7c-m9fqn" plugin="PodTopologySpread" node="kind-worker" score=200
I0501 08:21:16.480342       1 schedule_one.go:645] "Plugin scored node for pod" pod="default/nginx-deployment-66f58bff7c-m9fqn" plugin="PodTopologySpread" node="kind-worker3" score=160
I0501 08:21:16.480611       1 schedule_one.go:645] "Plugin scored node for pod" pod="default/nginx-deployment-66f58bff7c-m9fqn" plugin="PodTopologySpread" node="kind-worker2" score=200
I0501 08:21:16.480653       1 schedule_one.go:645] "Plugin scored node for pod" pod="default/nginx-deployment-66f58bff7c-m9fqn" plugin="InterPodAffinity" node="kind-worker" score=0
I0501 08:21:16.480740       1 schedule_one.go:645] "Plugin scored node for pod" pod="default/nginx-deployment-66f58bff7c-m9fqn" plugin="InterPodAffinity" node="kind-worker3" score=0
I0501 08:21:16.480808       1 schedule_one.go:645] "Plugin scored node for pod" pod="default/nginx-deployment-66f58bff7c-m9fqn" plugin="InterPodAffinity" node="kind-worker2" score=0
I0501 08:21:16.480893       1 schedule_one.go:645] "Plugin scored node for pod" pod="default/nginx-deployment-66f58bff7c-m9fqn" plugin="NodeResourcesBalancedAllocation" node="kind-worker" score=97
I0501 08:21:16.480937       1 schedule_one.go:645] "Plugin scored node for pod" pod="default/nginx-deployment-66f58bff7c-m9fqn" plugin="NodeResourcesBalancedAllocation" node="kind-worker3" score=95
I0501 08:21:16.481057       1 schedule_one.go:645] "Plugin scored node for pod" pod="default/nginx-deployment-66f58bff7c-m9fqn" plugin="NodeResourcesBalancedAllocation" node="kind-worker2" score=97
I0501 08:21:16.481139       1 schedule_one.go:645] "Plugin scored node for pod" pod="default/nginx-deployment-66f58bff7c-m9fqn" plugin="ImageLocality" node="kind-worker" score=0
I0501 08:21:16.481226       1 schedule_one.go:645] "Plugin scored node for pod" pod="default/nginx-deployment-66f58bff7c-m9fqn" plugin="ImageLocality" node="kind-worker3" score=0
I0501 08:21:16.481303       1 schedule_one.go:645] "Plugin scored node for pod" pod="default/nginx-deployment-66f58bff7c-m9fqn" plugin="ImageLocality" node="kind-worker2" score=0
I0501 08:21:16.481396       1 schedule_one.go:703] "Calculated node's final score for pod" pod="default/nginx-deployment-66f58bff7c-m9fqn" node="kind-worker" score=688
I0501 08:21:16.481477       1 schedule_one.go:703] "Calculated node's final score for pod" pod="default/nginx-deployment-66f58bff7c-m9fqn" node="kind-worker3" score=644
I0501 08:21:16.481556       1 schedule_one.go:703] "Calculated node's final score for pod" pod="default/nginx-deployment-66f58bff7c-m9fqn" node="kind-worker2" score=687
I0501 08:21:16.481925       1 scheduling_queue.go:956] "About to try and schedule pod" pod="default/nginx-deployment-66f58bff7c-dmm7c"
I0501 08:21:16.481966       1 schedule_one.go:84] "Attempting to schedule pod" pod="default/nginx-deployment-66f58bff7c-dmm7c"
I0501 08:21:16.482330       1 default_binder.go:52] "Attempting to bind pod to node" pod="default/nginx-deployment-66f58bff7c-m9fqn" node="kind-worker"
I0501 08:21:16.482523       1 request.go:1152] Request Body:
00000000  6b 38 73 00 0a 0d 0a 02  76 31 12 07 42 69 6e 64  |k8s.....v1..Bind|
00000010  69 6e 67 12 7f 0a 5e 0a  21 6e 67 69 6e 78 2d 64  |ing...^.!nginx-d|
00000020  65 70 6c 6f 79 6d 65 6e  74 2d 36 36 66 35 38 62  |eployment-66f58b|
00000030  66 66 37 63 2d 6d 39 66  71 6e 12 00 1a 07 64 65  |ff7c-m9fqn....de|
00000040  66 61 75 6c 74 22 00 2a  24 38 62 62 66 39 38 34  |fault".*$8bbf984|
00000050  66 2d 61 30 37 62 2d 34  65 61 61 2d 39 34 66 63  |f-a07b-4eaa-94fc|
00000060  2d 38 63 38 37 30 62 65  31 66 33 35 39 32 00 38  |-8c870be1f3592.8|
00000070  00 42 00 7a 00 12 1d 0a  04 4e 6f 64 65 12 00 1a  |.B.z.....Node...|
00000080  0b 6b 69 6e 64 2d 77 6f  72 6b 65 72 22 00 2a 00  |.kind-worker".*.|
00000090  32 00 3a 00 1a 00 22 00                           |2.:...".|
I0501 08:21:16.482636       1 resource_allocation.go:70] "Listing internal info for allocatable resources, requested resources and score" pod="default/nginx-deployment-66f58bff7c-dmm7c" node="kind-worker" resourceAllocationScorer="LeastAllocated" allocatableResource=map[cpu:8000 memory:8362762240] requestedResource=map[cpu:800 memory:891289600] resourceScore=89
I0501 08:21:16.482715       1 resource_allocation.go:70] "Listing internal info for allocatable resources, requested resources and score" pod="default/nginx-deployment-66f58bff7c-dmm7c" node="kind-worker" resourceAllocationScorer="NodeResourcesBalancedAllocation" allocatableResource=map[cpu:8000 memory:8362762240] requestedResource=map[cpu:700 memory:52428800] resourceScore=95
I0501 08:21:16.482770       1 resource_allocation.go:70] "Listing internal info for allocatable resources, requested resources and score" pod="default/nginx-deployment-66f58bff7c-dmm7c" node="kind-worker2" resourceAllocationScorer="LeastAllocated" allocatableResource=map[cpu:8000 memory:8362762240] requestedResource=map[cpu:700 memory:891289600] resourceScore=90
I0501 08:21:16.482820       1 resource_allocation.go:70] "Listing internal info for allocatable resources, requested resources and score" pod="default/nginx-deployment-66f58bff7c-dmm7c" node="kind-worker2" resourceAllocationScorer="NodeResourcesBalancedAllocation" allocatableResource=map[cpu:8000 memory:8362762240] requestedResource=map[cpu:600 memory:262144000] resourceScore=97
I0501 08:21:16.482723       1 round_trippers.go:466] curl -v -XPOST  -H "Content-Type: application/vnd.kubernetes.protobuf" -H "User-Agent: kube-scheduler/v1.24.7 (linux/amd64) kubernetes/e6f3597/scheduler" -H "Accept: application/vnd.kubernetes.protobuf, */*" 'https://172.18.0.2:6443/api/v1/namespaces/default/pods/nginx-deployment-66f58bff7c-m9fqn/binding'
I0501 08:21:16.482959       1 resource_allocation.go:70] "Listing internal info for allocatable resources, requested resources and score" pod="default/nginx-deployment-66f58bff7c-dmm7c" node="kind-worker3" resourceAllocationScorer="LeastAllocated" allocatableResource=map[cpu:8000 memory:8362762240] requestedResource=map[cpu:800 memory:891289600] resourceScore=89
I0501 08:21:16.483121       1 resource_allocation.go:70] "Listing internal info for allocatable resources, requested resources and score" pod="default/nginx-deployment-66f58bff7c-dmm7c" node="kind-worker3" resourceAllocationScorer="NodeResourcesBalancedAllocation" allocatableResource=map[cpu:8000 memory:8362762240] requestedResource=map[cpu:700 memory:52428800] resourceScore=95
I0501 08:21:16.483533       1 schedule_one.go:645] "Plugin scored node for pod" pod="default/nginx-deployment-66f58bff7c-dmm7c" plugin="NodeAffinity" node="kind-worker" score=0
I0501 08:21:16.483622       1 schedule_one.go:645] "Plugin scored node for pod" pod="default/nginx-deployment-66f58bff7c-dmm7c" plugin="NodeAffinity" node="kind-worker3" score=0
I0501 08:21:16.483650       1 schedule_one.go:645] "Plugin scored node for pod" pod="default/nginx-deployment-66f58bff7c-dmm7c" plugin="NodeAffinity" node="kind-worker2" score=0
I0501 08:21:16.483721       1 schedule_one.go:645] "Plugin scored node for pod" pod="default/nginx-deployment-66f58bff7c-dmm7c" plugin="NodeResourcesFit" node="kind-worker" score=89
I0501 08:21:16.483748       1 schedule_one.go:645] "Plugin scored node for pod" pod="default/nginx-deployment-66f58bff7c-dmm7c" plugin="NodeResourcesFit" node="kind-worker3" score=89
I0501 08:21:16.483773       1 schedule_one.go:645] "Plugin scored node for pod" pod="default/nginx-deployment-66f58bff7c-dmm7c" plugin="NodeResourcesFit" node="kind-worker2" score=90
I0501 08:21:16.483796       1 schedule_one.go:645] "Plugin scored node for pod" pod="default/nginx-deployment-66f58bff7c-dmm7c" plugin="VolumeBinding" node="kind-worker" score=0
I0501 08:21:16.483819       1 schedule_one.go:645] "Plugin scored node for pod" pod="default/nginx-deployment-66f58bff7c-dmm7c" plugin="VolumeBinding" node="kind-worker3" score=0
I0501 08:21:16.483841       1 schedule_one.go:645] "Plugin scored node for pod" pod="default/nginx-deployment-66f58bff7c-dmm7c" plugin="VolumeBinding" node="kind-worker2" score=0
I0501 08:21:16.483863       1 schedule_one.go:645] "Plugin scored node for pod" pod="default/nginx-deployment-66f58bff7c-dmm7c" plugin="PodTopologySpread" node="kind-worker" score=160
I0501 08:21:16.483885       1 schedule_one.go:645] "Plugin scored node for pod" pod="default/nginx-deployment-66f58bff7c-dmm7c" plugin="PodTopologySpread" node="kind-worker3" score=160
I0501 08:21:16.483907       1 schedule_one.go:645] "Plugin scored node for pod" pod="default/nginx-deployment-66f58bff7c-dmm7c" plugin="PodTopologySpread" node="kind-worker2" score=200
I0501 08:21:16.483929       1 schedule_one.go:645] "Plugin scored node for pod" pod="default/nginx-deployment-66f58bff7c-dmm7c" plugin="InterPodAffinity" node="kind-worker" score=0
I0501 08:21:16.483951       1 schedule_one.go:645] "Plugin scored node for pod" pod="default/nginx-deployment-66f58bff7c-dmm7c" plugin="InterPodAffinity" node="kind-worker3" score=0
I0501 08:21:16.483973       1 schedule_one.go:645] "Plugin scored node for pod" pod="default/nginx-deployment-66f58bff7c-dmm7c" plugin="InterPodAffinity" node="kind-worker2" score=0
I0501 08:21:16.483996       1 schedule_one.go:645] "Plugin scored node for pod" pod="default/nginx-deployment-66f58bff7c-dmm7c" plugin="NodeResourcesBalancedAllocation" node="kind-worker" score=95
I0501 08:21:16.484018       1 schedule_one.go:645] "Plugin scored node for pod" pod="default/nginx-deployment-66f58bff7c-dmm7c" plugin="NodeResourcesBalancedAllocation" node="kind-worker3" score=95
I0501 08:21:16.484041       1 schedule_one.go:645] "Plugin scored node for pod" pod="default/nginx-deployment-66f58bff7c-dmm7c" plugin="NodeResourcesBalancedAllocation" node="kind-worker2" score=97
I0501 08:21:16.484063       1 schedule_one.go:645] "Plugin scored node for pod" pod="default/nginx-deployment-66f58bff7c-dmm7c" plugin="ImageLocality" node="kind-worker" score=0
I0501 08:21:16.484101       1 schedule_one.go:645] "Plugin scored node for pod" pod="default/nginx-deployment-66f58bff7c-dmm7c" plugin="ImageLocality" node="kind-worker3" score=0
I0501 08:21:16.484123       1 schedule_one.go:645] "Plugin scored node for pod" pod="default/nginx-deployment-66f58bff7c-dmm7c" plugin="ImageLocality" node="kind-worker2" score=0
I0501 08:21:16.484145       1 schedule_one.go:645] "Plugin scored node for pod" pod="default/nginx-deployment-66f58bff7c-dmm7c" plugin="TaintToleration" node="kind-worker" score=300
I0501 08:21:16.484167       1 schedule_one.go:645] "Plugin scored node for pod" pod="default/nginx-deployment-66f58bff7c-dmm7c" plugin="TaintToleration" node="kind-worker3" score=300
I0501 08:21:16.484196       1 schedule_one.go:645] "Plugin scored node for pod" pod="default/nginx-deployment-66f58bff7c-dmm7c" plugin="TaintToleration" node="kind-worker2" score=300
I0501 08:21:16.484284       1 schedule_one.go:703] "Calculated node's final score for pod" pod="default/nginx-deployment-66f58bff7c-dmm7c" node="kind-worker" score=644
I0501 08:21:16.484373       1 schedule_one.go:703] "Calculated node's final score for pod" pod="default/nginx-deployment-66f58bff7c-dmm7c" node="kind-worker3" score=644
I0501 08:21:16.484451       1 schedule_one.go:703] "Calculated node's final score for pod" pod="default/nginx-deployment-66f58bff7c-dmm7c" node="kind-worker2" score=687
I0501 08:21:16.485221       1 default_binder.go:52] "Attempting to bind pod to node" pod="default/nginx-deployment-66f58bff7c-dmm7c" node="kind-worker2"
I0501 08:21:16.485306       1 request.go:1152] Request Body:
00000000  6b 38 73 00 0a 0d 0a 02  76 31 12 07 42 69 6e 64  |k8s.....v1..Bind|
00000010  69 6e 67 12 80 01 0a 5e  0a 21 6e 67 69 6e 78 2d  |ing....^.!nginx-|
00000020  64 65 70 6c 6f 79 6d 65  6e 74 2d 36 36 66 35 38  |deployment-66f58|
00000030  62 66 66 37 63 2d 64 6d  6d 37 63 12 00 1a 07 64  |bff7c-dmm7c....d|
00000040  65 66 61 75 6c 74 22 00  2a 24 39 34 39 31 32 35  |efault".*$949125|
00000050  31 38 2d 62 30 33 39 2d  34 39 32 38 2d 62 36 38  |18-b039-4928-b68|
00000060  34 2d 39 36 33 30 63 37  32 61 61 38 33 62 32 00  |4-9630c72aa83b2.|
00000070  38 00 42 00 7a 00 12 1e  0a 04 4e 6f 64 65 12 00  |8.B.z.....Node..|
00000080  1a 0c 6b 69 6e 64 2d 77  6f 72 6b 65 72 32 22 00  |..kind-worker2".|
00000090  2a 00 32 00 3a 00 1a 00  22 00                    |*.2.:...".|
I0501 08:21:16.485392       1 round_trippers.go:466] curl -v -XPOST  -H "Accept: application/vnd.kubernetes.protobuf, */*" -H "Content-Type: application/vnd.kubernetes.protobuf" -H "User-Agent: kube-scheduler/v1.24.7 (linux/amd64) kubernetes/e6f3597/scheduler" 'https://172.18.0.2:6443/api/v1/namespaces/default/pods/nginx-deployment-66f58bff7c-dmm7c/binding'
I0501 08:21:16.592499       1 round_trippers.go:553] GET https://172.18.0.2:6443/apis/coordination.k8s.io/v1/namespaces/kube-system/leases/kube-scheduler?timeout=5s 200 OK in 136 milliseconds
I0501 08:21:16.592555       1 round_trippers.go:570] HTTP Statistics: GetConnection 0 ms ServerProcessing 136 ms Duration 136 ms
I0501 08:21:16.592571       1 round_trippers.go:577] Response Headers:
I0501 08:21:16.592588       1 round_trippers.go:580]     Content-Length: 432
I0501 08:21:16.592603       1 round_trippers.go:580]     Date: Mon, 01 May 2023 08:21:16 GMT
I0501 08:21:16.592633       1 round_trippers.go:580]     Audit-Id: 52465a3a-cf66-4036-a4f1-f9987dd00231
I0501 08:21:16.592651       1 round_trippers.go:580]     Cache-Control: no-cache, private
I0501 08:21:16.592666       1 round_trippers.go:580]     Content-Type: application/vnd.kubernetes.protobuf
I0501 08:21:16.592680       1 round_trippers.go:580]     X-Kubernetes-Pf-Flowschema-Uid: 493426e8-0f6d-4ea6-bc2c-2d926c7e3221
I0501 08:21:16.592694       1 round_trippers.go:580]     X-Kubernetes-Pf-Prioritylevel-Uid: afabb116-6975-46b8-863b-3258bec9e1ea
I0501 08:21:16.592788       1 request.go:1152] Response Body:
00000000  6b 38 73 00 0a 1f 0a 16  63 6f 6f 72 64 69 6e 61  |k8s.....coordina|
00000010  74 69 6f 6e 2e 6b 38 73  2e 69 6f 2f 76 31 12 05  |tion.k8s.io/v1..|
00000020  4c 65 61 73 65 12 84 03  0a a6 02 0a 0e 6b 75 62  |Lease........kub|
00000030  65 2d 73 63 68 65 64 75  6c 65 72 12 00 1a 0b 6b  |e-scheduler....k|
00000040  75 62 65 2d 73 79 73 74  65 6d 22 00 2a 24 36 61  |ube-system".*$6a|
00000050  30 65 32 30 33 66 2d 65  32 38 30 2d 34 36 61 30  |0e203f-e280-46a0|
00000060  2d 39 35 33 62 2d 35 66  62 64 63 37 38 61 63 38  |-953b-5fbdc78ac8|
00000070  36 65 32 07 32 32 36 38  35 33 34 38 00 42 08 08  |6e2.22685348.B..|
00000080  b1 b2 e2 a1 06 10 00 7a  00 8a 01 c4 01 0a 0e 6b  |.......z.......k|
00000090  75 62 65 2d 73 63 68 65  64 75 6c 65 72 12 06 55  |ube-scheduler..U|
000000a0  70 64 61 74 65 1a 16 63  6f 6f 72 64 69 6e 61 74  |pdate..coordinat|
000000b0  69 6f 6e 2e 6b 38 73 2e  69 6f 2f 76 31 22 08 08  |ion.k8s.io/v1"..|
000000c0  b1 b2 e2 a1 06 10 00 32  08 46 69 65 6c 64 73 56  |.......2.FieldsV|
000000d0  31 3a 7c 0a 7a 7b 22 66  3a 73 70 65 63 22 3a 7b  |1:|.z{"f:spec":{|
000000e0  22 66 3a 61 63 71 75 69  72 65 54 69 6d 65 22 3a  |"f:acquireTime":|
000000f0  7b 7d 2c 22 66 3a 68 6f  6c 64 65 72 49 64 65 6e  |{},"f:holderIden|
00000100  74 69 74 79 22 3a 7b 7d  2c 22 66 3a 6c 65 61 73  |tity":{},"f:leas|
00000110  65 44 75 72 61 74 69 6f  6e 53 65 63 6f 6e 64 73  |eDurationSeconds|
00000120  22 3a 7b 7d 2c 22 66 3a  6c 65 61 73 65 54 72 61  |":{},"f:leaseTra|
00000130  6e 73 69 74 69 6f 6e 73  22 3a 7b 7d 2c 22 66 3a  |nsitions":{},"f:|
00000140  72 65 6e 65 77 54 69 6d  65 22 3a 7b 7d 7d 7d 42  |renewTime":{}}}B|
00000150  00 12 59 0a 37 6b 69 6e  64 2d 63 6f 6e 74 72 6f  |..Y.7kind-contro|
00000160  6c 2d 70 6c 61 6e 65 5f  30 64 32 66 61 66 39 33  |l-plane_0d2faf93|
00000170  2d 34 61 30 62 2d 34 66  32 38 2d 38 33 64 33 2d  |-4a0b-4f28-83d3-|
00000180  35 62 35 62 62 66 61 31  65 36 31 30 10 0f 1a 0c  |5b5bbfa1e610....|
00000190  08 f7 a5 86 a2 06 10 b9  84 b7 94 03 22 0c 08 fa  |............"...|
000001a0  ec bd a2 06 10 ee 98 ad  d2 01 28 0a 1a 00 22 00  |..........(...".|
I0501 08:21:16.593023       1 request.go:1152] Request Body:
00000000  6b 38 73 00 0a 1f 0a 16  63 6f 6f 72 64 69 6e 61  |k8s.....coordina|
00000010  74 69 6f 6e 2e 6b 38 73  2e 69 6f 2f 76 31 12 05  |tion.k8s.io/v1..|
00000020  4c 65 61 73 65 12 84 03  0a a6 02 0a 0e 6b 75 62  |Lease........kub|
00000030  65 2d 73 63 68 65 64 75  6c 65 72 12 00 1a 0b 6b  |e-scheduler....k|
00000040  75 62 65 2d 73 79 73 74  65 6d 22 00 2a 24 36 61  |ube-system".*$6a|
00000050  30 65 32 30 33 66 2d 65  32 38 30 2d 34 36 61 30  |0e203f-e280-46a0|
00000060  2d 39 35 33 62 2d 35 66  62 64 63 37 38 61 63 38  |-953b-5fbdc78ac8|
00000070  36 65 32 07 32 32 36 38  35 33 34 38 00 42 08 08  |6e2.22685348.B..|
00000080  b1 b2 e2 a1 06 10 00 7a  00 8a 01 c4 01 0a 0e 6b  |.......z.......k|
00000090  75 62 65 2d 73 63 68 65  64 75 6c 65 72 12 06 55  |ube-scheduler..U|
000000a0  70 64 61 74 65 1a 16 63  6f 6f 72 64 69 6e 61 74  |pdate..coordinat|
000000b0  69 6f 6e 2e 6b 38 73 2e  69 6f 2f 76 31 22 08 08  |ion.k8s.io/v1"..|
000000c0  b1 b2 e2 a1 06 10 00 32  08 46 69 65 6c 64 73 56  |.......2.FieldsV|
000000d0  31 3a 7c 0a 7a 7b 22 66  3a 73 70 65 63 22 3a 7b  |1:|.z{"f:spec":{|
000000e0  22 66 3a 61 63 71 75 69  72 65 54 69 6d 65 22 3a  |"f:acquireTime":|
000000f0  7b 7d 2c 22 66 3a 68 6f  6c 64 65 72 49 64 65 6e  |{},"f:holderIden|
00000100  74 69 74 79 22 3a 7b 7d  2c 22 66 3a 6c 65 61 73  |tity":{},"f:leas|
00000110  65 44 75 72 61 74 69 6f  6e 53 65 63 6f 6e 64 73  |eDurationSeconds|
00000120  22 3a 7b 7d 2c 22 66 3a  6c 65 61 73 65 54 72 61  |":{},"f:leaseTra|
00000130  6e 73 69 74 69 6f 6e 73  22 3a 7b 7d 2c 22 66 3a  |nsitions":{},"f:|
00000140  72 65 6e 65 77 54 69 6d  65 22 3a 7b 7d 7d 7d 42  |renewTime":{}}}B|
00000150  00 12 59 0a 37 6b 69 6e  64 2d 63 6f 6e 74 72 6f  |..Y.7kind-contro|
00000160  6c 2d 70 6c 61 6e 65 5f  30 64 32 66 61 66 39 33  |l-plane_0d2faf93|
00000170  2d 34 61 30 62 2d 34 66  32 38 2d 38 33 64 33 2d  |-4a0b-4f28-83d3-|
00000180  35 62 35 62 62 66 61 31  65 36 31 30 10 0f 1a 0c  |5b5bbfa1e610....|
00000190  08 f7 a5 86 a2 06 10 b9  84 b7 94 03 22 0c 08 fc  |............"...|
000001a0  ec bd a2 06 10 9a ab 91  d9 01 28 0a 1a 00 22 00  |..........(...".|
I0501 08:21:16.593177       1 round_trippers.go:466] curl -v -XPUT  -H "User-Agent: kube-scheduler/v1.24.7 (linux/amd64) kubernetes/e6f3597/leader-election" -H "Accept: application/vnd.kubernetes.protobuf, */*" -H "Content-Type: application/vnd.kubernetes.protobuf" 'https://172.18.0.2:6443/apis/coordination.k8s.io/v1/namespaces/kube-system/leases/kube-scheduler?timeout=5s'
I0501 08:21:16.599825       1 round_trippers.go:553] POST https://172.18.0.2:6443/api/v1/namespaces/default/pods/nginx-deployment-66f58bff7c-m9fqn/binding 201 Created in 116 milliseconds
I0501 08:21:16.599880       1 round_trippers.go:570] HTTP Statistics: GetConnection 0 ms ServerProcessing 116 ms Duration 116 ms
I0501 08:21:16.599896       1 round_trippers.go:577] Response Headers:
I0501 08:21:16.599914       1 round_trippers.go:580]     Cache-Control: no-cache, private
I0501 08:21:16.599930       1 round_trippers.go:580]     Content-Type: application/vnd.kubernetes.protobuf
I0501 08:21:16.599945       1 round_trippers.go:580]     X-Kubernetes-Pf-Flowschema-Uid: 8a935dea-6b5d-4402-a842-ba69f911704f
I0501 08:21:16.599961       1 round_trippers.go:580]     X-Kubernetes-Pf-Prioritylevel-Uid: 4ccc4fdb-4419-4777-8b6f-3ed0d4949e5d
I0501 08:21:16.599976       1 round_trippers.go:580]     Content-Length: 48
I0501 08:21:16.600006       1 round_trippers.go:580]     Date: Mon, 01 May 2023 08:21:16 GMT
I0501 08:21:16.600022       1 round_trippers.go:580]     Audit-Id: d60bd7d4-5891-43e9-8510-dcc2e2ecaba9
I0501 08:21:16.600120       1 request.go:1152] Response Body:
00000000  6b 38 73 00 0a 0c 0a 02  76 31 12 06 53 74 61 74  |k8s.....v1..Stat|
00000010  75 73 12 18 0a 06 0a 00  12 00 1a 00 12 07 53 75  |us............Su|
00000020  63 63 65 73 73 1a 00 22  00 30 c9 01 1a 00 22 00  |ccess..".0....".|
I0501 08:21:16.600196       1 round_trippers.go:553] POST https://172.18.0.2:6443/api/v1/namespaces/default/pods/nginx-deployment-66f58bff7c-dmm7c/binding 201 Created in 114 milliseconds
I0501 08:21:16.600226       1 round_trippers.go:570] HTTP Statistics: GetConnection 0 ms ServerProcessing 114 ms Duration 114 ms
I0501 08:21:16.600241       1 round_trippers.go:577] Response Headers:
I0501 08:21:16.600257       1 round_trippers.go:580]     Audit-Id: 410c4b27-44a6-4996-9c41-aeb96c5a5671
I0501 08:21:16.600272       1 cache.go:379] "Finished binding for pod, can be expired" pod="default/nginx-deployment-66f58bff7c-m9fqn"
I0501 08:21:16.600343       1 schedule_one.go:265] "Successfully bound pod to node" pod="default/nginx-deployment-66f58bff7c-m9fqn" node="kind-worker" evaluatedNodes=4 feasibleNodes=3
I0501 08:21:16.600581       1 request.go:1152] Request Body:
00000000  6b 38 73 00 0a 19 0a 10  65 76 65 6e 74 73 2e 6b  |k8s.....events.k|
00000010  38 73 2e 69 6f 2f 76 31  12 05 45 76 65 6e 74 12  |8s.io/v1..Event.|
00000020  f4 02 0a 4b 0a 32 6e 67  69 6e 78 2d 64 65 70 6c  |...K.2nginx-depl|
00000030  6f 79 6d 65 6e 74 2d 36  36 66 35 38 62 66 66 37  |oyment-66f58bff7|
00000040  63 2d 6d 39 66 71 6e 2e  31 37 35 61 66 37 34 32  |c-m9fqn.175af742|
00000050  62 31 64 64 66 35 63 63  12 00 1a 07 64 65 66 61  |b1ddf5cc....defa|
00000060  75 6c 74 22 00 2a 00 32  00 38 00 42 00 7a 00 12  |ult".*.2.8.B.z..|
00000070  0c 08 fc ec bd a2 06 10  ad b5 9f 9e 02 22 11 64  |.............".d|
00000080  65 66 61 75 6c 74 2d 73  63 68 65 64 75 6c 65 72  |efault-scheduler|
00000090  2a 24 64 65 66 61 75 6c  74 2d 73 63 68 65 64 75  |*$default-schedu|
000000a0  6c 65 72 2d 6b 69 6e 64  2d 63 6f 6e 74 72 6f 6c  |ler-kind-control|
000000b0  2d 70 6c 61 6e 65 32 07  42 69 6e 64 69 6e 67 3a  |-plane2.Binding:|
000000c0  09 53 63 68 65 64 75 6c  65 64 42 66 0a 03 50 6f  |.ScheduledBf..Po|
000000d0  64 12 07 64 65 66 61 75  6c 74 1a 21 6e 67 69 6e  |d..default.!ngin|
000000e0  78 2d 64 65 70 6c 6f 79  6d 65 6e 74 2d 36 36 66  |x-deployment-66f|
000000f0  35 38 62 66 66 37 63 2d  6d 39 66 71 6e 22 24 38  |58bff7c-m9fqn"$8|
00000100  62 62 66 39 38 34 66 2d  61 30 37 62 2d 34 65 61  |bbf984f-a07b-4ea|
00000110  61 2d 39 34 66 63 2d 38  63 38 37 30 62 65 31 66  |a-94fc-8c870be1f|
00000120  33 35 39 2a 02 76 31 32  07 32 32 36 38 35 35 31  |359*.v12.2268551|
00000130  3a 00 52 4e 53 75 63 63  65 73 73 66 75 6c 6c 79  |:.RNSuccessfully|
00000140  20 61 73 73 69 67 6e 65  64 20 64 65 66 61 75 6c  | assigned defaul|
00000150  74 2f 6e 67 69 6e 78 2d  64 65 70 6c 6f 79 6d 65  |t/nginx-deployme|
00000160  6e 74 2d 36 36 66 35 38  62 66 66 37 63 2d 6d 39  |nt-66f58bff7c-m9|
00000170  66 71 6e 20 74 6f 20 6b  69 6e 64 2d 77 6f 72 6b  |fqn to kind-work|
00000180  65 72 5a 06 4e 6f 72 6d  61 6c 62 04 0a 00 12 00  |erZ.Normalb.....|
00000190  6a 00 72 00 78 00 1a 00  22 00                    |j.r.x...".|
I0501 08:21:16.600704       1 round_trippers.go:466] curl -v -XPOST  -H "Accept: application/vnd.kubernetes.protobuf, */*" -H "Content-Type: application/vnd.kubernetes.protobuf" -H "User-Agent: kube-scheduler/v1.24.7 (linux/amd64) kubernetes/e6f3597/scheduler" 'https://172.18.0.2:6443/apis/events.k8s.io/v1/namespaces/default/events'
I0501 08:21:16.600286       1 round_trippers.go:580]     Cache-Control: no-cache, private
I0501 08:21:16.600955       1 round_trippers.go:580]     Content-Type: application/vnd.kubernetes.protobuf
I0501 08:21:16.600981       1 round_trippers.go:580]     X-Kubernetes-Pf-Flowschema-Uid: 8a935dea-6b5d-4402-a842-ba69f911704f
I0501 08:21:16.600997       1 round_trippers.go:580]     X-Kubernetes-Pf-Prioritylevel-Uid: 4ccc4fdb-4419-4777-8b6f-3ed0d4949e5d
I0501 08:21:16.601012       1 round_trippers.go:580]     Content-Length: 48
I0501 08:21:16.601027       1 round_trippers.go:580]     Date: Mon, 01 May 2023 08:21:16 GMT
I0501 08:21:16.601079       1 request.go:1152] Response Body:
00000000  6b 38 73 00 0a 0c 0a 02  76 31 12 06 53 74 61 74  |k8s.....v1..Stat|
00000010  75 73 12 18 0a 06 0a 00  12 00 1a 00 12 07 53 75  |us............Su|
00000020  63 63 65 73 73 1a 00 22  00 30 c9 01 1a 00 22 00  |ccess..".0....".|
I0501 08:21:16.601144       1 cache.go:379] "Finished binding for pod, can be expired" pod="default/nginx-deployment-66f58bff7c-dmm7c"
I0501 08:21:16.601192       1 schedule_one.go:265] "Successfully bound pod to node" pod="default/nginx-deployment-66f58bff7c-dmm7c" node="kind-worker2" evaluatedNodes=4 feasibleNodes=3
I0501 08:21:16.601295       1 request.go:1152] Request Body:
00000000  6b 38 73 00 0a 19 0a 10  65 76 65 6e 74 73 2e 6b  |k8s.....events.k|
00000010  38 73 2e 69 6f 2f 76 31  12 05 45 76 65 6e 74 12  |8s.io/v1..Event.|
00000020  f5 02 0a 4b 0a 32 6e 67  69 6e 78 2d 64 65 70 6c  |...K.2nginx-depl|
00000030  6f 79 6d 65 6e 74 2d 36  36 66 35 38 62 66 66 37  |oyment-66f58bff7|
00000040  63 2d 64 6d 6d 37 63 2e  31 37 35 61 66 37 34 32  |c-dmm7c.175af742|
00000050  62 31 65 62 30 36 39 61  12 00 1a 07 64 65 66 61  |b1eb069a....defa|
00000060  75 6c 74 22 00 2a 00 32  00 38 00 42 00 7a 00 12  |ult".*.2.8.B.z..|
00000070  0c 08 fc ec bd a2 06 10  a5 af d4 9e 02 22 11 64  |.............".d|
00000080  65 66 61 75 6c 74 2d 73  63 68 65 64 75 6c 65 72  |efault-scheduler|
00000090  2a 24 64 65 66 61 75 6c  74 2d 73 63 68 65 64 75  |*$default-schedu|
000000a0  6c 65 72 2d 6b 69 6e 64  2d 63 6f 6e 74 72 6f 6c  |ler-kind-control|
000000b0  2d 70 6c 61 6e 65 32 07  42 69 6e 64 69 6e 67 3a  |-plane2.Binding:|
000000c0  09 53 63 68 65 64 75 6c  65 64 42 66 0a 03 50 6f  |.ScheduledBf..Po|
000000d0  64 12 07 64 65 66 61 75  6c 74 1a 21 6e 67 69 6e  |d..default.!ngin|
000000e0  78 2d 64 65 70 6c 6f 79  6d 65 6e 74 2d 36 36 66  |x-deployment-66f|
000000f0  35 38 62 66 66 37 63 2d  64 6d 6d 37 63 22 24 39  |58bff7c-dmm7c"$9|
00000100  34 39 31 32 35 31 38 2d  62 30 33 39 2d 34 39 32  |4912518-b039-492|
00000110  38 2d 62 36 38 34 2d 39  36 33 30 63 37 32 61 61  |8-b684-9630c72aa|
00000120  38 33 62 2a 02 76 31 32  07 32 32 36 38 35 35 32  |83b*.v12.2268552|
00000130  3a 00 52 4f 53 75 63 63  65 73 73 66 75 6c 6c 79  |:.ROSuccessfully|
00000140  20 61 73 73 69 67 6e 65  64 20 64 65 66 61 75 6c  | assigned defaul|
00000150  74 2f 6e 67 69 6e 78 2d  64 65 70 6c 6f 79 6d 65  |t/nginx-deployme|
00000160  6e 74 2d 36 36 66 35 38  62 66 66 37 63 2d 64 6d  |nt-66f58bff7c-dm|
00000170  6d 37 63 20 74 6f 20 6b  69 6e 64 2d 77 6f 72 6b  |m7c to kind-work|
00000180  65 72 32 5a 06 4e 6f 72  6d 61 6c 62 04 0a 00 12  |er2Z.Normalb....|
00000190  00 6a 00 72 00 78 00 1a  00 22 00                 |.j.r.x...".|
I0501 08:21:16.602848       1 round_trippers.go:553] POST https://172.18.0.2:6443/apis/events.k8s.io/v1/namespaces/default/events 201 Created in 126 milliseconds
I0501 08:21:16.602895       1 round_trippers.go:570] HTTP Statistics: GetConnection 0 ms ServerProcessing 126 ms Duration 126 ms
I0501 08:21:16.602913       1 round_trippers.go:577] Response Headers:
I0501 08:21:16.602930       1 round_trippers.go:580]     X-Kubernetes-Pf-Flowschema-Uid: 8a935dea-6b5d-4402-a842-ba69f911704f
I0501 08:21:16.602946       1 round_trippers.go:580]     X-Kubernetes-Pf-Prioritylevel-Uid: 4ccc4fdb-4419-4777-8b6f-3ed0d4949e5d
I0501 08:21:16.602961       1 round_trippers.go:580]     Content-Length: 676
I0501 08:21:16.602990       1 round_trippers.go:580]     Date: Mon, 01 May 2023 08:21:16 GMT
I0501 08:21:16.603006       1 round_trippers.go:580]     Audit-Id: 209f91d7-4150-4d8f-85b6-2fcba17edb79
I0501 08:21:16.603022       1 round_trippers.go:580]     Cache-Control: no-cache, private
I0501 08:21:16.603050       1 round_trippers.go:580]     Content-Type: application/vnd.kubernetes.protobuf
I0501 08:21:16.603162       1 request.go:1152] Response Body:
00000000  6b 38 73 00 0a 19 0a 10  65 76 65 6e 74 73 2e 6b  |k8s.....events.k|
00000010  38 73 2e 69 6f 2f 76 31  12 05 45 76 65 6e 74 12  |8s.io/v1..Event.|
00000020  fe 04 0a d3 02 0a 32 6e  67 69 6e 78 2d 64 65 70  |......2nginx-dep|
00000030  6c 6f 79 6d 65 6e 74 2d  36 36 66 35 38 62 66 66  |loyment-66f58bff|
00000040  37 63 2d 7a 72 39 6d 35  2e 31 37 35 61 66 37 34  |7c-zr9m5.175af74|
00000050  32 61 61 37 30 39 66 63  32 12 00 1a 07 64 65 66  |2aa709fc2....def|
00000060  61 75 6c 74 22 00 2a 24  36 31 39 39 36 61 66 62  |ault".*$61996afb|
00000070  2d 35 38 62 65 2d 34 66  31 34 2d 39 37 61 61 2d  |-58be-4f14-97aa-|
00000080  31 33 66 39 33 33 33 63  61 36 66 37 32 07 32 32  |13f9333ca6f72.22|
00000090  36 38 35 35 37 38 00 42  08 08 fc ec bd a2 06 10  |685578.B........|
000000a0  00 7a 00 8a 01 d1 01 0a  0e 6b 75 62 65 2d 73 63  |.z.......kube-sc|
000000b0  68 65 64 75 6c 65 72 12  06 55 70 64 61 74 65 1a  |heduler..Update.|
000000c0  10 65 76 65 6e 74 73 2e  6b 38 73 2e 69 6f 2f 76  |.events.k8s.io/v|
000000d0  31 22 08 08 fc ec bd a2  06 10 00 32 08 46 69 65  |1".........2.Fie|
000000e0  6c 64 73 56 31 3a 8e 01  0a 8b 01 7b 22 66 3a 61  |ldsV1:.....{"f:a|
000000f0  63 74 69 6f 6e 22 3a 7b  7d 2c 22 66 3a 65 76 65  |ction":{},"f:eve|
00000100  6e 74 54 69 6d 65 22 3a  7b 7d 2c 22 66 3a 6e 6f  |ntTime":{},"f:no|
00000110  74 65 22 3a 7b 7d 2c 22  66 3a 72 65 61 73 6f 6e  |te":{},"f:reason|
00000120  22 3a 7b 7d 2c 22 66 3a  72 65 67 61 72 64 69 6e  |":{},"f:regardin|
00000130  67 22 3a 7b 7d 2c 22 66  3a 72 65 70 6f 72 74 69  |g":{},"f:reporti|
00000140  6e 67 43 6f 6e 74 72 6f  6c 6c 65 72 22 3a 7b 7d  |ngController":{}|
00000150  2c 22 66 3a 72 65 70 6f  72 74 69 6e 67 49 6e 73  |,"f:reportingIns|
00000160  74 61 6e 63 65 22 3a 7b  7d 2c 22 66 3a 74 79 70  |tance":{},"f:typ|
00000170  65 22 3a 7b 7d 7d 42 00  12 0c 08 fc ec bd a2 06  |e":{}}B.........|
00000180  10 96 96 ea e2 01 22 11  64 65 66 61 75 6c 74 2d  |......".default-|
00000190  73 63 68 65 64 75 6c 65  72 2a 24 64 65 66 61 75  |scheduler*$defau|
000001a0  6c 74 2d 73 63 68 65 64  75 6c 65 72 2d 6b 69 6e  |lt-scheduler-kin|
000001b0  64 2d 63 6f 6e 74 72 6f  6c 2d 70 6c 61 6e 65 32  |d-control-plane2|
000001c0  07 42 69 6e 64 69 6e 67  3a 09 53 63 68 65 64 75  |.Binding:.Schedu|
000001d0  6c 65 64 42 66 0a 03 50  6f 64 12 07 64 65 66 61  |ledBf..Pod..defa|
000001e0  75 6c 74 1a 21 6e 67 69  6e 78 2d 64 65 70 6c 6f  |ult.!nginx-deplo|
000001f0  79 6d 65 6e 74 2d 36 36  66 35 38 62 66 66 37 63  |yment-66f58bff7c|
00000200  2d 7a 72 39 6d 35 22 24  62 38 61 62 63 66 34 64  |-zr9m5"$b8abcf4d|
00000210  2d 66 30 39 65 2d 34 38  62 64 2d 62 31 61 33 2d  |-f09e-48bd-b1a3-|
00000220  64 61 31 33 30 35 62 36  62 64 38 63 2a 02 76 31  |da1305b6bd8c*.v1|
00000230  32 07 32 32 36 38 35 34  36 3a 00 52 4f 53 75 63  |2.2268546:.ROSuc|
00000240  63 65 73 73 66 75 6c 6c  79 20 61 73 73 69 67 6e  |cessfully assign|
00000250  65 64 20 64 65 66 61 75  6c 74 2f 6e 67 69 6e 78  |ed default/nginx|
00000260  2d 64 65 70 6c 6f 79 6d  65 6e 74 2d 36 36 66 35  |-deployment-66f5|
00000270  38 62 66 66 37 63 2d 7a  72 39 6d 35 20 74 6f 20  |8bff7c-zr9m5 to |
00000280  6b 69 6e 64 2d 77 6f 72  6b 65 72 33 5a 06 4e 6f  |kind-worker3Z.No|
00000290  72 6d 61 6c 62 04 0a 00  12 00 6a 00 72 00 78 00  |rmalb.....j.r.x.|
000002a0  1a 00 22 00                                       |..".|
I0501 08:21:16.601972       1 round_trippers.go:466] curl -v -XPOST  -H "Content-Type: application/vnd.kubernetes.protobuf" -H "User-Agent: kube-scheduler/v1.24.7 (linux/amd64) kubernetes/e6f3597/scheduler" -H "Accept: application/vnd.kubernetes.protobuf, */*" 'https://172.18.0.2:6443/apis/events.k8s.io/v1/namespaces/default/events'
I0501 08:21:16.612332       1 round_trippers.go:553] PUT https://172.18.0.2:6443/apis/coordination.k8s.io/v1/namespaces/kube-system/leases/kube-scheduler?timeout=5s 200 OK in 19 milliseconds
I0501 08:21:16.612405       1 round_trippers.go:570] HTTP Statistics: GetConnection 0 ms ServerProcessing 18 ms Duration 19 ms
I0501 08:21:16.612422       1 round_trippers.go:577] Response Headers:
I0501 08:21:16.612440       1 round_trippers.go:580]     Content-Type: application/vnd.kubernetes.protobuf
I0501 08:21:16.612456       1 round_trippers.go:580]     X-Kubernetes-Pf-Flowschema-Uid: 493426e8-0f6d-4ea6-bc2c-2d926c7e3221
I0501 08:21:16.612472       1 round_trippers.go:580]     X-Kubernetes-Pf-Prioritylevel-Uid: afabb116-6975-46b8-863b-3258bec9e1ea
I0501 08:21:16.612487       1 round_trippers.go:580]     Content-Length: 432
I0501 08:21:16.612502       1 round_trippers.go:580]     Date: Mon, 01 May 2023 08:21:16 GMT
I0501 08:21:16.612517       1 round_trippers.go:580]     Audit-Id: 80a6889c-f4c1-4191-a077-c93400c62383
I0501 08:21:16.612533       1 round_trippers.go:580]     Cache-Control: no-cache, private
I0501 08:21:16.612612       1 request.go:1152] Response Body:
00000000  6b 38 73 00 0a 1f 0a 16  63 6f 6f 72 64 69 6e 61  |k8s.....coordina|
00000010  74 69 6f 6e 2e 6b 38 73  2e 69 6f 2f 76 31 12 05  |tion.k8s.io/v1..|
00000020  4c 65 61 73 65 12 84 03  0a a6 02 0a 0e 6b 75 62  |Lease........kub|
00000030  65 2d 73 63 68 65 64 75  6c 65 72 12 00 1a 0b 6b  |e-scheduler....k|
00000040  75 62 65 2d 73 79 73 74  65 6d 22 00 2a 24 36 61  |ube-system".*$6a|
00000050  30 65 32 30 33 66 2d 65  32 38 30 2d 34 36 61 30  |0e203f-e280-46a0|
00000060  2d 39 35 33 62 2d 35 66  62 64 63 37 38 61 63 38  |-953b-5fbdc78ac8|
00000070  36 65 32 07 32 32 36 38  35 36 31 38 00 42 08 08  |6e2.22685618.B..|
00000080  b1 b2 e2 a1 06 10 00 7a  00 8a 01 c4 01 0a 0e 6b  |.......z.......k|
00000090  75 62 65 2d 73 63 68 65  64 75 6c 65 72 12 06 55  |ube-scheduler..U|
000000a0  70 64 61 74 65 1a 16 63  6f 6f 72 64 69 6e 61 74  |pdate..coordinat|
000000b0  69 6f 6e 2e 6b 38 73 2e  69 6f 2f 76 31 22 08 08  |ion.k8s.io/v1"..|
000000c0  b1 b2 e2 a1 06 10 00 32  08 46 69 65 6c 64 73 56  |.......2.FieldsV|
000000d0  31 3a 7c 0a 7a 7b 22 66  3a 73 70 65 63 22 3a 7b  |1:|.z{"f:spec":{|
000000e0  22 66 3a 61 63 71 75 69  72 65 54 69 6d 65 22 3a  |"f:acquireTime":|
000000f0  7b 7d 2c 22 66 3a 68 6f  6c 64 65 72 49 64 65 6e  |{},"f:holderIden|
00000100  74 69 74 79 22 3a 7b 7d  2c 22 66 3a 6c 65 61 73  |tity":{},"f:leas|
00000110  65 44 75 72 61 74 69 6f  6e 53 65 63 6f 6e 64 73  |eDurationSeconds|
00000120  22 3a 7b 7d 2c 22 66 3a  6c 65 61 73 65 54 72 61  |":{},"f:leaseTra|
00000130  6e 73 69 74 69 6f 6e 73  22 3a 7b 7d 2c 22 66 3a  |nsitions":{},"f:|
00000140  72 65 6e 65 77 54 69 6d  65 22 3a 7b 7d 7d 7d 42  |renewTime":{}}}B|
00000150  00 12 59 0a 37 6b 69 6e  64 2d 63 6f 6e 74 72 6f  |..Y.7kind-contro|
00000160  6c 2d 70 6c 61 6e 65 5f  30 64 32 66 61 66 39 33  |l-plane_0d2faf93|
00000170  2d 34 61 30 62 2d 34 66  32 38 2d 38 33 64 33 2d  |-4a0b-4f28-83d3-|
00000180  35 62 35 62 62 66 61 31  65 36 31 30 10 0f 1a 0c  |5b5bbfa1e610....|
00000190  08 f7 a5 86 a2 06 10 b9  84 b7 94 03 22 0c 08 fc  |............"...|
000001a0  ec bd a2 06 10 9a ab 91  d9 01 28 0a 1a 00 22 00  |..........(...".|
I0501 08:21:16.612744       1 leaderelection.go:278] successfully renewed lease kube-system/kube-scheduler
I0501 08:21:16.612792       1 eventhandlers.go:184] "Add event for scheduled pod" pod="default/nginx-deployment-66f58bff7c-m9fqn"
I0501 08:21:16.612893       1 eventhandlers.go:184] "Add event for scheduled pod" pod="default/nginx-deployment-66f58bff7c-dmm7c"
I0501 08:21:16.612743       1 eventhandlers.go:159] "Delete event for unscheduled pod" pod="default/nginx-deployment-66f58bff7c-m9fqn"
I0501 08:21:16.613041       1 eventhandlers.go:159] "Delete event for unscheduled pod" pod="default/nginx-deployment-66f58bff7c-dmm7c"
I0501 08:21:16.632907       1 eventhandlers.go:204] "Update event for scheduled pod" pod="default/nginx-deployment-66f58bff7c-x8rw9"
I0501 08:21:16.632987       1 eventhandlers.go:204] "Update event for scheduled pod" pod="default/nginx-deployment-66f58bff7c-l7r5r"
I0501 08:21:16.636016       1 round_trippers.go:553] POST https://172.18.0.2:6443/apis/events.k8s.io/v1/namespaces/default/events 201 Created in 35 milliseconds
I0501 08:21:16.636120       1 round_trippers.go:570] HTTP Statistics: GetConnection 0 ms ServerProcessing 35 ms Duration 35 ms
I0501 08:21:16.636187       1 round_trippers.go:577] Response Headers:
I0501 08:21:16.636251       1 round_trippers.go:580]     Audit-Id: 86910c4d-1871-402c-80ce-7dfd640b4208
I0501 08:21:16.636312       1 round_trippers.go:580]     Cache-Control: no-cache, private
I0501 08:21:16.636373       1 round_trippers.go:580]     Content-Type: application/vnd.kubernetes.protobuf
I0501 08:21:16.636434       1 round_trippers.go:580]     X-Kubernetes-Pf-Flowschema-Uid: 8a935dea-6b5d-4402-a842-ba69f911704f
I0501 08:21:16.636494       1 round_trippers.go:580]     X-Kubernetes-Pf-Prioritylevel-Uid: 4ccc4fdb-4419-4777-8b6f-3ed0d4949e5d
I0501 08:21:16.636555       1 round_trippers.go:580]     Content-Length: 675
I0501 08:21:16.636616       1 round_trippers.go:580]     Date: Mon, 01 May 2023 08:21:16 GMT
I0501 08:21:16.636744       1 request.go:1152] Response Body:
00000000  6b 38 73 00 0a 19 0a 10  65 76 65 6e 74 73 2e 6b  |k8s.....events.k|
00000010  38 73 2e 69 6f 2f 76 31  12 05 45 76 65 6e 74 12  |8s.io/v1..Event.|
00000020  fd 04 0a d3 02 0a 32 6e  67 69 6e 78 2d 64 65 70  |......2nginx-dep|
00000030  6c 6f 79 6d 65 6e 74 2d  36 36 66 35 38 62 66 66  |loyment-66f58bff|
00000040  37 63 2d 6d 39 66 71 6e  2e 31 37 35 61 66 37 34  |7c-m9fqn.175af74|
00000050  32 62 31 64 64 66 35 63  63 12 00 1a 07 64 65 66  |2b1ddf5cc....def|
00000060  61 75 6c 74 22 00 2a 24  62 63 62 61 31 62 63 66  |ault".*$bcba1bcf|
00000070  2d 63 38 39 65 2d 34 30  37 39 2d 38 61 66 33 2d  |-c89e-4079-8af3-|
00000080  31 35 34 38 66 66 31 62  39 38 62 37 32 07 32 32  |1548ff1b98b72.22|
00000090  36 38 35 36 34 38 00 42  08 08 fc ec bd a2 06 10  |685648.B........|
000000a0  00 7a 00 8a 01 d1 01 0a  0e 6b 75 62 65 2d 73 63  |.z.......kube-sc|
000000b0  68 65 64 75 6c 65 72 12  06 55 70 64 61 74 65 1a  |heduler..Update.|
000000c0  10 65 76 65 6e 74 73 2e  6b 38 73 2e 69 6f 2f 76  |.events.k8s.io/v|
000000d0  31 22 08 08 fc ec bd a2  06 10 00 32 08 46 69 65  |1".........2.Fie|
000000e0  6c 64 73 56 31 3a 8e 01  0a 8b 01 7b 22 66 3a 61  |ldsV1:.....{"f:a|
000000f0  63 74 69 6f 6e 22 3a 7b  7d 2c 22 66 3a 65 76 65  |ction":{},"f:eve|
00000100  6e 74 54 69 6d 65 22 3a  7b 7d 2c 22 66 3a 6e 6f  |ntTime":{},"f:no|
00000110  74 65 22 3a 7b 7d 2c 22  66 3a 72 65 61 73 6f 6e  |te":{},"f:reason|
00000120  22 3a 7b 7d 2c 22 66 3a  72 65 67 61 72 64 69 6e  |":{},"f:regardin|
00000130  67 22 3a 7b 7d 2c 22 66  3a 72 65 70 6f 72 74 69  |g":{},"f:reporti|
00000140  6e 67 43 6f 6e 74 72 6f  6c 6c 65 72 22 3a 7b 7d  |ngController":{}|
00000150  2c 22 66 3a 72 65 70 6f  72 74 69 6e 67 49 6e 73  |,"f:reportingIns|
00000160  74 61 6e 63 65 22 3a 7b  7d 2c 22 66 3a 74 79 70  |tance":{},"f:typ|
00000170  65 22 3a 7b 7d 7d 42 00  12 0c 08 fc ec bd a2 06  |e":{}}B.........|
00000180  10 ad b5 9f 9e 02 22 11  64 65 66 61 75 6c 74 2d  |......".default-|
00000190  73 63 68 65 64 75 6c 65  72 2a 24 64 65 66 61 75  |scheduler*$defau|
000001a0  6c 74 2d 73 63 68 65 64  75 6c 65 72 2d 6b 69 6e  |lt-scheduler-kin|
000001b0  64 2d 63 6f 6e 74 72 6f  6c 2d 70 6c 61 6e 65 32  |d-control-plane2|
000001c0  07 42 69 6e 64 69 6e 67  3a 09 53 63 68 65 64 75  |.Binding:.Schedu|
000001d0  6c 65 64 42 66 0a 03 50  6f 64 12 07 64 65 66 61  |ledBf..Pod..defa|
000001e0  75 6c 74 1a 21 6e 67 69  6e 78 2d 64 65 70 6c 6f  |ult.!nginx-deplo|
000001f0  79 6d 65 6e 74 2d 36 36  66 35 38 62 66 66 37 63  |yment-66f58bff7c|
00000200  2d 6d 39 66 71 6e 22 24  38 62 62 66 39 38 34 66  |-m9fqn"$8bbf984f|
00000210  2d 61 30 37 62 2d 34 65  61 61 2d 39 34 66 63 2d  |-a07b-4eaa-94fc-|
00000220  38 63 38 37 30 62 65 31  66 33 35 39 2a 02 76 31  |8c870be1f359*.v1|
00000230  32 07 32 32 36 38 35 35  31 3a 00 52 4e 53 75 63  |2.2268551:.RNSuc|
00000240  63 65 73 73 66 75 6c 6c  79 20 61 73 73 69 67 6e  |cessfully assign|
00000250  65 64 20 64 65 66 61 75  6c 74 2f 6e 67 69 6e 78  |ed default/nginx|
00000260  2d 64 65 70 6c 6f 79 6d  65 6e 74 2d 36 36 66 35  |-deployment-66f5|
00000270  38 62 66 66 37 63 2d 6d  39 66 71 6e 20 74 6f 20  |8bff7c-m9fqn to |
00000280  6b 69 6e 64 2d 77 6f 72  6b 65 72 5a 06 4e 6f 72  |kind-workerZ.Nor|
00000290  6d 61 6c 62 04 0a 00 12  00 6a 00 72 00 78 00 1a  |malb.....j.r.x..|
000002a0  00 22 00                                          |.".|
I0501 08:21:16.645075       1 round_trippers.go:553] POST https://172.18.0.2:6443/apis/events.k8s.io/v1/namespaces/default/events 201 Created in 41 milliseconds
I0501 08:21:16.645117       1 round_trippers.go:570] HTTP Statistics: GetConnection 0 ms ServerProcessing 40 ms Duration 41 ms
I0501 08:21:16.645133       1 round_trippers.go:577] Response Headers:
I0501 08:21:16.645151       1 round_trippers.go:580]     X-Kubernetes-Pf-Flowschema-Uid: 8a935dea-6b5d-4402-a842-ba69f911704f
I0501 08:21:16.645167       1 round_trippers.go:580]     X-Kubernetes-Pf-Prioritylevel-Uid: 4ccc4fdb-4419-4777-8b6f-3ed0d4949e5d
I0501 08:21:16.645182       1 round_trippers.go:580]     Content-Length: 676
I0501 08:21:16.645197       1 round_trippers.go:580]     Date: Mon, 01 May 2023 08:21:16 GMT
I0501 08:21:16.645213       1 round_trippers.go:580]     Audit-Id: 2bda11be-319d-47c2-832f-a1d9655a401c
I0501 08:21:16.645228       1 round_trippers.go:580]     Cache-Control: no-cache, private
I0501 08:21:16.645243       1 round_trippers.go:580]     Content-Type: application/vnd.kubernetes.protobuf
I0501 08:21:16.645519       1 request.go:1152] Response Body:
00000000  6b 38 73 00 0a 19 0a 10  65 76 65 6e 74 73 2e 6b  |k8s.....events.k|
00000010  38 73 2e 69 6f 2f 76 31  12 05 45 76 65 6e 74 12  |8s.io/v1..Event.|
00000020  fe 04 0a d3 02 0a 32 6e  67 69 6e 78 2d 64 65 70  |......2nginx-dep|
00000030  6c 6f 79 6d 65 6e 74 2d  36 36 66 35 38 62 66 66  |loyment-66f58bff|
00000040  37 63 2d 64 6d 6d 37 63  2e 31 37 35 61 66 37 34  |7c-dmm7c.175af74|
00000050  32 62 31 65 62 30 36 39  61 12 00 1a 07 64 65 66  |2b1eb069a....def|
00000060  61 75 6c 74 22 00 2a 24  66 33 33 61 37 39 36 34  |ault".*$f33a7964|
00000070  2d 38 36 33 34 2d 34 63  30 38 2d 62 63 64 34 2d  |-8634-4c08-bcd4-|
00000080  33 32 63 66 32 64 34 64  39 30 32 39 32 07 32 32  |32cf2d4d90292.22|
00000090  36 38 35 36 36 38 00 42  08 08 fc ec bd a2 06 10  |685668.B........|
000000a0  00 7a 00 8a 01 d1 01 0a  0e 6b 75 62 65 2d 73 63  |.z.......kube-sc|
000000b0  68 65 64 75 6c 65 72 12  06 55 70 64 61 74 65 1a  |heduler..Update.|
000000c0  10 65 76 65 6e 74 73 2e  6b 38 73 2e 69 6f 2f 76  |.events.k8s.io/v|
000000d0  31 22 08 08 fc ec bd a2  06 10 00 32 08 46 69 65  |1".........2.Fie|
000000e0  6c 64 73 56 31 3a 8e 01  0a 8b 01 7b 22 66 3a 61  |ldsV1:.....{"f:a|
000000f0  63 74 69 6f 6e 22 3a 7b  7d 2c 22 66 3a 65 76 65  |ction":{},"f:eve|
00000100  6e 74 54 69 6d 65 22 3a  7b 7d 2c 22 66 3a 6e 6f  |ntTime":{},"f:no|
00000110  74 65 22 3a 7b 7d 2c 22  66 3a 72 65 61 73 6f 6e  |te":{},"f:reason|
00000120  22 3a 7b 7d 2c 22 66 3a  72 65 67 61 72 64 69 6e  |":{},"f:regardin|
00000130  67 22 3a 7b 7d 2c 22 66  3a 72 65 70 6f 72 74 69  |g":{},"f:reporti|
00000140  6e 67 43 6f 6e 74 72 6f  6c 6c 65 72 22 3a 7b 7d  |ngController":{}|
00000150  2c 22 66 3a 72 65 70 6f  72 74 69 6e 67 49 6e 73  |,"f:reportingIns|
00000160  74 61 6e 63 65 22 3a 7b  7d 2c 22 66 3a 74 79 70  |tance":{},"f:typ|
00000170  65 22 3a 7b 7d 7d 42 00  12 0c 08 fc ec bd a2 06  |e":{}}B.........|
00000180  10 a5 af d4 9e 02 22 11  64 65 66 61 75 6c 74 2d  |......".default-|
00000190  73 63 68 65 64 75 6c 65  72 2a 24 64 65 66 61 75  |scheduler*$defau|
000001a0  6c 74 2d 73 63 68 65 64  75 6c 65 72 2d 6b 69 6e  |lt-scheduler-kin|
000001b0  64 2d 63 6f 6e 74 72 6f  6c 2d 70 6c 61 6e 65 32  |d-control-plane2|
000001c0  07 42 69 6e 64 69 6e 67  3a 09 53 63 68 65 64 75  |.Binding:.Schedu|
000001d0  6c 65 64 42 66 0a 03 50  6f 64 12 07 64 65 66 61  |ledBf..Pod..defa|
000001e0  75 6c 74 1a 21 6e 67 69  6e 78 2d 64 65 70 6c 6f  |ult.!nginx-deplo|
000001f0  79 6d 65 6e 74 2d 36 36  66 35 38 62 66 66 37 63  |yment-66f58bff7c|
00000200  2d 64 6d 6d 37 63 22 24  39 34 39 31 32 35 31 38  |-dmm7c"$94912518|
00000210  2d 62 30 33 39 2d 34 39  32 38 2d 62 36 38 34 2d  |-b039-4928-b684-|
00000220  39 36 33 30 63 37 32 61  61 38 33 62 2a 02 76 31  |9630c72aa83b*.v1|
00000230  32 07 32 32 36 38 35 35  32 3a 00 52 4f 53 75 63  |2.2268552:.ROSuc|
00000240  63 65 73 73 66 75 6c 6c  79 20 61 73 73 69 67 6e  |cessfully assign|
00000250  65 64 20 64 65 66 61 75  6c 74 2f 6e 67 69 6e 78  |ed default/nginx|
00000260  2d 64 65 70 6c 6f 79 6d  65 6e 74 2d 36 36 66 35  |-deployment-66f5|
00000270  38 62 66 66 37 63 2d 64  6d 6d 37 63 20 74 6f 20  |8bff7c-dmm7c to |
00000280  6b 69 6e 64 2d 77 6f 72  6b 65 72 32 5a 06 4e 6f  |kind-worker2Z.No|
00000290  72 6d 61 6c 62 04 0a 00  12 00 6a 00 72 00 78 00  |rmalb.....j.r.x.|
000002a0  1a 00 22 00                                       |..".|
I0501 08:21:16.688723       1 eventhandlers.go:204] "Update event for scheduled pod" pod="default/nginx-deployment-66f58bff7c-dmm7c"
I0501 08:21:16.787636       1 eventhandlers.go:204] "Update event for scheduled pod" pod="default/nginx-deployment-66f58bff7c-zr9m5"
I0501 08:21:16.789580       1 eventhandlers.go:204] "Update event for scheduled pod" pod="default/nginx-deployment-66f58bff7c-m9fqn"
I0501 08:21:18.614003       1 round_trippers.go:466] curl -v -XGET  -H "Accept: application/vnd.kubernetes.protobuf, */*" -H "User-Agent: kube-scheduler/v1.24.7 (linux/amd64) kubernetes/e6f3597/leader-election" 'https://172.18.0.2:6443/apis/coordination.k8s.io/v1/namespaces/kube-system/leases/kube-scheduler?timeout=5s'
I0501 08:21:18.657150       1 round_trippers.go:553] GET https://172.18.0.2:6443/apis/coordination.k8s.io/v1/namespaces/kube-system/leases/kube-scheduler?timeout=5s 200 OK in 43 milliseconds
I0501 08:21:18.657218       1 round_trippers.go:570] HTTP Statistics: GetConnection 0 ms ServerProcessing 42 ms Duration 43 ms
I0501 08:21:18.657236       1 round_trippers.go:577] Response Headers:
I0501 08:21:18.657257       1 round_trippers.go:580]     X-Kubernetes-Pf-Prioritylevel-Uid: afabb116-6975-46b8-863b-3258bec9e1ea
I0501 08:21:18.657285       1 round_trippers.go:580]     Content-Length: 432
I0501 08:21:18.657311       1 round_trippers.go:580]     Date: Mon, 01 May 2023 08:21:18 GMT
I0501 08:21:18.657328       1 round_trippers.go:580]     Audit-Id: 814f7640-97ec-4184-b6a7-6dd6a8ade5db
I0501 08:21:18.657353       1 round_trippers.go:580]     Cache-Control: no-cache, private
I0501 08:21:18.657369       1 round_trippers.go:580]     Content-Type: application/vnd.kubernetes.protobuf
I0501 08:21:18.657402       1 round_trippers.go:580]     X-Kubernetes-Pf-Flowschema-Uid: 493426e8-0f6d-4ea6-bc2c-2d926c7e3221
I0501 08:21:18.657547       1 request.go:1152] Response Body:
00000000  6b 38 73 00 0a 1f 0a 16  63 6f 6f 72 64 69 6e 61  |k8s.....coordina|
00000010  74 69 6f 6e 2e 6b 38 73  2e 69 6f 2f 76 31 12 05  |tion.k8s.io/v1..|
00000020  4c 65 61 73 65 12 84 03  0a a6 02 0a 0e 6b 75 62  |Lease........kub|
00000030  65 2d 73 63 68 65 64 75  6c 65 72 12 00 1a 0b 6b  |e-scheduler....k|
00000040  75 62 65 2d 73 79 73 74  65 6d 22 00 2a 24 36 61  |ube-system".*$6a|
00000050  30 65 32 30 33 66 2d 65  32 38 30 2d 34 36 61 30  |0e203f-e280-46a0|
00000060  2d 39 35 33 62 2d 35 66  62 64 63 37 38 61 63 38  |-953b-5fbdc78ac8|
00000070  36 65 32 07 32 32 36 38  35 36 31 38 00 42 08 08  |6e2.22685618.B..|
00000080  b1 b2 e2 a1 06 10 00 7a  00 8a 01 c4 01 0a 0e 6b  |.......z.......k|
00000090  75 62 65 2d 73 63 68 65  64 75 6c 65 72 12 06 55  |ube-scheduler..U|
000000a0  70 64 61 74 65 1a 16 63  6f 6f 72 64 69 6e 61 74  |pdate..coordinat|
000000b0  69 6f 6e 2e 6b 38 73 2e  69 6f 2f 76 31 22 08 08  |ion.k8s.io/v1"..|
000000c0  b1 b2 e2 a1 06 10 00 32  08 46 69 65 6c 64 73 56  |.......2.FieldsV|
000000d0  31 3a 7c 0a 7a 7b 22 66  3a 73 70 65 63 22 3a 7b  |1:|.z{"f:spec":{|
000000e0  22 66 3a 61 63 71 75 69  72 65 54 69 6d 65 22 3a  |"f:acquireTime":|
000000f0  7b 7d 2c 22 66 3a 68 6f  6c 64 65 72 49 64 65 6e  |{},"f:holderIden|
00000100  74 69 74 79 22 3a 7b 7d  2c 22 66 3a 6c 65 61 73  |tity":{},"f:leas|
00000110  65 44 75 72 61 74 69 6f  6e 53 65 63 6f 6e 64 73  |eDurationSeconds|
00000120  22 3a 7b 7d 2c 22 66 3a  6c 65 61 73 65 54 72 61  |":{},"f:leaseTra|
00000130  6e 73 69 74 69 6f 6e 73  22 3a 7b 7d 2c 22 66 3a  |nsitions":{},"f:|
00000140  72 65 6e 65 77 54 69 6d  65 22 3a 7b 7d 7d 7d 42  |renewTime":{}}}B|
00000150  00 12 59 0a 37 6b 69 6e  64 2d 63 6f 6e 74 72 6f  |..Y.7kind-contro|
00000160  6c 2d 70 6c 61 6e 65 5f  30 64 32 66 61 66 39 33  |l-plane_0d2faf93|
00000170  2d 34 61 30 62 2d 34 66  32 38 2d 38 33 64 33 2d  |-4a0b-4f28-83d3-|
00000180  35 62 35 62 62 66 61 31  65 36 31 30 10 0f 1a 0c  |5b5bbfa1e610....|
00000190  08 f7 a5 86 a2 06 10 b9  84 b7 94 03 22 0c 08 fc  |............"...|
000001a0  ec bd a2 06 10 9a ab 91  d9 01 28 0a 1a 00 22 00  |..........(...".|
I0501 08:21:18.657860       1 request.go:1152] Request Body:
00000000  6b 38 73 00 0a 1f 0a 16  63 6f 6f 72 64 69 6e 61  |k8s.....coordina|
00000010  74 69 6f 6e 2e 6b 38 73  2e 69 6f 2f 76 31 12 05  |tion.k8s.io/v1..|
00000020  4c 65 61 73 65 12 84 03  0a a6 02 0a 0e 6b 75 62  |Lease........kub|
00000030  65 2d 73 63 68 65 64 75  6c 65 72 12 00 1a 0b 6b  |e-scheduler....k|
00000040  75 62 65 2d 73 79 73 74  65 6d 22 00 2a 24 36 61  |ube-system".*$6a|
00000050  30 65 32 30 33 66 2d 65  32 38 30 2d 34 36 61 30  |0e203f-e280-46a0|
00000060  2d 39 35 33 62 2d 35 66  62 64 63 37 38 61 63 38  |-953b-5fbdc78ac8|
00000070  36 65 32 07 32 32 36 38  35 36 31 38 00 42 08 08  |6e2.22685618.B..|
00000080  b1 b2 e2 a1 06 10 00 7a  00 8a 01 c4 01 0a 0e 6b  |.......z.......k|
00000090  75 62 65 2d 73 63 68 65  64 75 6c 65 72 12 06 55  |ube-scheduler..U|
000000a0  70 64 61 74 65 1a 16 63  6f 6f 72 64 69 6e 61 74  |pdate..coordinat|
000000b0  69 6f 6e 2e 6b 38 73 2e  69 6f 2f 76 31 22 08 08  |ion.k8s.io/v1"..|
000000c0  b1 b2 e2 a1 06 10 00 32  08 46 69 65 6c 64 73 56  |.......2.FieldsV|
000000d0  31 3a 7c 0a 7a 7b 22 66  3a 73 70 65 63 22 3a 7b  |1:|.z{"f:spec":{|
000000e0  22 66 3a 61 63 71 75 69  72 65 54 69 6d 65 22 3a  |"f:acquireTime":|
000000f0  7b 7d 2c 22 66 3a 68 6f  6c 64 65 72 49 64 65 6e  |{},"f:holderIden|
00000100  74 69 74 79 22 3a 7b 7d  2c 22 66 3a 6c 65 61 73  |tity":{},"f:leas|
00000110  65 44 75 72 61 74 69 6f  6e 53 65 63 6f 6e 64 73  |eDurationSeconds|
00000120  22 3a 7b 7d 2c 22 66 3a  6c 65 61 73 65 54 72 61  |":{},"f:leaseTra|
00000130  6e 73 69 74 69 6f 6e 73  22 3a 7b 7d 2c 22 66 3a  |nsitions":{},"f:|
00000140  72 65 6e 65 77 54 69 6d  65 22 3a 7b 7d 7d 7d 42  |renewTime":{}}}B|
00000150  00 12 59 0a 37 6b 69 6e  64 2d 63 6f 6e 74 72 6f  |..Y.7kind-contro|
00000160  6c 2d 70 6c 61 6e 65 5f  30 64 32 66 61 66 39 33  |l-plane_0d2faf93|
00000170  2d 34 61 30 62 2d 34 66  32 38 2d 38 33 64 33 2d  |-4a0b-4f28-83d3-|
00000180  35 62 35 62 62 66 61 31  65 36 31 30 10 0f 1a 0c  |5b5bbfa1e610....|
00000190  08 f7 a5 86 a2 06 10 b9  84 b7 94 03 22 0c 08 fe  |............"...|
000001a0  ec bd a2 06 10 e6 c9 d5  a4 02 28 0a 1a 00 22 00  |..........(...".|
I0501 08:21:18.658002       1 round_trippers.go:466] curl -v -XPUT  -H "Accept: application/vnd.kubernetes.protobuf, */*" -H "Content-Type: application/vnd.kubernetes.protobuf" -H "User-Agent: kube-scheduler/v1.24.7 (linux/amd64) kubernetes/e6f3597/leader-election" 'https://172.18.0.2:6443/apis/coordination.k8s.io/v1/namespaces/kube-system/leases/kube-scheduler?timeout=5s'
I0501 08:21:18.768341       1 round_trippers.go:553] PUT https://172.18.0.2:6443/apis/coordination.k8s.io/v1/namespaces/kube-system/leases/kube-scheduler?timeout=5s 200 OK in 110 milliseconds
I0501 08:21:18.768394       1 round_trippers.go:570] HTTP Statistics: GetConnection 0 ms ServerProcessing 109 ms Duration 110 ms
I0501 08:21:18.768411       1 round_trippers.go:577] Response Headers:
I0501 08:21:18.768429       1 round_trippers.go:580]     Date: Mon, 01 May 2023 08:21:18 GMT
I0501 08:21:18.768444       1 round_trippers.go:580]     Audit-Id: b6b3024f-cd59-4a55-8441-a1a487b62bdc
I0501 08:21:18.768459       1 round_trippers.go:580]     Cache-Control: no-cache, private
I0501 08:21:18.768474       1 round_trippers.go:580]     Content-Type: application/vnd.kubernetes.protobuf
I0501 08:21:18.768489       1 round_trippers.go:580]     X-Kubernetes-Pf-Flowschema-Uid: 493426e8-0f6d-4ea6-bc2c-2d926c7e3221
I0501 08:21:18.768503       1 round_trippers.go:580]     X-Kubernetes-Pf-Prioritylevel-Uid: afabb116-6975-46b8-863b-3258bec9e1ea
I0501 08:21:18.768530       1 round_trippers.go:580]     Content-Length: 432
I0501 08:21:18.768614       1 request.go:1152] Response Body:
00000000  6b 38 73 00 0a 1f 0a 16  63 6f 6f 72 64 69 6e 61  |k8s.....coordina|
00000010  74 69 6f 6e 2e 6b 38 73  2e 69 6f 2f 76 31 12 05  |tion.k8s.io/v1..|
00000020  4c 65 61 73 65 12 84 03  0a a6 02 0a 0e 6b 75 62  |Lease........kub|
00000030  65 2d 73 63 68 65 64 75  6c 65 72 12 00 1a 0b 6b  |e-scheduler....k|
00000040  75 62 65 2d 73 79 73 74  65 6d 22 00 2a 24 36 61  |ube-system".*$6a|
00000050  30 65 32 30 33 66 2d 65  32 38 30 2d 34 36 61 30  |0e203f-e280-46a0|
00000060  2d 39 35 33 62 2d 35 66  62 64 63 37 38 61 63 38  |-953b-5fbdc78ac8|
00000070  36 65 32 07 32 32 36 38  35 38 31 38 00 42 08 08  |6e2.22685818.B..|
00000080  b1 b2 e2 a1 06 10 00 7a  00 8a 01 c4 01 0a 0e 6b  |.......z.......k|
00000090  75 62 65 2d 73 63 68 65  64 75 6c 65 72 12 06 55  |ube-scheduler..U|
000000a0  70 64 61 74 65 1a 16 63  6f 6f 72 64 69 6e 61 74  |pdate..coordinat|
000000b0  69 6f 6e 2e 6b 38 73 2e  69 6f 2f 76 31 22 08 08  |ion.k8s.io/v1"..|
000000c0  b1 b2 e2 a1 06 10 00 32  08 46 69 65 6c 64 73 56  |.......2.FieldsV|
000000d0  31 3a 7c 0a 7a 7b 22 66  3a 73 70 65 63 22 3a 7b  |1:|.z{"f:spec":{|
000000e0  22 66 3a 61 63 71 75 69  72 65 54 69 6d 65 22 3a  |"f:acquireTime":|
000000f0  7b 7d 2c 22 66 3a 68 6f  6c 64 65 72 49 64 65 6e  |{},"f:holderIden|
00000100  74 69 74 79 22 3a 7b 7d  2c 22 66 3a 6c 65 61 73  |tity":{},"f:leas|
00000110  65 44 75 72 61 74 69 6f  6e 53 65 63 6f 6e 64 73  |eDurationSeconds|
00000120  22 3a 7b 7d 2c 22 66 3a  6c 65 61 73 65 54 72 61  |":{},"f:leaseTra|
00000130  6e 73 69 74 69 6f 6e 73  22 3a 7b 7d 2c 22 66 3a  |nsitions":{},"f:|
00000140  72 65 6e 65 77 54 69 6d  65 22 3a 7b 7d 7d 7d 42  |renewTime":{}}}B|
00000150  00 12 59 0a 37 6b 69 6e  64 2d 63 6f 6e 74 72 6f  |..Y.7kind-contro|
00000160  6c 2d 70 6c 61 6e 65 5f  30 64 32 66 61 66 39 33  |l-plane_0d2faf93|
00000170  2d 34 61 30 62 2d 34 66  32 38 2d 38 33 64 33 2d  |-4a0b-4f28-83d3-|
00000180  35 62 35 62 62 66 61 31  65 36 31 30 10 0f 1a 0c  |5b5bbfa1e610....|
00000190  08 f7 a5 86 a2 06 10 b9  84 b7 94 03 22 0c 08 fe  |............"...|
000001a0  ec bd a2 06 10 e6 c9 d5  a4 02 28 0a 1a 00 22 00  |..........(...".|
I0501 08:21:18.768741       1 leaderelection.go:278] successfully renewed lease kube-system/kube-scheduler
I0501 08:21:18.950855       1 eventhandlers.go:204] "Update event for scheduled pod" pod="default/nginx-deployment-66f58bff7c-x8rw9"
I0501 08:21:19.670235       1 pathrecorder.go:241] kube-scheduler: "/healthz" satisfied by exact match
I0501 08:21:19.670526       1 httplog.go:131] "HTTP" verb="GET" URI="/healthz" latency="366.75µs" userAgent="kube-probe/1.24" audit-ID="" srcIP="127.0.0.1:57932" resp=200
I0501 08:21:19.734848       1 eventhandlers.go:204] "Update event for scheduled pod" pod="default/nginx-deployment-66f58bff7c-m9fqn"
I0501 08:21:19.894230       1 eventhandlers.go:204] "Update event for scheduled pod" pod="default/nginx-deployment-66f58bff7c-dmm7c"
I0501 08:21:19.920219       1 eventhandlers.go:204] "Update event for scheduled pod" pod="default/nginx-deployment-66f58bff7c-zr9m5"
I0501 08:21:20.769807       1 round_trippers.go:466] curl -v -XGET  -H "Accept: application/vnd.kubernetes.protobuf, */*" -H "User-Agent: kube-scheduler/v1.24.7 (linux/amd64) kubernetes/e6f3597/leader-election" 'https://172.18.0.2:6443/apis/coordination.k8s.io/v1/namespaces/kube-system/leases/kube-scheduler?timeout=5s'
I0501 08:21:20.776095       1 round_trippers.go:553] GET https://172.18.0.2:6443/apis/coordination.k8s.io/v1/namespaces/kube-system/leases/kube-scheduler?timeout=5s 200 OK in 5 milliseconds
I0501 08:21:20.776157       1 round_trippers.go:570] HTTP Statistics: GetConnection 0 ms ServerProcessing 5 ms Duration 5 ms
I0501 08:21:20.776176       1 round_trippers.go:577] Response Headers:
I0501 08:21:20.776196       1 round_trippers.go:580]     X-Kubernetes-Pf-Flowschema-Uid: 493426e8-0f6d-4ea6-bc2c-2d926c7e3221
I0501 08:21:20.776213       1 round_trippers.go:580]     X-Kubernetes-Pf-Prioritylevel-Uid: afabb116-6975-46b8-863b-3258bec9e1ea
I0501 08:21:20.776230       1 round_trippers.go:580]     Content-Length: 432
I0501 08:21:20.776246       1 round_trippers.go:580]     Date: Mon, 01 May 2023 08:21:20 GMT
I0501 08:21:20.776280       1 round_trippers.go:580]     Audit-Id: 8ed27de5-798d-4d92-8c33-b49d1fb9438b
I0501 08:21:20.776308       1 round_trippers.go:580]     Cache-Control: no-cache, private
I0501 08:21:20.776325       1 round_trippers.go:580]     Content-Type: application/vnd.kubernetes.protobuf
I0501 08:21:20.776415       1 request.go:1152] Response Body:
00000000  6b 38 73 00 0a 1f 0a 16  63 6f 6f 72 64 69 6e 61  |k8s.....coordina|
00000010  74 69 6f 6e 2e 6b 38 73  2e 69 6f 2f 76 31 12 05  |tion.k8s.io/v1..|
00000020  4c 65 61 73 65 12 84 03  0a a6 02 0a 0e 6b 75 62  |Lease........kub|
00000030  65 2d 73 63 68 65 64 75  6c 65 72 12 00 1a 0b 6b  |e-scheduler....k|
00000040  75 62 65 2d 73 79 73 74  65 6d 22 00 2a 24 36 61  |ube-system".*$6a|
00000050  30 65 32 30 33 66 2d 65  32 38 30 2d 34 36 61 30  |0e203f-e280-46a0|
00000060  2d 39 35 33 62 2d 35 66  62 64 63 37 38 61 63 38  |-953b-5fbdc78ac8|
00000070  36 65 32 07 32 32 36 38  35 38 31 38 00 42 08 08  |6e2.22685818.B..|
00000080  b1 b2 e2 a1 06 10 00 7a  00 8a 01 c4 01 0a 0e 6b  |.......z.......k|
00000090  75 62 65 2d 73 63 68 65  64 75 6c 65 72 12 06 55  |ube-scheduler..U|
000000a0  70 64 61 74 65 1a 16 63  6f 6f 72 64 69 6e 61 74  |pdate..coordinat|
000000b0  69 6f 6e 2e 6b 38 73 2e  69 6f 2f 76 31 22 08 08  |ion.k8s.io/v1"..|
000000c0  b1 b2 e2 a1 06 10 00 32  08 46 69 65 6c 64 73 56  |.......2.FieldsV|
000000d0  31 3a 7c 0a 7a 7b 22 66  3a 73 70 65 63 22 3a 7b  |1:|.z{"f:spec":{|
000000e0  22 66 3a 61 63 71 75 69  72 65 54 69 6d 65 22 3a  |"f:acquireTime":|
000000f0  7b 7d 2c 22 66 3a 68 6f  6c 64 65 72 49 64 65 6e  |{},"f:holderIden|
00000100  74 69 74 79 22 3a 7b 7d  2c 22 66 3a 6c 65 61 73  |tity":{},"f:leas|
00000110  65 44 75 72 61 74 69 6f  6e 53 65 63 6f 6e 64 73  |eDurationSeconds|
00000120  22 3a 7b 7d 2c 22 66 3a  6c 65 61 73 65 54 72 61  |":{},"f:leaseTra|
00000130  6e 73 69 74 69 6f 6e 73  22 3a 7b 7d 2c 22 66 3a  |nsitions":{},"f:|
00000140  72 65 6e 65 77 54 69 6d  65 22 3a 7b 7d 7d 7d 42  |renewTime":{}}}B|
00000150  00 12 59 0a 37 6b 69 6e  64 2d 63 6f 6e 74 72 6f  |..Y.7kind-contro|
00000160  6c 2d 70 6c 61 6e 65 5f  30 64 32 66 61 66 39 33  |l-plane_0d2faf93|
00000170  2d 34 61 30 62 2d 34 66  32 38 2d 38 33 64 33 2d  |-4a0b-4f28-83d3-|
00000180  35 62 35 62 62 66 61 31  65 36 31 30 10 0f 1a 0c  |5b5bbfa1e610....|
00000190  08 f7 a5 86 a2 06 10 b9  84 b7 94 03 22 0c 08 fe  |............"...|
000001a0  ec bd a2 06 10 e6 c9 d5  a4 02 28 0a 1a 00 22 00  |..........(...".|
I0501 08:21:20.776676       1 request.go:1152] Request Body:
00000000  6b 38 73 00 0a 1f 0a 16  63 6f 6f 72 64 69 6e 61  |k8s.....coordina|
00000010  74 69 6f 6e 2e 6b 38 73  2e 69 6f 2f 76 31 12 05  |tion.k8s.io/v1..|
00000020  4c 65 61 73 65 12 84 03  0a a6 02 0a 0e 6b 75 62  |Lease........kub|
00000030  65 2d 73 63 68 65 64 75  6c 65 72 12 00 1a 0b 6b  |e-scheduler....k|
00000040  75 62 65 2d 73 79 73 74  65 6d 22 00 2a 24 36 61  |ube-system".*$6a|
00000050  30 65 32 30 33 66 2d 65  32 38 30 2d 34 36 61 30  |0e203f-e280-46a0|
00000060  2d 39 35 33 62 2d 35 66  62 64 63 37 38 61 63 38  |-953b-5fbdc78ac8|
00000070  36 65 32 07 32 32 36 38  35 38 31 38 00 42 08 08  |6e2.22685818.B..|
00000080  b1 b2 e2 a1 06 10 00 7a  00 8a 01 c4 01 0a 0e 6b  |.......z.......k|
00000090  75 62 65 2d 73 63 68 65  64 75 6c 65 72 12 06 55  |ube-scheduler..U|
000000a0  70 64 61 74 65 1a 16 63  6f 6f 72 64 69 6e 61 74  |pdate..coordinat|
000000b0  69 6f 6e 2e 6b 38 73 2e  69 6f 2f 76 31 22 08 08  |ion.k8s.io/v1"..|
000000c0  b1 b2 e2 a1 06 10 00 32  08 46 69 65 6c 64 73 56  |.......2.FieldsV|
000000d0  31 3a 7c 0a 7a 7b 22 66  3a 73 70 65 63 22 3a 7b  |1:|.z{"f:spec":{|
000000e0  22 66 3a 61 63 71 75 69  72 65 54 69 6d 65 22 3a  |"f:acquireTime":|
000000f0  7b 7d 2c 22 66 3a 68 6f  6c 64 65 72 49 64 65 6e  |{},"f:holderIden|
00000100  74 69 74 79 22 3a 7b 7d  2c 22 66 3a 6c 65 61 73  |tity":{},"f:leas|
00000110  65 44 75 72 61 74 69 6f  6e 53 65 63 6f 6e 64 73  |eDurationSeconds|
00000120  22 3a 7b 7d 2c 22 66 3a  6c 65 61 73 65 54 72 61  |":{},"f:leaseTra|
00000130  6e 73 69 74 69 6f 6e 73  22 3a 7b 7d 2c 22 66 3a  |nsitions":{},"f:|
00000140  72 65 6e 65 77 54 69 6d  65 22 3a 7b 7d 7d 7d 42  |renewTime":{}}}B|
00000150  00 12 59 0a 37 6b 69 6e  64 2d 63 6f 6e 74 72 6f  |..Y.7kind-contro|
00000160  6c 2d 70 6c 61 6e 65 5f  30 64 32 66 61 66 39 33  |l-plane_0d2faf93|
00000170  2d 34 61 30 62 2d 34 66  32 38 2d 38 33 64 33 2d  |-4a0b-4f28-83d3-|
00000180  35 62 35 62 62 66 61 31  65 36 31 30 10 0f 1a 0c  |5b5bbfa1e610....|
00000190  08 f7 a5 86 a2 06 10 b9  84 b7 94 03 22 0c 08 80  |............"...|
000001a0  ed bd a2 06 10 ff 8a fa  ee 02 28 0a 1a 00 22 00  |..........(...".|
I0501 08:21:20.776843       1 round_trippers.go:466] curl -v -XPUT  -H "Accept: application/vnd.kubernetes.protobuf, */*" -H "User-Agent: kube-scheduler/v1.24.7 (linux/amd64) kubernetes/e6f3597/leader-election" -H "Content-Type: application/vnd.kubernetes.protobuf" 'https://172.18.0.2:6443/apis/coordination.k8s.io/v1/namespaces/kube-system/leases/kube-scheduler?timeout=5s'
I0501 08:21:20.782299       1 round_trippers.go:553] PUT https://172.18.0.2:6443/apis/coordination.k8s.io/v1/namespaces/kube-system/leases/kube-scheduler?timeout=5s 200 OK in 5 milliseconds
I0501 08:21:20.782341       1 round_trippers.go:570] HTTP Statistics: GetConnection 0 ms ServerProcessing 5 ms Duration 5 ms
I0501 08:21:20.782358       1 round_trippers.go:577] Response Headers:
I0501 08:21:20.782376       1 round_trippers.go:580]     X-Kubernetes-Pf-Prioritylevel-Uid: afabb116-6975-46b8-863b-3258bec9e1ea
I0501 08:21:20.782392       1 round_trippers.go:580]     Content-Length: 432
I0501 08:21:20.782460       1 round_trippers.go:580]     Date: Mon, 01 May 2023 08:21:20 GMT
I0501 08:21:20.782487       1 round_trippers.go:580]     Audit-Id: 71d700f4-333a-4916-b738-039143f1de1a
I0501 08:21:20.782543       1 round_trippers.go:580]     Cache-Control: no-cache, private
I0501 08:21:20.782570       1 round_trippers.go:580]     Content-Type: application/vnd.kubernetes.protobuf
I0501 08:21:20.782586       1 round_trippers.go:580]     X-Kubernetes-Pf-Flowschema-Uid: 493426e8-0f6d-4ea6-bc2c-2d926c7e3221
I0501 08:21:20.782737       1 request.go:1152] Response Body:
00000000  6b 38 73 00 0a 1f 0a 16  63 6f 6f 72 64 69 6e 61  |k8s.....coordina|
00000010  74 69 6f 6e 2e 6b 38 73  2e 69 6f 2f 76 31 12 05  |tion.k8s.io/v1..|
00000020  4c 65 61 73 65 12 84 03  0a a6 02 0a 0e 6b 75 62  |Lease........kub|
00000030  65 2d 73 63 68 65 64 75  6c 65 72 12 00 1a 0b 6b  |e-scheduler....k|
00000040  75 62 65 2d 73 79 73 74  65 6d 22 00 2a 24 36 61  |ube-system".*$6a|
00000050  30 65 32 30 33 66 2d 65  32 38 30 2d 34 36 61 30  |0e203f-e280-46a0|
00000060  2d 39 35 33 62 2d 35 66  62 64 63 37 38 61 63 38  |-953b-5fbdc78ac8|
00000070  36 65 32 07 32 32 36 38  36 30 34 38 00 42 08 08  |6e2.22686048.B..|
00000080  b1 b2 e2 a1 06 10 00 7a  00 8a 01 c4 01 0a 0e 6b  |.......z.......k|
00000090  75 62 65 2d 73 63 68 65  64 75 6c 65 72 12 06 55  |ube-scheduler..U|
000000a0  70 64 61 74 65 1a 16 63  6f 6f 72 64 69 6e 61 74  |pdate..coordinat|
000000b0  69 6f 6e 2e 6b 38 73 2e  69 6f 2f 76 31 22 08 08  |ion.k8s.io/v1"..|
000000c0  b1 b2 e2 a1 06 10 00 32  08 46 69 65 6c 64 73 56  |.......2.FieldsV|
000000d0  31 3a 7c 0a 7a 7b 22 66  3a 73 70 65 63 22 3a 7b  |1:|.z{"f:spec":{|
000000e0  22 66 3a 61 63 71 75 69  72 65 54 69 6d 65 22 3a  |"f:acquireTime":|
000000f0  7b 7d 2c 22 66 3a 68 6f  6c 64 65 72 49 64 65 6e  |{},"f:holderIden|
00000100  74 69 74 79 22 3a 7b 7d  2c 22 66 3a 6c 65 61 73  |tity":{},"f:leas|
00000110  65 44 75 72 61 74 69 6f  6e 53 65 63 6f 6e 64 73  |eDurationSeconds|
00000120  22 3a 7b 7d 2c 22 66 3a  6c 65 61 73 65 54 72 61  |":{},"f:leaseTra|
00000130  6e 73 69 74 69 6f 6e 73  22 3a 7b 7d 2c 22 66 3a  |nsitions":{},"f:|
00000140  72 65 6e 65 77 54 69 6d  65 22 3a 7b 7d 7d 7d 42  |renewTime":{}}}B|
00000150  00 12 59 0a 37 6b 69 6e  64 2d 63 6f 6e 74 72 6f  |..Y.7kind-contro|
00000160  6c 2d 70 6c 61 6e 65 5f  30 64 32 66 61 66 39 33  |l-plane_0d2faf93|
00000170  2d 34 61 30 62 2d 34 66  32 38 2d 38 33 64 33 2d  |-4a0b-4f28-83d3-|
00000180  35 62 35 62 62 66 61 31  65 36 31 30 10 0f 1a 0c  |5b5bbfa1e610....|
00000190  08 f7 a5 86 a2 06 10 b9  84 b7 94 03 22 0c 08 80  |............"...|
000001a0  ed bd a2 06 10 ff 8a fa  ee 02 28 0a 1a 00 22 00  |..........(...".|
I0501 08:21:20.782986       1 leaderelection.go:278] successfully renewed lease kube-system/kube-scheduler
I0501 08:21:20.899886       1 eventhandlers.go:204] "Update event for scheduled pod" pod="default/nginx-deployment-66f58bff7c-l7r5r"
I0501 08:21:22.784287       1 round_trippers.go:466] curl -v -XGET  -H "Accept: application/vnd.kubernetes.protobuf, */*" -H "User-Agent: kube-scheduler/v1.24.7 (linux/amd64) kubernetes/e6f3597/leader-election" 'https://172.18.0.2:6443/apis/coordination.k8s.io/v1/namespaces/kube-system/leases/kube-scheduler?timeout=5s'
I0501 08:21:22.793430       1 round_trippers.go:553] GET https://172.18.0.2:6443/apis/coordination.k8s.io/v1/namespaces/kube-system/leases/kube-scheduler?timeout=5s 200 OK in 8 milliseconds
I0501 08:21:22.794000       1 round_trippers.go:570] HTTP Statistics: GetConnection 0 ms ServerProcessing 8 ms Duration 8 ms
I0501 08:21:22.794328       1 round_trippers.go:577] Response Headers:
I0501 08:21:22.794633       1 round_trippers.go:580]     Date: Mon, 01 May 2023 08:21:22 GMT
I0501 08:21:22.794883       1 round_trippers.go:580]     Audit-Id: e035e975-43c4-4dbe-856c-83a0771949c4
I0501 08:21:22.795280       1 round_trippers.go:580]     Cache-Control: no-cache, private
I0501 08:21:22.795600       1 round_trippers.go:580]     Content-Type: application/vnd.kubernetes.protobuf
I0501 08:21:22.796002       1 round_trippers.go:580]     X-Kubernetes-Pf-Flowschema-Uid: 493426e8-0f6d-4ea6-bc2c-2d926c7e3221
I0501 08:21:22.796306       1 round_trippers.go:580]     X-Kubernetes-Pf-Prioritylevel-Uid: afabb116-6975-46b8-863b-3258bec9e1ea
I0501 08:21:22.796690       1 round_trippers.go:580]     Content-Length: 432
I0501 08:21:22.797015       1 request.go:1152] Response Body:
00000000  6b 38 73 00 0a 1f 0a 16  63 6f 6f 72 64 69 6e 61  |k8s.....coordina|
00000010  74 69 6f 6e 2e 6b 38 73  2e 69 6f 2f 76 31 12 05  |tion.k8s.io/v1..|
00000020  4c 65 61 73 65 12 84 03  0a a6 02 0a 0e 6b 75 62  |Lease........kub|
00000030  65 2d 73 63 68 65 64 75  6c 65 72 12 00 1a 0b 6b  |e-scheduler....k|
00000040  75 62 65 2d 73 79 73 74  65 6d 22 00 2a 24 36 61  |ube-system".*$6a|
00000050  30 65 32 30 33 66 2d 65  32 38 30 2d 34 36 61 30  |0e203f-e280-46a0|
00000060  2d 39 35 33 62 2d 35 66  62 64 63 37 38 61 63 38  |-953b-5fbdc78ac8|
00000070  36 65 32 07 32 32 36 38  36 30 34 38 00 42 08 08  |6e2.22686048.B..|
00000080  b1 b2 e2 a1 06 10 00 7a  00 8a 01 c4 01 0a 0e 6b  |.......z.......k|
00000090  75 62 65 2d 73 63 68 65  64 75 6c 65 72 12 06 55  |ube-scheduler..U|
000000a0  70 64 61 74 65 1a 16 63  6f 6f 72 64 69 6e 61 74  |pdate..coordinat|
000000b0  69 6f 6e 2e 6b 38 73 2e  69 6f 2f 76 31 22 08 08  |ion.k8s.io/v1"..|
000000c0  b1 b2 e2 a1 06 10 00 32  08 46 69 65 6c 64 73 56  |.......2.FieldsV|
000000d0  31 3a 7c 0a 7a 7b 22 66  3a 73 70 65 63 22 3a 7b  |1:|.z{"f:spec":{|
000000e0  22 66 3a 61 63 71 75 69  72 65 54 69 6d 65 22 3a  |"f:acquireTime":|
000000f0  7b 7d 2c 22 66 3a 68 6f  6c 64 65 72 49 64 65 6e  |{},"f:holderIden|
00000100  74 69 74 79 22 3a 7b 7d  2c 22 66 3a 6c 65 61 73  |tity":{},"f:leas|
00000110  65 44 75 72 61 74 69 6f  6e 53 65 63 6f 6e 64 73  |eDurationSeconds|
00000120  22 3a 7b 7d 2c 22 66 3a  6c 65 61 73 65 54 72 61  |":{},"f:leaseTra|
00000130  6e 73 69 74 69 6f 6e 73  22 3a 7b 7d 2c 22 66 3a  |nsitions":{},"f:|
00000140  72 65 6e 65 77 54 69 6d  65 22 3a 7b 7d 7d 7d 42  |renewTime":{}}}B|
00000150  00 12 59 0a 37 6b 69 6e  64 2d 63 6f 6e 74 72 6f  |..Y.7kind-contro|
00000160  6c 2d 70 6c 61 6e 65 5f  30 64 32 66 61 66 39 33  |l-plane_0d2faf93|
00000170  2d 34 61 30 62 2d 34 66  32 38 2d 38 33 64 33 2d  |-4a0b-4f28-83d3-|
00000180  35 62 35 62 62 66 61 31  65 36 31 30 10 0f 1a 0c  |5b5bbfa1e610....|
00000190  08 f7 a5 86 a2 06 10 b9  84 b7 94 03 22 0c 08 80  |............"...|
000001a0  ed bd a2 06 10 ff 8a fa  ee 02 28 0a 1a 00 22 00  |..........(...".|
I0501 08:21:22.797888       1 request.go:1152] Request Body:
00000000  6b 38 73 00 0a 1f 0a 16  63 6f 6f 72 64 69 6e 61  |k8s.....coordina|
00000010  74 69 6f 6e 2e 6b 38 73  2e 69 6f 2f 76 31 12 05  |tion.k8s.io/v1..|
00000020  4c 65 61 73 65 12 84 03  0a a6 02 0a 0e 6b 75 62  |Lease........kub|
00000030  65 2d 73 63 68 65 64 75  6c 65 72 12 00 1a 0b 6b  |e-scheduler....k|
00000040  75 62 65 2d 73 79 73 74  65 6d 22 00 2a 24 36 61  |ube-system".*$6a|
00000050  30 65 32 30 33 66 2d 65  32 38 30 2d 34 36 61 30  |0e203f-e280-46a0|
00000060  2d 39 35 33 62 2d 35 66  62 64 63 37 38 61 63 38  |-953b-5fbdc78ac8|
00000070  36 65 32 07 32 32 36 38  36 30 34 38 00 42 08 08  |6e2.22686048.B..|
00000080  b1 b2 e2 a1 06 10 00 7a  00 8a 01 c4 01 0a 0e 6b  |.......z.......k|
00000090  75 62 65 2d 73 63 68 65  64 75 6c 65 72 12 06 55  |ube-scheduler..U|
000000a0  70 64 61 74 65 1a 16 63  6f 6f 72 64 69 6e 61 74  |pdate..coordinat|
000000b0  69 6f 6e 2e 6b 38 73 2e  69 6f 2f 76 31 22 08 08  |ion.k8s.io/v1"..|
000000c0  b1 b2 e2 a1 06 10 00 32  08 46 69 65 6c 64 73 56  |.......2.FieldsV|
000000d0  31 3a 7c 0a 7a 7b 22 66  3a 73 70 65 63 22 3a 7b  |1:|.z{"f:spec":{|
000000e0  22 66 3a 61 63 71 75 69  72 65 54 69 6d 65 22 3a  |"f:acquireTime":|
000000f0  7b 7d 2c 22 66 3a 68 6f  6c 64 65 72 49 64 65 6e  |{},"f:holderIden|
00000100  74 69 74 79 22 3a 7b 7d  2c 22 66 3a 6c 65 61 73  |tity":{},"f:leas|
00000110  65 44 75 72 61 74 69 6f  6e 53 65 63 6f 6e 64 73  |eDurationSeconds|
00000120  22 3a 7b 7d 2c 22 66 3a  6c 65 61 73 65 54 72 61  |":{},"f:leaseTra|
00000130  6e 73 69 74 69 6f 6e 73  22 3a 7b 7d 2c 22 66 3a  |nsitions":{},"f:|
00000140  72 65 6e 65 77 54 69 6d  65 22 3a 7b 7d 7d 7d 42  |renewTime":{}}}B|
00000150  00 12 59 0a 37 6b 69 6e  64 2d 63 6f 6e 74 72 6f  |..Y.7kind-contro|
00000160  6c 2d 70 6c 61 6e 65 5f  30 64 32 66 61 66 39 33  |l-plane_0d2faf93|
00000170  2d 34 61 30 62 2d 34 66  32 38 2d 38 33 64 33 2d  |-4a0b-4f28-83d3-|
00000180  35 62 35 62 62 66 61 31  65 36 31 30 10 0f 1a 0c  |5b5bbfa1e610....|
00000190  08 f7 a5 86 a2 06 10 b9  84 b7 94 03 22 0c 08 82  |............"...|
000001a0  ed bd a2 06 10 9f 83 ea  f5 02 28 0a 1a 00 22 00  |..........(...".|
I0501 08:21:22.798250       1 round_trippers.go:466] curl -v -XPUT  -H "Accept: application/vnd.kubernetes.protobuf, */*" -H "Content-Type: application/vnd.kubernetes.protobuf" -H "User-Agent: kube-scheduler/v1.24.7 (linux/amd64) kubernetes/e6f3597/leader-election" 'https://172.18.0.2:6443/apis/coordination.k8s.io/v1/namespaces/kube-system/leases/kube-scheduler?timeout=5s'
I0501 08:21:22.804020       1 round_trippers.go:553] PUT https://172.18.0.2:6443/apis/coordination.k8s.io/v1/namespaces/kube-system/leases/kube-scheduler?timeout=5s 200 OK in 5 milliseconds
I0501 08:21:22.804183       1 round_trippers.go:570] HTTP Statistics: GetConnection 0 ms ServerProcessing 5 ms Duration 5 ms
I0501 08:21:22.804251       1 round_trippers.go:577] Response Headers:
I0501 08:21:22.804356       1 round_trippers.go:580]     X-Kubernetes-Pf-Prioritylevel-Uid: afabb116-6975-46b8-863b-3258bec9e1ea
I0501 08:21:22.804452       1 round_trippers.go:580]     Content-Length: 432
I0501 08:21:22.804520       1 round_trippers.go:580]     Date: Mon, 01 May 2023 08:21:22 GMT
I0501 08:21:22.804611       1 round_trippers.go:580]     Audit-Id: f9101d18-2ad0-43fa-be68-63f40d78393a
I0501 08:21:22.804669       1 round_trippers.go:580]     Cache-Control: no-cache, private
I0501 08:21:22.804769       1 round_trippers.go:580]     Content-Type: application/vnd.kubernetes.protobuf
I0501 08:21:22.804871       1 round_trippers.go:580]     X-Kubernetes-Pf-Flowschema-Uid: 493426e8-0f6d-4ea6-bc2c-2d926c7e3221
I0501 08:21:22.805013       1 request.go:1152] Response Body:
00000000  6b 38 73 00 0a 1f 0a 16  63 6f 6f 72 64 69 6e 61  |k8s.....coordina|
00000010  74 69 6f 6e 2e 6b 38 73  2e 69 6f 2f 76 31 12 05  |tion.k8s.io/v1..|
00000020  4c 65 61 73 65 12 84 03  0a a6 02 0a 0e 6b 75 62  |Lease........kub|
00000030  65 2d 73 63 68 65 64 75  6c 65 72 12 00 1a 0b 6b  |e-scheduler....k|
00000040  75 62 65 2d 73 79 73 74  65 6d 22 00 2a 24 36 61  |ube-system".*$6a|
00000050  30 65 32 30 33 66 2d 65  32 38 30 2d 34 36 61 30  |0e203f-e280-46a0|
00000060  2d 39 35 33 62 2d 35 66  62 64 63 37 38 61 63 38  |-953b-5fbdc78ac8|
00000070  36 65 32 07 32 32 36 38  36 31 31 38 00 42 08 08  |6e2.22686118.B..|
00000080  b1 b2 e2 a1 06 10 00 7a  00 8a 01 c4 01 0a 0e 6b  |.......z.......k|
00000090  75 62 65 2d 73 63 68 65  64 75 6c 65 72 12 06 55  |ube-scheduler..U|
000000a0  70 64 61 74 65 1a 16 63  6f 6f 72 64 69 6e 61 74  |pdate..coordinat|
000000b0  69 6f 6e 2e 6b 38 73 2e  69 6f 2f 76 31 22 08 08  |ion.k8s.io/v1"..|
000000c0  b1 b2 e2 a1 06 10 00 32  08 46 69 65 6c 64 73 56  |.......2.FieldsV|
000000d0  31 3a 7c 0a 7a 7b 22 66  3a 73 70 65 63 22 3a 7b  |1:|.z{"f:spec":{|
000000e0  22 66 3a 61 63 71 75 69  72 65 54 69 6d 65 22 3a  |"f:acquireTime":|
000000f0  7b 7d 2c 22 66 3a 68 6f  6c 64 65 72 49 64 65 6e  |{},"f:holderIden|
00000100  74 69 74 79 22 3a 7b 7d  2c 22 66 3a 6c 65 61 73  |tity":{},"f:leas|
00000110  65 44 75 72 61 74 69 6f  6e 53 65 63 6f 6e 64 73  |eDurationSeconds|
00000120  22 3a 7b 7d 2c 22 66 3a  6c 65 61 73 65 54 72 61  |":{},"f:leaseTra|
00000130  6e 73 69 74 69 6f 6e 73  22 3a 7b 7d 2c 22 66 3a  |nsitions":{},"f:|
00000140  72 65 6e 65 77 54 69 6d  65 22 3a 7b 7d 7d 7d 42  |renewTime":{}}}B|
00000150  00 12 59 0a 37 6b 69 6e  64 2d 63 6f 6e 74 72 6f  |..Y.7kind-contro|
00000160  6c 2d 70 6c 61 6e 65 5f  30 64 32 66 61 66 39 33  |l-plane_0d2faf93|
00000170  2d 34 61 30 62 2d 34 66  32 38 2d 38 33 64 33 2d  |-4a0b-4f28-83d3-|
00000180  35 62 35 62 62 66 61 31  65 36 31 30 10 0f 1a 0c  |5b5bbfa1e610....|
00000190  08 f7 a5 86 a2 06 10 b9  84 b7 94 03 22 0c 08 82  |............"...|
000001a0  ed bd a2 06 10 9f 83 ea  f5 02 28 0a 1a 00 22 00  |..........(...".|
I0501 08:21:22.805378       1 leaderelection.go:278] successfully renewed lease kube-system/kube-scheduler
I0501 08:21:24.806800       1 round_trippers.go:466] curl -v -XGET  -H "User-Agent: kube-scheduler/v1.24.7 (linux/amd64) kubernetes/e6f3597/leader-election" -H "Accept: application/vnd.kubernetes.protobuf, */*" 'https://172.18.0.2:6443/apis/coordination.k8s.io/v1/namespaces/kube-system/leases/kube-scheduler?timeout=5s'
I0501 08:21:24.812440       1 round_trippers.go:553] GET https://172.18.0.2:6443/apis/coordination.k8s.io/v1/namespaces/kube-system/leases/kube-scheduler?timeout=5s 200 OK in 5 milliseconds
I0501 08:21:24.812478       1 round_trippers.go:570] HTTP Statistics: GetConnection 0 ms ServerProcessing 4 ms Duration 5 ms
I0501 08:21:24.812495       1 round_trippers.go:577] Response Headers:
I0501 08:21:24.812513       1 round_trippers.go:580]     X-Kubernetes-Pf-Prioritylevel-Uid: afabb116-6975-46b8-863b-3258bec9e1ea
I0501 08:21:24.812528       1 round_trippers.go:580]     Content-Length: 432
I0501 08:21:24.812778       1 round_trippers.go:580]     Date: Mon, 01 May 2023 08:21:24 GMT
I0501 08:21:24.812796       1 round_trippers.go:580]     Audit-Id: d679fcca-ef2b-4cf8-8160-1701b5f26e05
I0501 08:21:24.812990       1 round_trippers.go:580]     Cache-Control: no-cache, private
I0501 08:21:24.813021       1 round_trippers.go:580]     Content-Type: application/vnd.kubernetes.protobuf
I0501 08:21:24.813049       1 round_trippers.go:580]     X-Kubernetes-Pf-Flowschema-Uid: 493426e8-0f6d-4ea6-bc2c-2d926c7e3221
I0501 08:21:24.813277       1 request.go:1152] Response Body:
00000000  6b 38 73 00 0a 1f 0a 16  63 6f 6f 72 64 69 6e 61  |k8s.....coordina|
00000010  74 69 6f 6e 2e 6b 38 73  2e 69 6f 2f 76 31 12 05  |tion.k8s.io/v1..|
00000020  4c 65 61 73 65 12 84 03  0a a6 02 0a 0e 6b 75 62  |Lease........kub|
00000030  65 2d 73 63 68 65 64 75  6c 65 72 12 00 1a 0b 6b  |e-scheduler....k|
00000040  75 62 65 2d 73 79 73 74  65 6d 22 00 2a 24 36 61  |ube-system".*$6a|
00000050  30 65 32 30 33 66 2d 65  32 38 30 2d 34 36 61 30  |0e203f-e280-46a0|
00000060  2d 39 35 33 62 2d 35 66  62 64 63 37 38 61 63 38  |-953b-5fbdc78ac8|
00000070  36 65 32 07 32 32 36 38  36 31 31 38 00 42 08 08  |6e2.22686118.B..|
00000080  b1 b2 e2 a1 06 10 00 7a  00 8a 01 c4 01 0a 0e 6b  |.......z.......k|
00000090  75 62 65 2d 73 63 68 65  64 75 6c 65 72 12 06 55  |ube-scheduler..U|
000000a0  70 64 61 74 65 1a 16 63  6f 6f 72 64 69 6e 61 74  |pdate..coordinat|
000000b0  69 6f 6e 2e 6b 38 73 2e  69 6f 2f 76 31 22 08 08  |ion.k8s.io/v1"..|
000000c0  b1 b2 e2 a1 06 10 00 32  08 46 69 65 6c 64 73 56  |.......2.FieldsV|
000000d0  31 3a 7c 0a 7a 7b 22 66  3a 73 70 65 63 22 3a 7b  |1:|.z{"f:spec":{|
000000e0  22 66 3a 61 63 71 75 69  72 65 54 69 6d 65 22 3a  |"f:acquireTime":|
000000f0  7b 7d 2c 22 66 3a 68 6f  6c 64 65 72 49 64 65 6e  |{},"f:holderIden|
00000100  74 69 74 79 22 3a 7b 7d  2c 22 66 3a 6c 65 61 73  |tity":{},"f:leas|
00000110  65 44 75 72 61 74 69 6f  6e 53 65 63 6f 6e 64 73  |eDurationSeconds|
00000120  22 3a 7b 7d 2c 22 66 3a  6c 65 61 73 65 54 72 61  |":{},"f:leaseTra|
00000130  6e 73 69 74 69 6f 6e 73  22 3a 7b 7d 2c 22 66 3a  |nsitions":{},"f:|
00000140  72 65 6e 65 77 54 69 6d  65 22 3a 7b 7d 7d 7d 42  |renewTime":{}}}B|
00000150  00 12 59 0a 37 6b 69 6e  64 2d 63 6f 6e 74 72 6f  |..Y.7kind-contro|
00000160  6c 2d 70 6c 61 6e 65 5f  30 64 32 66 61 66 39 33  |l-plane_0d2faf93|
00000170  2d 34 61 30 62 2d 34 66  32 38 2d 38 33 64 33 2d  |-4a0b-4f28-83d3-|
00000180  35 62 35 62 62 66 61 31  65 36 31 30 10 0f 1a 0c  |5b5bbfa1e610....|
00000190  08 f7 a5 86 a2 06 10 b9  84 b7 94 03 22 0c 08 82  |............"...|
000001a0  ed bd a2 06 10 9f 83 ea  f5 02 28 0a 1a 00 22 00  |..........(...".|
I0501 08:21:24.814056       1 request.go:1152] Request Body:
00000000  6b 38 73 00 0a 1f 0a 16  63 6f 6f 72 64 69 6e 61  |k8s.....coordina|
00000010  74 69 6f 6e 2e 6b 38 73  2e 69 6f 2f 76 31 12 05  |tion.k8s.io/v1..|
00000020  4c 65 61 73 65 12 84 03  0a a6 02 0a 0e 6b 75 62  |Lease........kub|
00000030  65 2d 73 63 68 65 64 75  6c 65 72 12 00 1a 0b 6b  |e-scheduler....k|
00000040  75 62 65 2d 73 79 73 74  65 6d 22 00 2a 24 36 61  |ube-system".*$6a|
00000050  30 65 32 30 33 66 2d 65  32 38 30 2d 34 36 61 30  |0e203f-e280-46a0|
00000060  2d 39 35 33 62 2d 35 66  62 64 63 37 38 61 63 38  |-953b-5fbdc78ac8|
00000070  36 65 32 07 32 32 36 38  36 31 31 38 00 42 08 08  |6e2.22686118.B..|
00000080  b1 b2 e2 a1 06 10 00 7a  00 8a 01 c4 01 0a 0e 6b  |.......z.......k|
00000090  75 62 65 2d 73 63 68 65  64 75 6c 65 72 12 06 55  |ube-scheduler..U|
000000a0  70 64 61 74 65 1a 16 63  6f 6f 72 64 69 6e 61 74  |pdate..coordinat|
000000b0  69 6f 6e 2e 6b 38 73 2e  69 6f 2f 76 31 22 08 08  |ion.k8s.io/v1"..|
000000c0  b1 b2 e2 a1 06 10 00 32  08 46 69 65 6c 64 73 56  |.......2.FieldsV|
000000d0  31 3a 7c 0a 7a 7b 22 66  3a 73 70 65 63 22 3a 7b  |1:|.z{"f:spec":{|
000000e0  22 66 3a 61 63 71 75 69  72 65 54 69 6d 65 22 3a  |"f:acquireTime":|
000000f0  7b 7d 2c 22 66 3a 68 6f  6c 64 65 72 49 64 65 6e  |{},"f:holderIden|
00000100  74 69 74 79 22 3a 7b 7d  2c 22 66 3a 6c 65 61 73  |tity":{},"f:leas|
00000110  65 44 75 72 61 74 69 6f  6e 53 65 63 6f 6e 64 73  |eDurationSeconds|
00000120  22 3a 7b 7d 2c 22 66 3a  6c 65 61 73 65 54 72 61  |":{},"f:leaseTra|
00000130  6e 73 69 74 69 6f 6e 73  22 3a 7b 7d 2c 22 66 3a  |nsitions":{},"f:|
00000140  72 65 6e 65 77 54 69 6d  65 22 3a 7b 7d 7d 7d 42  |renewTime":{}}}B|
00000150  00 12 59 0a 37 6b 69 6e  64 2d 63 6f 6e 74 72 6f  |..Y.7kind-contro|
00000160  6c 2d 70 6c 61 6e 65 5f  30 64 32 66 61 66 39 33  |l-plane_0d2faf93|
00000170  2d 34 61 30 62 2d 34 66  32 38 2d 38 33 64 33 2d  |-4a0b-4f28-83d3-|
00000180  35 62 35 62 62 66 61 31  65 36 31 30 10 0f 1a 0c  |5b5bbfa1e610....|
00000190  08 f7 a5 86 a2 06 10 b9  84 b7 94 03 22 0c 08 84  |............"...|
000001a0  ed bd a2 06 10 ef de cb  80 03 28 0a 1a 00 22 00  |..........(...".|
I0501 08:21:24.814623       1 round_trippers.go:466] curl -v -XPUT  -H "Content-Type: application/vnd.kubernetes.protobuf" -H "Accept: application/vnd.kubernetes.protobuf, */*" -H "User-Agent: kube-scheduler/v1.24.7 (linux/amd64) kubernetes/e6f3597/leader-election" 'https://172.18.0.2:6443/apis/coordination.k8s.io/v1/namespaces/kube-system/leases/kube-scheduler?timeout=5s'
I0501 08:21:24.823069       1 round_trippers.go:553] PUT https://172.18.0.2:6443/apis/coordination.k8s.io/v1/namespaces/kube-system/leases/kube-scheduler?timeout=5s 200 OK in 8 milliseconds
I0501 08:21:24.823170       1 round_trippers.go:570] HTTP Statistics: GetConnection 0 ms ServerProcessing 7 ms Duration 8 ms
I0501 08:21:24.823187       1 round_trippers.go:577] Response Headers:
I0501 08:21:24.823205       1 round_trippers.go:580]     Cache-Control: no-cache, private
I0501 08:21:24.823221       1 round_trippers.go:580]     Content-Type: application/vnd.kubernetes.protobuf
I0501 08:21:24.823236       1 round_trippers.go:580]     X-Kubernetes-Pf-Flowschema-Uid: 493426e8-0f6d-4ea6-bc2c-2d926c7e3221
I0501 08:21:24.823251       1 round_trippers.go:580]     X-Kubernetes-Pf-Prioritylevel-Uid: afabb116-6975-46b8-863b-3258bec9e1ea
I0501 08:21:24.823284       1 round_trippers.go:580]     Content-Length: 432
I0501 08:21:24.823300       1 round_trippers.go:580]     Date: Mon, 01 May 2023 08:21:24 GMT
I0501 08:21:24.823315       1 round_trippers.go:580]     Audit-Id: 3008680e-91bb-4b35-9db3-2dade4742db6
I0501 08:21:24.823405       1 request.go:1152] Response Body:
00000000  6b 38 73 00 0a 1f 0a 16  63 6f 6f 72 64 69 6e 61  |k8s.....coordina|
00000010  74 69 6f 6e 2e 6b 38 73  2e 69 6f 2f 76 31 12 05  |tion.k8s.io/v1..|
00000020  4c 65 61 73 65 12 84 03  0a a6 02 0a 0e 6b 75 62  |Lease........kub|
00000030  65 2d 73 63 68 65 64 75  6c 65 72 12 00 1a 0b 6b  |e-scheduler....k|
00000040  75 62 65 2d 73 79 73 74  65 6d 22 00 2a 24 36 61  |ube-system".*$6a|
00000050  30 65 32 30 33 66 2d 65  32 38 30 2d 34 36 61 30  |0e203f-e280-46a0|
00000060  2d 39 35 33 62 2d 35 66  62 64 63 37 38 61 63 38  |-953b-5fbdc78ac8|
00000070  36 65 32 07 32 32 36 38  36 31 34 38 00 42 08 08  |6e2.22686148.B..|
00000080  b1 b2 e2 a1 06 10 00 7a  00 8a 01 c4 01 0a 0e 6b  |.......z.......k|
00000090  75 62 65 2d 73 63 68 65  64 75 6c 65 72 12 06 55  |ube-scheduler..U|
000000a0  70 64 61 74 65 1a 16 63  6f 6f 72 64 69 6e 61 74  |pdate..coordinat|
000000b0  69 6f 6e 2e 6b 38 73 2e  69 6f 2f 76 31 22 08 08  |ion.k8s.io/v1"..|
000000c0  b1 b2 e2 a1 06 10 00 32  08 46 69 65 6c 64 73 56  |.......2.FieldsV|
000000d0  31 3a 7c 0a 7a 7b 22 66  3a 73 70 65 63 22 3a 7b  |1:|.z{"f:spec":{|
000000e0  22 66 3a 61 63 71 75 69  72 65 54 69 6d 65 22 3a  |"f:acquireTime":|
000000f0  7b 7d 2c 22 66 3a 68 6f  6c 64 65 72 49 64 65 6e  |{},"f:holderIden|
00000100  74 69 74 79 22 3a 7b 7d  2c 22 66 3a 6c 65 61 73  |tity":{},"f:leas|
00000110  65 44 75 72 61 74 69 6f  6e 53 65 63 6f 6e 64 73  |eDurationSeconds|
00000120  22 3a 7b 7d 2c 22 66 3a  6c 65 61 73 65 54 72 61  |":{},"f:leaseTra|
00000130  6e 73 69 74 69 6f 6e 73  22 3a 7b 7d 2c 22 66 3a  |nsitions":{},"f:|
00000140  72 65 6e 65 77 54 69 6d  65 22 3a 7b 7d 7d 7d 42  |renewTime":{}}}B|
00000150  00 12 59 0a 37 6b 69 6e  64 2d 63 6f 6e 74 72 6f  |..Y.7kind-contro|
00000160  6c 2d 70 6c 61 6e 65 5f  30 64 32 66 61 66 39 33  |l-plane_0d2faf93|
00000170  2d 34 61 30 62 2d 34 66  32 38 2d 38 33 64 33 2d  |-4a0b-4f28-83d3-|
00000180  35 62 35 62 62 66 61 31  65 36 31 30 10 0f 1a 0c  |5b5bbfa1e610....|
00000190  08 f7 a5 86 a2 06 10 b9  84 b7 94 03 22 0c 08 84  |............"...|
000001a0  ed bd a2 06 10 ef de cb  80 03 28 0a 1a 00 22 00  |..........(...".|
I0501 08:21:24.823553       1 leaderelection.go:278] successfully renewed lease kube-system/kube-scheduler
I0501 08:21:26.824363       1 round_trippers.go:466] curl -v -XGET  -H "Accept: application/vnd.kubernetes.protobuf, */*" -H "User-Agent: kube-scheduler/v1.24.7 (linux/amd64) kubernetes/e6f3597/leader-election" 'https://172.18.0.2:6443/apis/coordination.k8s.io/v1/namespaces/kube-system/leases/kube-scheduler?timeout=5s'
I0501 08:21:26.830753       1 round_trippers.go:553] GET https://172.18.0.2:6443/apis/coordination.k8s.io/v1/namespaces/kube-system/leases/kube-scheduler?timeout=5s 200 OK in 6 milliseconds
I0501 08:21:26.830830       1 round_trippers.go:570] HTTP Statistics: GetConnection 0 ms ServerProcessing 5 ms Duration 6 ms
I0501 08:21:26.830851       1 round_trippers.go:577] Response Headers:
I0501 08:21:26.830894       1 round_trippers.go:580]     Audit-Id: ce876ea7-4932-4bd4-bd54-1285be2728ec
I0501 08:21:26.830920       1 round_trippers.go:580]     Cache-Control: no-cache, private
I0501 08:21:26.830945       1 round_trippers.go:580]     Content-Type: application/vnd.kubernetes.protobuf
I0501 08:21:26.830978       1 round_trippers.go:580]     X-Kubernetes-Pf-Flowschema-Uid: 493426e8-0f6d-4ea6-bc2c-2d926c7e3221
I0501 08:21:26.830999       1 round_trippers.go:580]     X-Kubernetes-Pf-Prioritylevel-Uid: afabb116-6975-46b8-863b-3258bec9e1ea
I0501 08:21:26.831019       1 round_trippers.go:580]     Content-Length: 432
I0501 08:21:26.831038       1 round_trippers.go:580]     Date: Mon, 01 May 2023 08:21:26 GMT
I0501 08:21:26.831220       1 request.go:1152] Response Body:
00000000  6b 38 73 00 0a 1f 0a 16  63 6f 6f 72 64 69 6e 61  |k8s.....coordina|
00000010  74 69 6f 6e 2e 6b 38 73  2e 69 6f 2f 76 31 12 05  |tion.k8s.io/v1..|
00000020  4c 65 61 73 65 12 84 03  0a a6 02 0a 0e 6b 75 62  |Lease........kub|
00000030  65 2d 73 63 68 65 64 75  6c 65 72 12 00 1a 0b 6b  |e-scheduler....k|
00000040  75 62 65 2d 73 79 73 74  65 6d 22 00 2a 24 36 61  |ube-system".*$6a|
00000050  30 65 32 30 33 66 2d 65  32 38 30 2d 34 36 61 30  |0e203f-e280-46a0|
00000060  2d 39 35 33 62 2d 35 66  62 64 63 37 38 61 63 38  |-953b-5fbdc78ac8|
00000070  36 65 32 07 32 32 36 38  36 31 34 38 00 42 08 08  |6e2.22686148.B..|
00000080  b1 b2 e2 a1 06 10 00 7a  00 8a 01 c4 01 0a 0e 6b  |.......z.......k|
00000090  75 62 65 2d 73 63 68 65  64 75 6c 65 72 12 06 55  |ube-scheduler..U|
000000a0  70 64 61 74 65 1a 16 63  6f 6f 72 64 69 6e 61 74  |pdate..coordinat|
000000b0  69 6f 6e 2e 6b 38 73 2e  69 6f 2f 76 31 22 08 08  |ion.k8s.io/v1"..|
000000c0  b1 b2 e2 a1 06 10 00 32  08 46 69 65 6c 64 73 56  |.......2.FieldsV|
000000d0  31 3a 7c 0a 7a 7b 22 66  3a 73 70 65 63 22 3a 7b  |1:|.z{"f:spec":{|
000000e0  22 66 3a 61 63 71 75 69  72 65 54 69 6d 65 22 3a  |"f:acquireTime":|
000000f0  7b 7d 2c 22 66 3a 68 6f  6c 64 65 72 49 64 65 6e  |{},"f:holderIden|
00000100  74 69 74 79 22 3a 7b 7d  2c 22 66 3a 6c 65 61 73  |tity":{},"f:leas|
00000110  65 44 75 72 61 74 69 6f  6e 53 65 63 6f 6e 64 73  |eDurationSeconds|
00000120  22 3a 7b 7d 2c 22 66 3a  6c 65 61 73 65 54 72 61  |":{},"f:leaseTra|
00000130  6e 73 69 74 69 6f 6e 73  22 3a 7b 7d 2c 22 66 3a  |nsitions":{},"f:|
00000140  72 65 6e 65 77 54 69 6d  65 22 3a 7b 7d 7d 7d 42  |renewTime":{}}}B|
00000150  00 12 59 0a 37 6b 69 6e  64 2d 63 6f 6e 74 72 6f  |..Y.7kind-contro|
00000160  6c 2d 70 6c 61 6e 65 5f  30 64 32 66 61 66 39 33  |l-plane_0d2faf93|
00000170  2d 34 61 30 62 2d 34 66  32 38 2d 38 33 64 33 2d  |-4a0b-4f28-83d3-|
00000180  35 62 35 62 62 66 61 31  65 36 31 30 10 0f 1a 0c  |5b5bbfa1e610....|
00000190  08 f7 a5 86 a2 06 10 b9  84 b7 94 03 22 0c 08 84  |............"...|
000001a0  ed bd a2 06 10 ef de cb  80 03 28 0a 1a 00 22 00  |..........(...".|
I0501 08:21:26.835666       1 request.go:1152] Request Body:
00000000  6b 38 73 00 0a 1f 0a 16  63 6f 6f 72 64 69 6e 61  |k8s.....coordina|
00000010  74 69 6f 6e 2e 6b 38 73  2e 69 6f 2f 76 31 12 05  |tion.k8s.io/v1..|
00000020  4c 65 61 73 65 12 84 03  0a a6 02 0a 0e 6b 75 62  |Lease........kub|
00000030  65 2d 73 63 68 65 64 75  6c 65 72 12 00 1a 0b 6b  |e-scheduler....k|
00000040  75 62 65 2d 73 79 73 74  65 6d 22 00 2a 24 36 61  |ube-system".*$6a|
00000050  30 65 32 30 33 66 2d 65  32 38 30 2d 34 36 61 30  |0e203f-e280-46a0|
00000060  2d 39 35 33 62 2d 35 66  62 64 63 37 38 61 63 38  |-953b-5fbdc78ac8|
00000070  36 65 32 07 32 32 36 38  36 31 34 38 00 42 08 08  |6e2.22686148.B..|
00000080  b1 b2 e2 a1 06 10 00 7a  00 8a 01 c4 01 0a 0e 6b  |.......z.......k|
00000090  75 62 65 2d 73 63 68 65  64 75 6c 65 72 12 06 55  |ube-scheduler..U|
000000a0  70 64 61 74 65 1a 16 63  6f 6f 72 64 69 6e 61 74  |pdate..coordinat|
000000b0  69 6f 6e 2e 6b 38 73 2e  69 6f 2f 76 31 22 08 08  |ion.k8s.io/v1"..|
000000c0  b1 b2 e2 a1 06 10 00 32  08 46 69 65 6c 64 73 56  |.......2.FieldsV|
000000d0  31 3a 7c 0a 7a 7b 22 66  3a 73 70 65 63 22 3a 7b  |1:|.z{"f:spec":{|
000000e0  22 66 3a 61 63 71 75 69  72 65 54 69 6d 65 22 3a  |"f:acquireTime":|
000000f0  7b 7d 2c 22 66 3a 68 6f  6c 64 65 72 49 64 65 6e  |{},"f:holderIden|
00000100  74 69 74 79 22 3a 7b 7d  2c 22 66 3a 6c 65 61 73  |tity":{},"f:leas|
00000110  65 44 75 72 61 74 69 6f  6e 53 65 63 6f 6e 64 73  |eDurationSeconds|
00000120  22 3a 7b 7d 2c 22 66 3a  6c 65 61 73 65 54 72 61  |":{},"f:leaseTra|
00000130  6e 73 69 74 69 6f 6e 73  22 3a 7b 7d 2c 22 66 3a  |nsitions":{},"f:|
00000140  72 65 6e 65 77 54 69 6d  65 22 3a 7b 7d 7d 7d 42  |renewTime":{}}}B|
00000150  00 12 59 0a 37 6b 69 6e  64 2d 63 6f 6e 74 72 6f  |..Y.7kind-contro|
00000160  6c 2d 70 6c 61 6e 65 5f  30 64 32 66 61 66 39 33  |l-plane_0d2faf93|
00000170  2d 34 61 30 62 2d 34 66  32 38 2d 38 33 64 33 2d  |-4a0b-4f28-83d3-|
00000180  35 62 35 62 62 66 61 31  65 36 31 30 10 0f 1a 0c  |5b5bbfa1e610....|
00000190  08 f7 a5 86 a2 06 10 b9  84 b7 94 03 22 0c 08 86  |............"...|
000001a0  ed bd a2 06 10 ce d9 fa  88 03 28 0a 1a 00 22 00  |..........(...".|
I0501 08:21:26.836537       1 round_trippers.go:466] curl -v -XPUT  -H "Accept: application/vnd.kubernetes.protobuf, */*" -H "Content-Type: application/vnd.kubernetes.protobuf" -H "User-Agent: kube-scheduler/v1.24.7 (linux/amd64) kubernetes/e6f3597/leader-election" 'https://172.18.0.2:6443/apis/coordination.k8s.io/v1/namespaces/kube-system/leases/kube-scheduler?timeout=5s'
I0501 08:21:26.845252       1 round_trippers.go:553] PUT https://172.18.0.2:6443/apis/coordination.k8s.io/v1/namespaces/kube-system/leases/kube-scheduler?timeout=5s 200 OK in 8 milliseconds
I0501 08:21:26.845293       1 round_trippers.go:570] HTTP Statistics: GetConnection 0 ms ServerProcessing 7 ms Duration 8 ms
I0501 08:21:26.845309       1 round_trippers.go:577] Response Headers:
I0501 08:21:26.845326       1 round_trippers.go:580]     Content-Type: application/vnd.kubernetes.protobuf
I0501 08:21:26.845349       1 round_trippers.go:580]     X-Kubernetes-Pf-Flowschema-Uid: 493426e8-0f6d-4ea6-bc2c-2d926c7e3221
I0501 08:21:26.845374       1 round_trippers.go:580]     X-Kubernetes-Pf-Prioritylevel-Uid: afabb116-6975-46b8-863b-3258bec9e1ea
I0501 08:21:26.845410       1 round_trippers.go:580]     Content-Length: 432
I0501 08:21:26.845428       1 round_trippers.go:580]     Date: Mon, 01 May 2023 08:21:26 GMT
I0501 08:21:26.845443       1 round_trippers.go:580]     Audit-Id: 1c1314b2-5766-40bf-a4c3-c674a71a1931
I0501 08:21:26.845457       1 round_trippers.go:580]     Cache-Control: no-cache, private
I0501 08:21:26.845524       1 request.go:1152] Response Body:
00000000  6b 38 73 00 0a 1f 0a 16  63 6f 6f 72 64 69 6e 61  |k8s.....coordina|
00000010  74 69 6f 6e 2e 6b 38 73  2e 69 6f 2f 76 31 12 05  |tion.k8s.io/v1..|
00000020  4c 65 61 73 65 12 84 03  0a a6 02 0a 0e 6b 75 62  |Lease........kub|
00000030  65 2d 73 63 68 65 64 75  6c 65 72 12 00 1a 0b 6b  |e-scheduler....k|
00000040  75 62 65 2d 73 79 73 74  65 6d 22 00 2a 24 36 61  |ube-system".*$6a|
00000050  30 65 32 30 33 66 2d 65  32 38 30 2d 34 36 61 30  |0e203f-e280-46a0|
00000060  2d 39 35 33 62 2d 35 66  62 64 63 37 38 61 63 38  |-953b-5fbdc78ac8|
00000070  36 65 32 07 32 32 36 38  36 31 37 38 00 42 08 08  |6e2.22686178.B..|
00000080  b1 b2 e2 a1 06 10 00 7a  00 8a 01 c4 01 0a 0e 6b  |.......z.......k|
00000090  75 62 65 2d 73 63 68 65  64 75 6c 65 72 12 06 55  |ube-scheduler..U|
000000a0  70 64 61 74 65 1a 16 63  6f 6f 72 64 69 6e 61 74  |pdate..coordinat|
000000b0  69 6f 6e 2e 6b 38 73 2e  69 6f 2f 76 31 22 08 08  |ion.k8s.io/v1"..|
000000c0  b1 b2 e2 a1 06 10 00 32  08 46 69 65 6c 64 73 56  |.......2.FieldsV|
000000d0  31 3a 7c 0a 7a 7b 22 66  3a 73 70 65 63 22 3a 7b  |1:|.z{"f:spec":{|
000000e0  22 66 3a 61 63 71 75 69  72 65 54 69 6d 65 22 3a  |"f:acquireTime":|
000000f0  7b 7d 2c 22 66 3a 68 6f  6c 64 65 72 49 64 65 6e  |{},"f:holderIden|
00000100  74 69 74 79 22 3a 7b 7d  2c 22 66 3a 6c 65 61 73  |tity":{},"f:leas|
00000110  65 44 75 72 61 74 69 6f  6e 53 65 63 6f 6e 64 73  |eDurationSeconds|
00000120  22 3a 7b 7d 2c 22 66 3a  6c 65 61 73 65 54 72 61  |":{},"f:leaseTra|
00000130  6e 73 69 74 69 6f 6e 73  22 3a 7b 7d 2c 22 66 3a  |nsitions":{},"f:|
00000140  72 65 6e 65 77 54 69 6d  65 22 3a 7b 7d 7d 7d 42  |renewTime":{}}}B|
00000150  00 12 59 0a 37 6b 69 6e  64 2d 63 6f 6e 74 72 6f  |..Y.7kind-contro|
00000160  6c 2d 70 6c 61 6e 65 5f  30 64 32 66 61 66 39 33  |l-plane_0d2faf93|
00000170  2d 34 61 30 62 2d 34 66  32 38 2d 38 33 64 33 2d  |-4a0b-4f28-83d3-|
00000180  35 62 35 62 62 66 61 31  65 36 31 30 10 0f 1a 0c  |5b5bbfa1e610....|
00000190  08 f7 a5 86 a2 06 10 b9  84 b7 94 03 22 0c 08 86  |............"...|
000001a0  ed bd a2 06 10 ce d9 fa  88 03 28 0a 1a 00 22 00  |..........(...".|
I0501 08:21:26.845659       1 leaderelection.go:278] successfully renewed lease kube-system/kube-scheduler
I0501 08:21:28.847441       1 round_trippers.go:466] curl -v -XGET  -H "Accept: application/vnd.kubernetes.protobuf, */*" -H "User-Agent: kube-scheduler/v1.24.7 (linux/amd64) kubernetes/e6f3597/leader-election" 'https://172.18.0.2:6443/apis/coordination.k8s.io/v1/namespaces/kube-system/leases/kube-scheduler?timeout=5s'
I0501 08:21:28.852876       1 round_trippers.go:553] GET https://172.18.0.2:6443/apis/coordination.k8s.io/v1/namespaces/kube-system/leases/kube-scheduler?timeout=5s 200 OK in 5 milliseconds
I0501 08:21:28.852955       1 round_trippers.go:570] HTTP Statistics: GetConnection 0 ms ServerProcessing 5 ms Duration 5 ms
I0501 08:21:28.852982       1 round_trippers.go:577] Response Headers:
I0501 08:21:28.853032       1 round_trippers.go:580]     Cache-Control: no-cache, private
I0501 08:21:28.853053       1 round_trippers.go:580]     Content-Type: application/vnd.kubernetes.protobuf
I0501 08:21:28.853074       1 round_trippers.go:580]     X-Kubernetes-Pf-Flowschema-Uid: 493426e8-0f6d-4ea6-bc2c-2d926c7e3221
I0501 08:21:28.853097       1 round_trippers.go:580]     X-Kubernetes-Pf-Prioritylevel-Uid: afabb116-6975-46b8-863b-3258bec9e1ea
I0501 08:21:28.853130       1 round_trippers.go:580]     Content-Length: 432
I0501 08:21:28.853161       1 round_trippers.go:580]     Date: Mon, 01 May 2023 08:21:28 GMT
I0501 08:21:28.853184       1 round_trippers.go:580]     Audit-Id: 371fd894-8e8c-4442-99e1-25eee25ae32d
I0501 08:21:28.853277       1 request.go:1152] Response Body:
00000000  6b 38 73 00 0a 1f 0a 16  63 6f 6f 72 64 69 6e 61  |k8s.....coordina|
00000010  74 69 6f 6e 2e 6b 38 73  2e 69 6f 2f 76 31 12 05  |tion.k8s.io/v1..|
00000020  4c 65 61 73 65 12 84 03  0a a6 02 0a 0e 6b 75 62  |Lease........kub|
00000030  65 2d 73 63 68 65 64 75  6c 65 72 12 00 1a 0b 6b  |e-scheduler....k|
00000040  75 62 65 2d 73 79 73 74  65 6d 22 00 2a 24 36 61  |ube-system".*$6a|
00000050  30 65 32 30 33 66 2d 65  32 38 30 2d 34 36 61 30  |0e203f-e280-46a0|
00000060  2d 39 35 33 62 2d 35 66  62 64 63 37 38 61 63 38  |-953b-5fbdc78ac8|
00000070  36 65 32 07 32 32 36 38  36 31 37 38 00 42 08 08  |6e2.22686178.B..|
00000080  b1 b2 e2 a1 06 10 00 7a  00 8a 01 c4 01 0a 0e 6b  |.......z.......k|
00000090  75 62 65 2d 73 63 68 65  64 75 6c 65 72 12 06 55  |ube-scheduler..U|
000000a0  70 64 61 74 65 1a 16 63  6f 6f 72 64 69 6e 61 74  |pdate..coordinat|
000000b0  69 6f 6e 2e 6b 38 73 2e  69 6f 2f 76 31 22 08 08  |ion.k8s.io/v1"..|
000000c0  b1 b2 e2 a1 06 10 00 32  08 46 69 65 6c 64 73 56  |.......2.FieldsV|
000000d0  31 3a 7c 0a 7a 7b 22 66  3a 73 70 65 63 22 3a 7b  |1:|.z{"f:spec":{|
000000e0  22 66 3a 61 63 71 75 69  72 65 54 69 6d 65 22 3a  |"f:acquireTime":|
000000f0  7b 7d 2c 22 66 3a 68 6f  6c 64 65 72 49 64 65 6e  |{},"f:holderIden|
00000100  74 69 74 79 22 3a 7b 7d  2c 22 66 3a 6c 65 61 73  |tity":{},"f:leas|
00000110  65 44 75 72 61 74 69 6f  6e 53 65 63 6f 6e 64 73  |eDurationSeconds|
00000120  22 3a 7b 7d 2c 22 66 3a  6c 65 61 73 65 54 72 61  |":{},"f:leaseTra|
00000130  6e 73 69 74 69 6f 6e 73  22 3a 7b 7d 2c 22 66 3a  |nsitions":{},"f:|
00000140  72 65 6e 65 77 54 69 6d  65 22 3a 7b 7d 7d 7d 42  |renewTime":{}}}B|
00000150  00 12 59 0a 37 6b 69 6e  64 2d 63 6f 6e 74 72 6f  |..Y.7kind-contro|
00000160  6c 2d 70 6c 61 6e 65 5f  30 64 32 66 61 66 39 33  |l-plane_0d2faf93|
00000170  2d 34 61 30 62 2d 34 66  32 38 2d 38 33 64 33 2d  |-4a0b-4f28-83d3-|
00000180  35 62 35 62 62 66 61 31  65 36 31 30 10 0f 1a 0c  |5b5bbfa1e610....|
00000190  08 f7 a5 86 a2 06 10 b9  84 b7 94 03 22 0c 08 86  |............"...|
000001a0  ed bd a2 06 10 ce d9 fa  88 03 28 0a 1a 00 22 00  |..........(...".|
I0501 08:21:28.853543       1 request.go:1152] Request Body:
00000000  6b 38 73 00 0a 1f 0a 16  63 6f 6f 72 64 69 6e 61  |k8s.....coordina|
00000010  74 69 6f 6e 2e 6b 38 73  2e 69 6f 2f 76 31 12 05  |tion.k8s.io/v1..|
00000020  4c 65 61 73 65 12 84 03  0a a6 02 0a 0e 6b 75 62  |Lease........kub|
00000030  65 2d 73 63 68 65 64 75  6c 65 72 12 00 1a 0b 6b  |e-scheduler....k|
00000040  75 62 65 2d 73 79 73 74  65 6d 22 00 2a 24 36 61  |ube-system".*$6a|
00000050  30 65 32 30 33 66 2d 65  32 38 30 2d 34 36 61 30  |0e203f-e280-46a0|
00000060  2d 39 35 33 62 2d 35 66  62 64 63 37 38 61 63 38  |-953b-5fbdc78ac8|
00000070  36 65 32 07 32 32 36 38  36 31 37 38 00 42 08 08  |6e2.22686178.B..|
00000080  b1 b2 e2 a1 06 10 00 7a  00 8a 01 c4 01 0a 0e 6b  |.......z.......k|
00000090  75 62 65 2d 73 63 68 65  64 75 6c 65 72 12 06 55  |ube-scheduler..U|
000000a0  70 64 61 74 65 1a 16 63  6f 6f 72 64 69 6e 61 74  |pdate..coordinat|
000000b0  69 6f 6e 2e 6b 38 73 2e  69 6f 2f 76 31 22 08 08  |ion.k8s.io/v1"..|
000000c0  b1 b2 e2 a1 06 10 00 32  08 46 69 65 6c 64 73 56  |.......2.FieldsV|
000000d0  31 3a 7c 0a 7a 7b 22 66  3a 73 70 65 63 22 3a 7b  |1:|.z{"f:spec":{|
000000e0  22 66 3a 61 63 71 75 69  72 65 54 69 6d 65 22 3a  |"f:acquireTime":|
000000f0  7b 7d 2c 22 66 3a 68 6f  6c 64 65 72 49 64 65 6e  |{},"f:holderIden|
00000100  74 69 74 79 22 3a 7b 7d  2c 22 66 3a 6c 65 61 73  |tity":{},"f:leas|
00000110  65 44 75 72 61 74 69 6f  6e 53 65 63 6f 6e 64 73  |eDurationSeconds|
00000120  22 3a 7b 7d 2c 22 66 3a  6c 65 61 73 65 54 72 61  |":{},"f:leaseTra|
00000130  6e 73 69 74 69 6f 6e 73  22 3a 7b 7d 2c 22 66 3a  |nsitions":{},"f:|
00000140  72 65 6e 65 77 54 69 6d  65 22 3a 7b 7d 7d 7d 42  |renewTime":{}}}B|
00000150  00 12 59 0a 37 6b 69 6e  64 2d 63 6f 6e 74 72 6f  |..Y.7kind-contro|
00000160  6c 2d 70 6c 61 6e 65 5f  30 64 32 66 61 66 39 33  |l-plane_0d2faf93|
00000170  2d 34 61 30 62 2d 34 66  32 38 2d 38 33 64 33 2d  |-4a0b-4f28-83d3-|
00000180  35 62 35 62 62 66 61 31  65 36 31 30 10 0f 1a 0c  |5b5bbfa1e610....|
00000190  08 f7 a5 86 a2 06 10 b9  84 b7 94 03 22 0c 08 88  |............"...|
000001a0  ed bd a2 06 10 81 cc ff  93 03 28 0a 1a 00 22 00  |..........(...".|
I0501 08:21:28.853756       1 round_trippers.go:466] curl -v -XPUT  -H "Accept: application/vnd.kubernetes.protobuf, */*" -H "Content-Type: application/vnd.kubernetes.protobuf" -H "User-Agent: kube-scheduler/v1.24.7 (linux/amd64) kubernetes/e6f3597/leader-election" 'https://172.18.0.2:6443/apis/coordination.k8s.io/v1/namespaces/kube-system/leases/kube-scheduler?timeout=5s'
I0501 08:21:28.859072       1 round_trippers.go:553] PUT https://172.18.0.2:6443/apis/coordination.k8s.io/v1/namespaces/kube-system/leases/kube-scheduler?timeout=5s 200 OK in 5 milliseconds
I0501 08:21:28.859151       1 round_trippers.go:570] HTTP Statistics: GetConnection 0 ms ServerProcessing 4 ms Duration 5 ms
I0501 08:21:28.859167       1 round_trippers.go:577] Response Headers:
I0501 08:21:28.859185       1 round_trippers.go:580]     Audit-Id: e2f461b6-7769-4ad9-9048-458d7e20d859
I0501 08:21:28.859501       1 round_trippers.go:580]     Cache-Control: no-cache, private
I0501 08:21:28.859518       1 round_trippers.go:580]     Content-Type: application/vnd.kubernetes.protobuf
I0501 08:21:28.859534       1 round_trippers.go:580]     X-Kubernetes-Pf-Flowschema-Uid: 493426e8-0f6d-4ea6-bc2c-2d926c7e3221
I0501 08:21:28.859549       1 round_trippers.go:580]     X-Kubernetes-Pf-Prioritylevel-Uid: afabb116-6975-46b8-863b-3258bec9e1ea
I0501 08:21:28.859564       1 round_trippers.go:580]     Content-Length: 432
I0501 08:21:28.859579       1 round_trippers.go:580]     Date: Mon, 01 May 2023 08:21:28 GMT
I0501 08:21:28.859662       1 request.go:1152] Response Body:
00000000  6b 38 73 00 0a 1f 0a 16  63 6f 6f 72 64 69 6e 61  |k8s.....coordina|
00000010  74 69 6f 6e 2e 6b 38 73  2e 69 6f 2f 76 31 12 05  |tion.k8s.io/v1..|
00000020  4c 65 61 73 65 12 84 03  0a a6 02 0a 0e 6b 75 62  |Lease........kub|
00000030  65 2d 73 63 68 65 64 75  6c 65 72 12 00 1a 0b 6b  |e-scheduler....k|
00000040  75 62 65 2d 73 79 73 74  65 6d 22 00 2a 24 36 61  |ube-system".*$6a|
00000050  30 65 32 30 33 66 2d 65  32 38 30 2d 34 36 61 30  |0e203f-e280-46a0|
00000060  2d 39 35 33 62 2d 35 66  62 64 63 37 38 61 63 38  |-953b-5fbdc78ac8|
00000070  36 65 32 07 32 32 36 38  36 32 30 38 00 42 08 08  |6e2.22686208.B..|
00000080  b1 b2 e2 a1 06 10 00 7a  00 8a 01 c4 01 0a 0e 6b  |.......z.......k|
00000090  75 62 65 2d 73 63 68 65  64 75 6c 65 72 12 06 55  |ube-scheduler..U|
000000a0  70 64 61 74 65 1a 16 63  6f 6f 72 64 69 6e 61 74  |pdate..coordinat|
000000b0  69 6f 6e 2e 6b 38 73 2e  69 6f 2f 76 31 22 08 08  |ion.k8s.io/v1"..|
000000c0  b1 b2 e2 a1 06 10 00 32  08 46 69 65 6c 64 73 56  |.......2.FieldsV|
000000d0  31 3a 7c 0a 7a 7b 22 66  3a 73 70 65 63 22 3a 7b  |1:|.z{"f:spec":{|
000000e0  22 66 3a 61 63 71 75 69  72 65 54 69 6d 65 22 3a  |"f:acquireTime":|
000000f0  7b 7d 2c 22 66 3a 68 6f  6c 64 65 72 49 64 65 6e  |{},"f:holderIden|
00000100  74 69 74 79 22 3a 7b 7d  2c 22 66 3a 6c 65 61 73  |tity":{},"f:leas|
00000110  65 44 75 72 61 74 69 6f  6e 53 65 63 6f 6e 64 73  |eDurationSeconds|
00000120  22 3a 7b 7d 2c 22 66 3a  6c 65 61 73 65 54 72 61  |":{},"f:leaseTra|
00000130  6e 73 69 74 69 6f 6e 73  22 3a 7b 7d 2c 22 66 3a  |nsitions":{},"f:|
00000140  72 65 6e 65 77 54 69 6d  65 22 3a 7b 7d 7d 7d 42  |renewTime":{}}}B|
00000150  00 12 59 0a 37 6b 69 6e  64 2d 63 6f 6e 74 72 6f  |..Y.7kind-contro|
00000160  6c 2d 70 6c 61 6e 65 5f  30 64 32 66 61 66 39 33  |l-plane_0d2faf93|
00000170  2d 34 61 30 62 2d 34 66  32 38 2d 38 33 64 33 2d  |-4a0b-4f28-83d3-|
00000180  35 62 35 62 62 66 61 31  65 36 31 30 10 0f 1a 0c  |5b5bbfa1e610....|
00000190  08 f7 a5 86 a2 06 10 b9  84 b7 94 03 22 0c 08 88  |............"...|
000001a0  ed bd a2 06 10 81 cc ff  93 03 28 0a 1a 00 22 00  |..........(...".|
I0501 08:21:28.860269       1 leaderelection.go:278] successfully renewed lease kube-system/kube-scheduler
I0501 08:21:29.666807       1 pathrecorder.go:241] kube-scheduler: "/healthz" satisfied by exact match
I0501 08:21:29.667283       1 httplog.go:131] "HTTP" verb="GET" URI="/healthz" latency="222.004µs" userAgent="kube-probe/1.24" audit-ID="" srcIP="127.0.0.1:58488" resp=200
I0501 08:21:30.861988       1 round_trippers.go:466] curl -v -XGET  -H "Accept: application/vnd.kubernetes.protobuf, */*" -H "User-Agent: kube-scheduler/v1.24.7 (linux/amd64) kubernetes/e6f3597/leader-election" 'https://172.18.0.2:6443/apis/coordination.k8s.io/v1/namespaces/kube-system/leases/kube-scheduler?timeout=5s'
I0501 08:21:30.866266       1 round_trippers.go:553] GET https://172.18.0.2:6443/apis/coordination.k8s.io/v1/namespaces/kube-system/leases/kube-scheduler?timeout=5s 200 OK in 4 milliseconds
I0501 08:21:30.866303       1 round_trippers.go:570] HTTP Statistics: GetConnection 0 ms ServerProcessing 4 ms Duration 4 ms
I0501 08:21:30.866320       1 round_trippers.go:577] Response Headers:
I0501 08:21:30.866337       1 round_trippers.go:580]     Audit-Id: e84da49e-2612-46d4-84d9-deb825435052
I0501 08:21:30.866352       1 round_trippers.go:580]     Cache-Control: no-cache, private
I0501 08:21:30.866366       1 round_trippers.go:580]     Content-Type: application/vnd.kubernetes.protobuf
I0501 08:21:30.866381       1 round_trippers.go:580]     X-Kubernetes-Pf-Flowschema-Uid: 493426e8-0f6d-4ea6-bc2c-2d926c7e3221
I0501 08:21:30.866396       1 round_trippers.go:580]     X-Kubernetes-Pf-Prioritylevel-Uid: afabb116-6975-46b8-863b-3258bec9e1ea
I0501 08:21:30.866410       1 round_trippers.go:580]     Content-Length: 432
I0501 08:21:30.866424       1 round_trippers.go:580]     Date: Mon, 01 May 2023 08:21:30 GMT
I0501 08:21:30.866487       1 request.go:1152] Response Body:
00000000  6b 38 73 00 0a 1f 0a 16  63 6f 6f 72 64 69 6e 61  |k8s.....coordina|
00000010  74 69 6f 6e 2e 6b 38 73  2e 69 6f 2f 76 31 12 05  |tion.k8s.io/v1..|
00000020  4c 65 61 73 65 12 84 03  0a a6 02 0a 0e 6b 75 62  |Lease........kub|
00000030  65 2d 73 63 68 65 64 75  6c 65 72 12 00 1a 0b 6b  |e-scheduler....k|
00000040  75 62 65 2d 73 79 73 74  65 6d 22 00 2a 24 36 61  |ube-system".*$6a|
00000050  30 65 32 30 33 66 2d 65  32 38 30 2d 34 36 61 30  |0e203f-e280-46a0|
00000060  2d 39 35 33 62 2d 35 66  62 64 63 37 38 61 63 38  |-953b-5fbdc78ac8|
00000070  36 65 32 07 32 32 36 38  36 32 30 38 00 42 08 08  |6e2.22686208.B..|
00000080  b1 b2 e2 a1 06 10 00 7a  00 8a 01 c4 01 0a 0e 6b  |.......z.......k|
00000090  75 62 65 2d 73 63 68 65  64 75 6c 65 72 12 06 55  |ube-scheduler..U|
000000a0  70 64 61 74 65 1a 16 63  6f 6f 72 64 69 6e 61 74  |pdate..coordinat|
000000b0  69 6f 6e 2e 6b 38 73 2e  69 6f 2f 76 31 22 08 08  |ion.k8s.io/v1"..|
000000c0  b1 b2 e2 a1 06 10 00 32  08 46 69 65 6c 64 73 56  |.......2.FieldsV|
000000d0  31 3a 7c 0a 7a 7b 22 66  3a 73 70 65 63 22 3a 7b  |1:|.z{"f:spec":{|
000000e0  22 66 3a 61 63 71 75 69  72 65 54 69 6d 65 22 3a  |"f:acquireTime":|
000000f0  7b 7d 2c 22 66 3a 68 6f  6c 64 65 72 49 64 65 6e  |{},"f:holderIden|
00000100  74 69 74 79 22 3a 7b 7d  2c 22 66 3a 6c 65 61 73  |tity":{},"f:leas|
00000110  65 44 75 72 61 74 69 6f  6e 53 65 63 6f 6e 64 73  |eDurationSeconds|
00000120  22 3a 7b 7d 2c 22 66 3a  6c 65 61 73 65 54 72 61  |":{},"f:leaseTra|
00000130  6e 73 69 74 69 6f 6e 73  22 3a 7b 7d 2c 22 66 3a  |nsitions":{},"f:|
00000140  72 65 6e 65 77 54 69 6d  65 22 3a 7b 7d 7d 7d 42  |renewTime":{}}}B|
00000150  00 12 59 0a 37 6b 69 6e  64 2d 63 6f 6e 74 72 6f  |..Y.7kind-contro|
00000160  6c 2d 70 6c 61 6e 65 5f  30 64 32 66 61 66 39 33  |l-plane_0d2faf93|
00000170  2d 34 61 30 62 2d 34 66  32 38 2d 38 33 64 33 2d  |-4a0b-4f28-83d3-|
00000180  35 62 35 62 62 66 61 31  65 36 31 30 10 0f 1a 0c  |5b5bbfa1e610....|
00000190  08 f7 a5 86 a2 06 10 b9  84 b7 94 03 22 0c 08 88  |............"...|
000001a0  ed bd a2 06 10 81 cc ff  93 03 28 0a 1a 00 22 00  |..........(...".|
I0501 08:21:30.866681       1 request.go:1152] Request Body:
00000000  6b 38 73 00 0a 1f 0a 16  63 6f 6f 72 64 69 6e 61  |k8s.....coordina|
00000010  74 69 6f 6e 2e 6b 38 73  2e 69 6f 2f 76 31 12 05  |tion.k8s.io/v1..|
00000020  4c 65 61 73 65 12 84 03  0a a6 02 0a 0e 6b 75 62  |Lease........kub|
00000030  65 2d 73 63 68 65 64 75  6c 65 72 12 00 1a 0b 6b  |e-scheduler....k|
00000040  75 62 65 2d 73 79 73 74  65 6d 22 00 2a 24 36 61  |ube-system".*$6a|
00000050  30 65 32 30 33 66 2d 65  32 38 30 2d 34 36 61 30  |0e203f-e280-46a0|
00000060  2d 39 35 33 62 2d 35 66  62 64 63 37 38 61 63 38  |-953b-5fbdc78ac8|
00000070  36 65 32 07 32 32 36 38  36 32 30 38 00 42 08 08  |6e2.22686208.B..|
00000080  b1 b2 e2 a1 06 10 00 7a  00 8a 01 c4 01 0a 0e 6b  |.......z.......k|
00000090  75 62 65 2d 73 63 68 65  64 75 6c 65 72 12 06 55  |ube-scheduler..U|
000000a0  70 64 61 74 65 1a 16 63  6f 6f 72 64 69 6e 61 74  |pdate..coordinat|
000000b0  69 6f 6e 2e 6b 38 73 2e  69 6f 2f 76 31 22 08 08  |ion.k8s.io/v1"..|
000000c0  b1 b2 e2 a1 06 10 00 32  08 46 69 65 6c 64 73 56  |.......2.FieldsV|
000000d0  31 3a 7c 0a 7a 7b 22 66  3a 73 70 65 63 22 3a 7b  |1:|.z{"f:spec":{|
000000e0  22 66 3a 61 63 71 75 69  72 65 54 69 6d 65 22 3a  |"f:acquireTime":|
000000f0  7b 7d 2c 22 66 3a 68 6f  6c 64 65 72 49 64 65 6e  |{},"f:holderIden|
00000100  74 69 74 79 22 3a 7b 7d  2c 22 66 3a 6c 65 61 73  |tity":{},"f:leas|
00000110  65 44 75 72 61 74 69 6f  6e 53 65 63 6f 6e 64 73  |eDurationSeconds|
00000120  22 3a 7b 7d 2c 22 66 3a  6c 65 61 73 65 54 72 61  |":{},"f:leaseTra|
00000130  6e 73 69 74 69 6f 6e 73  22 3a 7b 7d 2c 22 66 3a  |nsitions":{},"f:|
00000140  72 65 6e 65 77 54 69 6d  65 22 3a 7b 7d 7d 7d 42  |renewTime":{}}}B|
00000150  00 12 59 0a 37 6b 69 6e  64 2d 63 6f 6e 74 72 6f  |..Y.7kind-contro|
00000160  6c 2d 70 6c 61 6e 65 5f  30 64 32 66 61 66 39 33  |l-plane_0d2faf93|
00000170  2d 34 61 30 62 2d 34 66  32 38 2d 38 33 64 33 2d  |-4a0b-4f28-83d3-|
00000180  35 62 35 62 62 66 61 31  65 36 31 30 10 0f 1a 0c  |5b5bbfa1e610....|
00000190  08 f7 a5 86 a2 06 10 b9  84 b7 94 03 22 0c 08 8a  |............"...|
000001a0  ed bd a2 06 10 83 95 f9  9a 03 28 0a 1a 00 22 00  |..........(...".|
I0501 08:21:30.866784       1 round_trippers.go:466] curl -v -XPUT  -H "Accept: application/vnd.kubernetes.protobuf, */*" -H "Content-Type: application/vnd.kubernetes.protobuf" -H "User-Agent: kube-scheduler/v1.24.7 (linux/amd64) kubernetes/e6f3597/leader-election" 'https://172.18.0.2:6443/apis/coordination.k8s.io/v1/namespaces/kube-system/leases/kube-scheduler?timeout=5s'
I0501 08:21:30.874327       1 round_trippers.go:553] PUT https://172.18.0.2:6443/apis/coordination.k8s.io/v1/namespaces/kube-system/leases/kube-scheduler?timeout=5s 200 OK in 7 milliseconds
I0501 08:21:30.874383       1 round_trippers.go:570] HTTP Statistics: GetConnection 0 ms ServerProcessing 7 ms Duration 7 ms
I0501 08:21:30.874409       1 round_trippers.go:577] Response Headers:
I0501 08:21:30.874446       1 round_trippers.go:580]     X-Kubernetes-Pf-Prioritylevel-Uid: afabb116-6975-46b8-863b-3258bec9e1ea
I0501 08:21:30.874474       1 round_trippers.go:580]     Content-Length: 432
I0501 08:21:30.874502       1 round_trippers.go:580]     Date: Mon, 01 May 2023 08:21:30 GMT
I0501 08:21:30.874530       1 round_trippers.go:580]     Audit-Id: 42c37a65-d8df-4311-b2c0-ff71175aacd8
I0501 08:21:30.874556       1 round_trippers.go:580]     Cache-Control: no-cache, private
I0501 08:21:30.874594       1 round_trippers.go:580]     Content-Type: application/vnd.kubernetes.protobuf
I0501 08:21:30.874622       1 round_trippers.go:580]     X-Kubernetes-Pf-Flowschema-Uid: 493426e8-0f6d-4ea6-bc2c-2d926c7e3221
I0501 08:21:30.874704       1 request.go:1152] Response Body:
00000000  6b 38 73 00 0a 1f 0a 16  63 6f 6f 72 64 69 6e 61  |k8s.....coordina|
00000010  74 69 6f 6e 2e 6b 38 73  2e 69 6f 2f 76 31 12 05  |tion.k8s.io/v1..|
00000020  4c 65 61 73 65 12 84 03  0a a6 02 0a 0e 6b 75 62  |Lease........kub|
00000030  65 2d 73 63 68 65 64 75  6c 65 72 12 00 1a 0b 6b  |e-scheduler....k|
00000040  75 62 65 2d 73 79 73 74  65 6d 22 00 2a 24 36 61  |ube-system".*$6a|
00000050  30 65 32 30 33 66 2d 65  32 38 30 2d 34 36 61 30  |0e203f-e280-46a0|
00000060  2d 39 35 33 62 2d 35 66  62 64 63 37 38 61 63 38  |-953b-5fbdc78ac8|
00000070  36 65 32 07 32 32 36 38  36 32 32 38 00 42 08 08  |6e2.22686228.B..|
00000080  b1 b2 e2 a1 06 10 00 7a  00 8a 01 c4 01 0a 0e 6b  |.......z.......k|
00000090  75 62 65 2d 73 63 68 65  64 75 6c 65 72 12 06 55  |ube-scheduler..U|
000000a0  70 64 61 74 65 1a 16 63  6f 6f 72 64 69 6e 61 74  |pdate..coordinat|
000000b0  69 6f 6e 2e 6b 38 73 2e  69 6f 2f 76 31 22 08 08  |ion.k8s.io/v1"..|
000000c0  b1 b2 e2 a1 06 10 00 32  08 46 69 65 6c 64 73 56  |.......2.FieldsV|
000000d0  31 3a 7c 0a 7a 7b 22 66  3a 73 70 65 63 22 3a 7b  |1:|.z{"f:spec":{|
000000e0  22 66 3a 61 63 71 75 69  72 65 54 69 6d 65 22 3a  |"f:acquireTime":|
000000f0  7b 7d 2c 22 66 3a 68 6f  6c 64 65 72 49 64 65 6e  |{},"f:holderIden|
00000100  74 69 74 79 22 3a 7b 7d  2c 22 66 3a 6c 65 61 73  |tity":{},"f:leas|
00000110  65 44 75 72 61 74 69 6f  6e 53 65 63 6f 6e 64 73  |eDurationSeconds|
00000120  22 3a 7b 7d 2c 22 66 3a  6c 65 61 73 65 54 72 61  |":{},"f:leaseTra|
00000130  6e 73 69 74 69 6f 6e 73  22 3a 7b 7d 2c 22 66 3a  |nsitions":{},"f:|
00000140  72 65 6e 65 77 54 69 6d  65 22 3a 7b 7d 7d 7d 42  |renewTime":{}}}B|
00000150  00 12 59 0a 37 6b 69 6e  64 2d 63 6f 6e 74 72 6f  |..Y.7kind-contro|
00000160  6c 2d 70 6c 61 6e 65 5f  30 64 32 66 61 66 39 33  |l-plane_0d2faf93|
00000170  2d 34 61 30 62 2d 34 66  32 38 2d 38 33 64 33 2d  |-4a0b-4f28-83d3-|
00000180  35 62 35 62 62 66 61 31  65 36 31 30 10 0f 1a 0c  |5b5bbfa1e610....|
00000190  08 f7 a5 86 a2 06 10 b9  84 b7 94 03 22 0c 08 8a  |............"...|
000001a0  ed bd a2 06 10 83 95 f9  9a 03 28 0a 1a 00 22 00  |..........(...".|
I0501 08:21:30.874873       1 leaderelection.go:278] successfully renewed lease kube-system/kube-scheduler
I0501 08:21:32.876095       1 round_trippers.go:466] curl -v -XGET  -H "Accept: application/vnd.kubernetes.protobuf, */*" -H "User-Agent: kube-scheduler/v1.24.7 (linux/amd64) kubernetes/e6f3597/leader-election" 'https://172.18.0.2:6443/apis/coordination.k8s.io/v1/namespaces/kube-system/leases/kube-scheduler?timeout=5s'
I0501 08:21:32.926862       1 round_trippers.go:553] GET https://172.18.0.2:6443/apis/coordination.k8s.io/v1/namespaces/kube-system/leases/kube-scheduler?timeout=5s 200 OK in 50 milliseconds
I0501 08:21:32.926926       1 round_trippers.go:570] HTTP Statistics: GetConnection 0 ms ServerProcessing 50 ms Duration 50 ms
I0501 08:21:32.926952       1 round_trippers.go:577] Response Headers:
I0501 08:21:32.926978       1 round_trippers.go:580]     Content-Length: 432
I0501 08:21:32.927001       1 round_trippers.go:580]     Date: Mon, 01 May 2023 08:21:32 GMT
I0501 08:21:32.927025       1 round_trippers.go:580]     Audit-Id: 2c2f675e-1e00-4a91-9a48-40f2a19e2615
I0501 08:21:32.927051       1 round_trippers.go:580]     Cache-Control: no-cache, private
I0501 08:21:32.927074       1 round_trippers.go:580]     Content-Type: application/vnd.kubernetes.protobuf
I0501 08:21:32.927148       1 round_trippers.go:580]     X-Kubernetes-Pf-Flowschema-Uid: 493426e8-0f6d-4ea6-bc2c-2d926c7e3221
I0501 08:21:32.927193       1 round_trippers.go:580]     X-Kubernetes-Pf-Prioritylevel-Uid: afabb116-6975-46b8-863b-3258bec9e1ea
I0501 08:21:32.927321       1 request.go:1152] Response Body:
00000000  6b 38 73 00 0a 1f 0a 16  63 6f 6f 72 64 69 6e 61  |k8s.....coordina|
00000010  74 69 6f 6e 2e 6b 38 73  2e 69 6f 2f 76 31 12 05  |tion.k8s.io/v1..|
00000020  4c 65 61 73 65 12 84 03  0a a6 02 0a 0e 6b 75 62  |Lease........kub|
00000030  65 2d 73 63 68 65 64 75  6c 65 72 12 00 1a 0b 6b  |e-scheduler....k|
00000040  75 62 65 2d 73 79 73 74  65 6d 22 00 2a 24 36 61  |ube-system".*$6a|
00000050  30 65 32 30 33 66 2d 65  32 38 30 2d 34 36 61 30  |0e203f-e280-46a0|
00000060  2d 39 35 33 62 2d 35 66  62 64 63 37 38 61 63 38  |-953b-5fbdc78ac8|
00000070  36 65 32 07 32 32 36 38  36 32 32 38 00 42 08 08  |6e2.22686228.B..|
00000080  b1 b2 e2 a1 06 10 00 7a  00 8a 01 c4 01 0a 0e 6b  |.......z.......k|
00000090  75 62 65 2d 73 63 68 65  64 75 6c 65 72 12 06 55  |ube-scheduler..U|
000000a0  70 64 61 74 65 1a 16 63  6f 6f 72 64 69 6e 61 74  |pdate..coordinat|
000000b0  69 6f 6e 2e 6b 38 73 2e  69 6f 2f 76 31 22 08 08  |ion.k8s.io/v1"..|
000000c0  b1 b2 e2 a1 06 10 00 32  08 46 69 65 6c 64 73 56  |.......2.FieldsV|
000000d0  31 3a 7c 0a 7a 7b 22 66  3a 73 70 65 63 22 3a 7b  |1:|.z{"f:spec":{|
000000e0  22 66 3a 61 63 71 75 69  72 65 54 69 6d 65 22 3a  |"f:acquireTime":|
000000f0  7b 7d 2c 22 66 3a 68 6f  6c 64 65 72 49 64 65 6e  |{},"f:holderIden|
00000100  74 69 74 79 22 3a 7b 7d  2c 22 66 3a 6c 65 61 73  |tity":{},"f:leas|
00000110  65 44 75 72 61 74 69 6f  6e 53 65 63 6f 6e 64 73  |eDurationSeconds|
00000120  22 3a 7b 7d 2c 22 66 3a  6c 65 61 73 65 54 72 61  |":{},"f:leaseTra|
00000130  6e 73 69 74 69 6f 6e 73  22 3a 7b 7d 2c 22 66 3a  |nsitions":{},"f:|
00000140  72 65 6e 65 77 54 69 6d  65 22 3a 7b 7d 7d 7d 42  |renewTime":{}}}B|
00000150  00 12 59 0a 37 6b 69 6e  64 2d 63 6f 6e 74 72 6f  |..Y.7kind-contro|
00000160  6c 2d 70 6c 61 6e 65 5f  30 64 32 66 61 66 39 33  |l-plane_0d2faf93|
00000170  2d 34 61 30 62 2d 34 66  32 38 2d 38 33 64 33 2d  |-4a0b-4f28-83d3-|
00000180  35 62 35 62 62 66 61 31  65 36 31 30 10 0f 1a 0c  |5b5bbfa1e610....|
00000190  08 f7 a5 86 a2 06 10 b9  84 b7 94 03 22 0c 08 8a  |............"...|
000001a0  ed bd a2 06 10 83 95 f9  9a 03 28 0a 1a 00 22 00  |..........(...".|
I0501 08:21:32.927906       1 request.go:1152] Request Body:
00000000  6b 38 73 00 0a 1f 0a 16  63 6f 6f 72 64 69 6e 61  |k8s.....coordina|
00000010  74 69 6f 6e 2e 6b 38 73  2e 69 6f 2f 76 31 12 05  |tion.k8s.io/v1..|
00000020  4c 65 61 73 65 12 84 03  0a a6 02 0a 0e 6b 75 62  |Lease........kub|
00000030  65 2d 73 63 68 65 64 75  6c 65 72 12 00 1a 0b 6b  |e-scheduler....k|
00000040  75 62 65 2d 73 79 73 74  65 6d 22 00 2a 24 36 61  |ube-system".*$6a|
00000050  30 65 32 30 33 66 2d 65  32 38 30 2d 34 36 61 30  |0e203f-e280-46a0|
00000060  2d 39 35 33 62 2d 35 66  62 64 63 37 38 61 63 38  |-953b-5fbdc78ac8|
00000070  36 65 32 07 32 32 36 38  36 32 32 38 00 42 08 08  |6e2.22686228.B..|
00000080  b1 b2 e2 a1 06 10 00 7a  00 8a 01 c4 01 0a 0e 6b  |.......z.......k|
00000090  75 62 65 2d 73 63 68 65  64 75 6c 65 72 12 06 55  |ube-scheduler..U|
000000a0  70 64 61 74 65 1a 16 63  6f 6f 72 64 69 6e 61 74  |pdate..coordinat|
000000b0  69 6f 6e 2e 6b 38 73 2e  69 6f 2f 76 31 22 08 08  |ion.k8s.io/v1"..|
000000c0  b1 b2 e2 a1 06 10 00 32  08 46 69 65 6c 64 73 56  |.......2.FieldsV|
000000d0  31 3a 7c 0a 7a 7b 22 66  3a 73 70 65 63 22 3a 7b  |1:|.z{"f:spec":{|
000000e0  22 66 3a 61 63 71 75 69  72 65 54 69 6d 65 22 3a  |"f:acquireTime":|
000000f0  7b 7d 2c 22 66 3a 68 6f  6c 64 65 72 49 64 65 6e  |{},"f:holderIden|
00000100  74 69 74 79 22 3a 7b 7d  2c 22 66 3a 6c 65 61 73  |tity":{},"f:leas|
00000110  65 44 75 72 61 74 69 6f  6e 53 65 63 6f 6e 64 73  |eDurationSeconds|
00000120  22 3a 7b 7d 2c 22 66 3a  6c 65 61 73 65 54 72 61  |":{},"f:leaseTra|
00000130  6e 73 69 74 69 6f 6e 73  22 3a 7b 7d 2c 22 66 3a  |nsitions":{},"f:|
00000140  72 65 6e 65 77 54 69 6d  65 22 3a 7b 7d 7d 7d 42  |renewTime":{}}}B|
00000150  00 12 59 0a 37 6b 69 6e  64 2d 63 6f 6e 74 72 6f  |..Y.7kind-contro|
00000160  6c 2d 70 6c 61 6e 65 5f  30 64 32 66 61 66 39 33  |l-plane_0d2faf93|
00000170  2d 34 61 30 62 2d 34 66  32 38 2d 38 33 64 33 2d  |-4a0b-4f28-83d3-|
00000180  35 62 35 62 62 66 61 31  65 36 31 30 10 0f 1a 0c  |5b5bbfa1e610....|
00000190  08 f7 a5 86 a2 06 10 b9  84 b7 94 03 22 0c 08 8c  |............"...|
000001a0  ed bd a2 06 10 c6 b7 cf  a1 03 28 0a 1a 00 22 00  |..........(...".|
I0501 08:21:32.928069       1 round_trippers.go:466] curl -v -XPUT  -H "Accept: application/vnd.kubernetes.protobuf, */*" -H "Content-Type: application/vnd.kubernetes.protobuf" -H "User-Agent: kube-scheduler/v1.24.7 (linux/amd64) kubernetes/e6f3597/leader-election" 'https://172.18.0.2:6443/apis/coordination.k8s.io/v1/namespaces/kube-system/leases/kube-scheduler?timeout=5s'
I0501 08:21:32.935805       1 round_trippers.go:553] PUT https://172.18.0.2:6443/apis/coordination.k8s.io/v1/namespaces/kube-system/leases/kube-scheduler?timeout=5s 200 OK in 7 milliseconds
I0501 08:21:32.935867       1 round_trippers.go:570] HTTP Statistics: GetConnection 0 ms ServerProcessing 7 ms Duration 7 ms
I0501 08:21:32.935888       1 round_trippers.go:577] Response Headers:
I0501 08:21:32.935907       1 round_trippers.go:580]     Content-Length: 432
I0501 08:21:32.935929       1 round_trippers.go:580]     Date: Mon, 01 May 2023 08:21:32 GMT
I0501 08:21:32.935947       1 round_trippers.go:580]     Audit-Id: bf79a4a6-904a-47ea-954e-e9c2f0921b1f
I0501 08:21:32.935965       1 round_trippers.go:580]     Cache-Control: no-cache, private
I0501 08:21:32.935983       1 round_trippers.go:580]     Content-Type: application/vnd.kubernetes.protobuf
I0501 08:21:32.936001       1 round_trippers.go:580]     X-Kubernetes-Pf-Flowschema-Uid: 493426e8-0f6d-4ea6-bc2c-2d926c7e3221
I0501 08:21:32.936019       1 round_trippers.go:580]     X-Kubernetes-Pf-Prioritylevel-Uid: afabb116-6975-46b8-863b-3258bec9e1ea
I0501 08:21:32.936098       1 request.go:1152] Response Body:
00000000  6b 38 73 00 0a 1f 0a 16  63 6f 6f 72 64 69 6e 61  |k8s.....coordina|
00000010  74 69 6f 6e 2e 6b 38 73  2e 69 6f 2f 76 31 12 05  |tion.k8s.io/v1..|
00000020  4c 65 61 73 65 12 84 03  0a a6 02 0a 0e 6b 75 62  |Lease........kub|
00000030  65 2d 73 63 68 65 64 75  6c 65 72 12 00 1a 0b 6b  |e-scheduler....k|
00000040  75 62 65 2d 73 79 73 74  65 6d 22 00 2a 24 36 61  |ube-system".*$6a|
00000050  30 65 32 30 33 66 2d 65  32 38 30 2d 34 36 61 30  |0e203f-e280-46a0|
00000060  2d 39 35 33 62 2d 35 66  62 64 63 37 38 61 63 38  |-953b-5fbdc78ac8|
00000070  36 65 32 07 32 32 36 38  36 32 37 38 00 42 08 08  |6e2.22686278.B..|
00000080  b1 b2 e2 a1 06 10 00 7a  00 8a 01 c4 01 0a 0e 6b  |.......z.......k|
00000090  75 62 65 2d 73 63 68 65  64 75 6c 65 72 12 06 55  |ube-scheduler..U|
000000a0  70 64 61 74 65 1a 16 63  6f 6f 72 64 69 6e 61 74  |pdate..coordinat|
000000b0  69 6f 6e 2e 6b 38 73 2e  69 6f 2f 76 31 22 08 08  |ion.k8s.io/v1"..|
000000c0  b1 b2 e2 a1 06 10 00 32  08 46 69 65 6c 64 73 56  |.......2.FieldsV|
000000d0  31 3a 7c 0a 7a 7b 22 66  3a 73 70 65 63 22 3a 7b  |1:|.z{"f:spec":{|
000000e0  22 66 3a 61 63 71 75 69  72 65 54 69 6d 65 22 3a  |"f:acquireTime":|
000000f0  7b 7d 2c 22 66 3a 68 6f  6c 64 65 72 49 64 65 6e  |{},"f:holderIden|
00000100  74 69 74 79 22 3a 7b 7d  2c 22 66 3a 6c 65 61 73  |tity":{},"f:leas|
00000110  65 44 75 72 61 74 69 6f  6e 53 65 63 6f 6e 64 73  |eDurationSeconds|
00000120  22 3a 7b 7d 2c 22 66 3a  6c 65 61 73 65 54 72 61  |":{},"f:leaseTra|
00000130  6e 73 69 74 69 6f 6e 73  22 3a 7b 7d 2c 22 66 3a  |nsitions":{},"f:|
00000140  72 65 6e 65 77 54 69 6d  65 22 3a 7b 7d 7d 7d 42  |renewTime":{}}}B|
00000150  00 12 59 0a 37 6b 69 6e  64 2d 63 6f 6e 74 72 6f  |..Y.7kind-contro|
00000160  6c 2d 70 6c 61 6e 65 5f  30 64 32 66 61 66 39 33  |l-plane_0d2faf93|
00000170  2d 34 61 30 62 2d 34 66  32 38 2d 38 33 64 33 2d  |-4a0b-4f28-83d3-|
00000180  35 62 35 62 62 66 61 31  65 36 31 30 10 0f 1a 0c  |5b5bbfa1e610....|
00000190  08 f7 a5 86 a2 06 10 b9  84 b7 94 03 22 0c 08 8c  |............"...|
000001a0  ed bd a2 06 10 c6 b7 cf  a1 03 28 0a 1a 00 22 00  |..........(...".|
I0501 08:21:32.936247       1 leaderelection.go:278] successfully renewed lease kube-system/kube-scheduler
I0501 08:21:34.937515       1 round_trippers.go:466] curl -v -XGET  -H "Accept: application/vnd.kubernetes.protobuf, */*" -H "User-Agent: kube-scheduler/v1.24.7 (linux/amd64) kubernetes/e6f3597/leader-election" 'https://172.18.0.2:6443/apis/coordination.k8s.io/v1/namespaces/kube-system/leases/kube-scheduler?timeout=5s'
I0501 08:21:34.945236       1 round_trippers.go:553] GET https://172.18.0.2:6443/apis/coordination.k8s.io/v1/namespaces/kube-system/leases/kube-scheduler?timeout=5s 200 OK in 7 milliseconds
I0501 08:21:34.945356       1 round_trippers.go:570] HTTP Statistics: GetConnection 0 ms ServerProcessing 6 ms Duration 7 ms
I0501 08:21:34.945382       1 round_trippers.go:577] Response Headers:
I0501 08:21:34.945459       1 round_trippers.go:580]     X-Kubernetes-Pf-Prioritylevel-Uid: afabb116-6975-46b8-863b-3258bec9e1ea
I0501 08:21:34.945487       1 round_trippers.go:580]     Content-Length: 432
I0501 08:21:34.945547       1 round_trippers.go:580]     Date: Mon, 01 May 2023 08:21:34 GMT
I0501 08:21:34.945633       1 round_trippers.go:580]     Audit-Id: 93b45955-5d5a-4620-8e58-a6622d433bd9
I0501 08:21:34.945771       1 round_trippers.go:580]     Cache-Control: no-cache, private
I0501 08:21:34.945849       1 round_trippers.go:580]     Content-Type: application/vnd.kubernetes.protobuf
I0501 08:21:34.945883       1 round_trippers.go:580]     X-Kubernetes-Pf-Flowschema-Uid: 493426e8-0f6d-4ea6-bc2c-2d926c7e3221
I0501 08:21:34.946086       1 request.go:1152] Response Body:
00000000  6b 38 73 00 0a 1f 0a 16  63 6f 6f 72 64 69 6e 61  |k8s.....coordina|
00000010  74 69 6f 6e 2e 6b 38 73  2e 69 6f 2f 76 31 12 05  |tion.k8s.io/v1..|
00000020  4c 65 61 73 65 12 84 03  0a a6 02 0a 0e 6b 75 62  |Lease........kub|
00000030  65 2d 73 63 68 65 64 75  6c 65 72 12 00 1a 0b 6b  |e-scheduler....k|
00000040  75 62 65 2d 73 79 73 74  65 6d 22 00 2a 24 36 61  |ube-system".*$6a|
00000050  30 65 32 30 33 66 2d 65  32 38 30 2d 34 36 61 30  |0e203f-e280-46a0|
00000060  2d 39 35 33 62 2d 35 66  62 64 63 37 38 61 63 38  |-953b-5fbdc78ac8|
00000070  36 65 32 07 32 32 36 38  36 32 37 38 00 42 08 08  |6e2.22686278.B..|
00000080  b1 b2 e2 a1 06 10 00 7a  00 8a 01 c4 01 0a 0e 6b  |.......z.......k|
00000090  75 62 65 2d 73 63 68 65  64 75 6c 65 72 12 06 55  |ube-scheduler..U|
000000a0  70 64 61 74 65 1a 16 63  6f 6f 72 64 69 6e 61 74  |pdate..coordinat|
000000b0  69 6f 6e 2e 6b 38 73 2e  69 6f 2f 76 31 22 08 08  |ion.k8s.io/v1"..|
000000c0  b1 b2 e2 a1 06 10 00 32  08 46 69 65 6c 64 73 56  |.......2.FieldsV|
000000d0  31 3a 7c 0a 7a 7b 22 66  3a 73 70 65 63 22 3a 7b  |1:|.z{"f:spec":{|
000000e0  22 66 3a 61 63 71 75 69  72 65 54 69 6d 65 22 3a  |"f:acquireTime":|
000000f0  7b 7d 2c 22 66 3a 68 6f  6c 64 65 72 49 64 65 6e  |{},"f:holderIden|
00000100  74 69 74 79 22 3a 7b 7d  2c 22 66 3a 6c 65 61 73  |tity":{},"f:leas|
00000110  65 44 75 72 61 74 69 6f  6e 53 65 63 6f 6e 64 73  |eDurationSeconds|
00000120  22 3a 7b 7d 2c 22 66 3a  6c 65 61 73 65 54 72 61  |":{},"f:leaseTra|
00000130  6e 73 69 74 69 6f 6e 73  22 3a 7b 7d 2c 22 66 3a  |nsitions":{},"f:|
00000140  72 65 6e 65 77 54 69 6d  65 22 3a 7b 7d 7d 7d 42  |renewTime":{}}}B|
00000150  00 12 59 0a 37 6b 69 6e  64 2d 63 6f 6e 74 72 6f  |..Y.7kind-contro|
00000160  6c 2d 70 6c 61 6e 65 5f  30 64 32 66 61 66 39 33  |l-plane_0d2faf93|
00000170  2d 34 61 30 62 2d 34 66  32 38 2d 38 33 64 33 2d  |-4a0b-4f28-83d3-|
00000180  35 62 35 62 62 66 61 31  65 36 31 30 10 0f 1a 0c  |5b5bbfa1e610....|
00000190  08 f7 a5 86 a2 06 10 b9  84 b7 94 03 22 0c 08 8c  |............"...|
000001a0  ed bd a2 06 10 c6 b7 cf  a1 03 28 0a 1a 00 22 00  |..........(...".|
I0501 08:21:34.946470       1 request.go:1152] Request Body:
00000000  6b 38 73 00 0a 1f 0a 16  63 6f 6f 72 64 69 6e 61  |k8s.....coordina|
00000010  74 69 6f 6e 2e 6b 38 73  2e 69 6f 2f 76 31 12 05  |tion.k8s.io/v1..|
00000020  4c 65 61 73 65 12 84 03  0a a6 02 0a 0e 6b 75 62  |Lease........kub|
00000030  65 2d 73 63 68 65 64 75  6c 65 72 12 00 1a 0b 6b  |e-scheduler....k|
00000040  75 62 65 2d 73 79 73 74  65 6d 22 00 2a 24 36 61  |ube-system".*$6a|
00000050  30 65 32 30 33 66 2d 65  32 38 30 2d 34 36 61 30  |0e203f-e280-46a0|
00000060  2d 39 35 33 62 2d 35 66  62 64 63 37 38 61 63 38  |-953b-5fbdc78ac8|
00000070  36 65 32 07 32 32 36 38  36 32 37 38 00 42 08 08  |6e2.22686278.B..|
00000080  b1 b2 e2 a1 06 10 00 7a  00 8a 01 c4 01 0a 0e 6b  |.......z.......k|
00000090  75 62 65 2d 73 63 68 65  64 75 6c 65 72 12 06 55  |ube-scheduler..U|
000000a0  70 64 61 74 65 1a 16 63  6f 6f 72 64 69 6e 61 74  |pdate..coordinat|
000000b0  69 6f 6e 2e 6b 38 73 2e  69 6f 2f 76 31 22 08 08  |ion.k8s.io/v1"..|
000000c0  b1 b2 e2 a1 06 10 00 32  08 46 69 65 6c 64 73 56  |.......2.FieldsV|
000000d0  31 3a 7c 0a 7a 7b 22 66  3a 73 70 65 63 22 3a 7b  |1:|.z{"f:spec":{|
000000e0  22 66 3a 61 63 71 75 69  72 65 54 69 6d 65 22 3a  |"f:acquireTime":|
000000f0  7b 7d 2c 22 66 3a 68 6f  6c 64 65 72 49 64 65 6e  |{},"f:holderIden|
00000100  74 69 74 79 22 3a 7b 7d  2c 22 66 3a 6c 65 61 73  |tity":{},"f:leas|
00000110  65 44 75 72 61 74 69 6f  6e 53 65 63 6f 6e 64 73  |eDurationSeconds|
00000120  22 3a 7b 7d 2c 22 66 3a  6c 65 61 73 65 54 72 61  |":{},"f:leaseTra|
00000130  6e 73 69 74 69 6f 6e 73  22 3a 7b 7d 2c 22 66 3a  |nsitions":{},"f:|
00000140  72 65 6e 65 77 54 69 6d  65 22 3a 7b 7d 7d 7d 42  |renewTime":{}}}B|
00000150  00 12 59 0a 37 6b 69 6e  64 2d 63 6f 6e 74 72 6f  |..Y.7kind-contro|
00000160  6c 2d 70 6c 61 6e 65 5f  30 64 32 66 61 66 39 33  |l-plane_0d2faf93|
00000170  2d 34 61 30 62 2d 34 66  32 38 2d 38 33 64 33 2d  |-4a0b-4f28-83d3-|
00000180  35 62 35 62 62 66 61 31  65 36 31 30 10 0f 1a 0c  |5b5bbfa1e610....|
00000190  08 f7 a5 86 a2 06 10 b9  84 b7 94 03 22 0c 08 8e  |............"...|
000001a0  ed bd a2 06 10 91 e2 f3  be 03 28 0a 1a 00 22 00  |..........(...".|
I0501 08:21:34.946745       1 round_trippers.go:466] curl -v -XPUT  -H "Content-Type: application/vnd.kubernetes.protobuf" -H "Accept: application/vnd.kubernetes.protobuf, */*" -H "User-Agent: kube-scheduler/v1.24.7 (linux/amd64) kubernetes/e6f3597/leader-election" 'https://172.18.0.2:6443/apis/coordination.k8s.io/v1/namespaces/kube-system/leases/kube-scheduler?timeout=5s'
I0501 08:21:34.955372       1 round_trippers.go:553] PUT https://172.18.0.2:6443/apis/coordination.k8s.io/v1/namespaces/kube-system/leases/kube-scheduler?timeout=5s 200 OK in 8 milliseconds
I0501 08:21:34.955465       1 round_trippers.go:570] HTTP Statistics: GetConnection 0 ms ServerProcessing 7 ms Duration 8 ms
I0501 08:21:34.955483       1 round_trippers.go:577] Response Headers:
I0501 08:21:34.955557       1 round_trippers.go:580]     X-Kubernetes-Pf-Flowschema-Uid: 493426e8-0f6d-4ea6-bc2c-2d926c7e3221
I0501 08:21:34.955586       1 round_trippers.go:580]     X-Kubernetes-Pf-Prioritylevel-Uid: afabb116-6975-46b8-863b-3258bec9e1ea
I0501 08:21:34.955645       1 round_trippers.go:580]     Content-Length: 432
I0501 08:21:34.955674       1 round_trippers.go:580]     Date: Mon, 01 May 2023 08:21:34 GMT
I0501 08:21:34.955737       1 round_trippers.go:580]     Audit-Id: 926341cc-dd17-472b-94d2-5e87e7fc1fb3
I0501 08:21:34.955756       1 round_trippers.go:580]     Cache-Control: no-cache, private
I0501 08:21:34.955851       1 round_trippers.go:580]     Content-Type: application/vnd.kubernetes.protobuf
I0501 08:21:34.956010       1 request.go:1152] Response Body:
00000000  6b 38 73 00 0a 1f 0a 16  63 6f 6f 72 64 69 6e 61  |k8s.....coordina|
00000010  74 69 6f 6e 2e 6b 38 73  2e 69 6f 2f 76 31 12 05  |tion.k8s.io/v1..|
00000020  4c 65 61 73 65 12 84 03  0a a6 02 0a 0e 6b 75 62  |Lease........kub|
00000030  65 2d 73 63 68 65 64 75  6c 65 72 12 00 1a 0b 6b  |e-scheduler....k|
00000040  75 62 65 2d 73 79 73 74  65 6d 22 00 2a 24 36 61  |ube-system".*$6a|
00000050  30 65 32 30 33 66 2d 65  32 38 30 2d 34 36 61 30  |0e203f-e280-46a0|
00000060  2d 39 35 33 62 2d 35 66  62 64 63 37 38 61 63 38  |-953b-5fbdc78ac8|
00000070  36 65 32 07 32 32 36 38  36 33 30 38 00 42 08 08  |6e2.22686308.B..|
00000080  b1 b2 e2 a1 06 10 00 7a  00 8a 01 c4 01 0a 0e 6b  |.......z.......k|
00000090  75 62 65 2d 73 63 68 65  64 75 6c 65 72 12 06 55  |ube-scheduler..U|
000000a0  70 64 61 74 65 1a 16 63  6f 6f 72 64 69 6e 61 74  |pdate..coordinat|
000000b0  69 6f 6e 2e 6b 38 73 2e  69 6f 2f 76 31 22 08 08  |ion.k8s.io/v1"..|
000000c0  b1 b2 e2 a1 06 10 00 32  08 46 69 65 6c 64 73 56  |.......2.FieldsV|
000000d0  31 3a 7c 0a 7a 7b 22 66  3a 73 70 65 63 22 3a 7b  |1:|.z{"f:spec":{|
000000e0  22 66 3a 61 63 71 75 69  72 65 54 69 6d 65 22 3a  |"f:acquireTime":|
000000f0  7b 7d 2c 22 66 3a 68 6f  6c 64 65 72 49 64 65 6e  |{},"f:holderIden|
00000100  74 69 74 79 22 3a 7b 7d  2c 22 66 3a 6c 65 61 73  |tity":{},"f:leas|
00000110  65 44 75 72 61 74 69 6f  6e 53 65 63 6f 6e 64 73  |eDurationSeconds|
00000120  22 3a 7b 7d 2c 22 66 3a  6c 65 61 73 65 54 72 61  |":{},"f:leaseTra|
00000130  6e 73 69 74 69 6f 6e 73  22 3a 7b 7d 2c 22 66 3a  |nsitions":{},"f:|
00000140  72 65 6e 65 77 54 69 6d  65 22 3a 7b 7d 7d 7d 42  |renewTime":{}}}B|
00000150  00 12 59 0a 37 6b 69 6e  64 2d 63 6f 6e 74 72 6f  |..Y.7kind-contro|
00000160  6c 2d 70 6c 61 6e 65 5f  30 64 32 66 61 66 39 33  |l-plane_0d2faf93|
00000170  2d 34 61 30 62 2d 34 66  32 38 2d 38 33 64 33 2d  |-4a0b-4f28-83d3-|
00000180  35 62 35 62 62 66 61 31  65 36 31 30 10 0f 1a 0c  |5b5bbfa1e610....|
00000190  08 f7 a5 86 a2 06 10 b9  84 b7 94 03 22 0c 08 8e  |............"...|
000001a0  ed bd a2 06 10 91 e2 f3  be 03 28 0a 1a 00 22 00  |..........(...".|
I0501 08:21:34.956248       1 leaderelection.go:278] successfully renewed lease kube-system/kube-scheduler
I0501 08:21:36.956974       1 round_trippers.go:466] curl -v -XGET  -H "Accept: application/vnd.kubernetes.protobuf, */*" -H "User-Agent: kube-scheduler/v1.24.7 (linux/amd64) kubernetes/e6f3597/leader-election" 'https://172.18.0.2:6443/apis/coordination.k8s.io/v1/namespaces/kube-system/leases/kube-scheduler?timeout=5s'
I0501 08:21:36.965457       1 round_trippers.go:553] GET https://172.18.0.2:6443/apis/coordination.k8s.io/v1/namespaces/kube-system/leases/kube-scheduler?timeout=5s 200 OK in 7 milliseconds
I0501 08:21:36.965493       1 round_trippers.go:570] HTTP Statistics: GetConnection 0 ms ServerProcessing 7 ms Duration 7 ms
I0501 08:21:36.965575       1 round_trippers.go:577] Response Headers:
I0501 08:21:36.965895       1 round_trippers.go:580]     X-Kubernetes-Pf-Prioritylevel-Uid: afabb116-6975-46b8-863b-3258bec9e1ea
I0501 08:21:36.965983       1 round_trippers.go:580]     Content-Length: 432
I0501 08:21:36.966022       1 round_trippers.go:580]     Date: Mon, 01 May 2023 08:21:36 GMT
I0501 08:21:36.966045       1 round_trippers.go:580]     Audit-Id: ae9dc50e-9f7c-4106-80b9-86aeedb33239
I0501 08:21:36.966067       1 round_trippers.go:580]     Cache-Control: no-cache, private
I0501 08:21:36.966145       1 round_trippers.go:580]     Content-Type: application/vnd.kubernetes.protobuf
I0501 08:21:36.966236       1 round_trippers.go:580]     X-Kubernetes-Pf-Flowschema-Uid: 493426e8-0f6d-4ea6-bc2c-2d926c7e3221
I0501 08:21:36.966492       1 request.go:1152] Response Body:
00000000  6b 38 73 00 0a 1f 0a 16  63 6f 6f 72 64 69 6e 61  |k8s.....coordina|
00000010  74 69 6f 6e 2e 6b 38 73  2e 69 6f 2f 76 31 12 05  |tion.k8s.io/v1..|
00000020  4c 65 61 73 65 12 84 03  0a a6 02 0a 0e 6b 75 62  |Lease........kub|
00000030  65 2d 73 63 68 65 64 75  6c 65 72 12 00 1a 0b 6b  |e-scheduler....k|
00000040  75 62 65 2d 73 79 73 74  65 6d 22 00 2a 24 36 61  |ube-system".*$6a|
00000050  30 65 32 30 33 66 2d 65  32 38 30 2d 34 36 61 30  |0e203f-e280-46a0|
00000060  2d 39 35 33 62 2d 35 66  62 64 63 37 38 61 63 38  |-953b-5fbdc78ac8|
00000070  36 65 32 07 32 32 36 38  36 33 30 38 00 42 08 08  |6e2.22686308.B..|
00000080  b1 b2 e2 a1 06 10 00 7a  00 8a 01 c4 01 0a 0e 6b  |.......z.......k|
00000090  75 62 65 2d 73 63 68 65  64 75 6c 65 72 12 06 55  |ube-scheduler..U|
000000a0  70 64 61 74 65 1a 16 63  6f 6f 72 64 69 6e 61 74  |pdate..coordinat|
000000b0  69 6f 6e 2e 6b 38 73 2e  69 6f 2f 76 31 22 08 08  |ion.k8s.io/v1"..|
000000c0  b1 b2 e2 a1 06 10 00 32  08 46 69 65 6c 64 73 56  |.......2.FieldsV|
000000d0  31 3a 7c 0a 7a 7b 22 66  3a 73 70 65 63 22 3a 7b  |1:|.z{"f:spec":{|
000000e0  22 66 3a 61 63 71 75 69  72 65 54 69 6d 65 22 3a  |"f:acquireTime":|
000000f0  7b 7d 2c 22 66 3a 68 6f  6c 64 65 72 49 64 65 6e  |{},"f:holderIden|
00000100  74 69 74 79 22 3a 7b 7d  2c 22 66 3a 6c 65 61 73  |tity":{},"f:leas|
00000110  65 44 75 72 61 74 69 6f  6e 53 65 63 6f 6e 64 73  |eDurationSeconds|
00000120  22 3a 7b 7d 2c 22 66 3a  6c 65 61 73 65 54 72 61  |":{},"f:leaseTra|
00000130  6e 73 69 74 69 6f 6e 73  22 3a 7b 7d 2c 22 66 3a  |nsitions":{},"f:|
00000140  72 65 6e 65 77 54 69 6d  65 22 3a 7b 7d 7d 7d 42  |renewTime":{}}}B|
00000150  00 12 59 0a 37 6b 69 6e  64 2d 63 6f 6e 74 72 6f  |..Y.7kind-contro|
00000160  6c 2d 70 6c 61 6e 65 5f  30 64 32 66 61 66 39 33  |l-plane_0d2faf93|
00000170  2d 34 61 30 62 2d 34 66  32 38 2d 38 33 64 33 2d  |-4a0b-4f28-83d3-|
00000180  35 62 35 62 62 66 61 31  65 36 31 30 10 0f 1a 0c  |5b5bbfa1e610....|
00000190  08 f7 a5 86 a2 06 10 b9  84 b7 94 03 22 0c 08 8e  |............"...|
000001a0  ed bd a2 06 10 91 e2 f3  be 03 28 0a 1a 00 22 00  |..........(...".|
I0501 08:21:36.967436       1 request.go:1152] Request Body:
00000000  6b 38 73 00 0a 1f 0a 16  63 6f 6f 72 64 69 6e 61  |k8s.....coordina|
00000010  74 69 6f 6e 2e 6b 38 73  2e 69 6f 2f 76 31 12 05  |tion.k8s.io/v1..|
00000020  4c 65 61 73 65 12 84 03  0a a6 02 0a 0e 6b 75 62  |Lease........kub|
00000030  65 2d 73 63 68 65 64 75  6c 65 72 12 00 1a 0b 6b  |e-scheduler....k|
00000040  75 62 65 2d 73 79 73 74  65 6d 22 00 2a 24 36 61  |ube-system".*$6a|
00000050  30 65 32 30 33 66 2d 65  32 38 30 2d 34 36 61 30  |0e203f-e280-46a0|
00000060  2d 39 35 33 62 2d 35 66  62 64 63 37 38 61 63 38  |-953b-5fbdc78ac8|
00000070  36 65 32 07 32 32 36 38  36 33 30 38 00 42 08 08  |6e2.22686308.B..|
00000080  b1 b2 e2 a1 06 10 00 7a  00 8a 01 c4 01 0a 0e 6b  |.......z.......k|
00000090  75 62 65 2d 73 63 68 65  64 75 6c 65 72 12 06 55  |ube-scheduler..U|
000000a0  70 64 61 74 65 1a 16 63  6f 6f 72 64 69 6e 61 74  |pdate..coordinat|
000000b0  69 6f 6e 2e 6b 38 73 2e  69 6f 2f 76 31 22 08 08  |ion.k8s.io/v1"..|
000000c0  b1 b2 e2 a1 06 10 00 32  08 46 69 65 6c 64 73 56  |.......2.FieldsV|
000000d0  31 3a 7c 0a 7a 7b 22 66  3a 73 70 65 63 22 3a 7b  |1:|.z{"f:spec":{|
000000e0  22 66 3a 61 63 71 75 69  72 65 54 69 6d 65 22 3a  |"f:acquireTime":|
000000f0  7b 7d 2c 22 66 3a 68 6f  6c 64 65 72 49 64 65 6e  |{},"f:holderIden|
00000100  74 69 74 79 22 3a 7b 7d  2c 22 66 3a 6c 65 61 73  |tity":{},"f:leas|
00000110  65 44 75 72 61 74 69 6f  6e 53 65 63 6f 6e 64 73  |eDurationSeconds|
00000120  22 3a 7b 7d 2c 22 66 3a  6c 65 61 73 65 54 72 61  |":{},"f:leaseTra|
00000130  6e 73 69 74 69 6f 6e 73  22 3a 7b 7d 2c 22 66 3a  |nsitions":{},"f:|
00000140  72 65 6e 65 77 54 69 6d  65 22 3a 7b 7d 7d 7d 42  |renewTime":{}}}B|
00000150  00 12 59 0a 37 6b 69 6e  64 2d 63 6f 6e 74 72 6f  |..Y.7kind-contro|
00000160  6c 2d 70 6c 61 6e 65 5f  30 64 32 66 61 66 39 33  |l-plane_0d2faf93|
00000170  2d 34 61 30 62 2d 34 66  32 38 2d 38 33 64 33 2d  |-4a0b-4f28-83d3-|
00000180  35 62 35 62 62 66 61 31  65 36 31 30 10 0f 1a 0c  |5b5bbfa1e610....|
00000190  08 f7 a5 86 a2 06 10 b9  84 b7 94 03 22 0c 08 90  |............"...|
000001a0  ed bd a2 06 10 c3 9d 92  c8 03 28 0a 1a 00 22 00  |..........(...".|
I0501 08:21:36.967661       1 round_trippers.go:466] curl -v -XPUT  -H "Accept: application/vnd.kubernetes.protobuf, */*" -H "Content-Type: application/vnd.kubernetes.protobuf" -H "User-Agent: kube-scheduler/v1.24.7 (linux/amd64) kubernetes/e6f3597/leader-election" 'https://172.18.0.2:6443/apis/coordination.k8s.io/v1/namespaces/kube-system/leases/kube-scheduler?timeout=5s'
I0501 08:21:36.974716       1 round_trippers.go:553] PUT https://172.18.0.2:6443/apis/coordination.k8s.io/v1/namespaces/kube-system/leases/kube-scheduler?timeout=5s 200 OK in 7 milliseconds
I0501 08:21:36.974781       1 round_trippers.go:570] HTTP Statistics: GetConnection 0 ms ServerProcessing 6 ms Duration 7 ms
I0501 08:21:36.974799       1 round_trippers.go:577] Response Headers:
I0501 08:21:36.974820       1 round_trippers.go:580]     X-Kubernetes-Pf-Prioritylevel-Uid: afabb116-6975-46b8-863b-3258bec9e1ea
I0501 08:21:36.974914       1 round_trippers.go:580]     Content-Length: 432
I0501 08:21:36.974978       1 round_trippers.go:580]     Date: Mon, 01 May 2023 08:21:36 GMT
I0501 08:21:36.975185       1 round_trippers.go:580]     Audit-Id: 307eb052-87ff-4e70-9739-00ab2dbceb31
I0501 08:21:36.975234       1 round_trippers.go:580]     Cache-Control: no-cache, private
I0501 08:21:36.975297       1 round_trippers.go:580]     Content-Type: application/vnd.kubernetes.protobuf
I0501 08:21:36.975319       1 round_trippers.go:580]     X-Kubernetes-Pf-Flowschema-Uid: 493426e8-0f6d-4ea6-bc2c-2d926c7e3221
I0501 08:21:36.975459       1 request.go:1152] Response Body:
00000000  6b 38 73 00 0a 1f 0a 16  63 6f 6f 72 64 69 6e 61  |k8s.....coordina|
00000010  74 69 6f 6e 2e 6b 38 73  2e 69 6f 2f 76 31 12 05  |tion.k8s.io/v1..|
00000020  4c 65 61 73 65 12 84 03  0a a6 02 0a 0e 6b 75 62  |Lease........kub|
00000030  65 2d 73 63 68 65 64 75  6c 65 72 12 00 1a 0b 6b  |e-scheduler....k|
00000040  75 62 65 2d 73 79 73 74  65 6d 22 00 2a 24 36 61  |ube-system".*$6a|
00000050  30 65 32 30 33 66 2d 65  32 38 30 2d 34 36 61 30  |0e203f-e280-46a0|
00000060  2d 39 35 33 62 2d 35 66  62 64 63 37 38 61 63 38  |-953b-5fbdc78ac8|
00000070  36 65 32 07 32 32 36 38  36 33 33 38 00 42 08 08  |6e2.22686338.B..|
00000080  b1 b2 e2 a1 06 10 00 7a  00 8a 01 c4 01 0a 0e 6b  |.......z.......k|
00000090  75 62 65 2d 73 63 68 65  64 75 6c 65 72 12 06 55  |ube-scheduler..U|
000000a0  70 64 61 74 65 1a 16 63  6f 6f 72 64 69 6e 61 74  |pdate..coordinat|
000000b0  69 6f 6e 2e 6b 38 73 2e  69 6f 2f 76 31 22 08 08  |ion.k8s.io/v1"..|
000000c0  b1 b2 e2 a1 06 10 00 32  08 46 69 65 6c 64 73 56  |.......2.FieldsV|
000000d0  31 3a 7c 0a 7a 7b 22 66  3a 73 70 65 63 22 3a 7b  |1:|.z{"f:spec":{|
000000e0  22 66 3a 61 63 71 75 69  72 65 54 69 6d 65 22 3a  |"f:acquireTime":|
000000f0  7b 7d 2c 22 66 3a 68 6f  6c 64 65 72 49 64 65 6e  |{},"f:holderIden|
00000100  74 69 74 79 22 3a 7b 7d  2c 22 66 3a 6c 65 61 73  |tity":{},"f:leas|
00000110  65 44 75 72 61 74 69 6f  6e 53 65 63 6f 6e 64 73  |eDurationSeconds|
00000120  22 3a 7b 7d 2c 22 66 3a  6c 65 61 73 65 54 72 61  |":{},"f:leaseTra|
00000130  6e 73 69 74 69 6f 6e 73  22 3a 7b 7d 2c 22 66 3a  |nsitions":{},"f:|
00000140  72 65 6e 65 77 54 69 6d  65 22 3a 7b 7d 7d 7d 42  |renewTime":{}}}B|
00000150  00 12 59 0a 37 6b 69 6e  64 2d 63 6f 6e 74 72 6f  |..Y.7kind-contro|
00000160  6c 2d 70 6c 61 6e 65 5f  30 64 32 66 61 66 39 33  |l-plane_0d2faf93|
00000170  2d 34 61 30 62 2d 34 66  32 38 2d 38 33 64 33 2d  |-4a0b-4f28-83d3-|
00000180  35 62 35 62 62 66 61 31  65 36 31 30 10 0f 1a 0c  |5b5bbfa1e610....|
00000190  08 f7 a5 86 a2 06 10 b9  84 b7 94 03 22 0c 08 90  |............"...|
000001a0  ed bd a2 06 10 c3 9d 92  c8 03 28 0a 1a 00 22 00  |..........(...".|
I0501 08:21:36.975747       1 leaderelection.go:278] successfully renewed lease kube-system/kube-scheduler
I0501 08:21:38.976690       1 round_trippers.go:466] curl -v -XGET  -H "Accept: application/vnd.kubernetes.protobuf, */*" -H "User-Agent: kube-scheduler/v1.24.7 (linux/amd64) kubernetes/e6f3597/leader-election" 'https://172.18.0.2:6443/apis/coordination.k8s.io/v1/namespaces/kube-system/leases/kube-scheduler?timeout=5s'
I0501 08:21:38.981810       1 round_trippers.go:553] GET https://172.18.0.2:6443/apis/coordination.k8s.io/v1/namespaces/kube-system/leases/kube-scheduler?timeout=5s 200 OK in 4 milliseconds
I0501 08:21:38.981935       1 round_trippers.go:570] HTTP Statistics: GetConnection 0 ms ServerProcessing 4 ms Duration 4 ms
I0501 08:21:38.982056       1 round_trippers.go:577] Response Headers:
I0501 08:21:38.982127       1 round_trippers.go:580]     Audit-Id: 9fae9450-fe95-4c53-b4a7-a2fd718a11c0
I0501 08:21:38.982203       1 round_trippers.go:580]     Cache-Control: no-cache, private
I0501 08:21:38.982322       1 round_trippers.go:580]     Content-Type: application/vnd.kubernetes.protobuf
I0501 08:21:38.982438       1 round_trippers.go:580]     X-Kubernetes-Pf-Flowschema-Uid: 493426e8-0f6d-4ea6-bc2c-2d926c7e3221
I0501 08:21:38.982559       1 round_trippers.go:580]     X-Kubernetes-Pf-Prioritylevel-Uid: afabb116-6975-46b8-863b-3258bec9e1ea
I0501 08:21:38.982672       1 round_trippers.go:580]     Content-Length: 432
I0501 08:21:38.982786       1 round_trippers.go:580]     Date: Mon, 01 May 2023 08:21:38 GMT
I0501 08:21:38.982951       1 request.go:1152] Response Body:
00000000  6b 38 73 00 0a 1f 0a 16  63 6f 6f 72 64 69 6e 61  |k8s.....coordina|
00000010  74 69 6f 6e 2e 6b 38 73  2e 69 6f 2f 76 31 12 05  |tion.k8s.io/v1..|
00000020  4c 65 61 73 65 12 84 03  0a a6 02 0a 0e 6b 75 62  |Lease........kub|
00000030  65 2d 73 63 68 65 64 75  6c 65 72 12 00 1a 0b 6b  |e-scheduler....k|
00000040  75 62 65 2d 73 79 73 74  65 6d 22 00 2a 24 36 61  |ube-system".*$6a|
00000050  30 65 32 30 33 66 2d 65  32 38 30 2d 34 36 61 30  |0e203f-e280-46a0|
00000060  2d 39 35 33 62 2d 35 66  62 64 63 37 38 61 63 38  |-953b-5fbdc78ac8|
00000070  36 65 32 07 32 32 36 38  36 33 33 38 00 42 08 08  |6e2.22686338.B..|
00000080  b1 b2 e2 a1 06 10 00 7a  00 8a 01 c4 01 0a 0e 6b  |.......z.......k|
00000090  75 62 65 2d 73 63 68 65  64 75 6c 65 72 12 06 55  |ube-scheduler..U|
000000a0  70 64 61 74 65 1a 16 63  6f 6f 72 64 69 6e 61 74  |pdate..coordinat|
000000b0  69 6f 6e 2e 6b 38 73 2e  69 6f 2f 76 31 22 08 08  |ion.k8s.io/v1"..|
000000c0  b1 b2 e2 a1 06 10 00 32  08 46 69 65 6c 64 73 56  |.......2.FieldsV|
000000d0  31 3a 7c 0a 7a 7b 22 66  3a 73 70 65 63 22 3a 7b  |1:|.z{"f:spec":{|
000000e0  22 66 3a 61 63 71 75 69  72 65 54 69 6d 65 22 3a  |"f:acquireTime":|
000000f0  7b 7d 2c 22 66 3a 68 6f  6c 64 65 72 49 64 65 6e  |{},"f:holderIden|
00000100  74 69 74 79 22 3a 7b 7d  2c 22 66 3a 6c 65 61 73  |tity":{},"f:leas|
00000110  65 44 75 72 61 74 69 6f  6e 53 65 63 6f 6e 64 73  |eDurationSeconds|
00000120  22 3a 7b 7d 2c 22 66 3a  6c 65 61 73 65 54 72 61  |":{},"f:leaseTra|
00000130  6e 73 69 74 69 6f 6e 73  22 3a 7b 7d 2c 22 66 3a  |nsitions":{},"f:|
00000140  72 65 6e 65 77 54 69 6d  65 22 3a 7b 7d 7d 7d 42  |renewTime":{}}}B|
00000150  00 12 59 0a 37 6b 69 6e  64 2d 63 6f 6e 74 72 6f  |..Y.7kind-contro|
00000160  6c 2d 70 6c 61 6e 65 5f  30 64 32 66 61 66 39 33  |l-plane_0d2faf93|
00000170  2d 34 61 30 62 2d 34 66  32 38 2d 38 33 64 33 2d  |-4a0b-4f28-83d3-|
00000180  35 62 35 62 62 66 61 31  65 36 31 30 10 0f 1a 0c  |5b5bbfa1e610....|
00000190  08 f7 a5 86 a2 06 10 b9  84 b7 94 03 22 0c 08 90  |............"...|
000001a0  ed bd a2 06 10 c3 9d 92  c8 03 28 0a 1a 00 22 00  |..........(...".|
I0501 08:21:38.983279       1 request.go:1152] Request Body:
00000000  6b 38 73 00 0a 1f 0a 16  63 6f 6f 72 64 69 6e 61  |k8s.....coordina|
00000010  74 69 6f 6e 2e 6b 38 73  2e 69 6f 2f 76 31 12 05  |tion.k8s.io/v1..|
00000020  4c 65 61 73 65 12 84 03  0a a6 02 0a 0e 6b 75 62  |Lease........kub|
00000030  65 2d 73 63 68 65 64 75  6c 65 72 12 00 1a 0b 6b  |e-scheduler....k|
00000040  75 62 65 2d 73 79 73 74  65 6d 22 00 2a 24 36 61  |ube-system".*$6a|
00000050  30 65 32 30 33 66 2d 65  32 38 30 2d 34 36 61 30  |0e203f-e280-46a0|
00000060  2d 39 35 33 62 2d 35 66  62 64 63 37 38 61 63 38  |-953b-5fbdc78ac8|
00000070  36 65 32 07 32 32 36 38  36 33 33 38 00 42 08 08  |6e2.22686338.B..|
00000080  b1 b2 e2 a1 06 10 00 7a  00 8a 01 c4 01 0a 0e 6b  |.......z.......k|
00000090  75 62 65 2d 73 63 68 65  64 75 6c 65 72 12 06 55  |ube-scheduler..U|
000000a0  70 64 61 74 65 1a 16 63  6f 6f 72 64 69 6e 61 74  |pdate..coordinat|
000000b0  69 6f 6e 2e 6b 38 73 2e  69 6f 2f 76 31 22 08 08  |ion.k8s.io/v1"..|
000000c0  b1 b2 e2 a1 06 10 00 32  08 46 69 65 6c 64 73 56  |.......2.FieldsV|
000000d0  31 3a 7c 0a 7a 7b 22 66  3a 73 70 65 63 22 3a 7b  |1:|.z{"f:spec":{|
000000e0  22 66 3a 61 63 71 75 69  72 65 54 69 6d 65 22 3a  |"f:acquireTime":|
000000f0  7b 7d 2c 22 66 3a 68 6f  6c 64 65 72 49 64 65 6e  |{},"f:holderIden|
00000100  74 69 74 79 22 3a 7b 7d  2c 22 66 3a 6c 65 61 73  |tity":{},"f:leas|
00000110  65 44 75 72 61 74 69 6f  6e 53 65 63 6f 6e 64 73  |eDurationSeconds|
00000120  22 3a 7b 7d 2c 22 66 3a  6c 65 61 73 65 54 72 61  |":{},"f:leaseTra|
00000130  6e 73 69 74 69 6f 6e 73  22 3a 7b 7d 2c 22 66 3a  |nsitions":{},"f:|
00000140  72 65 6e 65 77 54 69 6d  65 22 3a 7b 7d 7d 7d 42  |renewTime":{}}}B|
00000150  00 12 59 0a 37 6b 69 6e  64 2d 63 6f 6e 74 72 6f  |..Y.7kind-contro|
00000160  6c 2d 70 6c 61 6e 65 5f  30 64 32 66 61 66 39 33  |l-plane_0d2faf93|
00000170  2d 34 61 30 62 2d 34 66  32 38 2d 38 33 64 33 2d  |-4a0b-4f28-83d3-|
00000180  35 62 35 62 62 66 61 31  65 36 31 30 10 0f 1a 0c  |5b5bbfa1e610....|
00000190  08 f7 a5 86 a2 06 10 b9  84 b7 94 03 22 0c 08 92  |............"...|
000001a0  ed bd a2 06 10 95 c1 cc  d1 03 28 0a 1a 00 22 00  |..........(...".|
I0501 08:21:38.983521       1 round_trippers.go:466] curl -v -XPUT  -H "Accept: application/vnd.kubernetes.protobuf, */*" -H "Content-Type: application/vnd.kubernetes.protobuf" -H "User-Agent: kube-scheduler/v1.24.7 (linux/amd64) kubernetes/e6f3597/leader-election" 'https://172.18.0.2:6443/apis/coordination.k8s.io/v1/namespaces/kube-system/leases/kube-scheduler?timeout=5s'
I0501 08:21:38.989139       1 round_trippers.go:553] PUT https://172.18.0.2:6443/apis/coordination.k8s.io/v1/namespaces/kube-system/leases/kube-scheduler?timeout=5s 200 OK in 5 milliseconds
I0501 08:21:38.989389       1 round_trippers.go:570] HTTP Statistics: GetConnection 0 ms ServerProcessing 5 ms Duration 5 ms
I0501 08:21:38.989473       1 round_trippers.go:577] Response Headers:
I0501 08:21:38.989633       1 round_trippers.go:580]     X-Kubernetes-Pf-Prioritylevel-Uid: afabb116-6975-46b8-863b-3258bec9e1ea
I0501 08:21:38.989821       1 round_trippers.go:580]     Content-Length: 432
I0501 08:21:38.989901       1 round_trippers.go:580]     Date: Mon, 01 May 2023 08:21:38 GMT
I0501 08:21:38.990045       1 round_trippers.go:580]     Audit-Id: ef029d68-37e6-4d4a-8e73-8867dc516eb2
I0501 08:21:38.990159       1 round_trippers.go:580]     Cache-Control: no-cache, private
I0501 08:21:38.990509       1 round_trippers.go:580]     Content-Type: application/vnd.kubernetes.protobuf
I0501 08:21:38.990697       1 round_trippers.go:580]     X-Kubernetes-Pf-Flowschema-Uid: 493426e8-0f6d-4ea6-bc2c-2d926c7e3221
I0501 08:21:38.990947       1 request.go:1152] Response Body:
00000000  6b 38 73 00 0a 1f 0a 16  63 6f 6f 72 64 69 6e 61  |k8s.....coordina|
00000010  74 69 6f 6e 2e 6b 38 73  2e 69 6f 2f 76 31 12 05  |tion.k8s.io/v1..|
00000020  4c 65 61 73 65 12 84 03  0a a6 02 0a 0e 6b 75 62  |Lease........kub|
00000030  65 2d 73 63 68 65 64 75  6c 65 72 12 00 1a 0b 6b  |e-scheduler....k|
00000040  75 62 65 2d 73 79 73 74  65 6d 22 00 2a 24 36 61  |ube-system".*$6a|
00000050  30 65 32 30 33 66 2d 65  32 38 30 2d 34 36 61 30  |0e203f-e280-46a0|
00000060  2d 39 35 33 62 2d 35 66  62 64 63 37 38 61 63 38  |-953b-5fbdc78ac8|
00000070  36 65 32 07 32 32 36 38  36 33 36 38 00 42 08 08  |6e2.22686368.B..|
00000080  b1 b2 e2 a1 06 10 00 7a  00 8a 01 c4 01 0a 0e 6b  |.......z.......k|
00000090  75 62 65 2d 73 63 68 65  64 75 6c 65 72 12 06 55  |ube-scheduler..U|
000000a0  70 64 61 74 65 1a 16 63  6f 6f 72 64 69 6e 61 74  |pdate..coordinat|
000000b0  69 6f 6e 2e 6b 38 73 2e  69 6f 2f 76 31 22 08 08  |ion.k8s.io/v1"..|
000000c0  b1 b2 e2 a1 06 10 00 32  08 46 69 65 6c 64 73 56  |.......2.FieldsV|
000000d0  31 3a 7c 0a 7a 7b 22 66  3a 73 70 65 63 22 3a 7b  |1:|.z{"f:spec":{|
000000e0  22 66 3a 61 63 71 75 69  72 65 54 69 6d 65 22 3a  |"f:acquireTime":|
000000f0  7b 7d 2c 22 66 3a 68 6f  6c 64 65 72 49 64 65 6e  |{},"f:holderIden|
00000100  74 69 74 79 22 3a 7b 7d  2c 22 66 3a 6c 65 61 73  |tity":{},"f:leas|
00000110  65 44 75 72 61 74 69 6f  6e 53 65 63 6f 6e 64 73  |eDurationSeconds|
00000120  22 3a 7b 7d 2c 22 66 3a  6c 65 61 73 65 54 72 61  |":{},"f:leaseTra|
00000130  6e 73 69 74 69 6f 6e 73  22 3a 7b 7d 2c 22 66 3a  |nsitions":{},"f:|
00000140  72 65 6e 65 77 54 69 6d  65 22 3a 7b 7d 7d 7d 42  |renewTime":{}}}B|
00000150  00 12 59 0a 37 6b 69 6e  64 2d 63 6f 6e 74 72 6f  |..Y.7kind-contro|
00000160  6c 2d 70 6c 61 6e 65 5f  30 64 32 66 61 66 39 33  |l-plane_0d2faf93|
00000170  2d 34 61 30 62 2d 34 66  32 38 2d 38 33 64 33 2d  |-4a0b-4f28-83d3-|
00000180  35 62 35 62 62 66 61 31  65 36 31 30 10 0f 1a 0c  |5b5bbfa1e610....|
00000190  08 f7 a5 86 a2 06 10 b9  84 b7 94 03 22 0c 08 92  |............"...|
000001a0  ed bd a2 06 10 95 c1 cc  d1 03 28 0a 1a 00 22 00  |..........(...".|
I0501 08:21:38.991354       1 leaderelection.go:278] successfully renewed lease kube-system/kube-scheduler
I0501 08:21:39.668141       1 pathrecorder.go:241] kube-scheduler: "/healthz" satisfied by exact match
I0501 08:21:39.668726       1 httplog.go:131] "HTTP" verb="GET" URI="/healthz" latency="639.223µs" userAgent="kube-probe/1.24" audit-ID="" srcIP="127.0.0.1:59044" resp=200
I0501 08:21:40.992398       1 round_trippers.go:466] curl -v -XGET  -H "Accept: application/vnd.kubernetes.protobuf, */*" -H "User-Agent: kube-scheduler/v1.24.7 (linux/amd64) kubernetes/e6f3597/leader-election" 'https://172.18.0.2:6443/apis/coordination.k8s.io/v1/namespaces/kube-system/leases/kube-scheduler?timeout=5s'
I0501 08:21:41.021851       1 round_trippers.go:553] GET https://172.18.0.2:6443/apis/coordination.k8s.io/v1/namespaces/kube-system/leases/kube-scheduler?timeout=5s 200 OK in 29 milliseconds
I0501 08:21:41.021910       1 round_trippers.go:570] HTTP Statistics: GetConnection 0 ms ServerProcessing 28 ms Duration 29 ms
I0501 08:21:41.021927       1 round_trippers.go:577] Response Headers:
I0501 08:21:41.021946       1 round_trippers.go:580]     Date: Mon, 01 May 2023 08:21:41 GMT
I0501 08:21:41.021962       1 round_trippers.go:580]     Audit-Id: f35cc428-d9a6-4c78-9a83-b8d33c0ad6cd
I0501 08:21:41.021978       1 round_trippers.go:580]     Cache-Control: no-cache, private
I0501 08:21:41.021993       1 round_trippers.go:580]     Content-Type: application/vnd.kubernetes.protobuf
I0501 08:21:41.022107       1 round_trippers.go:580]     X-Kubernetes-Pf-Flowschema-Uid: 493426e8-0f6d-4ea6-bc2c-2d926c7e3221
I0501 08:21:41.022124       1 round_trippers.go:580]     X-Kubernetes-Pf-Prioritylevel-Uid: afabb116-6975-46b8-863b-3258bec9e1ea
I0501 08:21:41.022139       1 round_trippers.go:580]     Content-Length: 432
I0501 08:21:41.022258       1 request.go:1152] Response Body:
00000000  6b 38 73 00 0a 1f 0a 16  63 6f 6f 72 64 69 6e 61  |k8s.....coordina|
00000010  74 69 6f 6e 2e 6b 38 73  2e 69 6f 2f 76 31 12 05  |tion.k8s.io/v1..|
00000020  4c 65 61 73 65 12 84 03  0a a6 02 0a 0e 6b 75 62  |Lease........kub|
00000030  65 2d 73 63 68 65 64 75  6c 65 72 12 00 1a 0b 6b  |e-scheduler....k|
00000040  75 62 65 2d 73 79 73 74  65 6d 22 00 2a 24 36 61  |ube-system".*$6a|
00000050  30 65 32 30 33 66 2d 65  32 38 30 2d 34 36 61 30  |0e203f-e280-46a0|
00000060  2d 39 35 33 62 2d 35 66  62 64 63 37 38 61 63 38  |-953b-5fbdc78ac8|
00000070  36 65 32 07 32 32 36 38  36 33 36 38 00 42 08 08  |6e2.22686368.B..|
00000080  b1 b2 e2 a1 06 10 00 7a  00 8a 01 c4 01 0a 0e 6b  |.......z.......k|
00000090  75 62 65 2d 73 63 68 65  64 75 6c 65 72 12 06 55  |ube-scheduler..U|
000000a0  70 64 61 74 65 1a 16 63  6f 6f 72 64 69 6e 61 74  |pdate..coordinat|
000000b0  69 6f 6e 2e 6b 38 73 2e  69 6f 2f 76 31 22 08 08  |ion.k8s.io/v1"..|
000000c0  b1 b2 e2 a1 06 10 00 32  08 46 69 65 6c 64 73 56  |.......2.FieldsV|
000000d0  31 3a 7c 0a 7a 7b 22 66  3a 73 70 65 63 22 3a 7b  |1:|.z{"f:spec":{|
000000e0  22 66 3a 61 63 71 75 69  72 65 54 69 6d 65 22 3a  |"f:acquireTime":|
000000f0  7b 7d 2c 22 66 3a 68 6f  6c 64 65 72 49 64 65 6e  |{},"f:holderIden|
00000100  74 69 74 79 22 3a 7b 7d  2c 22 66 3a 6c 65 61 73  |tity":{},"f:leas|
00000110  65 44 75 72 61 74 69 6f  6e 53 65 63 6f 6e 64 73  |eDurationSeconds|
00000120  22 3a 7b 7d 2c 22 66 3a  6c 65 61 73 65 54 72 61  |":{},"f:leaseTra|
00000130  6e 73 69 74 69 6f 6e 73  22 3a 7b 7d 2c 22 66 3a  |nsitions":{},"f:|
00000140  72 65 6e 65 77 54 69 6d  65 22 3a 7b 7d 7d 7d 42  |renewTime":{}}}B|
00000150  00 12 59 0a 37 6b 69 6e  64 2d 63 6f 6e 74 72 6f  |..Y.7kind-contro|
00000160  6c 2d 70 6c 61 6e 65 5f  30 64 32 66 61 66 39 33  |l-plane_0d2faf93|
00000170  2d 34 61 30 62 2d 34 66  32 38 2d 38 33 64 33 2d  |-4a0b-4f28-83d3-|
00000180  35 62 35 62 62 66 61 31  65 36 31 30 10 0f 1a 0c  |5b5bbfa1e610....|
00000190  08 f7 a5 86 a2 06 10 b9  84 b7 94 03 22 0c 08 92  |............"...|
000001a0  ed bd a2 06 10 95 c1 cc  d1 03 28 0a 1a 00 22 00  |..........(...".|
I0501 08:21:41.022582       1 request.go:1152] Request Body:
00000000  6b 38 73 00 0a 1f 0a 16  63 6f 6f 72 64 69 6e 61  |k8s.....coordina|
00000010  74 69 6f 6e 2e 6b 38 73  2e 69 6f 2f 76 31 12 05  |tion.k8s.io/v1..|
00000020  4c 65 61 73 65 12 84 03  0a a6 02 0a 0e 6b 75 62  |Lease........kub|
00000030  65 2d 73 63 68 65 64 75  6c 65 72 12 00 1a 0b 6b  |e-scheduler....k|
00000040  75 62 65 2d 73 79 73 74  65 6d 22 00 2a 24 36 61  |ube-system".*$6a|
00000050  30 65 32 30 33 66 2d 65  32 38 30 2d 34 36 61 30  |0e203f-e280-46a0|
00000060  2d 39 35 33 62 2d 35 66  62 64 63 37 38 61 63 38  |-953b-5fbdc78ac8|
00000070  36 65 32 07 32 32 36 38  36 33 36 38 00 42 08 08  |6e2.22686368.B..|
00000080  b1 b2 e2 a1 06 10 00 7a  00 8a 01 c4 01 0a 0e 6b  |.......z.......k|
00000090  75 62 65 2d 73 63 68 65  64 75 6c 65 72 12 06 55  |ube-scheduler..U|
000000a0  70 64 61 74 65 1a 16 63  6f 6f 72 64 69 6e 61 74  |pdate..coordinat|
000000b0  69 6f 6e 2e 6b 38 73 2e  69 6f 2f 76 31 22 08 08  |ion.k8s.io/v1"..|
000000c0  b1 b2 e2 a1 06 10 00 32  08 46 69 65 6c 64 73 56  |.......2.FieldsV|
000000d0  31 3a 7c 0a 7a 7b 22 66  3a 73 70 65 63 22 3a 7b  |1:|.z{"f:spec":{|
000000e0  22 66 3a 61 63 71 75 69  72 65 54 69 6d 65 22 3a  |"f:acquireTime":|
000000f0  7b 7d 2c 22 66 3a 68 6f  6c 64 65 72 49 64 65 6e  |{},"f:holderIden|
00000100  74 69 74 79 22 3a 7b 7d  2c 22 66 3a 6c 65 61 73  |tity":{},"f:leas|
00000110  65 44 75 72 61 74 69 6f  6e 53 65 63 6f 6e 64 73  |eDurationSeconds|
00000120  22 3a 7b 7d 2c 22 66 3a  6c 65 61 73 65 54 72 61  |":{},"f:leaseTra|
00000130  6e 73 69 74 69 6f 6e 73  22 3a 7b 7d 2c 22 66 3a  |nsitions":{},"f:|
00000140  72 65 6e 65 77 54 69 6d  65 22 3a 7b 7d 7d 7d 42  |renewTime":{}}}B|
00000150  00 12 59 0a 37 6b 69 6e  64 2d 63 6f 6e 74 72 6f  |..Y.7kind-contro|
00000160  6c 2d 70 6c 61 6e 65 5f  30 64 32 66 61 66 39 33  |l-plane_0d2faf93|
00000170  2d 34 61 30 62 2d 34 66  32 38 2d 38 33 64 33 2d  |-4a0b-4f28-83d3-|
00000180  35 62 35 62 62 66 61 31  65 36 31 30 10 0f 1a 0c  |5b5bbfa1e610....|
00000190  08 f7 a5 86 a2 06 10 b9  84 b7 94 03 22 0c 08 94  |............"...|
000001a0  ed bd a2 06 10 fa a3 ff  d8 03 28 0a 1a 00 22 00  |..........(...".|
I0501 08:21:41.022775       1 round_trippers.go:466] curl -v -XPUT  -H "Accept: application/vnd.kubernetes.protobuf, */*" -H "Content-Type: application/vnd.kubernetes.protobuf" -H "User-Agent: kube-scheduler/v1.24.7 (linux/amd64) kubernetes/e6f3597/leader-election" 'https://172.18.0.2:6443/apis/coordination.k8s.io/v1/namespaces/kube-system/leases/kube-scheduler?timeout=5s'
I0501 08:21:41.029297       1 round_trippers.go:553] PUT https://172.18.0.2:6443/apis/coordination.k8s.io/v1/namespaces/kube-system/leases/kube-scheduler?timeout=5s 200 OK in 6 milliseconds
I0501 08:21:41.029362       1 round_trippers.go:570] HTTP Statistics: GetConnection 0 ms ServerProcessing 6 ms Duration 6 ms
I0501 08:21:41.029426       1 round_trippers.go:577] Response Headers:
I0501 08:21:41.029457       1 round_trippers.go:580]     Cache-Control: no-cache, private
I0501 08:21:41.029641       1 round_trippers.go:580]     Content-Type: application/vnd.kubernetes.protobuf
I0501 08:21:41.029679       1 round_trippers.go:580]     X-Kubernetes-Pf-Flowschema-Uid: 493426e8-0f6d-4ea6-bc2c-2d926c7e3221
I0501 08:21:41.029696       1 round_trippers.go:580]     X-Kubernetes-Pf-Prioritylevel-Uid: afabb116-6975-46b8-863b-3258bec9e1ea
I0501 08:21:41.029759       1 round_trippers.go:580]     Content-Length: 432
I0501 08:21:41.029777       1 round_trippers.go:580]     Date: Mon, 01 May 2023 08:21:41 GMT
I0501 08:21:41.029842       1 round_trippers.go:580]     Audit-Id: 31b99d65-c576-4fe2-a48d-a8f65a385470
I0501 08:21:41.030020       1 request.go:1152] Response Body:
00000000  6b 38 73 00 0a 1f 0a 16  63 6f 6f 72 64 69 6e 61  |k8s.....coordina|
00000010  74 69 6f 6e 2e 6b 38 73  2e 69 6f 2f 76 31 12 05  |tion.k8s.io/v1..|
00000020  4c 65 61 73 65 12 84 03  0a a6 02 0a 0e 6b 75 62  |Lease........kub|
00000030  65 2d 73 63 68 65 64 75  6c 65 72 12 00 1a 0b 6b  |e-scheduler....k|
00000040  75 62 65 2d 73 79 73 74  65 6d 22 00 2a 24 36 61  |ube-system".*$6a|
00000050  30 65 32 30 33 66 2d 65  32 38 30 2d 34 36 61 30  |0e203f-e280-46a0|
00000060  2d 39 35 33 62 2d 35 66  62 64 63 37 38 61 63 38  |-953b-5fbdc78ac8|
00000070  36 65 32 07 32 32 36 38  36 33 38 38 00 42 08 08  |6e2.22686388.B..|
00000080  b1 b2 e2 a1 06 10 00 7a  00 8a 01 c4 01 0a 0e 6b  |.......z.......k|
00000090  75 62 65 2d 73 63 68 65  64 75 6c 65 72 12 06 55  |ube-scheduler..U|
000000a0  70 64 61 74 65 1a 16 63  6f 6f 72 64 69 6e 61 74  |pdate..coordinat|
000000b0  69 6f 6e 2e 6b 38 73 2e  69 6f 2f 76 31 22 08 08  |ion.k8s.io/v1"..|
000000c0  b1 b2 e2 a1 06 10 00 32  08 46 69 65 6c 64 73 56  |.......2.FieldsV|
000000d0  31 3a 7c 0a 7a 7b 22 66  3a 73 70 65 63 22 3a 7b  |1:|.z{"f:spec":{|
000000e0  22 66 3a 61 63 71 75 69  72 65 54 69 6d 65 22 3a  |"f:acquireTime":|
000000f0  7b 7d 2c 22 66 3a 68 6f  6c 64 65 72 49 64 65 6e  |{},"f:holderIden|
00000100  74 69 74 79 22 3a 7b 7d  2c 22 66 3a 6c 65 61 73  |tity":{},"f:leas|
00000110  65 44 75 72 61 74 69 6f  6e 53 65 63 6f 6e 64 73  |eDurationSeconds|
00000120  22 3a 7b 7d 2c 22 66 3a  6c 65 61 73 65 54 72 61  |":{},"f:leaseTra|
00000130  6e 73 69 74 69 6f 6e 73  22 3a 7b 7d 2c 22 66 3a  |nsitions":{},"f:|
00000140  72 65 6e 65 77 54 69 6d  65 22 3a 7b 7d 7d 7d 42  |renewTime":{}}}B|
00000150  00 12 59 0a 37 6b 69 6e  64 2d 63 6f 6e 74 72 6f  |..Y.7kind-contro|
00000160  6c 2d 70 6c 61 6e 65 5f  30 64 32 66 61 66 39 33  |l-plane_0d2faf93|
00000170  2d 34 61 30 62 2d 34 66  32 38 2d 38 33 64 33 2d  |-4a0b-4f28-83d3-|
00000180  35 62 35 62 62 66 61 31  65 36 31 30 10 0f 1a 0c  |5b5bbfa1e610....|
00000190  08 f7 a5 86 a2 06 10 b9  84 b7 94 03 22 0c 08 94  |............"...|
000001a0  ed bd a2 06 10 fa a3 ff  d8 03 28 0a 1a 00 22 00  |..........(...".|
I0501 08:21:41.030307       1 leaderelection.go:278] successfully renewed lease kube-system/kube-scheduler
I0501 08:21:42.264998       1 reflector.go:536] vendor/k8s.io/client-go/informers/factory.go:134: Watch close - *v1.PodDisruptionBudget total 3 items received
I0501 08:21:42.265589       1 round_trippers.go:466] curl -v -XGET  -H "Accept: application/vnd.kubernetes.protobuf, */*" -H "User-Agent: kube-scheduler/v1.24.7 (linux/amd64) kubernetes/e6f3597/scheduler" 'https://172.18.0.2:6443/apis/policy/v1/poddisruptionbudgets?allowWatchBookmarks=true&resourceVersion=2268403&timeout=8m32s&timeoutSeconds=512&watch=true'
I0501 08:21:42.275460       1 round_trippers.go:553] GET https://172.18.0.2:6443/apis/policy/v1/poddisruptionbudgets?allowWatchBookmarks=true&resourceVersion=2268403&timeout=8m32s&timeoutSeconds=512&watch=true 200 OK in 9 milliseconds
I0501 08:21:42.275519       1 round_trippers.go:570] HTTP Statistics: GetConnection 0 ms ServerProcessing 6 ms Duration 9 ms
I0501 08:21:42.275535       1 round_trippers.go:577] Response Headers:
I0501 08:21:42.275554       1 round_trippers.go:580]     Cache-Control: no-cache, private
I0501 08:21:42.275569       1 round_trippers.go:580]     Content-Type: application/vnd.kubernetes.protobuf;stream=watch
I0501 08:21:42.275584       1 round_trippers.go:580]     X-Kubernetes-Pf-Flowschema-Uid: 8a935dea-6b5d-4402-a842-ba69f911704f
I0501 08:21:42.275599       1 round_trippers.go:580]     X-Kubernetes-Pf-Prioritylevel-Uid: 4ccc4fdb-4419-4777-8b6f-3ed0d4949e5d
I0501 08:21:42.275614       1 round_trippers.go:580]     Date: Mon, 01 May 2023 08:21:42 GMT
I0501 08:21:42.275629       1 round_trippers.go:580]     Audit-Id: 4bd14c34-506b-46d8-bda3-175f5beb0f5e
I0501 08:21:43.031456       1 round_trippers.go:466] curl -v -XGET  -H "Accept: application/vnd.kubernetes.protobuf, */*" -H "User-Agent: kube-scheduler/v1.24.7 (linux/amd64) kubernetes/e6f3597/leader-election" 'https://172.18.0.2:6443/apis/coordination.k8s.io/v1/namespaces/kube-system/leases/kube-scheduler?timeout=5s'
I0501 08:21:43.037390       1 round_trippers.go:553] GET https://172.18.0.2:6443/apis/coordination.k8s.io/v1/namespaces/kube-system/leases/kube-scheduler?timeout=5s 200 OK in 5 milliseconds
I0501 08:21:43.037445       1 round_trippers.go:570] HTTP Statistics: GetConnection 0 ms ServerProcessing 2 ms Duration 5 ms
I0501 08:21:43.037467       1 round_trippers.go:577] Response Headers:
I0501 08:21:43.037489       1 round_trippers.go:580]     Cache-Control: no-cache, private
I0501 08:21:43.037529       1 round_trippers.go:580]     Content-Type: application/vnd.kubernetes.protobuf
I0501 08:21:43.037551       1 round_trippers.go:580]     X-Kubernetes-Pf-Flowschema-Uid: 493426e8-0f6d-4ea6-bc2c-2d926c7e3221
I0501 08:21:43.037571       1 round_trippers.go:580]     X-Kubernetes-Pf-Prioritylevel-Uid: afabb116-6975-46b8-863b-3258bec9e1ea
I0501 08:21:43.037590       1 round_trippers.go:580]     Content-Length: 432
I0501 08:21:43.037609       1 round_trippers.go:580]     Date: Mon, 01 May 2023 08:21:43 GMT
I0501 08:21:43.037667       1 round_trippers.go:580]     Audit-Id: fb7154ba-e322-4cf3-a4a0-6c693d2d4430
I0501 08:21:43.037812       1 request.go:1152] Response Body:
00000000  6b 38 73 00 0a 1f 0a 16  63 6f 6f 72 64 69 6e 61  |k8s.....coordina|
00000010  74 69 6f 6e 2e 6b 38 73  2e 69 6f 2f 76 31 12 05  |tion.k8s.io/v1..|
00000020  4c 65 61 73 65 12 84 03  0a a6 02 0a 0e 6b 75 62  |Lease........kub|
00000030  65 2d 73 63 68 65 64 75  6c 65 72 12 00 1a 0b 6b  |e-scheduler....k|
00000040  75 62 65 2d 73 79 73 74  65 6d 22 00 2a 24 36 61  |ube-system".*$6a|
00000050  30 65 32 30 33 66 2d 65  32 38 30 2d 34 36 61 30  |0e203f-e280-46a0|
00000060  2d 39 35 33 62 2d 35 66  62 64 63 37 38 61 63 38  |-953b-5fbdc78ac8|
00000070  36 65 32 07 32 32 36 38  36 33 38 38 00 42 08 08  |6e2.22686388.B..|
00000080  b1 b2 e2 a1 06 10 00 7a  00 8a 01 c4 01 0a 0e 6b  |.......z.......k|
00000090  75 62 65 2d 73 63 68 65  64 75 6c 65 72 12 06 55  |ube-scheduler..U|
000000a0  70 64 61 74 65 1a 16 63  6f 6f 72 64 69 6e 61 74  |pdate..coordinat|
000000b0  69 6f 6e 2e 6b 38 73 2e  69 6f 2f 76 31 22 08 08  |ion.k8s.io/v1"..|
000000c0  b1 b2 e2 a1 06 10 00 32  08 46 69 65 6c 64 73 56  |.......2.FieldsV|
000000d0  31 3a 7c 0a 7a 7b 22 66  3a 73 70 65 63 22 3a 7b  |1:|.z{"f:spec":{|
000000e0  22 66 3a 61 63 71 75 69  72 65 54 69 6d 65 22 3a  |"f:acquireTime":|
000000f0  7b 7d 2c 22 66 3a 68 6f  6c 64 65 72 49 64 65 6e  |{},"f:holderIden|
00000100  74 69 74 79 22 3a 7b 7d  2c 22 66 3a 6c 65 61 73  |tity":{},"f:leas|
00000110  65 44 75 72 61 74 69 6f  6e 53 65 63 6f 6e 64 73  |eDurationSeconds|
00000120  22 3a 7b 7d 2c 22 66 3a  6c 65 61 73 65 54 72 61  |":{},"f:leaseTra|
00000130  6e 73 69 74 69 6f 6e 73  22 3a 7b 7d 2c 22 66 3a  |nsitions":{},"f:|
00000140  72 65 6e 65 77 54 69 6d  65 22 3a 7b 7d 7d 7d 42  |renewTime":{}}}B|
00000150  00 12 59 0a 37 6b 69 6e  64 2d 63 6f 6e 74 72 6f  |..Y.7kind-contro|
00000160  6c 2d 70 6c 61 6e 65 5f  30 64 32 66 61 66 39 33  |l-plane_0d2faf93|
00000170  2d 34 61 30 62 2d 34 66  32 38 2d 38 33 64 33 2d  |-4a0b-4f28-83d3-|
00000180  35 62 35 62 62 66 61 31  65 36 31 30 10 0f 1a 0c  |5b5bbfa1e610....|
00000190  08 f7 a5 86 a2 06 10 b9  84 b7 94 03 22 0c 08 94  |............"...|
000001a0  ed bd a2 06 10 fa a3 ff  d8 03 28 0a 1a 00 22 00  |..........(...".|
I0501 08:21:43.038093       1 request.go:1152] Request Body:
00000000  6b 38 73 00 0a 1f 0a 16  63 6f 6f 72 64 69 6e 61  |k8s.....coordina|
00000010  74 69 6f 6e 2e 6b 38 73  2e 69 6f 2f 76 31 12 05  |tion.k8s.io/v1..|
00000020  4c 65 61 73 65 12 83 03  0a a6 02 0a 0e 6b 75 62  |Lease........kub|
00000030  65 2d 73 63 68 65 64 75  6c 65 72 12 00 1a 0b 6b  |e-scheduler....k|
00000040  75 62 65 2d 73 79 73 74  65 6d 22 00 2a 24 36 61  |ube-system".*$6a|
00000050  30 65 32 30 33 66 2d 65  32 38 30 2d 34 36 61 30  |0e203f-e280-46a0|
00000060  2d 39 35 33 62 2d 35 66  62 64 63 37 38 61 63 38  |-953b-5fbdc78ac8|
00000070  36 65 32 07 32 32 36 38  36 33 38 38 00 42 08 08  |6e2.22686388.B..|
00000080  b1 b2 e2 a1 06 10 00 7a  00 8a 01 c4 01 0a 0e 6b  |.......z.......k|
00000090  75 62 65 2d 73 63 68 65  64 75 6c 65 72 12 06 55  |ube-scheduler..U|
000000a0  70 64 61 74 65 1a 16 63  6f 6f 72 64 69 6e 61 74  |pdate..coordinat|
000000b0  69 6f 6e 2e 6b 38 73 2e  69 6f 2f 76 31 22 08 08  |ion.k8s.io/v1"..|
000000c0  b1 b2 e2 a1 06 10 00 32  08 46 69 65 6c 64 73 56  |.......2.FieldsV|
000000d0  31 3a 7c 0a 7a 7b 22 66  3a 73 70 65 63 22 3a 7b  |1:|.z{"f:spec":{|
000000e0  22 66 3a 61 63 71 75 69  72 65 54 69 6d 65 22 3a  |"f:acquireTime":|
000000f0  7b 7d 2c 22 66 3a 68 6f  6c 64 65 72 49 64 65 6e  |{},"f:holderIden|
00000100  74 69 74 79 22 3a 7b 7d  2c 22 66 3a 6c 65 61 73  |tity":{},"f:leas|
00000110  65 44 75 72 61 74 69 6f  6e 53 65 63 6f 6e 64 73  |eDurationSeconds|
00000120  22 3a 7b 7d 2c 22 66 3a  6c 65 61 73 65 54 72 61  |":{},"f:leaseTra|
00000130  6e 73 69 74 69 6f 6e 73  22 3a 7b 7d 2c 22 66 3a  |nsitions":{},"f:|
00000140  72 65 6e 65 77 54 69 6d  65 22 3a 7b 7d 7d 7d 42  |renewTime":{}}}B|
00000150  00 12 58 0a 37 6b 69 6e  64 2d 63 6f 6e 74 72 6f  |..X.7kind-contro|
00000160  6c 2d 70 6c 61 6e 65 5f  30 64 32 66 61 66 39 33  |l-plane_0d2faf93|
00000170  2d 34 61 30 62 2d 34 66  32 38 2d 38 33 64 33 2d  |-4a0b-4f28-83d3-|
00000180  35 62 35 62 62 66 61 31  65 36 31 30 10 0f 1a 0c  |5b5bbfa1e610....|
00000190  08 f7 a5 86 a2 06 10 b9  84 b7 94 03 22 0b 08 97  |............"...|
000001a0  ed bd a2 06 10 d5 dd f1  0e 28 0a 1a 00 22 00     |.........(...".|
I0501 08:21:43.038238       1 round_trippers.go:466] curl -v -XPUT  -H "Accept: application/vnd.kubernetes.protobuf, */*" -H "Content-Type: application/vnd.kubernetes.protobuf" -H "User-Agent: kube-scheduler/v1.24.7 (linux/amd64) kubernetes/e6f3597/leader-election" 'https://172.18.0.2:6443/apis/coordination.k8s.io/v1/namespaces/kube-system/leases/kube-scheduler?timeout=5s'
I0501 08:21:43.045749       1 round_trippers.go:553] PUT https://172.18.0.2:6443/apis/coordination.k8s.io/v1/namespaces/kube-system/leases/kube-scheduler?timeout=5s 200 OK in 7 milliseconds
I0501 08:21:43.045797       1 round_trippers.go:570] HTTP Statistics: GetConnection 0 ms ServerProcessing 7 ms Duration 7 ms
I0501 08:21:43.045814       1 round_trippers.go:577] Response Headers:
I0501 08:21:43.045844       1 round_trippers.go:580]     Content-Type: application/vnd.kubernetes.protobuf
I0501 08:21:43.045947       1 round_trippers.go:580]     X-Kubernetes-Pf-Flowschema-Uid: 493426e8-0f6d-4ea6-bc2c-2d926c7e3221
I0501 08:21:43.046017       1 round_trippers.go:580]     X-Kubernetes-Pf-Prioritylevel-Uid: afabb116-6975-46b8-863b-3258bec9e1ea
I0501 08:21:43.046267       1 round_trippers.go:580]     Content-Length: 431
I0501 08:21:43.046350       1 round_trippers.go:580]     Date: Mon, 01 May 2023 08:21:43 GMT
I0501 08:21:43.046390       1 round_trippers.go:580]     Audit-Id: 8d9c9695-31ea-446d-8379-ab38ed93168e
I0501 08:21:43.046406       1 round_trippers.go:580]     Cache-Control: no-cache, private
I0501 08:21:43.046571       1 request.go:1152] Response Body:
00000000  6b 38 73 00 0a 1f 0a 16  63 6f 6f 72 64 69 6e 61  |k8s.....coordina|
00000010  74 69 6f 6e 2e 6b 38 73  2e 69 6f 2f 76 31 12 05  |tion.k8s.io/v1..|
00000020  4c 65 61 73 65 12 83 03  0a a6 02 0a 0e 6b 75 62  |Lease........kub|
00000030  65 2d 73 63 68 65 64 75  6c 65 72 12 00 1a 0b 6b  |e-scheduler....k|
00000040  75 62 65 2d 73 79 73 74  65 6d 22 00 2a 24 36 61  |ube-system".*$6a|
00000050  30 65 32 30 33 66 2d 65  32 38 30 2d 34 36 61 30  |0e203f-e280-46a0|
00000060  2d 39 35 33 62 2d 35 66  62 64 63 37 38 61 63 38  |-953b-5fbdc78ac8|
00000070  36 65 32 07 32 32 36 38  36 34 32 38 00 42 08 08  |6e2.22686428.B..|
00000080  b1 b2 e2 a1 06 10 00 7a  00 8a 01 c4 01 0a 0e 6b  |.......z.......k|
00000090  75 62 65 2d 73 63 68 65  64 75 6c 65 72 12 06 55  |ube-scheduler..U|
000000a0  70 64 61 74 65 1a 16 63  6f 6f 72 64 69 6e 61 74  |pdate..coordinat|
000000b0  69 6f 6e 2e 6b 38 73 2e  69 6f 2f 76 31 22 08 08  |ion.k8s.io/v1"..|
000000c0  b1 b2 e2 a1 06 10 00 32  08 46 69 65 6c 64 73 56  |.......2.FieldsV|
000000d0  31 3a 7c 0a 7a 7b 22 66  3a 73 70 65 63 22 3a 7b  |1:|.z{"f:spec":{|
000000e0  22 66 3a 61 63 71 75 69  72 65 54 69 6d 65 22 3a  |"f:acquireTime":|
000000f0  7b 7d 2c 22 66 3a 68 6f  6c 64 65 72 49 64 65 6e  |{},"f:holderIden|
00000100  74 69 74 79 22 3a 7b 7d  2c 22 66 3a 6c 65 61 73  |tity":{},"f:leas|
00000110  65 44 75 72 61 74 69 6f  6e 53 65 63 6f 6e 64 73  |eDurationSeconds|
00000120  22 3a 7b 7d 2c 22 66 3a  6c 65 61 73 65 54 72 61  |":{},"f:leaseTra|
00000130  6e 73 69 74 69 6f 6e 73  22 3a 7b 7d 2c 22 66 3a  |nsitions":{},"f:|
00000140  72 65 6e 65 77 54 69 6d  65 22 3a 7b 7d 7d 7d 42  |renewTime":{}}}B|
00000150  00 12 58 0a 37 6b 69 6e  64 2d 63 6f 6e 74 72 6f  |..X.7kind-contro|
00000160  6c 2d 70 6c 61 6e 65 5f  30 64 32 66 61 66 39 33  |l-plane_0d2faf93|
00000170  2d 34 61 30 62 2d 34 66  32 38 2d 38 33 64 33 2d  |-4a0b-4f28-83d3-|
00000180  35 62 35 62 62 66 61 31  65 36 31 30 10 0f 1a 0c  |5b5bbfa1e610....|
00000190  08 f7 a5 86 a2 06 10 b9  84 b7 94 03 22 0b 08 97  |............"...|
000001a0  ed bd a2 06 10 d5 dd f1  0e 28 0a 1a 00 22 00     |.........(...".|
I0501 08:21:43.046793       1 leaderelection.go:278] successfully renewed lease kube-system/kube-scheduler
I0501 08:21:45.048074       1 round_trippers.go:466] curl -v -XGET  -H "Accept: application/vnd.kubernetes.protobuf, */*" -H "User-Agent: kube-scheduler/v1.24.7 (linux/amd64) kubernetes/e6f3597/leader-election" 'https://172.18.0.2:6443/apis/coordination.k8s.io/v1/namespaces/kube-system/leases/kube-scheduler?timeout=5s'
I0501 08:21:45.053801       1 round_trippers.go:553] GET https://172.18.0.2:6443/apis/coordination.k8s.io/v1/namespaces/kube-system/leases/kube-scheduler?timeout=5s 200 OK in 5 milliseconds
I0501 08:21:45.053840       1 round_trippers.go:570] HTTP Statistics: GetConnection 0 ms ServerProcessing 5 ms Duration 5 ms
I0501 08:21:45.053856       1 round_trippers.go:577] Response Headers:
I0501 08:21:45.053874       1 round_trippers.go:580]     Audit-Id: c5b7c280-2976-4e3d-8f5e-b0406cc567b7
I0501 08:21:45.053897       1 round_trippers.go:580]     Cache-Control: no-cache, private
I0501 08:21:45.053912       1 round_trippers.go:580]     Content-Type: application/vnd.kubernetes.protobuf
I0501 08:21:45.053928       1 round_trippers.go:580]     X-Kubernetes-Pf-Flowschema-Uid: 493426e8-0f6d-4ea6-bc2c-2d926c7e3221
I0501 08:21:45.053943       1 round_trippers.go:580]     X-Kubernetes-Pf-Prioritylevel-Uid: afabb116-6975-46b8-863b-3258bec9e1ea
I0501 08:21:45.053957       1 round_trippers.go:580]     Content-Length: 431
I0501 08:21:45.053976       1 round_trippers.go:580]     Date: Mon, 01 May 2023 08:21:45 GMT
I0501 08:21:45.054082       1 request.go:1152] Response Body:
00000000  6b 38 73 00 0a 1f 0a 16  63 6f 6f 72 64 69 6e 61  |k8s.....coordina|
00000010  74 69 6f 6e 2e 6b 38 73  2e 69 6f 2f 76 31 12 05  |tion.k8s.io/v1..|
00000020  4c 65 61 73 65 12 83 03  0a a6 02 0a 0e 6b 75 62  |Lease........kub|
00000030  65 2d 73 63 68 65 64 75  6c 65 72 12 00 1a 0b 6b  |e-scheduler....k|
00000040  75 62 65 2d 73 79 73 74  65 6d 22 00 2a 24 36 61  |ube-system".*$6a|
00000050  30 65 32 30 33 66 2d 65  32 38 30 2d 34 36 61 30  |0e203f-e280-46a0|
00000060  2d 39 35 33 62 2d 35 66  62 64 63 37 38 61 63 38  |-953b-5fbdc78ac8|
00000070  36 65 32 07 32 32 36 38  36 34 32 38 00 42 08 08  |6e2.22686428.B..|
00000080  b1 b2 e2 a1 06 10 00 7a  00 8a 01 c4 01 0a 0e 6b  |.......z.......k|
00000090  75 62 65 2d 73 63 68 65  64 75 6c 65 72 12 06 55  |ube-scheduler..U|
000000a0  70 64 61 74 65 1a 16 63  6f 6f 72 64 69 6e 61 74  |pdate..coordinat|
000000b0  69 6f 6e 2e 6b 38 73 2e  69 6f 2f 76 31 22 08 08  |ion.k8s.io/v1"..|
000000c0  b1 b2 e2 a1 06 10 00 32  08 46 69 65 6c 64 73 56  |.......2.FieldsV|
000000d0  31 3a 7c 0a 7a 7b 22 66  3a 73 70 65 63 22 3a 7b  |1:|.z{"f:spec":{|
000000e0  22 66 3a 61 63 71 75 69  72 65 54 69 6d 65 22 3a  |"f:acquireTime":|
000000f0  7b 7d 2c 22 66 3a 68 6f  6c 64 65 72 49 64 65 6e  |{},"f:holderIden|
00000100  74 69 74 79 22 3a 7b 7d  2c 22 66 3a 6c 65 61 73  |tity":{},"f:leas|
00000110  65 44 75 72 61 74 69 6f  6e 53 65 63 6f 6e 64 73  |eDurationSeconds|
00000120  22 3a 7b 7d 2c 22 66 3a  6c 65 61 73 65 54 72 61  |":{},"f:leaseTra|
00000130  6e 73 69 74 69 6f 6e 73  22 3a 7b 7d 2c 22 66 3a  |nsitions":{},"f:|
00000140  72 65 6e 65 77 54 69 6d  65 22 3a 7b 7d 7d 7d 42  |renewTime":{}}}B|
00000150  00 12 58 0a 37 6b 69 6e  64 2d 63 6f 6e 74 72 6f  |..X.7kind-contro|
00000160  6c 2d 70 6c 61 6e 65 5f  30 64 32 66 61 66 39 33  |l-plane_0d2faf93|
00000170  2d 34 61 30 62 2d 34 66  32 38 2d 38 33 64 33 2d  |-4a0b-4f28-83d3-|
00000180  35 62 35 62 62 66 61 31  65 36 31 30 10 0f 1a 0c  |5b5bbfa1e610....|
00000190  08 f7 a5 86 a2 06 10 b9  84 b7 94 03 22 0b 08 97  |............"...|
000001a0  ed bd a2 06 10 d5 dd f1  0e 28 0a 1a 00 22 00     |.........(...".|
I0501 08:21:45.054291       1 request.go:1152] Request Body:
00000000  6b 38 73 00 0a 1f 0a 16  63 6f 6f 72 64 69 6e 61  |k8s.....coordina|
00000010  74 69 6f 6e 2e 6b 38 73  2e 69 6f 2f 76 31 12 05  |tion.k8s.io/v1..|
00000020  4c 65 61 73 65 12 83 03  0a a6 02 0a 0e 6b 75 62  |Lease........kub|
00000030  65 2d 73 63 68 65 64 75  6c 65 72 12 00 1a 0b 6b  |e-scheduler....k|
00000040  75 62 65 2d 73 79 73 74  65 6d 22 00 2a 24 36 61  |ube-system".*$6a|
00000050  30 65 32 30 33 66 2d 65  32 38 30 2d 34 36 61 30  |0e203f-e280-46a0|
00000060  2d 39 35 33 62 2d 35 66  62 64 63 37 38 61 63 38  |-953b-5fbdc78ac8|
00000070  36 65 32 07 32 32 36 38  36 34 32 38 00 42 08 08  |6e2.22686428.B..|
00000080  b1 b2 e2 a1 06 10 00 7a  00 8a 01 c4 01 0a 0e 6b  |.......z.......k|
00000090  75 62 65 2d 73 63 68 65  64 75 6c 65 72 12 06 55  |ube-scheduler..U|
000000a0  70 64 61 74 65 1a 16 63  6f 6f 72 64 69 6e 61 74  |pdate..coordinat|
000000b0  69 6f 6e 2e 6b 38 73 2e  69 6f 2f 76 31 22 08 08  |ion.k8s.io/v1"..|
000000c0  b1 b2 e2 a1 06 10 00 32  08 46 69 65 6c 64 73 56  |.......2.FieldsV|
000000d0  31 3a 7c 0a 7a 7b 22 66  3a 73 70 65 63 22 3a 7b  |1:|.z{"f:spec":{|
000000e0  22 66 3a 61 63 71 75 69  72 65 54 69 6d 65 22 3a  |"f:acquireTime":|
000000f0  7b 7d 2c 22 66 3a 68 6f  6c 64 65 72 49 64 65 6e  |{},"f:holderIden|
00000100  74 69 74 79 22 3a 7b 7d  2c 22 66 3a 6c 65 61 73  |tity":{},"f:leas|
00000110  65 44 75 72 61 74 69 6f  6e 53 65 63 6f 6e 64 73  |eDurationSeconds|
00000120  22 3a 7b 7d 2c 22 66 3a  6c 65 61 73 65 54 72 61  |":{},"f:leaseTra|
00000130  6e 73 69 74 69 6f 6e 73  22 3a 7b 7d 2c 22 66 3a  |nsitions":{},"f:|
00000140  72 65 6e 65 77 54 69 6d  65 22 3a 7b 7d 7d 7d 42  |renewTime":{}}}B|
00000150  00 12 58 0a 37 6b 69 6e  64 2d 63 6f 6e 74 72 6f  |..X.7kind-contro|
00000160  6c 2d 70 6c 61 6e 65 5f  30 64 32 66 61 66 39 33  |l-plane_0d2faf93|
00000170  2d 34 61 30 62 2d 34 66  32 38 2d 38 33 64 33 2d  |-4a0b-4f28-83d3-|
00000180  35 62 35 62 62 66 61 31  65 36 31 30 10 0f 1a 0c  |5b5bbfa1e610....|
00000190  08 f7 a5 86 a2 06 10 b9  84 b7 94 03 22 0b 08 99  |............"...|
000001a0  ed bd a2 06 10 d3 de e7  16 28 0a 1a 00 22 00     |.........(...".|
I0501 08:21:45.054414       1 round_trippers.go:466] curl -v -XPUT  -H "Accept: application/vnd.kubernetes.protobuf, */*" -H "Content-Type: application/vnd.kubernetes.protobuf" -H "User-Agent: kube-scheduler/v1.24.7 (linux/amd64) kubernetes/e6f3597/leader-election" 'https://172.18.0.2:6443/apis/coordination.k8s.io/v1/namespaces/kube-system/leases/kube-scheduler?timeout=5s'
I0501 08:21:45.060769       1 round_trippers.go:553] PUT https://172.18.0.2:6443/apis/coordination.k8s.io/v1/namespaces/kube-system/leases/kube-scheduler?timeout=5s 200 OK in 6 milliseconds
I0501 08:21:45.060840       1 round_trippers.go:570] HTTP Statistics: GetConnection 0 ms ServerProcessing 5 ms Duration 6 ms
I0501 08:21:45.060862       1 round_trippers.go:577] Response Headers:
I0501 08:21:45.060885       1 round_trippers.go:580]     Audit-Id: 716c4fda-68d4-4b8f-84c1-f90a6cbfd57a
I0501 08:21:45.060906       1 round_trippers.go:580]     Cache-Control: no-cache, private
I0501 08:21:45.060925       1 round_trippers.go:580]     Content-Type: application/vnd.kubernetes.protobuf
I0501 08:21:45.060944       1 round_trippers.go:580]     X-Kubernetes-Pf-Flowschema-Uid: 493426e8-0f6d-4ea6-bc2c-2d926c7e3221
I0501 08:21:45.060981       1 round_trippers.go:580]     X-Kubernetes-Pf-Prioritylevel-Uid: afabb116-6975-46b8-863b-3258bec9e1ea
I0501 08:21:45.061002       1 round_trippers.go:580]     Content-Length: 431
I0501 08:21:45.061029       1 round_trippers.go:580]     Date: Mon, 01 May 2023 08:21:45 GMT
I0501 08:21:45.061169       1 request.go:1152] Response Body:
00000000  6b 38 73 00 0a 1f 0a 16  63 6f 6f 72 64 69 6e 61  |k8s.....coordina|
00000010  74 69 6f 6e 2e 6b 38 73  2e 69 6f 2f 76 31 12 05  |tion.k8s.io/v1..|
00000020  4c 65 61 73 65 12 83 03  0a a6 02 0a 0e 6b 75 62  |Lease........kub|
00000030  65 2d 73 63 68 65 64 75  6c 65 72 12 00 1a 0b 6b  |e-scheduler....k|
00000040  75 62 65 2d 73 79 73 74  65 6d 22 00 2a 24 36 61  |ube-system".*$6a|
00000050  30 65 32 30 33 66 2d 65  32 38 30 2d 34 36 61 30  |0e203f-e280-46a0|
00000060  2d 39 35 33 62 2d 35 66  62 64 63 37 38 61 63 38  |-953b-5fbdc78ac8|
00000070  36 65 32 07 32 32 36 38  36 34 35 38 00 42 08 08  |6e2.22686458.B..|
00000080  b1 b2 e2 a1 06 10 00 7a  00 8a 01 c4 01 0a 0e 6b  |.......z.......k|
00000090  75 62 65 2d 73 63 68 65  64 75 6c 65 72 12 06 55  |ube-scheduler..U|
000000a0  70 64 61 74 65 1a 16 63  6f 6f 72 64 69 6e 61 74  |pdate..coordinat|
000000b0  69 6f 6e 2e 6b 38 73 2e  69 6f 2f 76 31 22 08 08  |ion.k8s.io/v1"..|
000000c0  b1 b2 e2 a1 06 10 00 32  08 46 69 65 6c 64 73 56  |.......2.FieldsV|
000000d0  31 3a 7c 0a 7a 7b 22 66  3a 73 70 65 63 22 3a 7b  |1:|.z{"f:spec":{|
000000e0  22 66 3a 61 63 71 75 69  72 65 54 69 6d 65 22 3a  |"f:acquireTime":|
000000f0  7b 7d 2c 22 66 3a 68 6f  6c 64 65 72 49 64 65 6e  |{},"f:holderIden|
00000100  74 69 74 79 22 3a 7b 7d  2c 22 66 3a 6c 65 61 73  |tity":{},"f:leas|
00000110  65 44 75 72 61 74 69 6f  6e 53 65 63 6f 6e 64 73  |eDurationSeconds|
00000120  22 3a 7b 7d 2c 22 66 3a  6c 65 61 73 65 54 72 61  |":{},"f:leaseTra|
00000130  6e 73 69 74 69 6f 6e 73  22 3a 7b 7d 2c 22 66 3a  |nsitions":{},"f:|
00000140  72 65 6e 65 77 54 69 6d  65 22 3a 7b 7d 7d 7d 42  |renewTime":{}}}B|
00000150  00 12 58 0a 37 6b 69 6e  64 2d 63 6f 6e 74 72 6f  |..X.7kind-contro|
00000160  6c 2d 70 6c 61 6e 65 5f  30 64 32 66 61 66 39 33  |l-plane_0d2faf93|
00000170  2d 34 61 30 62 2d 34 66  32 38 2d 38 33 64 33 2d  |-4a0b-4f28-83d3-|
00000180  35 62 35 62 62 66 61 31  65 36 31 30 10 0f 1a 0c  |5b5bbfa1e610....|
00000190  08 f7 a5 86 a2 06 10 b9  84 b7 94 03 22 0b 08 99  |............"...|
000001a0  ed bd a2 06 10 d3 de e7  16 28 0a 1a 00 22 00     |.........(...".|
I0501 08:21:45.061355       1 leaderelection.go:278] successfully renewed lease kube-system/kube-scheduler
I0501 08:21:47.063056       1 round_trippers.go:466] curl -v -XGET  -H "Accept: application/vnd.kubernetes.protobuf, */*" -H "User-Agent: kube-scheduler/v1.24.7 (linux/amd64) kubernetes/e6f3597/leader-election" 'https://172.18.0.2:6443/apis/coordination.k8s.io/v1/namespaces/kube-system/leases/kube-scheduler?timeout=5s'
I0501 08:21:47.068749       1 round_trippers.go:553] GET https://172.18.0.2:6443/apis/coordination.k8s.io/v1/namespaces/kube-system/leases/kube-scheduler?timeout=5s 200 OK in 5 milliseconds
I0501 08:21:47.068797       1 round_trippers.go:570] HTTP Statistics: GetConnection 0 ms ServerProcessing 5 ms Duration 5 ms
I0501 08:21:47.068813       1 round_trippers.go:577] Response Headers:
I0501 08:21:47.068838       1 round_trippers.go:580]     Date: Mon, 01 May 2023 08:21:47 GMT
I0501 08:21:47.068854       1 round_trippers.go:580]     Audit-Id: 4cee7c2f-98f6-4e74-bc66-0fa389be3dea
I0501 08:21:47.068868       1 round_trippers.go:580]     Cache-Control: no-cache, private
I0501 08:21:47.068883       1 round_trippers.go:580]     Content-Type: application/vnd.kubernetes.protobuf
I0501 08:21:47.068898       1 round_trippers.go:580]     X-Kubernetes-Pf-Flowschema-Uid: 493426e8-0f6d-4ea6-bc2c-2d926c7e3221
I0501 08:21:47.068943       1 round_trippers.go:580]     X-Kubernetes-Pf-Prioritylevel-Uid: afabb116-6975-46b8-863b-3258bec9e1ea
I0501 08:21:47.068973       1 round_trippers.go:580]     Content-Length: 431
I0501 08:21:47.069086       1 request.go:1152] Response Body:
00000000  6b 38 73 00 0a 1f 0a 16  63 6f 6f 72 64 69 6e 61  |k8s.....coordina|
00000010  74 69 6f 6e 2e 6b 38 73  2e 69 6f 2f 76 31 12 05  |tion.k8s.io/v1..|
00000020  4c 65 61 73 65 12 83 03  0a a6 02 0a 0e 6b 75 62  |Lease........kub|
00000030  65 2d 73 63 68 65 64 75  6c 65 72 12 00 1a 0b 6b  |e-scheduler....k|
00000040  75 62 65 2d 73 79 73 74  65 6d 22 00 2a 24 36 61  |ube-system".*$6a|
00000050  30 65 32 30 33 66 2d 65  32 38 30 2d 34 36 61 30  |0e203f-e280-46a0|
00000060  2d 39 35 33 62 2d 35 66  62 64 63 37 38 61 63 38  |-953b-5fbdc78ac8|
00000070  36 65 32 07 32 32 36 38  36 34 35 38 00 42 08 08  |6e2.22686458.B..|
00000080  b1 b2 e2 a1 06 10 00 7a  00 8a 01 c4 01 0a 0e 6b  |.......z.......k|
00000090  75 62 65 2d 73 63 68 65  64 75 6c 65 72 12 06 55  |ube-scheduler..U|
000000a0  70 64 61 74 65 1a 16 63  6f 6f 72 64 69 6e 61 74  |pdate..coordinat|
000000b0  69 6f 6e 2e 6b 38 73 2e  69 6f 2f 76 31 22 08 08  |ion.k8s.io/v1"..|
000000c0  b1 b2 e2 a1 06 10 00 32  08 46 69 65 6c 64 73 56  |.......2.FieldsV|
000000d0  31 3a 7c 0a 7a 7b 22 66  3a 73 70 65 63 22 3a 7b  |1:|.z{"f:spec":{|
000000e0  22 66 3a 61 63 71 75 69  72 65 54 69 6d 65 22 3a  |"f:acquireTime":|
000000f0  7b 7d 2c 22 66 3a 68 6f  6c 64 65 72 49 64 65 6e  |{},"f:holderIden|
00000100  74 69 74 79 22 3a 7b 7d  2c 22 66 3a 6c 65 61 73  |tity":{},"f:leas|
00000110  65 44 75 72 61 74 69 6f  6e 53 65 63 6f 6e 64 73  |eDurationSeconds|
00000120  22 3a 7b 7d 2c 22 66 3a  6c 65 61 73 65 54 72 61  |":{},"f:leaseTra|
00000130  6e 73 69 74 69 6f 6e 73  22 3a 7b 7d 2c 22 66 3a  |nsitions":{},"f:|
00000140  72 65 6e 65 77 54 69 6d  65 22 3a 7b 7d 7d 7d 42  |renewTime":{}}}B|
00000150  00 12 58 0a 37 6b 69 6e  64 2d 63 6f 6e 74 72 6f  |..X.7kind-contro|
00000160  6c 2d 70 6c 61 6e 65 5f  30 64 32 66 61 66 39 33  |l-plane_0d2faf93|
00000170  2d 34 61 30 62 2d 34 66  32 38 2d 38 33 64 33 2d  |-4a0b-4f28-83d3-|
00000180  35 62 35 62 62 66 61 31  65 36 31 30 10 0f 1a 0c  |5b5bbfa1e610....|
00000190  08 f7 a5 86 a2 06 10 b9  84 b7 94 03 22 0b 08 99  |............"...|
000001a0  ed bd a2 06 10 d3 de e7  16 28 0a 1a 00 22 00     |.........(...".|
I0501 08:21:47.069372       1 request.go:1152] Request Body:
00000000  6b 38 73 00 0a 1f 0a 16  63 6f 6f 72 64 69 6e 61  |k8s.....coordina|
00000010  74 69 6f 6e 2e 6b 38 73  2e 69 6f 2f 76 31 12 05  |tion.k8s.io/v1..|
00000020  4c 65 61 73 65 12 83 03  0a a6 02 0a 0e 6b 75 62  |Lease........kub|
00000030  65 2d 73 63 68 65 64 75  6c 65 72 12 00 1a 0b 6b  |e-scheduler....k|
00000040  75 62 65 2d 73 79 73 74  65 6d 22 00 2a 24 36 61  |ube-system".*$6a|
00000050  30 65 32 30 33 66 2d 65  32 38 30 2d 34 36 61 30  |0e203f-e280-46a0|
00000060  2d 39 35 33 62 2d 35 66  62 64 63 37 38 61 63 38  |-953b-5fbdc78ac8|
00000070  36 65 32 07 32 32 36 38  36 34 35 38 00 42 08 08  |6e2.22686458.B..|
00000080  b1 b2 e2 a1 06 10 00 7a  00 8a 01 c4 01 0a 0e 6b  |.......z.......k|
00000090  75 62 65 2d 73 63 68 65  64 75 6c 65 72 12 06 55  |ube-scheduler..U|
000000a0  70 64 61 74 65 1a 16 63  6f 6f 72 64 69 6e 61 74  |pdate..coordinat|
000000b0  69 6f 6e 2e 6b 38 73 2e  69 6f 2f 76 31 22 08 08  |ion.k8s.io/v1"..|
000000c0  b1 b2 e2 a1 06 10 00 32  08 46 69 65 6c 64 73 56  |.......2.FieldsV|
000000d0  31 3a 7c 0a 7a 7b 22 66  3a 73 70 65 63 22 3a 7b  |1:|.z{"f:spec":{|
000000e0  22 66 3a 61 63 71 75 69  72 65 54 69 6d 65 22 3a  |"f:acquireTime":|
000000f0  7b 7d 2c 22 66 3a 68 6f  6c 64 65 72 49 64 65 6e  |{},"f:holderIden|
00000100  74 69 74 79 22 3a 7b 7d  2c 22 66 3a 6c 65 61 73  |tity":{},"f:leas|
00000110  65 44 75 72 61 74 69 6f  6e 53 65 63 6f 6e 64 73  |eDurationSeconds|
00000120  22 3a 7b 7d 2c 22 66 3a  6c 65 61 73 65 54 72 61  |":{},"f:leaseTra|
00000130  6e 73 69 74 69 6f 6e 73  22 3a 7b 7d 2c 22 66 3a  |nsitions":{},"f:|
00000140  72 65 6e 65 77 54 69 6d  65 22 3a 7b 7d 7d 7d 42  |renewTime":{}}}B|
00000150  00 12 58 0a 37 6b 69 6e  64 2d 63 6f 6e 74 72 6f  |..X.7kind-contro|
00000160  6c 2d 70 6c 61 6e 65 5f  30 64 32 66 61 66 39 33  |l-plane_0d2faf93|
00000170  2d 34 61 30 62 2d 34 66  32 38 2d 38 33 64 33 2d  |-4a0b-4f28-83d3-|
00000180  35 62 35 62 62 66 61 31  65 36 31 30 10 0f 1a 0c  |5b5bbfa1e610....|
00000190  08 f7 a5 86 a2 06 10 b9  84 b7 94 03 22 0b 08 9b  |............"...|
000001a0  ed bd a2 06 10 cb e1 f0  1d 28 0a 1a 00 22 00     |.........(...".|
I0501 08:21:47.069502       1 round_trippers.go:466] curl -v -XPUT  -H "Accept: application/vnd.kubernetes.protobuf, */*" -H "Content-Type: application/vnd.kubernetes.protobuf" -H "User-Agent: kube-scheduler/v1.24.7 (linux/amd64) kubernetes/e6f3597/leader-election" 'https://172.18.0.2:6443/apis/coordination.k8s.io/v1/namespaces/kube-system/leases/kube-scheduler?timeout=5s'
I0501 08:21:47.076239       1 round_trippers.go:553] PUT https://172.18.0.2:6443/apis/coordination.k8s.io/v1/namespaces/kube-system/leases/kube-scheduler?timeout=5s 200 OK in 6 milliseconds
I0501 08:21:47.076284       1 round_trippers.go:570] HTTP Statistics: GetConnection 0 ms ServerProcessing 6 ms Duration 6 ms
I0501 08:21:47.076300       1 round_trippers.go:577] Response Headers:
I0501 08:21:47.076317       1 round_trippers.go:580]     Content-Type: application/vnd.kubernetes.protobuf
I0501 08:21:47.076332       1 round_trippers.go:580]     X-Kubernetes-Pf-Flowschema-Uid: 493426e8-0f6d-4ea6-bc2c-2d926c7e3221
I0501 08:21:47.076346       1 round_trippers.go:580]     X-Kubernetes-Pf-Prioritylevel-Uid: afabb116-6975-46b8-863b-3258bec9e1ea
I0501 08:21:47.076360       1 round_trippers.go:580]     Content-Length: 431
I0501 08:21:47.076387       1 round_trippers.go:580]     Date: Mon, 01 May 2023 08:21:47 GMT
I0501 08:21:47.076402       1 round_trippers.go:580]     Audit-Id: f9d21976-5327-4e4e-a7a7-88e9a4fb8961
I0501 08:21:47.076417       1 round_trippers.go:580]     Cache-Control: no-cache, private
I0501 08:21:47.076491       1 request.go:1152] Response Body:
00000000  6b 38 73 00 0a 1f 0a 16  63 6f 6f 72 64 69 6e 61  |k8s.....coordina|
00000010  74 69 6f 6e 2e 6b 38 73  2e 69 6f 2f 76 31 12 05  |tion.k8s.io/v1..|
00000020  4c 65 61 73 65 12 83 03  0a a6 02 0a 0e 6b 75 62  |Lease........kub|
00000030  65 2d 73 63 68 65 64 75  6c 65 72 12 00 1a 0b 6b  |e-scheduler....k|
00000040  75 62 65 2d 73 79 73 74  65 6d 22 00 2a 24 36 61  |ube-system".*$6a|
00000050  30 65 32 30 33 66 2d 65  32 38 30 2d 34 36 61 30  |0e203f-e280-46a0|
00000060  2d 39 35 33 62 2d 35 66  62 64 63 37 38 61 63 38  |-953b-5fbdc78ac8|
00000070  36 65 32 07 32 32 36 38  36 34 39 38 00 42 08 08  |6e2.22686498.B..|
00000080  b1 b2 e2 a1 06 10 00 7a  00 8a 01 c4 01 0a 0e 6b  |.......z.......k|
00000090  75 62 65 2d 73 63 68 65  64 75 6c 65 72 12 06 55  |ube-scheduler..U|
000000a0  70 64 61 74 65 1a 16 63  6f 6f 72 64 69 6e 61 74  |pdate..coordinat|
000000b0  69 6f 6e 2e 6b 38 73 2e  69 6f 2f 76 31 22 08 08  |ion.k8s.io/v1"..|
000000c0  b1 b2 e2 a1 06 10 00 32  08 46 69 65 6c 64 73 56  |.......2.FieldsV|
000000d0  31 3a 7c 0a 7a 7b 22 66  3a 73 70 65 63 22 3a 7b  |1:|.z{"f:spec":{|
000000e0  22 66 3a 61 63 71 75 69  72 65 54 69 6d 65 22 3a  |"f:acquireTime":|
000000f0  7b 7d 2c 22 66 3a 68 6f  6c 64 65 72 49 64 65 6e  |{},"f:holderIden|
00000100  74 69 74 79 22 3a 7b 7d  2c 22 66 3a 6c 65 61 73  |tity":{},"f:leas|
00000110  65 44 75 72 61 74 69 6f  6e 53 65 63 6f 6e 64 73  |eDurationSeconds|
00000120  22 3a 7b 7d 2c 22 66 3a  6c 65 61 73 65 54 72 61  |":{},"f:leaseTra|
00000130  6e 73 69 74 69 6f 6e 73  22 3a 7b 7d 2c 22 66 3a  |nsitions":{},"f:|
00000140  72 65 6e 65 77 54 69 6d  65 22 3a 7b 7d 7d 7d 42  |renewTime":{}}}B|
00000150  00 12 58 0a 37 6b 69 6e  64 2d 63 6f 6e 74 72 6f  |..X.7kind-contro|
00000160  6c 2d 70 6c 61 6e 65 5f  30 64 32 66 61 66 39 33  |l-plane_0d2faf93|
00000170  2d 34 61 30 62 2d 34 66  32 38 2d 38 33 64 33 2d  |-4a0b-4f28-83d3-|
00000180  35 62 35 62 62 66 61 31  65 36 31 30 10 0f 1a 0c  |5b5bbfa1e610....|
00000190  08 f7 a5 86 a2 06 10 b9  84 b7 94 03 22 0b 08 9b  |............"...|
000001a0  ed bd a2 06 10 cb e1 f0  1d 28 0a 1a 00 22 00     |.........(...".|
I0501 08:21:47.076629       1 leaderelection.go:278] successfully renewed lease kube-system/kube-scheduler
I0501 08:21:47.239900       1 eventhandlers.go:204] "Update event for scheduled pod" pod="default/nginx-deployment-66f58bff7c-x8rw9"
I0501 08:21:47.320669       1 eventhandlers.go:204] "Update event for scheduled pod" pod="default/nginx-deployment-66f58bff7c-zr9m5"
I0501 08:21:47.320745       1 eventhandlers.go:204] "Update event for scheduled pod" pod="default/nginx-deployment-66f58bff7c-l7r5r"
I0501 08:21:49.001890       1 eventhandlers.go:204] "Update event for scheduled pod" pod="default/nginx-deployment-66f58bff7c-x8rw9"
I0501 08:21:49.078067       1 round_trippers.go:466] curl -v -XGET  -H "Accept: application/vnd.kubernetes.protobuf, */*" -H "User-Agent: kube-scheduler/v1.24.7 (linux/amd64) kubernetes/e6f3597/leader-election" 'https://172.18.0.2:6443/apis/coordination.k8s.io/v1/namespaces/kube-system/leases/kube-scheduler?timeout=5s'
I0501 08:21:49.138136       1 round_trippers.go:553] GET https://172.18.0.2:6443/apis/coordination.k8s.io/v1/namespaces/kube-system/leases/kube-scheduler?timeout=5s 200 OK in 59 milliseconds
I0501 08:21:49.138196       1 round_trippers.go:570] HTTP Statistics: GetConnection 0 ms ServerProcessing 55 ms Duration 59 ms
I0501 08:21:49.138213       1 round_trippers.go:577] Response Headers:
I0501 08:21:49.138233       1 round_trippers.go:580]     Cache-Control: no-cache, private
I0501 08:21:49.138249       1 round_trippers.go:580]     Content-Type: application/vnd.kubernetes.protobuf
I0501 08:21:49.138265       1 round_trippers.go:580]     X-Kubernetes-Pf-Flowschema-Uid: 493426e8-0f6d-4ea6-bc2c-2d926c7e3221
I0501 08:21:49.138280       1 round_trippers.go:580]     X-Kubernetes-Pf-Prioritylevel-Uid: afabb116-6975-46b8-863b-3258bec9e1ea
I0501 08:21:49.138295       1 round_trippers.go:580]     Content-Length: 431
I0501 08:21:49.138310       1 round_trippers.go:580]     Date: Mon, 01 May 2023 08:21:49 GMT
I0501 08:21:49.138371       1 round_trippers.go:580]     Audit-Id: d0003b6b-b05d-47b0-9fcb-3a9f31294f93
I0501 08:21:49.138516       1 request.go:1152] Response Body:
00000000  6b 38 73 00 0a 1f 0a 16  63 6f 6f 72 64 69 6e 61  |k8s.....coordina|
00000010  74 69 6f 6e 2e 6b 38 73  2e 69 6f 2f 76 31 12 05  |tion.k8s.io/v1..|
00000020  4c 65 61 73 65 12 83 03  0a a6 02 0a 0e 6b 75 62  |Lease........kub|
00000030  65 2d 73 63 68 65 64 75  6c 65 72 12 00 1a 0b 6b  |e-scheduler....k|
00000040  75 62 65 2d 73 79 73 74  65 6d 22 00 2a 24 36 61  |ube-system".*$6a|
00000050  30 65 32 30 33 66 2d 65  32 38 30 2d 34 36 61 30  |0e203f-e280-46a0|
00000060  2d 39 35 33 62 2d 35 66  62 64 63 37 38 61 63 38  |-953b-5fbdc78ac8|
00000070  36 65 32 07 32 32 36 38  36 34 39 38 00 42 08 08  |6e2.22686498.B..|
00000080  b1 b2 e2 a1 06 10 00 7a  00 8a 01 c4 01 0a 0e 6b  |.......z.......k|
00000090  75 62 65 2d 73 63 68 65  64 75 6c 65 72 12 06 55  |ube-scheduler..U|
000000a0  70 64 61 74 65 1a 16 63  6f 6f 72 64 69 6e 61 74  |pdate..coordinat|
000000b0  69 6f 6e 2e 6b 38 73 2e  69 6f 2f 76 31 22 08 08  |ion.k8s.io/v1"..|
000000c0  b1 b2 e2 a1 06 10 00 32  08 46 69 65 6c 64 73 56  |.......2.FieldsV|
000000d0  31 3a 7c 0a 7a 7b 22 66  3a 73 70 65 63 22 3a 7b  |1:|.z{"f:spec":{|
000000e0  22 66 3a 61 63 71 75 69  72 65 54 69 6d 65 22 3a  |"f:acquireTime":|
000000f0  7b 7d 2c 22 66 3a 68 6f  6c 64 65 72 49 64 65 6e  |{},"f:holderIden|
00000100  74 69 74 79 22 3a 7b 7d  2c 22 66 3a 6c 65 61 73  |tity":{},"f:leas|
00000110  65 44 75 72 61 74 69 6f  6e 53 65 63 6f 6e 64 73  |eDurationSeconds|
00000120  22 3a 7b 7d 2c 22 66 3a  6c 65 61 73 65 54 72 61  |":{},"f:leaseTra|
00000130  6e 73 69 74 69 6f 6e 73  22 3a 7b 7d 2c 22 66 3a  |nsitions":{},"f:|
00000140  72 65 6e 65 77 54 69 6d  65 22 3a 7b 7d 7d 7d 42  |renewTime":{}}}B|
00000150  00 12 58 0a 37 6b 69 6e  64 2d 63 6f 6e 74 72 6f  |..X.7kind-contro|
00000160  6c 2d 70 6c 61 6e 65 5f  30 64 32 66 61 66 39 33  |l-plane_0d2faf93|
00000170  2d 34 61 30 62 2d 34 66  32 38 2d 38 33 64 33 2d  |-4a0b-4f28-83d3-|
00000180  35 62 35 62 62 66 61 31  65 36 31 30 10 0f 1a 0c  |5b5bbfa1e610....|
00000190  08 f7 a5 86 a2 06 10 b9  84 b7 94 03 22 0b 08 9b  |............"...|
000001a0  ed bd a2 06 10 cb e1 f0  1d 28 0a 1a 00 22 00     |.........(...".|
I0501 08:21:49.139220       1 request.go:1152] Request Body:
00000000  6b 38 73 00 0a 1f 0a 16  63 6f 6f 72 64 69 6e 61  |k8s.....coordina|
00000010  74 69 6f 6e 2e 6b 38 73  2e 69 6f 2f 76 31 12 05  |tion.k8s.io/v1..|
00000020  4c 65 61 73 65 12 83 03  0a a6 02 0a 0e 6b 75 62  |Lease........kub|
00000030  65 2d 73 63 68 65 64 75  6c 65 72 12 00 1a 0b 6b  |e-scheduler....k|
00000040  75 62 65 2d 73 79 73 74  65 6d 22 00 2a 24 36 61  |ube-system".*$6a|
00000050  30 65 32 30 33 66 2d 65  32 38 30 2d 34 36 61 30  |0e203f-e280-46a0|
00000060  2d 39 35 33 62 2d 35 66  62 64 63 37 38 61 63 38  |-953b-5fbdc78ac8|
00000070  36 65 32 07 32 32 36 38  36 34 39 38 00 42 08 08  |6e2.22686498.B..|
00000080  b1 b2 e2 a1 06 10 00 7a  00 8a 01 c4 01 0a 0e 6b  |.......z.......k|
00000090  75 62 65 2d 73 63 68 65  64 75 6c 65 72 12 06 55  |ube-scheduler..U|
000000a0  70 64 61 74 65 1a 16 63  6f 6f 72 64 69 6e 61 74  |pdate..coordinat|
000000b0  69 6f 6e 2e 6b 38 73 2e  69 6f 2f 76 31 22 08 08  |ion.k8s.io/v1"..|
000000c0  b1 b2 e2 a1 06 10 00 32  08 46 69 65 6c 64 73 56  |.......2.FieldsV|
000000d0  31 3a 7c 0a 7a 7b 22 66  3a 73 70 65 63 22 3a 7b  |1:|.z{"f:spec":{|
000000e0  22 66 3a 61 63 71 75 69  72 65 54 69 6d 65 22 3a  |"f:acquireTime":|
000000f0  7b 7d 2c 22 66 3a 68 6f  6c 64 65 72 49 64 65 6e  |{},"f:holderIden|
00000100  74 69 74 79 22 3a 7b 7d  2c 22 66 3a 6c 65 61 73  |tity":{},"f:leas|
00000110  65 44 75 72 61 74 69 6f  6e 53 65 63 6f 6e 64 73  |eDurationSeconds|
00000120  22 3a 7b 7d 2c 22 66 3a  6c 65 61 73 65 54 72 61  |":{},"f:leaseTra|
00000130  6e 73 69 74 69 6f 6e 73  22 3a 7b 7d 2c 22 66 3a  |nsitions":{},"f:|
00000140  72 65 6e 65 77 54 69 6d  65 22 3a 7b 7d 7d 7d 42  |renewTime":{}}}B|
00000150  00 12 58 0a 37 6b 69 6e  64 2d 63 6f 6e 74 72 6f  |..X.7kind-contro|
00000160  6c 2d 70 6c 61 6e 65 5f  30 64 32 66 61 66 39 33  |l-plane_0d2faf93|
00000170  2d 34 61 30 62 2d 34 66  32 38 2d 38 33 64 33 2d  |-4a0b-4f28-83d3-|
00000180  35 62 35 62 62 66 61 31  65 36 31 30 10 0f 1a 0c  |5b5bbfa1e610....|
00000190  08 f7 a5 86 a2 06 10 b9  84 b7 94 03 22 0b 08 9d  |............"...|
000001a0  ed bd a2 06 10 d3 bd 8a  25 28 0a 1a 00 22 00     |........%(...".|
I0501 08:21:49.139395       1 round_trippers.go:466] curl -v -XPUT  -H "Content-Type: application/vnd.kubernetes.protobuf" -H "Accept: application/vnd.kubernetes.protobuf, */*" -H "User-Agent: kube-scheduler/v1.24.7 (linux/amd64) kubernetes/e6f3597/leader-election" 'https://172.18.0.2:6443/apis/coordination.k8s.io/v1/namespaces/kube-system/leases/kube-scheduler?timeout=5s'
I0501 08:21:49.140140       1 eventhandlers.go:204] "Update event for scheduled pod" pod="default/nginx-deployment-66f58bff7c-l7r5r"
I0501 08:21:49.142586       1 eventhandlers.go:204] "Update event for scheduled pod" pod="default/nginx-deployment-66f58bff7c-x8rw9"
I0501 08:21:49.313177       1 round_trippers.go:553] PUT https://172.18.0.2:6443/apis/coordination.k8s.io/v1/namespaces/kube-system/leases/kube-scheduler?timeout=5s 200 OK in 173 milliseconds
I0501 08:21:49.313317       1 round_trippers.go:570] HTTP Statistics: GetConnection 0 ms ServerProcessing 173 ms Duration 173 ms
I0501 08:21:49.313348       1 round_trippers.go:577] Response Headers:
I0501 08:21:49.313416       1 round_trippers.go:580]     Content-Length: 431
I0501 08:21:49.313465       1 round_trippers.go:580]     Date: Mon, 01 May 2023 08:21:49 GMT
I0501 08:21:49.313496       1 round_trippers.go:580]     Audit-Id: 5f18e3c3-3b13-4f9e-99af-c198a78ed91c
I0501 08:21:49.313532       1 round_trippers.go:580]     Cache-Control: no-cache, private
I0501 08:21:49.313563       1 round_trippers.go:580]     Content-Type: application/vnd.kubernetes.protobuf
I0501 08:21:49.313593       1 round_trippers.go:580]     X-Kubernetes-Pf-Flowschema-Uid: 493426e8-0f6d-4ea6-bc2c-2d926c7e3221
I0501 08:21:49.313758       1 round_trippers.go:580]     X-Kubernetes-Pf-Prioritylevel-Uid: afabb116-6975-46b8-863b-3258bec9e1ea
I0501 08:21:49.313944       1 request.go:1152] Response Body:
00000000  6b 38 73 00 0a 1f 0a 16  63 6f 6f 72 64 69 6e 61  |k8s.....coordina|
00000010  74 69 6f 6e 2e 6b 38 73  2e 69 6f 2f 76 31 12 05  |tion.k8s.io/v1..|
00000020  4c 65 61 73 65 12 83 03  0a a6 02 0a 0e 6b 75 62  |Lease........kub|
00000030  65 2d 73 63 68 65 64 75  6c 65 72 12 00 1a 0b 6b  |e-scheduler....k|
00000040  75 62 65 2d 73 79 73 74  65 6d 22 00 2a 24 36 61  |ube-system".*$6a|
00000050  30 65 32 30 33 66 2d 65  32 38 30 2d 34 36 61 30  |0e203f-e280-46a0|
00000060  2d 39 35 33 62 2d 35 66  62 64 63 37 38 61 63 38  |-953b-5fbdc78ac8|
00000070  36 65 32 07 32 32 36 38  36 37 32 38 00 42 08 08  |6e2.22686728.B..|
00000080  b1 b2 e2 a1 06 10 00 7a  00 8a 01 c4 01 0a 0e 6b  |.......z.......k|
00000090  75 62 65 2d 73 63 68 65  64 75 6c 65 72 12 06 55  |ube-scheduler..U|
000000a0  70 64 61 74 65 1a 16 63  6f 6f 72 64 69 6e 61 74  |pdate..coordinat|
000000b0  69 6f 6e 2e 6b 38 73 2e  69 6f 2f 76 31 22 08 08  |ion.k8s.io/v1"..|
000000c0  b1 b2 e2 a1 06 10 00 32  08 46 69 65 6c 64 73 56  |.......2.FieldsV|
000000d0  31 3a 7c 0a 7a 7b 22 66  3a 73 70 65 63 22 3a 7b  |1:|.z{"f:spec":{|
000000e0  22 66 3a 61 63 71 75 69  72 65 54 69 6d 65 22 3a  |"f:acquireTime":|
000000f0  7b 7d 2c 22 66 3a 68 6f  6c 64 65 72 49 64 65 6e  |{},"f:holderIden|
00000100  74 69 74 79 22 3a 7b 7d  2c 22 66 3a 6c 65 61 73  |tity":{},"f:leas|
00000110  65 44 75 72 61 74 69 6f  6e 53 65 63 6f 6e 64 73  |eDurationSeconds|
00000120  22 3a 7b 7d 2c 22 66 3a  6c 65 61 73 65 54 72 61  |":{},"f:leaseTra|
00000130  6e 73 69 74 69 6f 6e 73  22 3a 7b 7d 2c 22 66 3a  |nsitions":{},"f:|
00000140  72 65 6e 65 77 54 69 6d  65 22 3a 7b 7d 7d 7d 42  |renewTime":{}}}B|
00000150  00 12 58 0a 37 6b 69 6e  64 2d 63 6f 6e 74 72 6f  |..X.7kind-contro|
00000160  6c 2d 70 6c 61 6e 65 5f  30 64 32 66 61 66 39 33  |l-plane_0d2faf93|
00000170  2d 34 61 30 62 2d 34 66  32 38 2d 38 33 64 33 2d  |-4a0b-4f28-83d3-|
00000180  35 62 35 62 62 66 61 31  65 36 31 30 10 0f 1a 0c  |5b5bbfa1e610....|
00000190  08 f7 a5 86 a2 06 10 b9  84 b7 94 03 22 0b 08 9d  |............"...|
000001a0  ed bd a2 06 10 d3 bd 8a  25 28 0a 1a 00 22 00     |........%(...".|
I0501 08:21:49.314174       1 leaderelection.go:278] successfully renewed lease kube-system/kube-scheduler
I0501 08:21:49.317318       1 eventhandlers.go:229] "Delete event for scheduled pod" pod="default/nginx-deployment-66f58bff7c-x8rw9"
I0501 08:21:49.343968       1 eventhandlers.go:204] "Update event for scheduled pod" pod="default/nginx-deployment-66f58bff7c-l7r5r"
I0501 08:21:49.504679       1 eventhandlers.go:229] "Delete event for scheduled pod" pod="default/nginx-deployment-66f58bff7c-l7r5r"
I0501 08:21:49.525661       1 eventhandlers.go:204] "Update event for scheduled pod" pod="default/nginx-deployment-66f58bff7c-zr9m5"
I0501 08:21:49.565984       1 eventhandlers.go:204] "Update event for scheduled pod" pod="default/nginx-deployment-66f58bff7c-zr9m5"
I0501 08:21:49.653319       1 eventhandlers.go:229] "Delete event for scheduled pod" pod="default/nginx-deployment-66f58bff7c-zr9m5"
I0501 08:21:49.668198       1 pathrecorder.go:241] kube-scheduler: "/healthz" satisfied by exact match
I0501 08:21:49.668349       1 httplog.go:131] "HTTP" verb="GET" URI="/healthz" latency="240.811µs" userAgent="kube-probe/1.24" audit-ID="" srcIP="127.0.0.1:59596" resp=200
I0501 08:21:51.315640       1 round_trippers.go:466] curl -v -XGET  -H "Accept: application/vnd.kubernetes.protobuf, */*" -H "User-Agent: kube-scheduler/v1.24.7 (linux/amd64) kubernetes/e6f3597/leader-election" 'https://172.18.0.2:6443/apis/coordination.k8s.io/v1/namespaces/kube-system/leases/kube-scheduler?timeout=5s'
I0501 08:21:51.324700       1 round_trippers.go:553] GET https://172.18.0.2:6443/apis/coordination.k8s.io/v1/namespaces/kube-system/leases/kube-scheduler?timeout=5s 200 OK in 8 milliseconds
I0501 08:21:51.324783       1 round_trippers.go:570] HTTP Statistics: GetConnection 0 ms ServerProcessing 8 ms Duration 8 ms
I0501 08:21:51.324833       1 round_trippers.go:577] Response Headers:
I0501 08:21:51.324869       1 round_trippers.go:580]     Cache-Control: no-cache, private
I0501 08:21:51.324897       1 round_trippers.go:580]     Content-Type: application/vnd.kubernetes.protobuf
I0501 08:21:51.324928       1 round_trippers.go:580]     X-Kubernetes-Pf-Flowschema-Uid: 493426e8-0f6d-4ea6-bc2c-2d926c7e3221
I0501 08:21:51.324966       1 round_trippers.go:580]     X-Kubernetes-Pf-Prioritylevel-Uid: afabb116-6975-46b8-863b-3258bec9e1ea
I0501 08:21:51.325008       1 round_trippers.go:580]     Content-Length: 431
I0501 08:21:51.325044       1 round_trippers.go:580]     Date: Mon, 01 May 2023 08:21:51 GMT
I0501 08:21:51.325081       1 round_trippers.go:580]     Audit-Id: a8d644ba-a447-4bc0-bc1c-cf46d66b5270
I0501 08:21:51.325204       1 request.go:1152] Response Body:
00000000  6b 38 73 00 0a 1f 0a 16  63 6f 6f 72 64 69 6e 61  |k8s.....coordina|
00000010  74 69 6f 6e 2e 6b 38 73  2e 69 6f 2f 76 31 12 05  |tion.k8s.io/v1..|
00000020  4c 65 61 73 65 12 83 03  0a a6 02 0a 0e 6b 75 62  |Lease........kub|
00000030  65 2d 73 63 68 65 64 75  6c 65 72 12 00 1a 0b 6b  |e-scheduler....k|
00000040  75 62 65 2d 73 79 73 74  65 6d 22 00 2a 24 36 61  |ube-system".*$6a|
00000050  30 65 32 30 33 66 2d 65  32 38 30 2d 34 36 61 30  |0e203f-e280-46a0|
00000060  2d 39 35 33 62 2d 35 66  62 64 63 37 38 61 63 38  |-953b-5fbdc78ac8|
00000070  36 65 32 07 32 32 36 38  36 37 32 38 00 42 08 08  |6e2.22686728.B..|
00000080  b1 b2 e2 a1 06 10 00 7a  00 8a 01 c4 01 0a 0e 6b  |.......z.......k|
00000090  75 62 65 2d 73 63 68 65  64 75 6c 65 72 12 06 55  |ube-scheduler..U|
000000a0  70 64 61 74 65 1a 16 63  6f 6f 72 64 69 6e 61 74  |pdate..coordinat|
000000b0  69 6f 6e 2e 6b 38 73 2e  69 6f 2f 76 31 22 08 08  |ion.k8s.io/v1"..|
000000c0  b1 b2 e2 a1 06 10 00 32  08 46 69 65 6c 64 73 56  |.......2.FieldsV|
000000d0  31 3a 7c 0a 7a 7b 22 66  3a 73 70 65 63 22 3a 7b  |1:|.z{"f:spec":{|
000000e0  22 66 3a 61 63 71 75 69  72 65 54 69 6d 65 22 3a  |"f:acquireTime":|
000000f0  7b 7d 2c 22 66 3a 68 6f  6c 64 65 72 49 64 65 6e  |{},"f:holderIden|
00000100  74 69 74 79 22 3a 7b 7d  2c 22 66 3a 6c 65 61 73  |tity":{},"f:leas|
00000110  65 44 75 72 61 74 69 6f  6e 53 65 63 6f 6e 64 73  |eDurationSeconds|
00000120  22 3a 7b 7d 2c 22 66 3a  6c 65 61 73 65 54 72 61  |":{},"f:leaseTra|
00000130  6e 73 69 74 69 6f 6e 73  22 3a 7b 7d 2c 22 66 3a  |nsitions":{},"f:|
00000140  72 65 6e 65 77 54 69 6d  65 22 3a 7b 7d 7d 7d 42  |renewTime":{}}}B|
00000150  00 12 58 0a 37 6b 69 6e  64 2d 63 6f 6e 74 72 6f  |..X.7kind-contro|
00000160  6c 2d 70 6c 61 6e 65 5f  30 64 32 66 61 66 39 33  |l-plane_0d2faf93|
00000170  2d 34 61 30 62 2d 34 66  32 38 2d 38 33 64 33 2d  |-4a0b-4f28-83d3-|
00000180  35 62 35 62 62 66 61 31  65 36 31 30 10 0f 1a 0c  |5b5bbfa1e610....|
00000190  08 f7 a5 86 a2 06 10 b9  84 b7 94 03 22 0b 08 9d  |............"...|
000001a0  ed bd a2 06 10 d3 bd 8a  25 28 0a 1a 00 22 00     |........%(...".|
I0501 08:21:51.325603       1 request.go:1152] Request Body:
00000000  6b 38 73 00 0a 1f 0a 16  63 6f 6f 72 64 69 6e 61  |k8s.....coordina|
00000010  74 69 6f 6e 2e 6b 38 73  2e 69 6f 2f 76 31 12 05  |tion.k8s.io/v1..|
00000020  4c 65 61 73 65 12 84 03  0a a6 02 0a 0e 6b 75 62  |Lease........kub|
00000030  65 2d 73 63 68 65 64 75  6c 65 72 12 00 1a 0b 6b  |e-scheduler....k|
00000040  75 62 65 2d 73 79 73 74  65 6d 22 00 2a 24 36 61  |ube-system".*$6a|
00000050  30 65 32 30 33 66 2d 65  32 38 30 2d 34 36 61 30  |0e203f-e280-46a0|
00000060  2d 39 35 33 62 2d 35 66  62 64 63 37 38 61 63 38  |-953b-5fbdc78ac8|
00000070  36 65 32 07 32 32 36 38  36 37 32 38 00 42 08 08  |6e2.22686728.B..|
00000080  b1 b2 e2 a1 06 10 00 7a  00 8a 01 c4 01 0a 0e 6b  |.......z.......k|
00000090  75 62 65 2d 73 63 68 65  64 75 6c 65 72 12 06 55  |ube-scheduler..U|
000000a0  70 64 61 74 65 1a 16 63  6f 6f 72 64 69 6e 61 74  |pdate..coordinat|
000000b0  69 6f 6e 2e 6b 38 73 2e  69 6f 2f 76 31 22 08 08  |ion.k8s.io/v1"..|
000000c0  b1 b2 e2 a1 06 10 00 32  08 46 69 65 6c 64 73 56  |.......2.FieldsV|
000000d0  31 3a 7c 0a 7a 7b 22 66  3a 73 70 65 63 22 3a 7b  |1:|.z{"f:spec":{|
000000e0  22 66 3a 61 63 71 75 69  72 65 54 69 6d 65 22 3a  |"f:acquireTime":|
000000f0  7b 7d 2c 22 66 3a 68 6f  6c 64 65 72 49 64 65 6e  |{},"f:holderIden|
00000100  74 69 74 79 22 3a 7b 7d  2c 22 66 3a 6c 65 61 73  |tity":{},"f:leas|
00000110  65 44 75 72 61 74 69 6f  6e 53 65 63 6f 6e 64 73  |eDurationSeconds|
00000120  22 3a 7b 7d 2c 22 66 3a  6c 65 61 73 65 54 72 61  |":{},"f:leaseTra|
00000130  6e 73 69 74 69 6f 6e 73  22 3a 7b 7d 2c 22 66 3a  |nsitions":{},"f:|
00000140  72 65 6e 65 77 54 69 6d  65 22 3a 7b 7d 7d 7d 42  |renewTime":{}}}B|
00000150  00 12 59 0a 37 6b 69 6e  64 2d 63 6f 6e 74 72 6f  |..Y.7kind-contro|
00000160  6c 2d 70 6c 61 6e 65 5f  30 64 32 66 61 66 39 33  |l-plane_0d2faf93|
00000170  2d 34 61 30 62 2d 34 66  32 38 2d 38 33 64 33 2d  |-4a0b-4f28-83d3-|
00000180  35 62 35 62 62 66 61 31  65 36 31 30 10 0f 1a 0c  |5b5bbfa1e610....|
00000190  08 f7 a5 86 a2 06 10 b9  84 b7 94 03 22 0c 08 9f  |............"...|
000001a0  ed bd a2 06 10 8e cf ae  96 01 28 0a 1a 00 22 00  |..........(...".|
I0501 08:21:51.325911       1 round_trippers.go:466] curl -v -XPUT  -H "Accept: application/vnd.kubernetes.protobuf, */*" -H "Content-Type: application/vnd.kubernetes.protobuf" -H "User-Agent: kube-scheduler/v1.24.7 (linux/amd64) kubernetes/e6f3597/leader-election" 'https://172.18.0.2:6443/apis/coordination.k8s.io/v1/namespaces/kube-system/leases/kube-scheduler?timeout=5s'
I0501 08:21:51.332409       1 round_trippers.go:553] PUT https://172.18.0.2:6443/apis/coordination.k8s.io/v1/namespaces/kube-system/leases/kube-scheduler?timeout=5s 200 OK in 6 milliseconds
I0501 08:21:51.332479       1 round_trippers.go:570] HTTP Statistics: GetConnection 0 ms ServerProcessing 5 ms Duration 6 ms
I0501 08:21:51.332522       1 round_trippers.go:577] Response Headers:
I0501 08:21:51.332556       1 round_trippers.go:580]     Cache-Control: no-cache, private
I0501 08:21:51.332587       1 round_trippers.go:580]     Content-Type: application/vnd.kubernetes.protobuf
I0501 08:21:51.332633       1 round_trippers.go:580]     X-Kubernetes-Pf-Flowschema-Uid: 493426e8-0f6d-4ea6-bc2c-2d926c7e3221
I0501 08:21:51.332655       1 round_trippers.go:580]     X-Kubernetes-Pf-Prioritylevel-Uid: afabb116-6975-46b8-863b-3258bec9e1ea
I0501 08:21:51.332689       1 round_trippers.go:580]     Content-Length: 432
I0501 08:21:51.332709       1 round_trippers.go:580]     Date: Mon, 01 May 2023 08:21:51 GMT
I0501 08:21:51.332788       1 round_trippers.go:580]     Audit-Id: 2cfd2394-3339-496a-a8a8-ff35c69c006f
I0501 08:21:51.333026       1 request.go:1152] Response Body:
00000000  6b 38 73 00 0a 1f 0a 16  63 6f 6f 72 64 69 6e 61  |k8s.....coordina|
00000010  74 69 6f 6e 2e 6b 38 73  2e 69 6f 2f 76 31 12 05  |tion.k8s.io/v1..|
00000020  4c 65 61 73 65 12 84 03  0a a6 02 0a 0e 6b 75 62  |Lease........kub|
00000030  65 2d 73 63 68 65 64 75  6c 65 72 12 00 1a 0b 6b  |e-scheduler....k|
00000040  75 62 65 2d 73 79 73 74  65 6d 22 00 2a 24 36 61  |ube-system".*$6a|
00000050  30 65 32 30 33 66 2d 65  32 38 30 2d 34 36 61 30  |0e203f-e280-46a0|
00000060  2d 39 35 33 62 2d 35 66  62 64 63 37 38 61 63 38  |-953b-5fbdc78ac8|
00000070  36 65 32 07 32 32 36 38  36 38 31 38 00 42 08 08  |6e2.22686818.B..|
00000080  b1 b2 e2 a1 06 10 00 7a  00 8a 01 c4 01 0a 0e 6b  |.......z.......k|
00000090  75 62 65 2d 73 63 68 65  64 75 6c 65 72 12 06 55  |ube-scheduler..U|
000000a0  70 64 61 74 65 1a 16 63  6f 6f 72 64 69 6e 61 74  |pdate..coordinat|
000000b0  69 6f 6e 2e 6b 38 73 2e  69 6f 2f 76 31 22 08 08  |ion.k8s.io/v1"..|
000000c0  b1 b2 e2 a1 06 10 00 32  08 46 69 65 6c 64 73 56  |.......2.FieldsV|
000000d0  31 3a 7c 0a 7a 7b 22 66  3a 73 70 65 63 22 3a 7b  |1:|.z{"f:spec":{|
000000e0  22 66 3a 61 63 71 75 69  72 65 54 69 6d 65 22 3a  |"f:acquireTime":|
000000f0  7b 7d 2c 22 66 3a 68 6f  6c 64 65 72 49 64 65 6e  |{},"f:holderIden|
00000100  74 69 74 79 22 3a 7b 7d  2c 22 66 3a 6c 65 61 73  |tity":{},"f:leas|
00000110  65 44 75 72 61 74 69 6f  6e 53 65 63 6f 6e 64 73  |eDurationSeconds|
00000120  22 3a 7b 7d 2c 22 66 3a  6c 65 61 73 65 54 72 61  |":{},"f:leaseTra|
00000130  6e 73 69 74 69 6f 6e 73  22 3a 7b 7d 2c 22 66 3a  |nsitions":{},"f:|
00000140  72 65 6e 65 77 54 69 6d  65 22 3a 7b 7d 7d 7d 42  |renewTime":{}}}B|
00000150  00 12 59 0a 37 6b 69 6e  64 2d 63 6f 6e 74 72 6f  |..Y.7kind-contro|
00000160  6c 2d 70 6c 61 6e 65 5f  30 64 32 66 61 66 39 33  |l-plane_0d2faf93|
00000170  2d 34 61 30 62 2d 34 66  32 38 2d 38 33 64 33 2d  |-4a0b-4f28-83d3-|
00000180  35 62 35 62 62 66 61 31  65 36 31 30 10 0f 1a 0c  |5b5bbfa1e610....|
00000190  08 f7 a5 86 a2 06 10 b9  84 b7 94 03 22 0c 08 9f  |............"...|
000001a0  ed bd a2 06 10 8e cf ae  96 01 28 0a 1a 00 22 00  |..........(...".|
I0501 08:21:51.333602       1 leaderelection.go:278] successfully renewed lease kube-system/kube-scheduler
I0501 08:21:53.334475       1 round_trippers.go:466] curl -v -XGET  -H "Accept: application/vnd.kubernetes.protobuf, */*" -H "User-Agent: kube-scheduler/v1.24.7 (linux/amd64) kubernetes/e6f3597/leader-election" 'https://172.18.0.2:6443/apis/coordination.k8s.io/v1/namespaces/kube-system/leases/kube-scheduler?timeout=5s'
I0501 08:21:53.346281       1 round_trippers.go:553] GET https://172.18.0.2:6443/apis/coordination.k8s.io/v1/namespaces/kube-system/leases/kube-scheduler?timeout=5s 200 OK in 11 milliseconds
I0501 08:21:53.346373       1 round_trippers.go:570] HTTP Statistics: GetConnection 0 ms ServerProcessing 11 ms Duration 11 ms
I0501 08:21:53.346468       1 round_trippers.go:577] Response Headers:
I0501 08:21:53.346493       1 round_trippers.go:580]     Audit-Id: d6fced16-dc61-4dfa-a596-dfdbc5fd791c
I0501 08:21:53.346921       1 round_trippers.go:580]     Cache-Control: no-cache, private
I0501 08:21:53.346989       1 round_trippers.go:580]     Content-Type: application/vnd.kubernetes.protobuf
I0501 08:21:53.347029       1 round_trippers.go:580]     X-Kubernetes-Pf-Flowschema-Uid: 493426e8-0f6d-4ea6-bc2c-2d926c7e3221
I0501 08:21:53.347047       1 round_trippers.go:580]     X-Kubernetes-Pf-Prioritylevel-Uid: afabb116-6975-46b8-863b-3258bec9e1ea
I0501 08:21:53.347064       1 round_trippers.go:580]     Content-Length: 432
I0501 08:21:53.347420       1 round_trippers.go:580]     Date: Mon, 01 May 2023 08:21:53 GMT
I0501 08:21:53.347788       1 request.go:1152] Response Body:
00000000  6b 38 73 00 0a 1f 0a 16  63 6f 6f 72 64 69 6e 61  |k8s.....coordina|
00000010  74 69 6f 6e 2e 6b 38 73  2e 69 6f 2f 76 31 12 05  |tion.k8s.io/v1..|
00000020  4c 65 61 73 65 12 84 03  0a a6 02 0a 0e 6b 75 62  |Lease........kub|
00000030  65 2d 73 63 68 65 64 75  6c 65 72 12 00 1a 0b 6b  |e-scheduler....k|
00000040  75 62 65 2d 73 79 73 74  65 6d 22 00 2a 24 36 61  |ube-system".*$6a|
00000050  30 65 32 30 33 66 2d 65  32 38 30 2d 34 36 61 30  |0e203f-e280-46a0|
00000060  2d 39 35 33 62 2d 35 66  62 64 63 37 38 61 63 38  |-953b-5fbdc78ac8|
00000070  36 65 32 07 32 32 36 38  36 38 31 38 00 42 08 08  |6e2.22686818.B..|
00000080  b1 b2 e2 a1 06 10 00 7a  00 8a 01 c4 01 0a 0e 6b  |.......z.......k|
00000090  75 62 65 2d 73 63 68 65  64 75 6c 65 72 12 06 55  |ube-scheduler..U|
000000a0  70 64 61 74 65 1a 16 63  6f 6f 72 64 69 6e 61 74  |pdate..coordinat|
000000b0  69 6f 6e 2e 6b 38 73 2e  69 6f 2f 76 31 22 08 08  |ion.k8s.io/v1"..|
000000c0  b1 b2 e2 a1 06 10 00 32  08 46 69 65 6c 64 73 56  |.......2.FieldsV|
000000d0  31 3a 7c 0a 7a 7b 22 66  3a 73 70 65 63 22 3a 7b  |1:|.z{"f:spec":{|
000000e0  22 66 3a 61 63 71 75 69  72 65 54 69 6d 65 22 3a  |"f:acquireTime":|
000000f0  7b 7d 2c 22 66 3a 68 6f  6c 64 65 72 49 64 65 6e  |{},"f:holderIden|
00000100  74 69 74 79 22 3a 7b 7d  2c 22 66 3a 6c 65 61 73  |tity":{},"f:leas|
00000110  65 44 75 72 61 74 69 6f  6e 53 65 63 6f 6e 64 73  |eDurationSeconds|
00000120  22 3a 7b 7d 2c 22 66 3a  6c 65 61 73 65 54 72 61  |":{},"f:leaseTra|
00000130  6e 73 69 74 69 6f 6e 73  22 3a 7b 7d 2c 22 66 3a  |nsitions":{},"f:|
00000140  72 65 6e 65 77 54 69 6d  65 22 3a 7b 7d 7d 7d 42  |renewTime":{}}}B|
00000150  00 12 59 0a 37 6b 69 6e  64 2d 63 6f 6e 74 72 6f  |..Y.7kind-contro|
00000160  6c 2d 70 6c 61 6e 65 5f  30 64 32 66 61 66 39 33  |l-plane_0d2faf93|
00000170  2d 34 61 30 62 2d 34 66  32 38 2d 38 33 64 33 2d  |-4a0b-4f28-83d3-|
00000180  35 62 35 62 62 66 61 31  65 36 31 30 10 0f 1a 0c  |5b5bbfa1e610....|
00000190  08 f7 a5 86 a2 06 10 b9  84 b7 94 03 22 0c 08 9f  |............"...|
000001a0  ed bd a2 06 10 8e cf ae  96 01 28 0a 1a 00 22 00  |..........(...".|
I0501 08:21:53.348800       1 request.go:1152] Request Body:
00000000  6b 38 73 00 0a 1f 0a 16  63 6f 6f 72 64 69 6e 61  |k8s.....coordina|
00000010  74 69 6f 6e 2e 6b 38 73  2e 69 6f 2f 76 31 12 05  |tion.k8s.io/v1..|
00000020  4c 65 61 73 65 12 84 03  0a a6 02 0a 0e 6b 75 62  |Lease........kub|
00000030  65 2d 73 63 68 65 64 75  6c 65 72 12 00 1a 0b 6b  |e-scheduler....k|
00000040  75 62 65 2d 73 79 73 74  65 6d 22 00 2a 24 36 61  |ube-system".*$6a|
00000050  30 65 32 30 33 66 2d 65  32 38 30 2d 34 36 61 30  |0e203f-e280-46a0|
00000060  2d 39 35 33 62 2d 35 66  62 64 63 37 38 61 63 38  |-953b-5fbdc78ac8|
00000070  36 65 32 07 32 32 36 38  36 38 31 38 00 42 08 08  |6e2.22686818.B..|
00000080  b1 b2 e2 a1 06 10 00 7a  00 8a 01 c4 01 0a 0e 6b  |.......z.......k|
00000090  75 62 65 2d 73 63 68 65  64 75 6c 65 72 12 06 55  |ube-scheduler..U|
000000a0  70 64 61 74 65 1a 16 63  6f 6f 72 64 69 6e 61 74  |pdate..coordinat|
000000b0  69 6f 6e 2e 6b 38 73 2e  69 6f 2f 76 31 22 08 08  |ion.k8s.io/v1"..|
000000c0  b1 b2 e2 a1 06 10 00 32  08 46 69 65 6c 64 73 56  |.......2.FieldsV|
000000d0  31 3a 7c 0a 7a 7b 22 66  3a 73 70 65 63 22 3a 7b  |1:|.z{"f:spec":{|
000000e0  22 66 3a 61 63 71 75 69  72 65 54 69 6d 65 22 3a  |"f:acquireTime":|
000000f0  7b 7d 2c 22 66 3a 68 6f  6c 64 65 72 49 64 65 6e  |{},"f:holderIden|
00000100  74 69 74 79 22 3a 7b 7d  2c 22 66 3a 6c 65 61 73  |tity":{},"f:leas|
00000110  65 44 75 72 61 74 69 6f  6e 53 65 63 6f 6e 64 73  |eDurationSeconds|
00000120  22 3a 7b 7d 2c 22 66 3a  6c 65 61 73 65 54 72 61  |":{},"f:leaseTra|
00000130  6e 73 69 74 69 6f 6e 73  22 3a 7b 7d 2c 22 66 3a  |nsitions":{},"f:|
00000140  72 65 6e 65 77 54 69 6d  65 22 3a 7b 7d 7d 7d 42  |renewTime":{}}}B|
00000150  00 12 59 0a 37 6b 69 6e  64 2d 63 6f 6e 74 72 6f  |..Y.7kind-contro|
00000160  6c 2d 70 6c 61 6e 65 5f  30 64 32 66 61 66 39 33  |l-plane_0d2faf93|
00000170  2d 34 61 30 62 2d 34 66  32 38 2d 38 33 64 33 2d  |-4a0b-4f28-83d3-|
00000180  35 62 35 62 62 66 61 31  65 36 31 30 10 0f 1a 0c  |5b5bbfa1e610....|
00000190  08 f7 a5 86 a2 06 10 b9  84 b7 94 03 22 0c 08 a1  |............"...|
000001a0  ed bd a2 06 10 d0 8d ad  9f 01 28 0a 1a 00 22 00  |..........(...".|
I0501 08:21:53.349559       1 round_trippers.go:466] curl -v -XPUT  -H "Accept: application/vnd.kubernetes.protobuf, */*" -H "Content-Type: application/vnd.kubernetes.protobuf" -H "User-Agent: kube-scheduler/v1.24.7 (linux/amd64) kubernetes/e6f3597/leader-election" 'https://172.18.0.2:6443/apis/coordination.k8s.io/v1/namespaces/kube-system/leases/kube-scheduler?timeout=5s'
I0501 08:21:53.356778       1 round_trippers.go:553] PUT https://172.18.0.2:6443/apis/coordination.k8s.io/v1/namespaces/kube-system/leases/kube-scheduler?timeout=5s 200 OK in 7 milliseconds
I0501 08:21:53.356826       1 round_trippers.go:570] HTTP Statistics: GetConnection 0 ms ServerProcessing 6 ms Duration 7 ms
I0501 08:21:53.356846       1 round_trippers.go:577] Response Headers:
I0501 08:21:53.356869       1 round_trippers.go:580]     Date: Mon, 01 May 2023 08:21:53 GMT
I0501 08:21:53.356890       1 round_trippers.go:580]     Audit-Id: c8f93034-e645-4706-a75b-fd94593c52ea
I0501 08:21:53.356909       1 round_trippers.go:580]     Cache-Control: no-cache, private
I0501 08:21:53.356928       1 round_trippers.go:580]     Content-Type: application/vnd.kubernetes.protobuf
I0501 08:21:53.356947       1 round_trippers.go:580]     X-Kubernetes-Pf-Flowschema-Uid: 493426e8-0f6d-4ea6-bc2c-2d926c7e3221
I0501 08:21:53.356966       1 round_trippers.go:580]     X-Kubernetes-Pf-Prioritylevel-Uid: afabb116-6975-46b8-863b-3258bec9e1ea
I0501 08:21:53.356985       1 round_trippers.go:580]     Content-Length: 432
I0501 08:21:53.357083       1 request.go:1152] Response Body:
00000000  6b 38 73 00 0a 1f 0a 16  63 6f 6f 72 64 69 6e 61  |k8s.....coordina|
00000010  74 69 6f 6e 2e 6b 38 73  2e 69 6f 2f 76 31 12 05  |tion.k8s.io/v1..|
00000020  4c 65 61 73 65 12 84 03  0a a6 02 0a 0e 6b 75 62  |Lease........kub|
00000030  65 2d 73 63 68 65 64 75  6c 65 72 12 00 1a 0b 6b  |e-scheduler....k|
00000040  75 62 65 2d 73 79 73 74  65 6d 22 00 2a 24 36 61  |ube-system".*$6a|
00000050  30 65 32 30 33 66 2d 65  32 38 30 2d 34 36 61 30  |0e203f-e280-46a0|
00000060  2d 39 35 33 62 2d 35 66  62 64 63 37 38 61 63 38  |-953b-5fbdc78ac8|
00000070  36 65 32 07 32 32 36 38  36 38 35 38 00 42 08 08  |6e2.22686858.B..|
00000080  b1 b2 e2 a1 06 10 00 7a  00 8a 01 c4 01 0a 0e 6b  |.......z.......k|
00000090  75 62 65 2d 73 63 68 65  64 75 6c 65 72 12 06 55  |ube-scheduler..U|
000000a0  70 64 61 74 65 1a 16 63  6f 6f 72 64 69 6e 61 74  |pdate..coordinat|
000000b0  69 6f 6e 2e 6b 38 73 2e  69 6f 2f 76 31 22 08 08  |ion.k8s.io/v1"..|
000000c0  b1 b2 e2 a1 06 10 00 32  08 46 69 65 6c 64 73 56  |.......2.FieldsV|
000000d0  31 3a 7c 0a 7a 7b 22 66  3a 73 70 65 63 22 3a 7b  |1:|.z{"f:spec":{|
000000e0  22 66 3a 61 63 71 75 69  72 65 54 69 6d 65 22 3a  |"f:acquireTime":|
000000f0  7b 7d 2c 22 66 3a 68 6f  6c 64 65 72 49 64 65 6e  |{},"f:holderIden|
00000100  74 69 74 79 22 3a 7b 7d  2c 22 66 3a 6c 65 61 73  |tity":{},"f:leas|
00000110  65 44 75 72 61 74 69 6f  6e 53 65 63 6f 6e 64 73  |eDurationSeconds|
00000120  22 3a 7b 7d 2c 22 66 3a  6c 65 61 73 65 54 72 61  |":{},"f:leaseTra|
00000130  6e 73 69 74 69 6f 6e 73  22 3a 7b 7d 2c 22 66 3a  |nsitions":{},"f:|
00000140  72 65 6e 65 77 54 69 6d  65 22 3a 7b 7d 7d 7d 42  |renewTime":{}}}B|
00000150  00 12 59 0a 37 6b 69 6e  64 2d 63 6f 6e 74 72 6f  |..Y.7kind-contro|
00000160  6c 2d 70 6c 61 6e 65 5f  30 64 32 66 61 66 39 33  |l-plane_0d2faf93|
00000170  2d 34 61 30 62 2d 34 66  32 38 2d 38 33 64 33 2d  |-4a0b-4f28-83d3-|
00000180  35 62 35 62 62 66 61 31  65 36 31 30 10 0f 1a 0c  |5b5bbfa1e610....|
00000190  08 f7 a5 86 a2 06 10 b9  84 b7 94 03 22 0c 08 a1  |............"...|
000001a0  ed bd a2 06 10 d0 8d ad  9f 01 28 0a 1a 00 22 00  |..........(...".|
I0501 08:21:53.357257       1 leaderelection.go:278] successfully renewed lease kube-system/kube-scheduler
I0501 08:21:55.359067       1 round_trippers.go:466] curl -v -XGET  -H "Accept: application/vnd.kubernetes.protobuf, */*" -H "User-Agent: kube-scheduler/v1.24.7 (linux/amd64) kubernetes/e6f3597/leader-election" 'https://172.18.0.2:6443/apis/coordination.k8s.io/v1/namespaces/kube-system/leases/kube-scheduler?timeout=5s'
I0501 08:21:55.366626       1 round_trippers.go:553] GET https://172.18.0.2:6443/apis/coordination.k8s.io/v1/namespaces/kube-system/leases/kube-scheduler?timeout=5s 200 OK in 7 milliseconds
I0501 08:21:55.366686       1 round_trippers.go:570] HTTP Statistics: GetConnection 0 ms ServerProcessing 6 ms Duration 7 ms
I0501 08:21:55.366704       1 round_trippers.go:577] Response Headers:
I0501 08:21:55.366723       1 round_trippers.go:580]     Audit-Id: ff0d281a-5c87-4220-a6f4-e2ef8b407bc5
I0501 08:21:55.366748       1 round_trippers.go:580]     Cache-Control: no-cache, private
I0501 08:21:55.366764       1 round_trippers.go:580]     Content-Type: application/vnd.kubernetes.protobuf
I0501 08:21:55.367113       1 round_trippers.go:580]     X-Kubernetes-Pf-Flowschema-Uid: 493426e8-0f6d-4ea6-bc2c-2d926c7e3221
I0501 08:21:55.367147       1 round_trippers.go:580]     X-Kubernetes-Pf-Prioritylevel-Uid: afabb116-6975-46b8-863b-3258bec9e1ea
I0501 08:21:55.367341       1 round_trippers.go:580]     Content-Length: 432
I0501 08:21:55.367375       1 round_trippers.go:580]     Date: Mon, 01 May 2023 08:21:55 GMT
I0501 08:21:55.367636       1 request.go:1152] Response Body:
00000000  6b 38 73 00 0a 1f 0a 16  63 6f 6f 72 64 69 6e 61  |k8s.....coordina|
00000010  74 69 6f 6e 2e 6b 38 73  2e 69 6f 2f 76 31 12 05  |tion.k8s.io/v1..|
00000020  4c 65 61 73 65 12 84 03  0a a6 02 0a 0e 6b 75 62  |Lease........kub|
00000030  65 2d 73 63 68 65 64 75  6c 65 72 12 00 1a 0b 6b  |e-scheduler....k|
00000040  75 62 65 2d 73 79 73 74  65 6d 22 00 2a 24 36 61  |ube-system".*$6a|
00000050  30 65 32 30 33 66 2d 65  32 38 30 2d 34 36 61 30  |0e203f-e280-46a0|
00000060  2d 39 35 33 62 2d 35 66  62 64 63 37 38 61 63 38  |-953b-5fbdc78ac8|
00000070  36 65 32 07 32 32 36 38  36 38 35 38 00 42 08 08  |6e2.22686858.B..|
00000080  b1 b2 e2 a1 06 10 00 7a  00 8a 01 c4 01 0a 0e 6b  |.......z.......k|
00000090  75 62 65 2d 73 63 68 65  64 75 6c 65 72 12 06 55  |ube-scheduler..U|
000000a0  70 64 61 74 65 1a 16 63  6f 6f 72 64 69 6e 61 74  |pdate..coordinat|
000000b0  69 6f 6e 2e 6b 38 73 2e  69 6f 2f 76 31 22 08 08  |ion.k8s.io/v1"..|
000000c0  b1 b2 e2 a1 06 10 00 32  08 46 69 65 6c 64 73 56  |.......2.FieldsV|
000000d0  31 3a 7c 0a 7a 7b 22 66  3a 73 70 65 63 22 3a 7b  |1:|.z{"f:spec":{|
000000e0  22 66 3a 61 63 71 75 69  72 65 54 69 6d 65 22 3a  |"f:acquireTime":|
000000f0  7b 7d 2c 22 66 3a 68 6f  6c 64 65 72 49 64 65 6e  |{},"f:holderIden|
00000100  74 69 74 79 22 3a 7b 7d  2c 22 66 3a 6c 65 61 73  |tity":{},"f:leas|
00000110  65 44 75 72 61 74 69 6f  6e 53 65 63 6f 6e 64 73  |eDurationSeconds|
00000120  22 3a 7b 7d 2c 22 66 3a  6c 65 61 73 65 54 72 61  |":{},"f:leaseTra|
00000130  6e 73 69 74 69 6f 6e 73  22 3a 7b 7d 2c 22 66 3a  |nsitions":{},"f:|
00000140  72 65 6e 65 77 54 69 6d  65 22 3a 7b 7d 7d 7d 42  |renewTime":{}}}B|
00000150  00 12 59 0a 37 6b 69 6e  64 2d 63 6f 6e 74 72 6f  |..Y.7kind-contro|
00000160  6c 2d 70 6c 61 6e 65 5f  30 64 32 66 61 66 39 33  |l-plane_0d2faf93|
00000170  2d 34 61 30 62 2d 34 66  32 38 2d 38 33 64 33 2d  |-4a0b-4f28-83d3-|
00000180  35 62 35 62 62 66 61 31  65 36 31 30 10 0f 1a 0c  |5b5bbfa1e610....|
00000190  08 f7 a5 86 a2 06 10 b9  84 b7 94 03 22 0c 08 a1  |............"...|
000001a0  ed bd a2 06 10 d0 8d ad  9f 01 28 0a 1a 00 22 00  |..........(...".|
I0501 08:21:55.368040       1 request.go:1152] Request Body:
00000000  6b 38 73 00 0a 1f 0a 16  63 6f 6f 72 64 69 6e 61  |k8s.....coordina|
00000010  74 69 6f 6e 2e 6b 38 73  2e 69 6f 2f 76 31 12 05  |tion.k8s.io/v1..|
00000020  4c 65 61 73 65 12 84 03  0a a6 02 0a 0e 6b 75 62  |Lease........kub|
00000030  65 2d 73 63 68 65 64 75  6c 65 72 12 00 1a 0b 6b  |e-scheduler....k|
00000040  75 62 65 2d 73 79 73 74  65 6d 22 00 2a 24 36 61  |ube-system".*$6a|
00000050  30 65 32 30 33 66 2d 65  32 38 30 2d 34 36 61 30  |0e203f-e280-46a0|
00000060  2d 39 35 33 62 2d 35 66  62 64 63 37 38 61 63 38  |-953b-5fbdc78ac8|
00000070  36 65 32 07 32 32 36 38  36 38 35 38 00 42 08 08  |6e2.22686858.B..|
00000080  b1 b2 e2 a1 06 10 00 7a  00 8a 01 c4 01 0a 0e 6b  |.......z.......k|
00000090  75 62 65 2d 73 63 68 65  64 75 6c 65 72 12 06 55  |ube-scheduler..U|
000000a0  70 64 61 74 65 1a 16 63  6f 6f 72 64 69 6e 61 74  |pdate..coordinat|
000000b0  69 6f 6e 2e 6b 38 73 2e  69 6f 2f 76 31 22 08 08  |ion.k8s.io/v1"..|
000000c0  b1 b2 e2 a1 06 10 00 32  08 46 69 65 6c 64 73 56  |.......2.FieldsV|
000000d0  31 3a 7c 0a 7a 7b 22 66  3a 73 70 65 63 22 3a 7b  |1:|.z{"f:spec":{|
000000e0  22 66 3a 61 63 71 75 69  72 65 54 69 6d 65 22 3a  |"f:acquireTime":|
000000f0  7b 7d 2c 22 66 3a 68 6f  6c 64 65 72 49 64 65 6e  |{},"f:holderIden|
00000100  74 69 74 79 22 3a 7b 7d  2c 22 66 3a 6c 65 61 73  |tity":{},"f:leas|
00000110  65 44 75 72 61 74 69 6f  6e 53 65 63 6f 6e 64 73  |eDurationSeconds|
00000120  22 3a 7b 7d 2c 22 66 3a  6c 65 61 73 65 54 72 61  |":{},"f:leaseTra|
00000130  6e 73 69 74 69 6f 6e 73  22 3a 7b 7d 2c 22 66 3a  |nsitions":{},"f:|
00000140  72 65 6e 65 77 54 69 6d  65 22 3a 7b 7d 7d 7d 42  |renewTime":{}}}B|
00000150  00 12 59 0a 37 6b 69 6e  64 2d 63 6f 6e 74 72 6f  |..Y.7kind-contro|
00000160  6c 2d 70 6c 61 6e 65 5f  30 64 32 66 61 66 39 33  |l-plane_0d2faf93|
00000170  2d 34 61 30 62 2d 34 66  32 38 2d 38 33 64 33 2d  |-4a0b-4f28-83d3-|
00000180  35 62 35 62 62 66 61 31  65 36 31 30 10 0f 1a 0c  |5b5bbfa1e610....|
00000190  08 f7 a5 86 a2 06 10 b9  84 b7 94 03 22 0c 08 a3  |............"...|
000001a0  ed bd a2 06 10 ea b4 f3  aa 01 28 0a 1a 00 22 00  |..........(...".|
I0501 08:21:55.368345       1 round_trippers.go:466] curl -v -XPUT  -H "Accept: application/vnd.kubernetes.protobuf, */*" -H "Content-Type: application/vnd.kubernetes.protobuf" -H "User-Agent: kube-scheduler/v1.24.7 (linux/amd64) kubernetes/e6f3597/leader-election" 'https://172.18.0.2:6443/apis/coordination.k8s.io/v1/namespaces/kube-system/leases/kube-scheduler?timeout=5s'
I0501 08:21:55.374573       1 round_trippers.go:553] PUT https://172.18.0.2:6443/apis/coordination.k8s.io/v1/namespaces/kube-system/leases/kube-scheduler?timeout=5s 200 OK in 6 milliseconds
I0501 08:21:55.374610       1 round_trippers.go:570] HTTP Statistics: GetConnection 0 ms ServerProcessing 5 ms Duration 6 ms
I0501 08:21:55.374626       1 round_trippers.go:577] Response Headers:
I0501 08:21:55.374643       1 round_trippers.go:580]     Audit-Id: 7ccf4ca1-fd33-47bb-befe-023a77f87817
I0501 08:21:55.374871       1 round_trippers.go:580]     Cache-Control: no-cache, private
I0501 08:21:55.374902       1 round_trippers.go:580]     Content-Type: application/vnd.kubernetes.protobuf
I0501 08:21:55.374918       1 round_trippers.go:580]     X-Kubernetes-Pf-Flowschema-Uid: 493426e8-0f6d-4ea6-bc2c-2d926c7e3221
I0501 08:21:55.374933       1 round_trippers.go:580]     X-Kubernetes-Pf-Prioritylevel-Uid: afabb116-6975-46b8-863b-3258bec9e1ea
I0501 08:21:55.374949       1 round_trippers.go:580]     Content-Length: 432
I0501 08:21:55.375190       1 round_trippers.go:580]     Date: Mon, 01 May 2023 08:21:55 GMT
I0501 08:21:55.375296       1 request.go:1152] Response Body:
00000000  6b 38 73 00 0a 1f 0a 16  63 6f 6f 72 64 69 6e 61  |k8s.....coordina|
00000010  74 69 6f 6e 2e 6b 38 73  2e 69 6f 2f 76 31 12 05  |tion.k8s.io/v1..|
00000020  4c 65 61 73 65 12 84 03  0a a6 02 0a 0e 6b 75 62  |Lease........kub|
00000030  65 2d 73 63 68 65 64 75  6c 65 72 12 00 1a 0b 6b  |e-scheduler....k|
00000040  75 62 65 2d 73 79 73 74  65 6d 22 00 2a 24 36 61  |ube-system".*$6a|
00000050  30 65 32 30 33 66 2d 65  32 38 30 2d 34 36 61 30  |0e203f-e280-46a0|
00000060  2d 39 35 33 62 2d 35 66  62 64 63 37 38 61 63 38  |-953b-5fbdc78ac8|
00000070  36 65 32 07 32 32 36 38  36 38 38 38 00 42 08 08  |6e2.22686888.B..|
00000080  b1 b2 e2 a1 06 10 00 7a  00 8a 01 c4 01 0a 0e 6b  |.......z.......k|
00000090  75 62 65 2d 73 63 68 65  64 75 6c 65 72 12 06 55  |ube-scheduler..U|
000000a0  70 64 61 74 65 1a 16 63  6f 6f 72 64 69 6e 61 74  |pdate..coordinat|
000000b0  69 6f 6e 2e 6b 38 73 2e  69 6f 2f 76 31 22 08 08  |ion.k8s.io/v1"..|
000000c0  b1 b2 e2 a1 06 10 00 32  08 46 69 65 6c 64 73 56  |.......2.FieldsV|
000000d0  31 3a 7c 0a 7a 7b 22 66  3a 73 70 65 63 22 3a 7b  |1:|.z{"f:spec":{|
000000e0  22 66 3a 61 63 71 75 69  72 65 54 69 6d 65 22 3a  |"f:acquireTime":|
000000f0  7b 7d 2c 22 66 3a 68 6f  6c 64 65 72 49 64 65 6e  |{},"f:holderIden|
00000100  74 69 74 79 22 3a 7b 7d  2c 22 66 3a 6c 65 61 73  |tity":{},"f:leas|
00000110  65 44 75 72 61 74 69 6f  6e 53 65 63 6f 6e 64 73  |eDurationSeconds|
00000120  22 3a 7b 7d 2c 22 66 3a  6c 65 61 73 65 54 72 61  |":{},"f:leaseTra|
00000130  6e 73 69 74 69 6f 6e 73  22 3a 7b 7d 2c 22 66 3a  |nsitions":{},"f:|
00000140  72 65 6e 65 77 54 69 6d  65 22 3a 7b 7d 7d 7d 42  |renewTime":{}}}B|
00000150  00 12 59 0a 37 6b 69 6e  64 2d 63 6f 6e 74 72 6f  |..Y.7kind-contro|
00000160  6c 2d 70 6c 61 6e 65 5f  30 64 32 66 61 66 39 33  |l-plane_0d2faf93|
00000170  2d 34 61 30 62 2d 34 66  32 38 2d 38 33 64 33 2d  |-4a0b-4f28-83d3-|
00000180  35 62 35 62 62 66 61 31  65 36 31 30 10 0f 1a 0c  |5b5bbfa1e610....|
00000190  08 f7 a5 86 a2 06 10 b9  84 b7 94 03 22 0c 08 a3  |............"...|
000001a0  ed bd a2 06 10 ea b4 f3  aa 01 28 0a 1a 00 22 00  |..........(...".|
I0501 08:21:55.375537       1 leaderelection.go:278] successfully renewed lease kube-system/kube-scheduler
I0501 08:21:57.376828       1 round_trippers.go:466] curl -v -XGET  -H "Accept: application/vnd.kubernetes.protobuf, */*" -H "User-Agent: kube-scheduler/v1.24.7 (linux/amd64) kubernetes/e6f3597/leader-election" 'https://172.18.0.2:6443/apis/coordination.k8s.io/v1/namespaces/kube-system/leases/kube-scheduler?timeout=5s'
I0501 08:21:57.385185       1 round_trippers.go:553] GET https://172.18.0.2:6443/apis/coordination.k8s.io/v1/namespaces/kube-system/leases/kube-scheduler?timeout=5s 200 OK in 8 milliseconds
I0501 08:21:57.385451       1 round_trippers.go:570] HTTP Statistics: GetConnection 0 ms ServerProcessing 7 ms Duration 8 ms
I0501 08:21:57.385586       1 round_trippers.go:577] Response Headers:
I0501 08:21:57.385940       1 round_trippers.go:580]     Date: Mon, 01 May 2023 08:21:57 GMT
I0501 08:21:57.387335       1 round_trippers.go:580]     Audit-Id: eb810ec3-8923-4d77-99de-3d17936cd93f
I0501 08:21:57.387499       1 round_trippers.go:580]     Cache-Control: no-cache, private
I0501 08:21:57.387614       1 round_trippers.go:580]     Content-Type: application/vnd.kubernetes.protobuf
I0501 08:21:57.387749       1 round_trippers.go:580]     X-Kubernetes-Pf-Flowschema-Uid: 493426e8-0f6d-4ea6-bc2c-2d926c7e3221
I0501 08:21:57.387964       1 round_trippers.go:580]     X-Kubernetes-Pf-Prioritylevel-Uid: afabb116-6975-46b8-863b-3258bec9e1ea
I0501 08:21:57.388082       1 round_trippers.go:580]     Content-Length: 432
I0501 08:21:57.388369       1 request.go:1152] Response Body:
00000000  6b 38 73 00 0a 1f 0a 16  63 6f 6f 72 64 69 6e 61  |k8s.....coordina|
00000010  74 69 6f 6e 2e 6b 38 73  2e 69 6f 2f 76 31 12 05  |tion.k8s.io/v1..|
00000020  4c 65 61 73 65 12 84 03  0a a6 02 0a 0e 6b 75 62  |Lease........kub|
00000030  65 2d 73 63 68 65 64 75  6c 65 72 12 00 1a 0b 6b  |e-scheduler....k|
00000040  75 62 65 2d 73 79 73 74  65 6d 22 00 2a 24 36 61  |ube-system".*$6a|
00000050  30 65 32 30 33 66 2d 65  32 38 30 2d 34 36 61 30  |0e203f-e280-46a0|
00000060  2d 39 35 33 62 2d 35 66  62 64 63 37 38 61 63 38  |-953b-5fbdc78ac8|
00000070  36 65 32 07 32 32 36 38  36 38 38 38 00 42 08 08  |6e2.22686888.B..|
00000080  b1 b2 e2 a1 06 10 00 7a  00 8a 01 c4 01 0a 0e 6b  |.......z.......k|
00000090  75 62 65 2d 73 63 68 65  64 75 6c 65 72 12 06 55  |ube-scheduler..U|
000000a0  70 64 61 74 65 1a 16 63  6f 6f 72 64 69 6e 61 74  |pdate..coordinat|
000000b0  69 6f 6e 2e 6b 38 73 2e  69 6f 2f 76 31 22 08 08  |ion.k8s.io/v1"..|
000000c0  b1 b2 e2 a1 06 10 00 32  08 46 69 65 6c 64 73 56  |.......2.FieldsV|
000000d0  31 3a 7c 0a 7a 7b 22 66  3a 73 70 65 63 22 3a 7b  |1:|.z{"f:spec":{|
000000e0  22 66 3a 61 63 71 75 69  72 65 54 69 6d 65 22 3a  |"f:acquireTime":|
000000f0  7b 7d 2c 22 66 3a 68 6f  6c 64 65 72 49 64 65 6e  |{},"f:holderIden|
00000100  74 69 74 79 22 3a 7b 7d  2c 22 66 3a 6c 65 61 73  |tity":{},"f:leas|
00000110  65 44 75 72 61 74 69 6f  6e 53 65 63 6f 6e 64 73  |eDurationSeconds|
00000120  22 3a 7b 7d 2c 22 66 3a  6c 65 61 73 65 54 72 61  |":{},"f:leaseTra|
00000130  6e 73 69 74 69 6f 6e 73  22 3a 7b 7d 2c 22 66 3a  |nsitions":{},"f:|
00000140  72 65 6e 65 77 54 69 6d  65 22 3a 7b 7d 7d 7d 42  |renewTime":{}}}B|
00000150  00 12 59 0a 37 6b 69 6e  64 2d 63 6f 6e 74 72 6f  |..Y.7kind-contro|
00000160  6c 2d 70 6c 61 6e 65 5f  30 64 32 66 61 66 39 33  |l-plane_0d2faf93|
00000170  2d 34 61 30 62 2d 34 66  32 38 2d 38 33 64 33 2d  |-4a0b-4f28-83d3-|
00000180  35 62 35 62 62 66 61 31  65 36 31 30 10 0f 1a 0c  |5b5bbfa1e610....|
00000190  08 f7 a5 86 a2 06 10 b9  84 b7 94 03 22 0c 08 a3  |............"...|
000001a0  ed bd a2 06 10 ea b4 f3  aa 01 28 0a 1a 00 22 00  |..........(...".|
I0501 08:21:57.388951       1 request.go:1152] Request Body:
00000000  6b 38 73 00 0a 1f 0a 16  63 6f 6f 72 64 69 6e 61  |k8s.....coordina|
00000010  74 69 6f 6e 2e 6b 38 73  2e 69 6f 2f 76 31 12 05  |tion.k8s.io/v1..|
00000020  4c 65 61 73 65 12 84 03  0a a6 02 0a 0e 6b 75 62  |Lease........kub|
00000030  65 2d 73 63 68 65 64 75  6c 65 72 12 00 1a 0b 6b  |e-scheduler....k|
00000040  75 62 65 2d 73 79 73 74  65 6d 22 00 2a 24 36 61  |ube-system".*$6a|
00000050  30 65 32 30 33 66 2d 65  32 38 30 2d 34 36 61 30  |0e203f-e280-46a0|
00000060  2d 39 35 33 62 2d 35 66  62 64 63 37 38 61 63 38  |-953b-5fbdc78ac8|
00000070  36 65 32 07 32 32 36 38  36 38 38 38 00 42 08 08  |6e2.22686888.B..|
00000080  b1 b2 e2 a1 06 10 00 7a  00 8a 01 c4 01 0a 0e 6b  |.......z.......k|
00000090  75 62 65 2d 73 63 68 65  64 75 6c 65 72 12 06 55  |ube-scheduler..U|
000000a0  70 64 61 74 65 1a 16 63  6f 6f 72 64 69 6e 61 74  |pdate..coordinat|
000000b0  69 6f 6e 2e 6b 38 73 2e  69 6f 2f 76 31 22 08 08  |ion.k8s.io/v1"..|
000000c0  b1 b2 e2 a1 06 10 00 32  08 46 69 65 6c 64 73 56  |.......2.FieldsV|
000000d0  31 3a 7c 0a 7a 7b 22 66  3a 73 70 65 63 22 3a 7b  |1:|.z{"f:spec":{|
000000e0  22 66 3a 61 63 71 75 69  72 65 54 69 6d 65 22 3a  |"f:acquireTime":|
000000f0  7b 7d 2c 22 66 3a 68 6f  6c 64 65 72 49 64 65 6e  |{},"f:holderIden|
00000100  74 69 74 79 22 3a 7b 7d  2c 22 66 3a 6c 65 61 73  |tity":{},"f:leas|
00000110  65 44 75 72 61 74 69 6f  6e 53 65 63 6f 6e 64 73  |eDurationSeconds|
00000120  22 3a 7b 7d 2c 22 66 3a  6c 65 61 73 65 54 72 61  |":{},"f:leaseTra|
00000130  6e 73 69 74 69 6f 6e 73  22 3a 7b 7d 2c 22 66 3a  |nsitions":{},"f:|
00000140  72 65 6e 65 77 54 69 6d  65 22 3a 7b 7d 7d 7d 42  |renewTime":{}}}B|
00000150  00 12 59 0a 37 6b 69 6e  64 2d 63 6f 6e 74 72 6f  |..Y.7kind-contro|
00000160  6c 2d 70 6c 61 6e 65 5f  30 64 32 66 61 66 39 33  |l-plane_0d2faf93|
00000170  2d 34 61 30 62 2d 34 66  32 38 2d 38 33 64 33 2d  |-4a0b-4f28-83d3-|
00000180  35 62 35 62 62 66 61 31  65 36 31 30 10 0f 1a 0c  |5b5bbfa1e610....|
00000190  08 f7 a5 86 a2 06 10 b9  84 b7 94 03 22 0c 08 a5  |............"...|
000001a0  ed bd a2 06 10 fc d4 c3  b3 01 28 0a 1a 00 22 00  |..........(...".|
I0501 08:21:57.389364       1 round_trippers.go:466] curl -v -XPUT  -H "Accept: application/vnd.kubernetes.protobuf, */*" -H "Content-Type: application/vnd.kubernetes.protobuf" -H "User-Agent: kube-scheduler/v1.24.7 (linux/amd64) kubernetes/e6f3597/leader-election" 'https://172.18.0.2:6443/apis/coordination.k8s.io/v1/namespaces/kube-system/leases/kube-scheduler?timeout=5s'
I0501 08:21:57.397738       1 round_trippers.go:553] PUT https://172.18.0.2:6443/apis/coordination.k8s.io/v1/namespaces/kube-system/leases/kube-scheduler?timeout=5s 200 OK in 8 milliseconds
I0501 08:21:57.397793       1 round_trippers.go:570] HTTP Statistics: GetConnection 0 ms ServerProcessing 7 ms Duration 8 ms
I0501 08:21:57.397813       1 round_trippers.go:577] Response Headers:
I0501 08:21:57.397835       1 round_trippers.go:580]     Cache-Control: no-cache, private
I0501 08:21:57.397853       1 round_trippers.go:580]     Content-Type: application/vnd.kubernetes.protobuf
I0501 08:21:57.397872       1 round_trippers.go:580]     X-Kubernetes-Pf-Flowschema-Uid: 493426e8-0f6d-4ea6-bc2c-2d926c7e3221
I0501 08:21:57.397891       1 round_trippers.go:580]     X-Kubernetes-Pf-Prioritylevel-Uid: afabb116-6975-46b8-863b-3258bec9e1ea
I0501 08:21:57.397909       1 round_trippers.go:580]     Content-Length: 432
I0501 08:21:57.397931       1 round_trippers.go:580]     Date: Mon, 01 May 2023 08:21:57 GMT
I0501 08:21:57.398021       1 round_trippers.go:580]     Audit-Id: c513c04d-a29f-4d60-b67c-df983967cbdf
I0501 08:21:57.398211       1 request.go:1152] Response Body:
00000000  6b 38 73 00 0a 1f 0a 16  63 6f 6f 72 64 69 6e 61  |k8s.....coordina|
00000010  74 69 6f 6e 2e 6b 38 73  2e 69 6f 2f 76 31 12 05  |tion.k8s.io/v1..|
00000020  4c 65 61 73 65 12 84 03  0a a6 02 0a 0e 6b 75 62  |Lease........kub|
00000030  65 2d 73 63 68 65 64 75  6c 65 72 12 00 1a 0b 6b  |e-scheduler....k|
00000040  75 62 65 2d 73 79 73 74  65 6d 22 00 2a 24 36 61  |ube-system".*$6a|
00000050  30 65 32 30 33 66 2d 65  32 38 30 2d 34 36 61 30  |0e203f-e280-46a0|
00000060  2d 39 35 33 62 2d 35 66  62 64 63 37 38 61 63 38  |-953b-5fbdc78ac8|
00000070  36 65 32 07 32 32 36 38  36 39 31 38 00 42 08 08  |6e2.22686918.B..|
00000080  b1 b2 e2 a1 06 10 00 7a  00 8a 01 c4 01 0a 0e 6b  |.......z.......k|
00000090  75 62 65 2d 73 63 68 65  64 75 6c 65 72 12 06 55  |ube-scheduler..U|
000000a0  70 64 61 74 65 1a 16 63  6f 6f 72 64 69 6e 61 74  |pdate..coordinat|
000000b0  69 6f 6e 2e 6b 38 73 2e  69 6f 2f 76 31 22 08 08  |ion.k8s.io/v1"..|
000000c0  b1 b2 e2 a1 06 10 00 32  08 46 69 65 6c 64 73 56  |.......2.FieldsV|
000000d0  31 3a 7c 0a 7a 7b 22 66  3a 73 70 65 63 22 3a 7b  |1:|.z{"f:spec":{|
000000e0  22 66 3a 61 63 71 75 69  72 65 54 69 6d 65 22 3a  |"f:acquireTime":|
000000f0  7b 7d 2c 22 66 3a 68 6f  6c 64 65 72 49 64 65 6e  |{},"f:holderIden|
00000100  74 69 74 79 22 3a 7b 7d  2c 22 66 3a 6c 65 61 73  |tity":{},"f:leas|
00000110  65 44 75 72 61 74 69 6f  6e 53 65 63 6f 6e 64 73  |eDurationSeconds|
00000120  22 3a 7b 7d 2c 22 66 3a  6c 65 61 73 65 54 72 61  |":{},"f:leaseTra|
00000130  6e 73 69 74 69 6f 6e 73  22 3a 7b 7d 2c 22 66 3a  |nsitions":{},"f:|
00000140  72 65 6e 65 77 54 69 6d  65 22 3a 7b 7d 7d 7d 42  |renewTime":{}}}B|
00000150  00 12 59 0a 37 6b 69 6e  64 2d 63 6f 6e 74 72 6f  |..Y.7kind-contro|
00000160  6c 2d 70 6c 61 6e 65 5f  30 64 32 66 61 66 39 33  |l-plane_0d2faf93|
00000170  2d 34 61 30 62 2d 34 66  32 38 2d 38 33 64 33 2d  |-4a0b-4f28-83d3-|
00000180  35 62 35 62 62 66 61 31  65 36 31 30 10 0f 1a 0c  |5b5bbfa1e610....|
00000190  08 f7 a5 86 a2 06 10 b9  84 b7 94 03 22 0c 08 a5  |............"...|
000001a0  ed bd a2 06 10 fc d4 c3  b3 01 28 0a 1a 00 22 00  |..........(...".|
I0501 08:21:57.398608       1 leaderelection.go:278] successfully renewed lease kube-system/kube-scheduler
I0501 08:21:59.399638       1 round_trippers.go:466] curl -v -XGET  -H "Accept: application/vnd.kubernetes.protobuf, */*" -H "User-Agent: kube-scheduler/v1.24.7 (linux/amd64) kubernetes/e6f3597/leader-election" 'https://172.18.0.2:6443/apis/coordination.k8s.io/v1/namespaces/kube-system/leases/kube-scheduler?timeout=5s'
I0501 08:21:59.407556       1 round_trippers.go:553] GET https://172.18.0.2:6443/apis/coordination.k8s.io/v1/namespaces/kube-system/leases/kube-scheduler?timeout=5s 200 OK in 7 milliseconds
I0501 08:21:59.407608       1 round_trippers.go:570] HTTP Statistics: GetConnection 0 ms ServerProcessing 7 ms Duration 7 ms
I0501 08:21:59.407639       1 round_trippers.go:577] Response Headers:
I0501 08:21:59.407679       1 round_trippers.go:580]     Audit-Id: f25cc451-e647-4e83-8de4-035e74ca435e
I0501 08:21:59.407704       1 round_trippers.go:580]     Cache-Control: no-cache, private
I0501 08:21:59.407721       1 round_trippers.go:580]     Content-Type: application/vnd.kubernetes.protobuf
I0501 08:21:59.407747       1 round_trippers.go:580]     X-Kubernetes-Pf-Flowschema-Uid: 493426e8-0f6d-4ea6-bc2c-2d926c7e3221
I0501 08:21:59.407775       1 round_trippers.go:580]     X-Kubernetes-Pf-Prioritylevel-Uid: afabb116-6975-46b8-863b-3258bec9e1ea
I0501 08:21:59.408129       1 round_trippers.go:580]     Content-Length: 432
I0501 08:21:59.408158       1 round_trippers.go:580]     Date: Mon, 01 May 2023 08:21:59 GMT
I0501 08:21:59.408234       1 request.go:1152] Response Body:
00000000  6b 38 73 00 0a 1f 0a 16  63 6f 6f 72 64 69 6e 61  |k8s.....coordina|
00000010  74 69 6f 6e 2e 6b 38 73  2e 69 6f 2f 76 31 12 05  |tion.k8s.io/v1..|
00000020  4c 65 61 73 65 12 84 03  0a a6 02 0a 0e 6b 75 62  |Lease........kub|
00000030  65 2d 73 63 68 65 64 75  6c 65 72 12 00 1a 0b 6b  |e-scheduler....k|
00000040  75 62 65 2d 73 79 73 74  65 6d 22 00 2a 24 36 61  |ube-system".*$6a|
00000050  30 65 32 30 33 66 2d 65  32 38 30 2d 34 36 61 30  |0e203f-e280-46a0|
00000060  2d 39 35 33 62 2d 35 66  62 64 63 37 38 61 63 38  |-953b-5fbdc78ac8|
00000070  36 65 32 07 32 32 36 38  36 39 31 38 00 42 08 08  |6e2.22686918.B..|
00000080  b1 b2 e2 a1 06 10 00 7a  00 8a 01 c4 01 0a 0e 6b  |.......z.......k|
00000090  75 62 65 2d 73 63 68 65  64 75 6c 65 72 12 06 55  |ube-scheduler..U|
000000a0  70 64 61 74 65 1a 16 63  6f 6f 72 64 69 6e 61 74  |pdate..coordinat|
000000b0  69 6f 6e 2e 6b 38 73 2e  69 6f 2f 76 31 22 08 08  |ion.k8s.io/v1"..|
000000c0  b1 b2 e2 a1 06 10 00 32  08 46 69 65 6c 64 73 56  |.......2.FieldsV|
000000d0  31 3a 7c 0a 7a 7b 22 66  3a 73 70 65 63 22 3a 7b  |1:|.z{"f:spec":{|
000000e0  22 66 3a 61 63 71 75 69  72 65 54 69 6d 65 22 3a  |"f:acquireTime":|
000000f0  7b 7d 2c 22 66 3a 68 6f  6c 64 65 72 49 64 65 6e  |{},"f:holderIden|
00000100  74 69 74 79 22 3a 7b 7d  2c 22 66 3a 6c 65 61 73  |tity":{},"f:leas|
00000110  65 44 75 72 61 74 69 6f  6e 53 65 63 6f 6e 64 73  |eDurationSeconds|
00000120  22 3a 7b 7d 2c 22 66 3a  6c 65 61 73 65 54 72 61  |":{},"f:leaseTra|
00000130  6e 73 69 74 69 6f 6e 73  22 3a 7b 7d 2c 22 66 3a  |nsitions":{},"f:|
00000140  72 65 6e 65 77 54 69 6d  65 22 3a 7b 7d 7d 7d 42  |renewTime":{}}}B|
00000150  00 12 59 0a 37 6b 69 6e  64 2d 63 6f 6e 74 72 6f  |..Y.7kind-contro|
00000160  6c 2d 70 6c 61 6e 65 5f  30 64 32 66 61 66 39 33  |l-plane_0d2faf93|
00000170  2d 34 61 30 62 2d 34 66  32 38 2d 38 33 64 33 2d  |-4a0b-4f28-83d3-|
00000180  35 62 35 62 62 66 61 31  65 36 31 30 10 0f 1a 0c  |5b5bbfa1e610....|
00000190  08 f7 a5 86 a2 06 10 b9  84 b7 94 03 22 0c 08 a5  |............"...|
000001a0  ed bd a2 06 10 fc d4 c3  b3 01 28 0a 1a 00 22 00  |..........(...".|
I0501 08:21:59.408454       1 request.go:1152] Request Body:
00000000  6b 38 73 00 0a 1f 0a 16  63 6f 6f 72 64 69 6e 61  |k8s.....coordina|
00000010  74 69 6f 6e 2e 6b 38 73  2e 69 6f 2f 76 31 12 05  |tion.k8s.io/v1..|
00000020  4c 65 61 73 65 12 84 03  0a a6 02 0a 0e 6b 75 62  |Lease........kub|
00000030  65 2d 73 63 68 65 64 75  6c 65 72 12 00 1a 0b 6b  |e-scheduler....k|
00000040  75 62 65 2d 73 79 73 74  65 6d 22 00 2a 24 36 61  |ube-system".*$6a|
00000050  30 65 32 30 33 66 2d 65  32 38 30 2d 34 36 61 30  |0e203f-e280-46a0|
00000060  2d 39 35 33 62 2d 35 66  62 64 63 37 38 61 63 38  |-953b-5fbdc78ac8|
00000070  36 65 32 07 32 32 36 38  36 39 31 38 00 42 08 08  |6e2.22686918.B..|
00000080  b1 b2 e2 a1 06 10 00 7a  00 8a 01 c4 01 0a 0e 6b  |.......z.......k|
00000090  75 62 65 2d 73 63 68 65  64 75 6c 65 72 12 06 55  |ube-scheduler..U|
000000a0  70 64 61 74 65 1a 16 63  6f 6f 72 64 69 6e 61 74  |pdate..coordinat|
000000b0  69 6f 6e 2e 6b 38 73 2e  69 6f 2f 76 31 22 08 08  |ion.k8s.io/v1"..|
000000c0  b1 b2 e2 a1 06 10 00 32  08 46 69 65 6c 64 73 56  |.......2.FieldsV|
000000d0  31 3a 7c 0a 7a 7b 22 66  3a 73 70 65 63 22 3a 7b  |1:|.z{"f:spec":{|
000000e0  22 66 3a 61 63 71 75 69  72 65 54 69 6d 65 22 3a  |"f:acquireTime":|
000000f0  7b 7d 2c 22 66 3a 68 6f  6c 64 65 72 49 64 65 6e  |{},"f:holderIden|
00000100  74 69 74 79 22 3a 7b 7d  2c 22 66 3a 6c 65 61 73  |tity":{},"f:leas|
00000110  65 44 75 72 61 74 69 6f  6e 53 65 63 6f 6e 64 73  |eDurationSeconds|
00000120  22 3a 7b 7d 2c 22 66 3a  6c 65 61 73 65 54 72 61  |":{},"f:leaseTra|
00000130  6e 73 69 74 69 6f 6e 73  22 3a 7b 7d 2c 22 66 3a  |nsitions":{},"f:|
00000140  72 65 6e 65 77 54 69 6d  65 22 3a 7b 7d 7d 7d 42  |renewTime":{}}}B|
00000150  00 12 59 0a 37 6b 69 6e  64 2d 63 6f 6e 74 72 6f  |..Y.7kind-contro|
00000160  6c 2d 70 6c 61 6e 65 5f  30 64 32 66 61 66 39 33  |l-plane_0d2faf93|
00000170  2d 34 61 30 62 2d 34 66  32 38 2d 38 33 64 33 2d  |-4a0b-4f28-83d3-|
00000180  35 62 35 62 62 66 61 31  65 36 31 30 10 0f 1a 0c  |5b5bbfa1e610....|
00000190  08 f7 a5 86 a2 06 10 b9  84 b7 94 03 22 0c 08 a7  |............"...|
000001a0  ed bd a2 06 10 8a ed b9  be 01 28 0a 1a 00 22 00  |..........(...".|
I0501 08:21:59.408582       1 round_trippers.go:466] curl -v -XPUT  -H "Content-Type: application/vnd.kubernetes.protobuf" -H "Accept: application/vnd.kubernetes.protobuf, */*" -H "User-Agent: kube-scheduler/v1.24.7 (linux/amd64) kubernetes/e6f3597/leader-election" 'https://172.18.0.2:6443/apis/coordination.k8s.io/v1/namespaces/kube-system/leases/kube-scheduler?timeout=5s'
I0501 08:21:59.414894       1 round_trippers.go:553] PUT https://172.18.0.2:6443/apis/coordination.k8s.io/v1/namespaces/kube-system/leases/kube-scheduler?timeout=5s 200 OK in 6 milliseconds
I0501 08:21:59.414977       1 round_trippers.go:570] HTTP Statistics: GetConnection 0 ms ServerProcessing 6 ms Duration 6 ms
I0501 08:21:59.415005       1 round_trippers.go:577] Response Headers:
I0501 08:21:59.415064       1 round_trippers.go:580]     Audit-Id: e3c75033-4beb-4251-9fcf-88753942e0e4
I0501 08:21:59.415143       1 round_trippers.go:580]     Cache-Control: no-cache, private
I0501 08:21:59.415170       1 round_trippers.go:580]     Content-Type: application/vnd.kubernetes.protobuf
I0501 08:21:59.415186       1 round_trippers.go:580]     X-Kubernetes-Pf-Flowschema-Uid: 493426e8-0f6d-4ea6-bc2c-2d926c7e3221
I0501 08:21:59.415242       1 round_trippers.go:580]     X-Kubernetes-Pf-Prioritylevel-Uid: afabb116-6975-46b8-863b-3258bec9e1ea
I0501 08:21:59.415260       1 round_trippers.go:580]     Content-Length: 432
I0501 08:21:59.415316       1 round_trippers.go:580]     Date: Mon, 01 May 2023 08:21:59 GMT
I0501 08:21:59.415415       1 request.go:1152] Response Body:
00000000  6b 38 73 00 0a 1f 0a 16  63 6f 6f 72 64 69 6e 61  |k8s.....coordina|
00000010  74 69 6f 6e 2e 6b 38 73  2e 69 6f 2f 76 31 12 05  |tion.k8s.io/v1..|
00000020  4c 65 61 73 65 12 84 03  0a a6 02 0a 0e 6b 75 62  |Lease........kub|
00000030  65 2d 73 63 68 65 64 75  6c 65 72 12 00 1a 0b 6b  |e-scheduler....k|
00000040  75 62 65 2d 73 79 73 74  65 6d 22 00 2a 24 36 61  |ube-system".*$6a|
00000050  30 65 32 30 33 66 2d 65  32 38 30 2d 34 36 61 30  |0e203f-e280-46a0|
00000060  2d 39 35 33 62 2d 35 66  62 64 63 37 38 61 63 38  |-953b-5fbdc78ac8|
00000070  36 65 32 07 32 32 36 38  36 39 34 38 00 42 08 08  |6e2.22686948.B..|
00000080  b1 b2 e2 a1 06 10 00 7a  00 8a 01 c4 01 0a 0e 6b  |.......z.......k|
00000090  75 62 65 2d 73 63 68 65  64 75 6c 65 72 12 06 55  |ube-scheduler..U|
000000a0  70 64 61 74 65 1a 16 63  6f 6f 72 64 69 6e 61 74  |pdate..coordinat|
000000b0  69 6f 6e 2e 6b 38 73 2e  69 6f 2f 76 31 22 08 08  |ion.k8s.io/v1"..|
000000c0  b1 b2 e2 a1 06 10 00 32  08 46 69 65 6c 64 73 56  |.......2.FieldsV|
000000d0  31 3a 7c 0a 7a 7b 22 66  3a 73 70 65 63 22 3a 7b  |1:|.z{"f:spec":{|
000000e0  22 66 3a 61 63 71 75 69  72 65 54 69 6d 65 22 3a  |"f:acquireTime":|
000000f0  7b 7d 2c 22 66 3a 68 6f  6c 64 65 72 49 64 65 6e  |{},"f:holderIden|
00000100  74 69 74 79 22 3a 7b 7d  2c 22 66 3a 6c 65 61 73  |tity":{},"f:leas|
00000110  65 44 75 72 61 74 69 6f  6e 53 65 63 6f 6e 64 73  |eDurationSeconds|
00000120  22 3a 7b 7d 2c 22 66 3a  6c 65 61 73 65 54 72 61  |":{},"f:leaseTra|
00000130  6e 73 69 74 69 6f 6e 73  22 3a 7b 7d 2c 22 66 3a  |nsitions":{},"f:|
00000140  72 65 6e 65 77 54 69 6d  65 22 3a 7b 7d 7d 7d 42  |renewTime":{}}}B|
00000150  00 12 59 0a 37 6b 69 6e  64 2d 63 6f 6e 74 72 6f  |..Y.7kind-contro|
00000160  6c 2d 70 6c 61 6e 65 5f  30 64 32 66 61 66 39 33  |l-plane_0d2faf93|
00000170  2d 34 61 30 62 2d 34 66  32 38 2d 38 33 64 33 2d  |-4a0b-4f28-83d3-|
00000180  35 62 35 62 62 66 61 31  65 36 31 30 10 0f 1a 0c  |5b5bbfa1e610....|
00000190  08 f7 a5 86 a2 06 10 b9  84 b7 94 03 22 0c 08 a7  |............"...|
000001a0  ed bd a2 06 10 8a ed b9  be 01 28 0a 1a 00 22 00  |..........(...".|
I0501 08:21:59.415640       1 leaderelection.go:278] successfully renewed lease kube-system/kube-scheduler
I0501 08:21:59.667034       1 pathrecorder.go:241] kube-scheduler: "/healthz" satisfied by exact match
I0501 08:21:59.667370       1 httplog.go:131] "HTTP" verb="GET" URI="/healthz" latency="205.075µs" userAgent="kube-probe/1.24" audit-ID="" srcIP="127.0.0.1:60144" resp=200
I0501 08:22:01.417282       1 round_trippers.go:466] curl -v -XGET  -H "Accept: application/vnd.kubernetes.protobuf, */*" -H "User-Agent: kube-scheduler/v1.24.7 (linux/amd64) kubernetes/e6f3597/leader-election" 'https://172.18.0.2:6443/apis/coordination.k8s.io/v1/namespaces/kube-system/leases/kube-scheduler?timeout=5s'
I0501 08:22:01.422790       1 round_trippers.go:553] GET https://172.18.0.2:6443/apis/coordination.k8s.io/v1/namespaces/kube-system/leases/kube-scheduler?timeout=5s 200 OK in 5 milliseconds
I0501 08:22:01.422845       1 round_trippers.go:570] HTTP Statistics: GetConnection 0 ms ServerProcessing 5 ms Duration 5 ms
I0501 08:22:01.422863       1 round_trippers.go:577] Response Headers:
I0501 08:22:01.422883       1 round_trippers.go:580]     X-Kubernetes-Pf-Prioritylevel-Uid: afabb116-6975-46b8-863b-3258bec9e1ea
I0501 08:22:01.422900       1 round_trippers.go:580]     Content-Length: 432
I0501 08:22:01.422917       1 round_trippers.go:580]     Date: Mon, 01 May 2023 08:22:01 GMT
I0501 08:22:01.422934       1 round_trippers.go:580]     Audit-Id: 90193f9e-d200-4ebd-9c9e-58a65107e1f2
I0501 08:22:01.422950       1 round_trippers.go:580]     Cache-Control: no-cache, private
I0501 08:22:01.422967       1 round_trippers.go:580]     Content-Type: application/vnd.kubernetes.protobuf
I0501 08:22:01.422983       1 round_trippers.go:580]     X-Kubernetes-Pf-Flowschema-Uid: 493426e8-0f6d-4ea6-bc2c-2d926c7e3221
I0501 08:22:01.423062       1 request.go:1152] Response Body:
00000000  6b 38 73 00 0a 1f 0a 16  63 6f 6f 72 64 69 6e 61  |k8s.....coordina|
00000010  74 69 6f 6e 2e 6b 38 73  2e 69 6f 2f 76 31 12 05  |tion.k8s.io/v1..|
00000020  4c 65 61 73 65 12 84 03  0a a6 02 0a 0e 6b 75 62  |Lease........kub|
00000030  65 2d 73 63 68 65 64 75  6c 65 72 12 00 1a 0b 6b  |e-scheduler....k|
00000040  75 62 65 2d 73 79 73 74  65 6d 22 00 2a 24 36 61  |ube-system".*$6a|
00000050  30 65 32 30 33 66 2d 65  32 38 30 2d 34 36 61 30  |0e203f-e280-46a0|
00000060  2d 39 35 33 62 2d 35 66  62 64 63 37 38 61 63 38  |-953b-5fbdc78ac8|
00000070  36 65 32 07 32 32 36 38  36 39 34 38 00 42 08 08  |6e2.22686948.B..|
00000080  b1 b2 e2 a1 06 10 00 7a  00 8a 01 c4 01 0a 0e 6b  |.......z.......k|
00000090  75 62 65 2d 73 63 68 65  64 75 6c 65 72 12 06 55  |ube-scheduler..U|
000000a0  70 64 61 74 65 1a 16 63  6f 6f 72 64 69 6e 61 74  |pdate..coordinat|
000000b0  69 6f 6e 2e 6b 38 73 2e  69 6f 2f 76 31 22 08 08  |ion.k8s.io/v1"..|
000000c0  b1 b2 e2 a1 06 10 00 32  08 46 69 65 6c 64 73 56  |.......2.FieldsV|
000000d0  31 3a 7c 0a 7a 7b 22 66  3a 73 70 65 63 22 3a 7b  |1:|.z{"f:spec":{|
000000e0  22 66 3a 61 63 71 75 69  72 65 54 69 6d 65 22 3a  |"f:acquireTime":|
000000f0  7b 7d 2c 22 66 3a 68 6f  6c 64 65 72 49 64 65 6e  |{},"f:holderIden|
00000100  74 69 74 79 22 3a 7b 7d  2c 22 66 3a 6c 65 61 73  |tity":{},"f:leas|
00000110  65 44 75 72 61 74 69 6f  6e 53 65 63 6f 6e 64 73  |eDurationSeconds|
00000120  22 3a 7b 7d 2c 22 66 3a  6c 65 61 73 65 54 72 61  |":{},"f:leaseTra|
00000130  6e 73 69 74 69 6f 6e 73  22 3a 7b 7d 2c 22 66 3a  |nsitions":{},"f:|
00000140  72 65 6e 65 77 54 69 6d  65 22 3a 7b 7d 7d 7d 42  |renewTime":{}}}B|
00000150  00 12 59 0a 37 6b 69 6e  64 2d 63 6f 6e 74 72 6f  |..Y.7kind-contro|
00000160  6c 2d 70 6c 61 6e 65 5f  30 64 32 66 61 66 39 33  |l-plane_0d2faf93|
00000170  2d 34 61 30 62 2d 34 66  32 38 2d 38 33 64 33 2d  |-4a0b-4f28-83d3-|
00000180  35 62 35 62 62 66 61 31  65 36 31 30 10 0f 1a 0c  |5b5bbfa1e610....|
00000190  08 f7 a5 86 a2 06 10 b9  84 b7 94 03 22 0c 08 a7  |............"...|
000001a0  ed bd a2 06 10 8a ed b9  be 01 28 0a 1a 00 22 00  |..........(...".|
I0501 08:22:01.423499       1 request.go:1152] Request Body:
00000000  6b 38 73 00 0a 1f 0a 16  63 6f 6f 72 64 69 6e 61  |k8s.....coordina|
00000010  74 69 6f 6e 2e 6b 38 73  2e 69 6f 2f 76 31 12 05  |tion.k8s.io/v1..|
00000020  4c 65 61 73 65 12 84 03  0a a6 02 0a 0e 6b 75 62  |Lease........kub|
00000030  65 2d 73 63 68 65 64 75  6c 65 72 12 00 1a 0b 6b  |e-scheduler....k|
00000040  75 62 65 2d 73 79 73 74  65 6d 22 00 2a 24 36 61  |ube-system".*$6a|
00000050  30 65 32 30 33 66 2d 65  32 38 30 2d 34 36 61 30  |0e203f-e280-46a0|
00000060  2d 39 35 33 62 2d 35 66  62 64 63 37 38 61 63 38  |-953b-5fbdc78ac8|
00000070  36 65 32 07 32 32 36 38  36 39 34 38 00 42 08 08  |6e2.22686948.B..|
00000080  b1 b2 e2 a1 06 10 00 7a  00 8a 01 c4 01 0a 0e 6b  |.......z.......k|
00000090  75 62 65 2d 73 63 68 65  64 75 6c 65 72 12 06 55  |ube-scheduler..U|
000000a0  70 64 61 74 65 1a 16 63  6f 6f 72 64 69 6e 61 74  |pdate..coordinat|
000000b0  69 6f 6e 2e 6b 38 73 2e  69 6f 2f 76 31 22 08 08  |ion.k8s.io/v1"..|
000000c0  b1 b2 e2 a1 06 10 00 32  08 46 69 65 6c 64 73 56  |.......2.FieldsV|
000000d0  31 3a 7c 0a 7a 7b 22 66  3a 73 70 65 63 22 3a 7b  |1:|.z{"f:spec":{|
000000e0  22 66 3a 61 63 71 75 69  72 65 54 69 6d 65 22 3a  |"f:acquireTime":|
000000f0  7b 7d 2c 22 66 3a 68 6f  6c 64 65 72 49 64 65 6e  |{},"f:holderIden|
00000100  74 69 74 79 22 3a 7b 7d  2c 22 66 3a 6c 65 61 73  |tity":{},"f:leas|
00000110  65 44 75 72 61 74 69 6f  6e 53 65 63 6f 6e 64 73  |eDurationSeconds|
00000120  22 3a 7b 7d 2c 22 66 3a  6c 65 61 73 65 54 72 61  |":{},"f:leaseTra|
00000130  6e 73 69 74 69 6f 6e 73  22 3a 7b 7d 2c 22 66 3a  |nsitions":{},"f:|
00000140  72 65 6e 65 77 54 69 6d  65 22 3a 7b 7d 7d 7d 42  |renewTime":{}}}B|
00000150  00 12 59 0a 37 6b 69 6e  64 2d 63 6f 6e 74 72 6f  |..Y.7kind-contro|
00000160  6c 2d 70 6c 61 6e 65 5f  30 64 32 66 61 66 39 33  |l-plane_0d2faf93|
00000170  2d 34 61 30 62 2d 34 66  32 38 2d 38 33 64 33 2d  |-4a0b-4f28-83d3-|
00000180  35 62 35 62 62 66 61 31  65 36 31 30 10 0f 1a 0c  |5b5bbfa1e610....|
00000190  08 f7 a5 86 a2 06 10 b9  84 b7 94 03 22 0c 08 a9  |............"...|
000001a0  ed bd a2 06 10 e2 8b da  c6 01 28 0a 1a 00 22 00  |..........(...".|
I0501 08:22:01.423666       1 round_trippers.go:466] curl -v -XPUT  -H "Accept: application/vnd.kubernetes.protobuf, */*" -H "Content-Type: application/vnd.kubernetes.protobuf" -H "User-Agent: kube-scheduler/v1.24.7 (linux/amd64) kubernetes/e6f3597/leader-election" 'https://172.18.0.2:6443/apis/coordination.k8s.io/v1/namespaces/kube-system/leases/kube-scheduler?timeout=5s'
I0501 08:22:01.431223       1 round_trippers.go:553] PUT https://172.18.0.2:6443/apis/coordination.k8s.io/v1/namespaces/kube-system/leases/kube-scheduler?timeout=5s 200 OK in 7 milliseconds
I0501 08:22:01.431261       1 round_trippers.go:570] HTTP Statistics: GetConnection 0 ms ServerProcessing 7 ms Duration 7 ms
I0501 08:22:01.431280       1 round_trippers.go:577] Response Headers:
I0501 08:22:01.431311       1 round_trippers.go:580]     Content-Type: application/vnd.kubernetes.protobuf
I0501 08:22:01.431329       1 round_trippers.go:580]     X-Kubernetes-Pf-Flowschema-Uid: 493426e8-0f6d-4ea6-bc2c-2d926c7e3221
I0501 08:22:01.431347       1 round_trippers.go:580]     X-Kubernetes-Pf-Prioritylevel-Uid: afabb116-6975-46b8-863b-3258bec9e1ea
I0501 08:22:01.431364       1 round_trippers.go:580]     Content-Length: 432
I0501 08:22:01.431381       1 round_trippers.go:580]     Date: Mon, 01 May 2023 08:22:01 GMT
I0501 08:22:01.431398       1 round_trippers.go:580]     Audit-Id: f3005ec2-27bf-465d-beda-53f2a757d166
I0501 08:22:01.431415       1 round_trippers.go:580]     Cache-Control: no-cache, private
I0501 08:22:01.431479       1 request.go:1152] Response Body:
00000000  6b 38 73 00 0a 1f 0a 16  63 6f 6f 72 64 69 6e 61  |k8s.....coordina|
00000010  74 69 6f 6e 2e 6b 38 73  2e 69 6f 2f 76 31 12 05  |tion.k8s.io/v1..|
00000020  4c 65 61 73 65 12 84 03  0a a6 02 0a 0e 6b 75 62  |Lease........kub|
00000030  65 2d 73 63 68 65 64 75  6c 65 72 12 00 1a 0b 6b  |e-scheduler....k|
00000040  75 62 65 2d 73 79 73 74  65 6d 22 00 2a 24 36 61  |ube-system".*$6a|
00000050  30 65 32 30 33 66 2d 65  32 38 30 2d 34 36 61 30  |0e203f-e280-46a0|
00000060  2d 39 35 33 62 2d 35 66  62 64 63 37 38 61 63 38  |-953b-5fbdc78ac8|
00000070  36 65 32 07 32 32 36 38  36 39 36 38 00 42 08 08  |6e2.22686968.B..|
00000080  b1 b2 e2 a1 06 10 00 7a  00 8a 01 c4 01 0a 0e 6b  |.......z.......k|
00000090  75 62 65 2d 73 63 68 65  64 75 6c 65 72 12 06 55  |ube-scheduler..U|
000000a0  70 64 61 74 65 1a 16 63  6f 6f 72 64 69 6e 61 74  |pdate..coordinat|
000000b0  69 6f 6e 2e 6b 38 73 2e  69 6f 2f 76 31 22 08 08  |ion.k8s.io/v1"..|
000000c0  b1 b2 e2 a1 06 10 00 32  08 46 69 65 6c 64 73 56  |.......2.FieldsV|
000000d0  31 3a 7c 0a 7a 7b 22 66  3a 73 70 65 63 22 3a 7b  |1:|.z{"f:spec":{|
000000e0  22 66 3a 61 63 71 75 69  72 65 54 69 6d 65 22 3a  |"f:acquireTime":|
000000f0  7b 7d 2c 22 66 3a 68 6f  6c 64 65 72 49 64 65 6e  |{},"f:holderIden|
00000100  74 69 74 79 22 3a 7b 7d  2c 22 66 3a 6c 65 61 73  |tity":{},"f:leas|
00000110  65 44 75 72 61 74 69 6f  6e 53 65 63 6f 6e 64 73  |eDurationSeconds|
00000120  22 3a 7b 7d 2c 22 66 3a  6c 65 61 73 65 54 72 61  |":{},"f:leaseTra|
00000130  6e 73 69 74 69 6f 6e 73  22 3a 7b 7d 2c 22 66 3a  |nsitions":{},"f:|
00000140  72 65 6e 65 77 54 69 6d  65 22 3a 7b 7d 7d 7d 42  |renewTime":{}}}B|
00000150  00 12 59 0a 37 6b 69 6e  64 2d 63 6f 6e 74 72 6f  |..Y.7kind-contro|
00000160  6c 2d 70 6c 61 6e 65 5f  30 64 32 66 61 66 39 33  |l-plane_0d2faf93|
00000170  2d 34 61 30 62 2d 34 66  32 38 2d 38 33 64 33 2d  |-4a0b-4f28-83d3-|
00000180  35 62 35 62 62 66 61 31  65 36 31 30 10 0f 1a 0c  |5b5bbfa1e610....|
00000190  08 f7 a5 86 a2 06 10 b9  84 b7 94 03 22 0c 08 a9  |............"...|
000001a0  ed bd a2 06 10 e2 8b da  c6 01 28 0a 1a 00 22 00  |..........(...".|
I0501 08:22:01.431605       1 leaderelection.go:278] successfully renewed lease kube-system/kube-scheduler
I0501 08:22:01.680068       1 eventhandlers.go:116] "Add event for unscheduled pod" pod="default/nginx-deployment-66f58bff7c-5qjrc"
I0501 08:22:01.680699       1 scheduling_queue.go:956] "About to try and schedule pod" pod="default/nginx-deployment-66f58bff7c-5qjrc"
I0501 08:22:01.680761       1 schedule_one.go:84] "Attempting to schedule pod" pod="default/nginx-deployment-66f58bff7c-5qjrc"
I0501 08:22:01.682836       1 resource_allocation.go:70] "Listing internal info for allocatable resources, requested resources and score" pod="default/nginx-deployment-66f58bff7c-5qjrc" node="kind-worker3" resourceAllocationScorer="LeastAllocated" allocatableResource=map[cpu:8000 memory:8362762240] requestedResource=map[cpu:400 memory:471859200] resourceScore=94
I0501 08:22:01.682906       1 resource_allocation.go:70] "Listing internal info for allocatable resources, requested resources and score" pod="default/nginx-deployment-66f58bff7c-5qjrc" node="kind-worker2" resourceAllocationScorer="LeastAllocated" allocatableResource=map[cpu:8000 memory:8362762240] requestedResource=map[cpu:700 memory:891289600] resourceScore=90
I0501 08:22:01.682985       1 resource_allocation.go:70] "Listing internal info for allocatable resources, requested resources and score" pod="default/nginx-deployment-66f58bff7c-5qjrc" node="kind-worker2" resourceAllocationScorer="NodeResourcesBalancedAllocation" allocatableResource=map[cpu:8000 memory:8362762240] requestedResource=map[cpu:600 memory:262144000] resourceScore=97
I0501 08:22:01.682931       1 resource_allocation.go:70] "Listing internal info for allocatable resources, requested resources and score" pod="default/nginx-deployment-66f58bff7c-5qjrc" node="kind-worker3" resourceAllocationScorer="NodeResourcesBalancedAllocation" allocatableResource=map[cpu:8000 memory:8362762240] requestedResource=map[cpu:300 memory:52428800] resourceScore=98
I0501 08:22:01.682837       1 resource_allocation.go:70] "Listing internal info for allocatable resources, requested resources and score" pod="default/nginx-deployment-66f58bff7c-5qjrc" node="kind-worker" resourceAllocationScorer="LeastAllocated" allocatableResource=map[cpu:8000 memory:8362762240] requestedResource=map[cpu:800 memory:891289600] resourceScore=89
I0501 08:22:01.683173       1 resource_allocation.go:70] "Listing internal info for allocatable resources, requested resources and score" pod="default/nginx-deployment-66f58bff7c-5qjrc" node="kind-worker" resourceAllocationScorer="NodeResourcesBalancedAllocation" allocatableResource=map[cpu:8000 memory:8362762240] requestedResource=map[cpu:700 memory:52428800] resourceScore=95
I0501 08:22:01.683319       1 schedule_one.go:645] "Plugin scored node for pod" pod="default/nginx-deployment-66f58bff7c-5qjrc" plugin="NodeResourcesFit" node="kind-worker3" score=94
I0501 08:22:01.683367       1 schedule_one.go:645] "Plugin scored node for pod" pod="default/nginx-deployment-66f58bff7c-5qjrc" plugin="NodeResourcesFit" node="kind-worker" score=89
I0501 08:22:01.683389       1 schedule_one.go:645] "Plugin scored node for pod" pod="default/nginx-deployment-66f58bff7c-5qjrc" plugin="NodeResourcesFit" node="kind-worker2" score=90
I0501 08:22:01.683409       1 schedule_one.go:645] "Plugin scored node for pod" pod="default/nginx-deployment-66f58bff7c-5qjrc" plugin="VolumeBinding" node="kind-worker3" score=0
I0501 08:22:01.683437       1 schedule_one.go:645] "Plugin scored node for pod" pod="default/nginx-deployment-66f58bff7c-5qjrc" plugin="VolumeBinding" node="kind-worker" score=0
I0501 08:22:01.683457       1 schedule_one.go:645] "Plugin scored node for pod" pod="default/nginx-deployment-66f58bff7c-5qjrc" plugin="VolumeBinding" node="kind-worker2" score=0
I0501 08:22:01.683482       1 schedule_one.go:645] "Plugin scored node for pod" pod="default/nginx-deployment-66f58bff7c-5qjrc" plugin="PodTopologySpread" node="kind-worker3" score=200
I0501 08:22:01.683501       1 schedule_one.go:645] "Plugin scored node for pod" pod="default/nginx-deployment-66f58bff7c-5qjrc" plugin="PodTopologySpread" node="kind-worker" score=80
I0501 08:22:01.683521       1 schedule_one.go:645] "Plugin scored node for pod" pod="default/nginx-deployment-66f58bff7c-5qjrc" plugin="PodTopologySpread" node="kind-worker2" score=120
I0501 08:22:01.683540       1 schedule_one.go:645] "Plugin scored node for pod" pod="default/nginx-deployment-66f58bff7c-5qjrc" plugin="InterPodAffinity" node="kind-worker3" score=0
I0501 08:22:01.683576       1 schedule_one.go:645] "Plugin scored node for pod" pod="default/nginx-deployment-66f58bff7c-5qjrc" plugin="InterPodAffinity" node="kind-worker" score=0
I0501 08:22:01.683598       1 schedule_one.go:645] "Plugin scored node for pod" pod="default/nginx-deployment-66f58bff7c-5qjrc" plugin="InterPodAffinity" node="kind-worker2" score=0
I0501 08:22:01.683625       1 schedule_one.go:645] "Plugin scored node for pod" pod="default/nginx-deployment-66f58bff7c-5qjrc" plugin="NodeResourcesBalancedAllocation" node="kind-worker3" score=98
I0501 08:22:01.683645       1 schedule_one.go:645] "Plugin scored node for pod" pod="default/nginx-deployment-66f58bff7c-5qjrc" plugin="NodeResourcesBalancedAllocation" node="kind-worker" score=95
I0501 08:22:01.683664       1 schedule_one.go:645] "Plugin scored node for pod" pod="default/nginx-deployment-66f58bff7c-5qjrc" plugin="NodeResourcesBalancedAllocation" node="kind-worker2" score=97
I0501 08:22:01.683683       1 schedule_one.go:645] "Plugin scored node for pod" pod="default/nginx-deployment-66f58bff7c-5qjrc" plugin="ImageLocality" node="kind-worker3" score=0
I0501 08:22:01.683708       1 schedule_one.go:645] "Plugin scored node for pod" pod="default/nginx-deployment-66f58bff7c-5qjrc" plugin="ImageLocality" node="kind-worker" score=0
I0501 08:22:01.683728       1 schedule_one.go:645] "Plugin scored node for pod" pod="default/nginx-deployment-66f58bff7c-5qjrc" plugin="ImageLocality" node="kind-worker2" score=0
I0501 08:22:01.683754       1 schedule_one.go:645] "Plugin scored node for pod" pod="default/nginx-deployment-66f58bff7c-5qjrc" plugin="TaintToleration" node="kind-worker3" score=300
I0501 08:22:01.683774       1 schedule_one.go:645] "Plugin scored node for pod" pod="default/nginx-deployment-66f58bff7c-5qjrc" plugin="TaintToleration" node="kind-worker" score=300
I0501 08:22:01.683799       1 schedule_one.go:645] "Plugin scored node for pod" pod="default/nginx-deployment-66f58bff7c-5qjrc" plugin="TaintToleration" node="kind-worker2" score=300
I0501 08:22:01.683818       1 schedule_one.go:645] "Plugin scored node for pod" pod="default/nginx-deployment-66f58bff7c-5qjrc" plugin="NodeAffinity" node="kind-worker3" score=0
I0501 08:22:01.683842       1 schedule_one.go:645] "Plugin scored node for pod" pod="default/nginx-deployment-66f58bff7c-5qjrc" plugin="NodeAffinity" node="kind-worker" score=0
I0501 08:22:01.683862       1 schedule_one.go:645] "Plugin scored node for pod" pod="default/nginx-deployment-66f58bff7c-5qjrc" plugin="NodeAffinity" node="kind-worker2" score=0
I0501 08:22:01.683889       1 schedule_one.go:703] "Calculated node's final score for pod" pod="default/nginx-deployment-66f58bff7c-5qjrc" node="kind-worker3" score=692
I0501 08:22:01.683909       1 schedule_one.go:703] "Calculated node's final score for pod" pod="default/nginx-deployment-66f58bff7c-5qjrc" node="kind-worker" score=564
I0501 08:22:01.683938       1 schedule_one.go:703] "Calculated node's final score for pod" pod="default/nginx-deployment-66f58bff7c-5qjrc" node="kind-worker2" score=607
I0501 08:22:01.684186       1 default_binder.go:52] "Attempting to bind pod to node" pod="default/nginx-deployment-66f58bff7c-5qjrc" node="kind-worker3"
I0501 08:22:01.684317       1 request.go:1152] Request Body:
00000000  6b 38 73 00 0a 0d 0a 02  76 31 12 07 42 69 6e 64  |k8s.....v1..Bind|
00000010  69 6e 67 12 80 01 0a 5e  0a 21 6e 67 69 6e 78 2d  |ing....^.!nginx-|
00000020  64 65 70 6c 6f 79 6d 65  6e 74 2d 36 36 66 35 38  |deployment-66f58|
00000030  62 66 66 37 63 2d 35 71  6a 72 63 12 00 1a 07 64  |bff7c-5qjrc....d|
00000040  65 66 61 75 6c 74 22 00  2a 24 32 64 37 65 35 62  |efault".*$2d7e5b|
00000050  33 30 2d 30 61 36 30 2d  34 30 30 64 2d 62 33 39  |30-0a60-400d-b39|
00000060  37 2d 36 66 39 66 35 61  63 32 33 38 63 32 32 00  |7-6f9f5ac238c22.|
00000070  38 00 42 00 7a 00 12 1e  0a 04 4e 6f 64 65 12 00  |8.B.z.....Node..|
00000080  1a 0c 6b 69 6e 64 2d 77  6f 72 6b 65 72 33 22 00  |..kind-worker3".|
00000090  2a 00 32 00 3a 00 1a 00  22 00                    |*.2.:...".|
I0501 08:22:01.684454       1 round_trippers.go:466] curl -v -XPOST  -H "Accept: application/vnd.kubernetes.protobuf, */*" -H "Content-Type: application/vnd.kubernetes.protobuf" -H "User-Agent: kube-scheduler/v1.24.7 (linux/amd64) kubernetes/e6f3597/scheduler" 'https://172.18.0.2:6443/api/v1/namespaces/default/pods/nginx-deployment-66f58bff7c-5qjrc/binding'
I0501 08:22:01.703599       1 round_trippers.go:553] POST https://172.18.0.2:6443/api/v1/namespaces/default/pods/nginx-deployment-66f58bff7c-5qjrc/binding 201 Created in 19 milliseconds
I0501 08:22:01.703651       1 round_trippers.go:570] HTTP Statistics: GetConnection 0 ms ServerProcessing 18 ms Duration 19 ms
I0501 08:22:01.703668       1 round_trippers.go:577] Response Headers:
I0501 08:22:01.703686       1 round_trippers.go:580]     Content-Length: 48
I0501 08:22:01.703702       1 round_trippers.go:580]     Date: Mon, 01 May 2023 08:22:01 GMT
I0501 08:22:01.703717       1 round_trippers.go:580]     Audit-Id: 17639c87-8199-412d-bb71-a8757001e20f
I0501 08:22:01.703732       1 round_trippers.go:580]     Cache-Control: no-cache, private
I0501 08:22:01.703747       1 round_trippers.go:580]     Content-Type: application/vnd.kubernetes.protobuf
I0501 08:22:01.703762       1 round_trippers.go:580]     X-Kubernetes-Pf-Flowschema-Uid: 8a935dea-6b5d-4402-a842-ba69f911704f
I0501 08:22:01.703779       1 round_trippers.go:580]     X-Kubernetes-Pf-Prioritylevel-Uid: 4ccc4fdb-4419-4777-8b6f-3ed0d4949e5d
I0501 08:22:01.703866       1 request.go:1152] Response Body:
00000000  6b 38 73 00 0a 0c 0a 02  76 31 12 06 53 74 61 74  |k8s.....v1..Stat|
00000010  75 73 12 18 0a 06 0a 00  12 00 1a 00 12 07 53 75  |us............Su|
00000020  63 63 65 73 73 1a 00 22  00 30 c9 01 1a 00 22 00  |ccess..".0....".|
I0501 08:22:01.703972       1 cache.go:379] "Finished binding for pod, can be expired" pod="default/nginx-deployment-66f58bff7c-5qjrc"
I0501 08:22:01.704137       1 schedule_one.go:265] "Successfully bound pod to node" pod="default/nginx-deployment-66f58bff7c-5qjrc" node="kind-worker3" evaluatedNodes=4 feasibleNodes=3
I0501 08:22:01.704499       1 request.go:1152] Request Body:
00000000  6b 38 73 00 0a 19 0a 10  65 76 65 6e 74 73 2e 6b  |k8s.....events.k|
00000010  38 73 2e 69 6f 2f 76 31  12 05 45 76 65 6e 74 12  |8s.io/v1..Event.|
00000020  f5 02 0a 4b 0a 32 6e 67  69 6e 78 2d 64 65 70 6c  |...K.2nginx-depl|
00000030  6f 79 6d 65 6e 74 2d 36  36 66 35 38 62 66 66 37  |oyment-66f58bff7|
00000040  63 2d 35 71 6a 72 63 2e  31 37 35 61 66 37 34 64  |c-5qjrc.175af74d|
00000050  33 32 34 32 31 39 37 31  12 00 1a 07 64 65 66 61  |32421971....defa|
00000060  75 6c 74 22 00 2a 00 32  00 38 00 42 00 7a 00 12  |ult".*.2.8.B.z..|
00000070  0c 08 a9 ed bd a2 06 10  cd f0 d8 cf 02 22 11 64  |.............".d|
00000080  65 66 61 75 6c 74 2d 73  63 68 65 64 75 6c 65 72  |efault-scheduler|
00000090  2a 24 64 65 66 61 75 6c  74 2d 73 63 68 65 64 75  |*$default-schedu|
000000a0  6c 65 72 2d 6b 69 6e 64  2d 63 6f 6e 74 72 6f 6c  |ler-kind-control|
000000b0  2d 70 6c 61 6e 65 32 07  42 69 6e 64 69 6e 67 3a  |-plane2.Binding:|
000000c0  09 53 63 68 65 64 75 6c  65 64 42 66 0a 03 50 6f  |.ScheduledBf..Po|
000000d0  64 12 07 64 65 66 61 75  6c 74 1a 21 6e 67 69 6e  |d..default.!ngin|
000000e0  78 2d 64 65 70 6c 6f 79  6d 65 6e 74 2d 36 36 66  |x-deployment-66f|
000000f0  35 38 62 66 66 37 63 2d  35 71 6a 72 63 22 24 32  |58bff7c-5qjrc"$2|
00000100  64 37 65 35 62 33 30 2d  30 61 36 30 2d 34 30 30  |d7e5b30-0a60-400|
00000110  64 2d 62 33 39 37 2d 36  66 39 66 35 61 63 32 33  |d-b397-6f9f5ac23|
00000120  38 63 32 2a 02 76 31 32  07 32 32 36 38 37 30 33  |8c2*.v12.2268703|
00000130  3a 00 52 4f 53 75 63 63  65 73 73 66 75 6c 6c 79  |:.ROSuccessfully|
00000140  20 61 73 73 69 67 6e 65  64 20 64 65 66 61 75 6c  | assigned defaul|
00000150  74 2f 6e 67 69 6e 78 2d  64 65 70 6c 6f 79 6d 65  |t/nginx-deployme|
00000160  6e 74 2d 36 36 66 35 38  62 66 66 37 63 2d 35 71  |nt-66f58bff7c-5q|
00000170  6a 72 63 20 74 6f 20 6b  69 6e 64 2d 77 6f 72 6b  |jrc to kind-work|
00000180  65 72 33 5a 06 4e 6f 72  6d 61 6c 62 04 0a 00 12  |er3Z.Normalb....|
00000190  00 6a 00 72 00 78 00 1a  00 22 00                 |.j.r.x...".|
I0501 08:22:01.707352       1 round_trippers.go:466] curl -v -XPOST  -H "Accept: application/vnd.kubernetes.protobuf, */*" -H "Content-Type: application/vnd.kubernetes.protobuf" -H "User-Agent: kube-scheduler/v1.24.7 (linux/amd64) kubernetes/e6f3597/scheduler" 'https://172.18.0.2:6443/apis/events.k8s.io/v1/namespaces/default/events'
I0501 08:22:01.709866       1 eventhandlers.go:159] "Delete event for unscheduled pod" pod="default/nginx-deployment-66f58bff7c-5qjrc"
I0501 08:22:01.709956       1 eventhandlers.go:184] "Add event for scheduled pod" pod="default/nginx-deployment-66f58bff7c-5qjrc"
I0501 08:22:01.710047       1 eventhandlers.go:116] "Add event for unscheduled pod" pod="default/nginx-deployment-66f58bff7c-jgvtk"
I0501 08:22:01.710107       1 eventhandlers.go:116] "Add event for unscheduled pod" pod="default/nginx-deployment-66f58bff7c-rdxnf"
I0501 08:22:01.710193       1 scheduling_queue.go:956] "About to try and schedule pod" pod="default/nginx-deployment-66f58bff7c-jgvtk"
I0501 08:22:01.710217       1 schedule_one.go:84] "Attempting to schedule pod" pod="default/nginx-deployment-66f58bff7c-jgvtk"
I0501 08:22:01.714690       1 resource_allocation.go:70] "Listing internal info for allocatable resources, requested resources and score" pod="default/nginx-deployment-66f58bff7c-jgvtk" node="kind-worker" resourceAllocationScorer="LeastAllocated" allocatableResource=map[cpu:8000 memory:8362762240] requestedResource=map[cpu:800 memory:891289600] resourceScore=89
I0501 08:22:01.714759       1 resource_allocation.go:70] "Listing internal info for allocatable resources, requested resources and score" pod="default/nginx-deployment-66f58bff7c-jgvtk" node="kind-worker" resourceAllocationScorer="NodeResourcesBalancedAllocation" allocatableResource=map[cpu:8000 memory:8362762240] requestedResource=map[cpu:700 memory:52428800] resourceScore=95
I0501 08:22:01.714820       1 resource_allocation.go:70] "Listing internal info for allocatable resources, requested resources and score" pod="default/nginx-deployment-66f58bff7c-jgvtk" node="kind-worker3" resourceAllocationScorer="LeastAllocated" allocatableResource=map[cpu:8000 memory:8362762240] requestedResource=map[cpu:600 memory:681574400] resourceScore=91
I0501 08:22:01.714864       1 resource_allocation.go:70] "Listing internal info for allocatable resources, requested resources and score" pod="default/nginx-deployment-66f58bff7c-jgvtk" node="kind-worker3" resourceAllocationScorer="NodeResourcesBalancedAllocation" allocatableResource=map[cpu:8000 memory:8362762240] requestedResource=map[cpu:500 memory:52428800] resourceScore=97
I0501 08:22:01.714903       1 resource_allocation.go:70] "Listing internal info for allocatable resources, requested resources and score" pod="default/nginx-deployment-66f58bff7c-jgvtk" node="kind-worker2" resourceAllocationScorer="LeastAllocated" allocatableResource=map[cpu:8000 memory:8362762240] requestedResource=map[cpu:700 memory:891289600] resourceScore=90
I0501 08:22:01.714985       1 resource_allocation.go:70] "Listing internal info for allocatable resources, requested resources and score" pod="default/nginx-deployment-66f58bff7c-jgvtk" node="kind-worker2" resourceAllocationScorer="NodeResourcesBalancedAllocation" allocatableResource=map[cpu:8000 memory:8362762240] requestedResource=map[cpu:600 memory:262144000] resourceScore=97
I0501 08:22:01.715150       1 schedule_one.go:645] "Plugin scored node for pod" pod="default/nginx-deployment-66f58bff7c-jgvtk" plugin="ImageLocality" node="kind-worker" score=0
I0501 08:22:01.715186       1 schedule_one.go:645] "Plugin scored node for pod" pod="default/nginx-deployment-66f58bff7c-jgvtk" plugin="ImageLocality" node="kind-worker3" score=0
I0501 08:22:01.715206       1 schedule_one.go:645] "Plugin scored node for pod" pod="default/nginx-deployment-66f58bff7c-jgvtk" plugin="ImageLocality" node="kind-worker2" score=0
I0501 08:22:01.715226       1 schedule_one.go:645] "Plugin scored node for pod" pod="default/nginx-deployment-66f58bff7c-jgvtk" plugin="TaintToleration" node="kind-worker" score=300
I0501 08:22:01.715262       1 schedule_one.go:645] "Plugin scored node for pod" pod="default/nginx-deployment-66f58bff7c-jgvtk" plugin="TaintToleration" node="kind-worker3" score=300
I0501 08:22:01.715293       1 schedule_one.go:645] "Plugin scored node for pod" pod="default/nginx-deployment-66f58bff7c-jgvtk" plugin="TaintToleration" node="kind-worker2" score=300
I0501 08:22:01.715315       1 schedule_one.go:645] "Plugin scored node for pod" pod="default/nginx-deployment-66f58bff7c-jgvtk" plugin="NodeAffinity" node="kind-worker" score=0
I0501 08:22:01.715340       1 schedule_one.go:645] "Plugin scored node for pod" pod="default/nginx-deployment-66f58bff7c-jgvtk" plugin="NodeAffinity" node="kind-worker3" score=0
I0501 08:22:01.715360       1 schedule_one.go:645] "Plugin scored node for pod" pod="default/nginx-deployment-66f58bff7c-jgvtk" plugin="NodeAffinity" node="kind-worker2" score=0
I0501 08:22:01.715382       1 schedule_one.go:645] "Plugin scored node for pod" pod="default/nginx-deployment-66f58bff7c-jgvtk" plugin="NodeResourcesFit" node="kind-worker" score=89
I0501 08:22:01.715403       1 schedule_one.go:645] "Plugin scored node for pod" pod="default/nginx-deployment-66f58bff7c-jgvtk" plugin="NodeResourcesFit" node="kind-worker3" score=91
I0501 08:22:01.715435       1 schedule_one.go:645] "Plugin scored node for pod" pod="default/nginx-deployment-66f58bff7c-jgvtk" plugin="NodeResourcesFit" node="kind-worker2" score=90
I0501 08:22:01.715455       1 schedule_one.go:645] "Plugin scored node for pod" pod="default/nginx-deployment-66f58bff7c-jgvtk" plugin="VolumeBinding" node="kind-worker" score=0
I0501 08:22:01.715474       1 schedule_one.go:645] "Plugin scored node for pod" pod="default/nginx-deployment-66f58bff7c-jgvtk" plugin="VolumeBinding" node="kind-worker3" score=0
I0501 08:22:01.715501       1 schedule_one.go:645] "Plugin scored node for pod" pod="default/nginx-deployment-66f58bff7c-jgvtk" plugin="VolumeBinding" node="kind-worker2" score=0
I0501 08:22:01.715526       1 schedule_one.go:645] "Plugin scored node for pod" pod="default/nginx-deployment-66f58bff7c-jgvtk" plugin="PodTopologySpread" node="kind-worker" score=160
I0501 08:22:01.715547       1 schedule_one.go:645] "Plugin scored node for pod" pod="default/nginx-deployment-66f58bff7c-jgvtk" plugin="PodTopologySpread" node="kind-worker3" score=200
I0501 08:22:01.715566       1 schedule_one.go:645] "Plugin scored node for pod" pod="default/nginx-deployment-66f58bff7c-jgvtk" plugin="PodTopologySpread" node="kind-worker2" score=200
I0501 08:22:01.715599       1 schedule_one.go:645] "Plugin scored node for pod" pod="default/nginx-deployment-66f58bff7c-jgvtk" plugin="InterPodAffinity" node="kind-worker" score=0
I0501 08:22:01.715620       1 schedule_one.go:645] "Plugin scored node for pod" pod="default/nginx-deployment-66f58bff7c-jgvtk" plugin="InterPodAffinity" node="kind-worker3" score=0
I0501 08:22:01.715639       1 schedule_one.go:645] "Plugin scored node for pod" pod="default/nginx-deployment-66f58bff7c-jgvtk" plugin="InterPodAffinity" node="kind-worker2" score=0
I0501 08:22:01.715659       1 schedule_one.go:645] "Plugin scored node for pod" pod="default/nginx-deployment-66f58bff7c-jgvtk" plugin="NodeResourcesBalancedAllocation" node="kind-worker" score=95
I0501 08:22:01.715688       1 schedule_one.go:645] "Plugin scored node for pod" pod="default/nginx-deployment-66f58bff7c-jgvtk" plugin="NodeResourcesBalancedAllocation" node="kind-worker3" score=97
I0501 08:22:01.715760       1 schedule_one.go:645] "Plugin scored node for pod" pod="default/nginx-deployment-66f58bff7c-jgvtk" plugin="NodeResourcesBalancedAllocation" node="kind-worker2" score=97
I0501 08:22:01.715793       1 schedule_one.go:703] "Calculated node's final score for pod" pod="default/nginx-deployment-66f58bff7c-jgvtk" node="kind-worker" score=644
I0501 08:22:01.715820       1 schedule_one.go:703] "Calculated node's final score for pod" pod="default/nginx-deployment-66f58bff7c-jgvtk" node="kind-worker3" score=688
I0501 08:22:01.715839       1 schedule_one.go:703] "Calculated node's final score for pod" pod="default/nginx-deployment-66f58bff7c-jgvtk" node="kind-worker2" score=687
I0501 08:22:01.715973       1 scheduling_queue.go:956] "About to try and schedule pod" pod="default/nginx-deployment-66f58bff7c-rdxnf"
I0501 08:22:01.716002       1 schedule_one.go:84] "Attempting to schedule pod" pod="default/nginx-deployment-66f58bff7c-rdxnf"
I0501 08:22:01.716206       1 default_binder.go:52] "Attempting to bind pod to node" pod="default/nginx-deployment-66f58bff7c-jgvtk" node="kind-worker3"
I0501 08:22:01.716311       1 request.go:1152] Request Body:
00000000  6b 38 73 00 0a 0d 0a 02  76 31 12 07 42 69 6e 64  |k8s.....v1..Bind|
00000010  69 6e 67 12 80 01 0a 5e  0a 21 6e 67 69 6e 78 2d  |ing....^.!nginx-|
00000020  64 65 70 6c 6f 79 6d 65  6e 74 2d 36 36 66 35 38  |deployment-66f58|
00000030  62 66 66 37 63 2d 6a 67  76 74 6b 12 00 1a 07 64  |bff7c-jgvtk....d|
00000040  65 66 61 75 6c 74 22 00  2a 24 37 64 65 38 38 37  |efault".*$7de887|
00000050  31 64 2d 66 38 66 33 2d  34 37 30 61 2d 39 35 62  |1d-f8f3-470a-95b|
00000060  38 2d 32 62 35 66 63 30  36 63 35 34 31 66 32 00  |8-2b5fc06c541f2.|
00000070  38 00 42 00 7a 00 12 1e  0a 04 4e 6f 64 65 12 00  |8.B.z.....Node..|
00000080  1a 0c 6b 69 6e 64 2d 77  6f 72 6b 65 72 33 22 00  |..kind-worker3".|
00000090  2a 00 32 00 3a 00 1a 00  22 00                    |*.2.:...".|
I0501 08:22:01.716410       1 round_trippers.go:466] curl -v -XPOST  -H "Content-Type: application/vnd.kubernetes.protobuf" -H "User-Agent: kube-scheduler/v1.24.7 (linux/amd64) kubernetes/e6f3597/scheduler" -H "Accept: application/vnd.kubernetes.protobuf, */*" 'https://172.18.0.2:6443/api/v1/namespaces/default/pods/nginx-deployment-66f58bff7c-jgvtk/binding'
I0501 08:22:01.716762       1 resource_allocation.go:70] "Listing internal info for allocatable resources, requested resources and score" pod="default/nginx-deployment-66f58bff7c-rdxnf" node="kind-worker" resourceAllocationScorer="LeastAllocated" allocatableResource=map[cpu:8000 memory:8362762240] requestedResource=map[cpu:800 memory:891289600] resourceScore=89
I0501 08:22:01.716824       1 resource_allocation.go:70] "Listing internal info for allocatable resources, requested resources and score" pod="default/nginx-deployment-66f58bff7c-rdxnf" node="kind-worker" resourceAllocationScorer="NodeResourcesBalancedAllocation" allocatableResource=map[cpu:8000 memory:8362762240] requestedResource=map[cpu:700 memory:52428800] resourceScore=95
I0501 08:22:01.716871       1 resource_allocation.go:70] "Listing internal info for allocatable resources, requested resources and score" pod="default/nginx-deployment-66f58bff7c-rdxnf" node="kind-worker3" resourceAllocationScorer="LeastAllocated" allocatableResource=map[cpu:8000 memory:8362762240] requestedResource=map[cpu:800 memory:891289600] resourceScore=89
I0501 08:22:01.716937       1 resource_allocation.go:70] "Listing internal info for allocatable resources, requested resources and score" pod="default/nginx-deployment-66f58bff7c-rdxnf" node="kind-worker3" resourceAllocationScorer="NodeResourcesBalancedAllocation" allocatableResource=map[cpu:8000 memory:8362762240] requestedResource=map[cpu:700 memory:52428800] resourceScore=95
I0501 08:22:01.716984       1 resource_allocation.go:70] "Listing internal info for allocatable resources, requested resources and score" pod="default/nginx-deployment-66f58bff7c-rdxnf" node="kind-worker2" resourceAllocationScorer="LeastAllocated" allocatableResource=map[cpu:8000 memory:8362762240] requestedResource=map[cpu:700 memory:891289600] resourceScore=90
I0501 08:22:01.725616       1 resource_allocation.go:70] "Listing internal info for allocatable resources, requested resources and score" pod="default/nginx-deployment-66f58bff7c-rdxnf" node="kind-worker2" resourceAllocationScorer="NodeResourcesBalancedAllocation" allocatableResource=map[cpu:8000 memory:8362762240] requestedResource=map[cpu:600 memory:262144000] resourceScore=97
I0501 08:22:01.725998       1 schedule_one.go:645] "Plugin scored node for pod" pod="default/nginx-deployment-66f58bff7c-rdxnf" plugin="PodTopologySpread" node="kind-worker" score=160
I0501 08:22:01.726151       1 schedule_one.go:645] "Plugin scored node for pod" pod="default/nginx-deployment-66f58bff7c-rdxnf" plugin="PodTopologySpread" node="kind-worker3" score=160
I0501 08:22:01.726308       1 schedule_one.go:645] "Plugin scored node for pod" pod="default/nginx-deployment-66f58bff7c-rdxnf" plugin="PodTopologySpread" node="kind-worker2" score=200
I0501 08:22:01.726346       1 schedule_one.go:645] "Plugin scored node for pod" pod="default/nginx-deployment-66f58bff7c-rdxnf" plugin="InterPodAffinity" node="kind-worker" score=0
I0501 08:22:01.726477       1 schedule_one.go:645] "Plugin scored node for pod" pod="default/nginx-deployment-66f58bff7c-rdxnf" plugin="InterPodAffinity" node="kind-worker3" score=0
I0501 08:22:01.726510       1 schedule_one.go:645] "Plugin scored node for pod" pod="default/nginx-deployment-66f58bff7c-rdxnf" plugin="InterPodAffinity" node="kind-worker2" score=0
I0501 08:22:01.726634       1 schedule_one.go:645] "Plugin scored node for pod" pod="default/nginx-deployment-66f58bff7c-rdxnf" plugin="NodeResourcesBalancedAllocation" node="kind-worker" score=95
I0501 08:22:01.726772       1 schedule_one.go:645] "Plugin scored node for pod" pod="default/nginx-deployment-66f58bff7c-rdxnf" plugin="NodeResourcesBalancedAllocation" node="kind-worker3" score=95
I0501 08:22:01.726809       1 schedule_one.go:645] "Plugin scored node for pod" pod="default/nginx-deployment-66f58bff7c-rdxnf" plugin="NodeResourcesBalancedAllocation" node="kind-worker2" score=97
I0501 08:22:01.726934       1 schedule_one.go:645] "Plugin scored node for pod" pod="default/nginx-deployment-66f58bff7c-rdxnf" plugin="ImageLocality" node="kind-worker" score=0
I0501 08:22:01.726966       1 schedule_one.go:645] "Plugin scored node for pod" pod="default/nginx-deployment-66f58bff7c-rdxnf" plugin="ImageLocality" node="kind-worker3" score=0
I0501 08:22:01.726986       1 schedule_one.go:645] "Plugin scored node for pod" pod="default/nginx-deployment-66f58bff7c-rdxnf" plugin="ImageLocality" node="kind-worker2" score=0
I0501 08:22:01.727005       1 schedule_one.go:645] "Plugin scored node for pod" pod="default/nginx-deployment-66f58bff7c-rdxnf" plugin="TaintToleration" node="kind-worker" score=300
I0501 08:22:01.727034       1 schedule_one.go:645] "Plugin scored node for pod" pod="default/nginx-deployment-66f58bff7c-rdxnf" plugin="TaintToleration" node="kind-worker3" score=300
I0501 08:22:01.727054       1 schedule_one.go:645] "Plugin scored node for pod" pod="default/nginx-deployment-66f58bff7c-rdxnf" plugin="TaintToleration" node="kind-worker2" score=300
I0501 08:22:01.727073       1 schedule_one.go:645] "Plugin scored node for pod" pod="default/nginx-deployment-66f58bff7c-rdxnf" plugin="NodeAffinity" node="kind-worker" score=0
I0501 08:22:01.727124       1 schedule_one.go:645] "Plugin scored node for pod" pod="default/nginx-deployment-66f58bff7c-rdxnf" plugin="NodeAffinity" node="kind-worker3" score=0
I0501 08:22:01.727145       1 schedule_one.go:645] "Plugin scored node for pod" pod="default/nginx-deployment-66f58bff7c-rdxnf" plugin="NodeAffinity" node="kind-worker2" score=0
I0501 08:22:01.727164       1 schedule_one.go:645] "Plugin scored node for pod" pod="default/nginx-deployment-66f58bff7c-rdxnf" plugin="NodeResourcesFit" node="kind-worker" score=89
I0501 08:22:01.727183       1 schedule_one.go:645] "Plugin scored node for pod" pod="default/nginx-deployment-66f58bff7c-rdxnf" plugin="NodeResourcesFit" node="kind-worker3" score=89
I0501 08:22:01.727213       1 schedule_one.go:645] "Plugin scored node for pod" pod="default/nginx-deployment-66f58bff7c-rdxnf" plugin="NodeResourcesFit" node="kind-worker2" score=90
I0501 08:22:01.727242       1 schedule_one.go:645] "Plugin scored node for pod" pod="default/nginx-deployment-66f58bff7c-rdxnf" plugin="VolumeBinding" node="kind-worker" score=0
I0501 08:22:01.727262       1 schedule_one.go:645] "Plugin scored node for pod" pod="default/nginx-deployment-66f58bff7c-rdxnf" plugin="VolumeBinding" node="kind-worker3" score=0
I0501 08:22:01.727290       1 schedule_one.go:645] "Plugin scored node for pod" pod="default/nginx-deployment-66f58bff7c-rdxnf" plugin="VolumeBinding" node="kind-worker2" score=0
I0501 08:22:01.727316       1 schedule_one.go:703] "Calculated node's final score for pod" pod="default/nginx-deployment-66f58bff7c-rdxnf" node="kind-worker" score=644
I0501 08:22:01.727354       1 schedule_one.go:703] "Calculated node's final score for pod" pod="default/nginx-deployment-66f58bff7c-rdxnf" node="kind-worker3" score=644
I0501 08:22:01.727390       1 schedule_one.go:703] "Calculated node's final score for pod" pod="default/nginx-deployment-66f58bff7c-rdxnf" node="kind-worker2" score=687
I0501 08:22:01.727543       1 default_binder.go:52] "Attempting to bind pod to node" pod="default/nginx-deployment-66f58bff7c-rdxnf" node="kind-worker2"
I0501 08:22:01.727653       1 request.go:1152] Request Body:
00000000  6b 38 73 00 0a 0d 0a 02  76 31 12 07 42 69 6e 64  |k8s.....v1..Bind|
00000010  69 6e 67 12 80 01 0a 5e  0a 21 6e 67 69 6e 78 2d  |ing....^.!nginx-|
00000020  64 65 70 6c 6f 79 6d 65  6e 74 2d 36 36 66 35 38  |deployment-66f58|
00000030  62 66 66 37 63 2d 72 64  78 6e 66 12 00 1a 07 64  |bff7c-rdxnf....d|
00000040  65 66 61 75 6c 74 22 00  2a 24 31 61 33 62 64 66  |efault".*$1a3bdf|
00000050  37 34 2d 34 36 31 61 2d  34 34 36 35 2d 38 30 37  |74-461a-4465-807|
00000060  65 2d 37 34 61 65 62 35  66 37 32 37 64 33 32 00  |e-74aeb5f727d32.|
00000070  38 00 42 00 7a 00 12 1e  0a 04 4e 6f 64 65 12 00  |8.B.z.....Node..|
00000080  1a 0c 6b 69 6e 64 2d 77  6f 72 6b 65 72 32 22 00  |..kind-worker2".|
00000090  2a 00 32 00 3a 00 1a 00  22 00                    |*.2.:...".|
I0501 08:22:01.727778       1 round_trippers.go:466] curl -v -XPOST  -H "Accept: application/vnd.kubernetes.protobuf, */*" -H "Content-Type: application/vnd.kubernetes.protobuf" -H "User-Agent: kube-scheduler/v1.24.7 (linux/amd64) kubernetes/e6f3597/scheduler" 'https://172.18.0.2:6443/api/v1/namespaces/default/pods/nginx-deployment-66f58bff7c-rdxnf/binding'
I0501 08:22:01.748505       1 round_trippers.go:553] POST https://172.18.0.2:6443/api/v1/namespaces/default/pods/nginx-deployment-66f58bff7c-jgvtk/binding 201 Created in 32 milliseconds
I0501 08:22:01.748559       1 round_trippers.go:570] HTTP Statistics: GetConnection 0 ms ServerProcessing 31 ms Duration 32 ms
I0501 08:22:01.748577       1 round_trippers.go:577] Response Headers:
I0501 08:22:01.748597       1 round_trippers.go:580]     Content-Type: application/vnd.kubernetes.protobuf
I0501 08:22:01.748613       1 round_trippers.go:580]     X-Kubernetes-Pf-Flowschema-Uid: 8a935dea-6b5d-4402-a842-ba69f911704f
I0501 08:22:01.748634       1 round_trippers.go:580]     X-Kubernetes-Pf-Prioritylevel-Uid: 4ccc4fdb-4419-4777-8b6f-3ed0d4949e5d
I0501 08:22:01.748650       1 round_trippers.go:580]     Content-Length: 48
I0501 08:22:01.748665       1 round_trippers.go:580]     Date: Mon, 01 May 2023 08:22:01 GMT
I0501 08:22:01.748681       1 round_trippers.go:580]     Audit-Id: d989ac1b-ca12-4fce-8017-6ac7e2b7971f
I0501 08:22:01.748699       1 round_trippers.go:580]     Cache-Control: no-cache, private
I0501 08:22:01.749099       1 eventhandlers.go:159] "Delete event for unscheduled pod" pod="default/nginx-deployment-66f58bff7c-jgvtk"
I0501 08:22:01.749177       1 eventhandlers.go:184] "Add event for scheduled pod" pod="default/nginx-deployment-66f58bff7c-jgvtk"
I0501 08:22:01.749214       1 eventhandlers.go:184] "Add event for scheduled pod" pod="default/nginx-deployment-66f58bff7c-rdxnf"
I0501 08:22:01.749289       1 eventhandlers.go:159] "Delete event for unscheduled pod" pod="default/nginx-deployment-66f58bff7c-rdxnf"
I0501 08:22:01.749374       1 request.go:1152] Response Body:
00000000  6b 38 73 00 0a 0c 0a 02  76 31 12 06 53 74 61 74  |k8s.....v1..Stat|
00000010  75 73 12 18 0a 06 0a 00  12 00 1a 00 12 07 53 75  |us............Su|
00000020  63 63 65 73 73 1a 00 22  00 30 c9 01 1a 00 22 00  |ccess..".0....".|
I0501 08:22:01.749450       1 cache.go:379] "Finished binding for pod, can be expired" pod="default/nginx-deployment-66f58bff7c-jgvtk"
I0501 08:22:01.749504       1 schedule_one.go:265] "Successfully bound pod to node" pod="default/nginx-deployment-66f58bff7c-jgvtk" node="kind-worker3" evaluatedNodes=4 feasibleNodes=3
I0501 08:22:01.749692       1 request.go:1152] Request Body:
00000000  6b 38 73 00 0a 19 0a 10  65 76 65 6e 74 73 2e 6b  |k8s.....events.k|
00000010  38 73 2e 69 6f 2f 76 31  12 05 45 76 65 6e 74 12  |8s.io/v1..Event.|
00000020  f5 02 0a 4b 0a 32 6e 67  69 6e 78 2d 64 65 70 6c  |...K.2nginx-depl|
00000030  6f 79 6d 65 6e 74 2d 36  36 66 35 38 62 66 66 37  |oyment-66f58bff7|
00000040  63 2d 6a 67 76 74 6b 2e  31 37 35 61 66 37 34 64  |c-jgvtk.175af74d|
00000050  33 34 66 37 38 38 39 34  12 00 1a 07 64 65 66 61  |34f78894....defa|
00000060  75 6c 74 22 00 2a 00 32  00 38 00 42 00 7a 00 12  |ult".*.2.8.B.z..|
00000070  0c 08 a9 ed bd a2 06 10  c9 ee af e5 02 22 11 64  |.............".d|
00000080  65 66 61 75 6c 74 2d 73  63 68 65 64 75 6c 65 72  |efault-scheduler|
00000090  2a 24 64 65 66 61 75 6c  74 2d 73 63 68 65 64 75  |*$default-schedu|
000000a0  6c 65 72 2d 6b 69 6e 64  2d 63 6f 6e 74 72 6f 6c  |ler-kind-control|
000000b0  2d 70 6c 61 6e 65 32 07  42 69 6e 64 69 6e 67 3a  |-plane2.Binding:|
000000c0  09 53 63 68 65 64 75 6c  65 64 42 66 0a 03 50 6f  |.ScheduledBf..Po|
000000d0  64 12 07 64 65 66 61 75  6c 74 1a 21 6e 67 69 6e  |d..default.!ngin|
000000e0  78 2d 64 65 70 6c 6f 79  6d 65 6e 74 2d 36 36 66  |x-deployment-66f|
000000f0  35 38 62 66 66 37 63 2d  6a 67 76 74 6b 22 24 37  |58bff7c-jgvtk"$7|
00000100  64 65 38 38 37 31 64 2d  66 38 66 33 2d 34 37 30  |de8871d-f8f3-470|
00000110  61 2d 39 35 62 38 2d 32  62 35 66 63 30 36 63 35  |a-95b8-2b5fc06c5|
00000120  34 31 66 2a 02 76 31 32  07 32 32 36 38 37 30 36  |41f*.v12.2268706|
00000130  3a 00 52 4f 53 75 63 63  65 73 73 66 75 6c 6c 79  |:.ROSuccessfully|
00000140  20 61 73 73 69 67 6e 65  64 20 64 65 66 61 75 6c  | assigned defaul|
00000150  74 2f 6e 67 69 6e 78 2d  64 65 70 6c 6f 79 6d 65  |t/nginx-deployme|
00000160  6e 74 2d 36 36 66 35 38  62 66 66 37 63 2d 6a 67  |nt-66f58bff7c-jg|
00000170  76 74 6b 20 74 6f 20 6b  69 6e 64 2d 77 6f 72 6b  |vtk to kind-work|
00000180  65 72 33 5a 06 4e 6f 72  6d 61 6c 62 04 0a 00 12  |er3Z.Normalb....|
00000190  00 6a 00 72 00 78 00 1a  00 22 00                 |.j.r.x...".|
I0501 08:22:01.749815       1 round_trippers.go:466] curl -v -XPOST  -H "Accept: application/vnd.kubernetes.protobuf, */*" -H "Content-Type: application/vnd.kubernetes.protobuf" -H "User-Agent: kube-scheduler/v1.24.7 (linux/amd64) kubernetes/e6f3597/scheduler" 'https://172.18.0.2:6443/apis/events.k8s.io/v1/namespaces/default/events'
I0501 08:22:01.753850       1 round_trippers.go:553] POST https://172.18.0.2:6443/api/v1/namespaces/default/pods/nginx-deployment-66f58bff7c-rdxnf/binding 201 Created in 26 milliseconds
I0501 08:22:01.753888       1 round_trippers.go:570] HTTP Statistics: GetConnection 0 ms ServerProcessing 25 ms Duration 26 ms
I0501 08:22:01.753904       1 round_trippers.go:577] Response Headers:
I0501 08:22:01.753921       1 round_trippers.go:580]     Date: Mon, 01 May 2023 08:22:01 GMT
I0501 08:22:01.753950       1 round_trippers.go:580]     Audit-Id: 2019fc90-8155-47bf-8310-93a1faac008c
I0501 08:22:01.753966       1 round_trippers.go:580]     Cache-Control: no-cache, private
I0501 08:22:01.753996       1 round_trippers.go:580]     Content-Type: application/vnd.kubernetes.protobuf
I0501 08:22:01.754087       1 round_trippers.go:580]     X-Kubernetes-Pf-Flowschema-Uid: 8a935dea-6b5d-4402-a842-ba69f911704f
I0501 08:22:01.754273       1 round_trippers.go:580]     X-Kubernetes-Pf-Prioritylevel-Uid: 4ccc4fdb-4419-4777-8b6f-3ed0d4949e5d
I0501 08:22:01.754315       1 round_trippers.go:580]     Content-Length: 48
I0501 08:22:01.754363       1 request.go:1152] Response Body:
00000000  6b 38 73 00 0a 0c 0a 02  76 31 12 06 53 74 61 74  |k8s.....v1..Stat|
00000010  75 73 12 18 0a 06 0a 00  12 00 1a 00 12 07 53 75  |us............Su|
00000020  63 63 65 73 73 1a 00 22  00 30 c9 01 1a 00 22 00  |ccess..".0....".|
I0501 08:22:01.754436       1 cache.go:379] "Finished binding for pod, can be expired" pod="default/nginx-deployment-66f58bff7c-rdxnf"
I0501 08:22:01.754503       1 schedule_one.go:265] "Successfully bound pod to node" pod="default/nginx-deployment-66f58bff7c-rdxnf" node="kind-worker2" evaluatedNodes=4 feasibleNodes=3
I0501 08:22:01.754633       1 request.go:1152] Request Body:
00000000  6b 38 73 00 0a 19 0a 10  65 76 65 6e 74 73 2e 6b  |k8s.....events.k|
00000010  38 73 2e 69 6f 2f 76 31  12 05 45 76 65 6e 74 12  |8s.io/v1..Event.|
00000020  f5 02 0a 4b 0a 32 6e 67  69 6e 78 2d 64 65 70 6c  |...K.2nginx-depl|
00000030  6f 79 6d 65 6e 74 2d 36  36 66 35 38 62 66 66 37  |oyment-66f58bff7|
00000040  63 2d 72 64 78 6e 66 2e  31 37 35 61 66 37 34 64  |c-rdxnf.175af74d|
00000050  33 35 34 33 61 35 64 35  12 00 1a 07 64 65 66 61  |3543a5d5....defa|
00000060  75 6c 74 22 00 2a 00 32  00 38 00 42 00 7a 00 12  |ult".*.2.8.B.z..|
00000070  0c 08 a9 ed bd a2 06 10  f5 d7 e0 e7 02 22 11 64  |.............".d|
00000080  65 66 61 75 6c 74 2d 73  63 68 65 64 75 6c 65 72  |efault-scheduler|
00000090  2a 24 64 65 66 61 75 6c  74 2d 73 63 68 65 64 75  |*$default-schedu|
000000a0  6c 65 72 2d 6b 69 6e 64  2d 63 6f 6e 74 72 6f 6c  |ler-kind-control|
000000b0  2d 70 6c 61 6e 65 32 07  42 69 6e 64 69 6e 67 3a  |-plane2.Binding:|
000000c0  09 53 63 68 65 64 75 6c  65 64 42 66 0a 03 50 6f  |.ScheduledBf..Po|
000000d0  64 12 07 64 65 66 61 75  6c 74 1a 21 6e 67 69 6e  |d..default.!ngin|
000000e0  78 2d 64 65 70 6c 6f 79  6d 65 6e 74 2d 36 36 66  |x-deployment-66f|
000000f0  35 38 62 66 66 37 63 2d  72 64 78 6e 66 22 24 31  |58bff7c-rdxnf"$1|
00000100  61 33 62 64 66 37 34 2d  34 36 31 61 2d 34 34 36  |a3bdf74-461a-446|
00000110  35 2d 38 30 37 65 2d 37  34 61 65 62 35 66 37 32  |5-807e-74aeb5f72|
00000120  37 64 33 2a 02 76 31 32  07 32 32 36 38 37 30 37  |7d3*.v12.2268707|
00000130  3a 00 52 4f 53 75 63 63  65 73 73 66 75 6c 6c 79  |:.ROSuccessfully|
00000140  20 61 73 73 69 67 6e 65  64 20 64 65 66 61 75 6c  | assigned defaul|
00000150  74 2f 6e 67 69 6e 78 2d  64 65 70 6c 6f 79 6d 65  |t/nginx-deployme|
00000160  6e 74 2d 36 36 66 35 38  62 66 66 37 63 2d 72 64  |nt-66f58bff7c-rd|
00000170  78 6e 66 20 74 6f 20 6b  69 6e 64 2d 77 6f 72 6b  |xnf to kind-work|
00000180  65 72 32 5a 06 4e 6f 72  6d 61 6c 62 04 0a 00 12  |er2Z.Normalb....|
00000190  00 6a 00 72 00 78 00 1a  00 22 00                 |.j.r.x...".|
I0501 08:22:01.754733       1 round_trippers.go:466] curl -v -XPOST  -H "Accept: application/vnd.kubernetes.protobuf, */*" -H "Content-Type: application/vnd.kubernetes.protobuf" -H "User-Agent: kube-scheduler/v1.24.7 (linux/amd64) kubernetes/e6f3597/scheduler" 'https://172.18.0.2:6443/apis/events.k8s.io/v1/namespaces/default/events'
I0501 08:22:01.839502       1 round_trippers.go:553] POST https://172.18.0.2:6443/apis/events.k8s.io/v1/namespaces/default/events 201 Created in 84 milliseconds
I0501 08:22:01.839577       1 round_trippers.go:570] HTTP Statistics: GetConnection 0 ms ServerProcessing 84 ms Duration 84 ms
I0501 08:22:01.839607       1 round_trippers.go:577] Response Headers:
I0501 08:22:01.839640       1 round_trippers.go:580]     X-Kubernetes-Pf-Prioritylevel-Uid: 4ccc4fdb-4419-4777-8b6f-3ed0d4949e5d
I0501 08:22:01.839668       1 round_trippers.go:580]     Content-Length: 676
I0501 08:22:01.839703       1 round_trippers.go:553] POST https://172.18.0.2:6443/apis/events.k8s.io/v1/namespaces/default/events 201 Created in 89 milliseconds
I0501 08:22:01.839717       1 round_trippers.go:580]     Date: Mon, 01 May 2023 08:22:01 GMT
I0501 08:22:01.839752       1 round_trippers.go:580]     Audit-Id: ca88a4e9-a23a-4011-8846-f9c8998c34bc
I0501 08:22:01.839787       1 round_trippers.go:570] HTTP Statistics: GetConnection 0 ms ServerProcessing 89 ms Duration 89 ms
I0501 08:22:01.839790       1 round_trippers.go:580]     Cache-Control: no-cache, private
I0501 08:22:01.840006       1 round_trippers.go:580]     Content-Type: application/vnd.kubernetes.protobuf
I0501 08:22:01.839810       1 round_trippers.go:577] Response Headers:
I0501 08:22:01.840098       1 round_trippers.go:580]     X-Kubernetes-Pf-Prioritylevel-Uid: 4ccc4fdb-4419-4777-8b6f-3ed0d4949e5d
I0501 08:22:01.840125       1 round_trippers.go:580]     Content-Length: 676
I0501 08:22:01.840141       1 round_trippers.go:580]     Date: Mon, 01 May 2023 08:22:01 GMT
I0501 08:22:01.840156       1 round_trippers.go:580]     Audit-Id: 254e0998-b2b5-4a76-8f96-40517676aa9f
I0501 08:22:01.840184       1 round_trippers.go:580]     Cache-Control: no-cache, private
I0501 08:22:01.840200       1 round_trippers.go:580]     Content-Type: application/vnd.kubernetes.protobuf
I0501 08:22:01.840215       1 round_trippers.go:580]     X-Kubernetes-Pf-Flowschema-Uid: 8a935dea-6b5d-4402-a842-ba69f911704f
I0501 08:22:01.840326       1 request.go:1152] Response Body:
00000000  6b 38 73 00 0a 19 0a 10  65 76 65 6e 74 73 2e 6b  |k8s.....events.k|
00000010  38 73 2e 69 6f 2f 76 31  12 05 45 76 65 6e 74 12  |8s.io/v1..Event.|
00000020  fe 04 0a d3 02 0a 32 6e  67 69 6e 78 2d 64 65 70  |......2nginx-dep|
00000030  6c 6f 79 6d 65 6e 74 2d  36 36 66 35 38 62 66 66  |loyment-66f58bff|
00000040  37 63 2d 6a 67 76 74 6b  2e 31 37 35 61 66 37 34  |7c-jgvtk.175af74|
00000050  64 33 34 66 37 38 38 39  34 12 00 1a 07 64 65 66  |d34f78894....def|
00000060  61 75 6c 74 22 00 2a 24  31 65 38 63 64 66 37 34  |ault".*$1e8cdf74|
00000070  2d 62 35 61 35 2d 34 38  64 34 2d 39 37 35 61 2d  |-b5a5-48d4-975a-|
00000080  30 31 66 63 30 38 38 62  32 35 32 37 32 07 32 32  |01fc088b25272.22|
00000090  36 38 37 31 35 38 00 42  08 08 a9 ed bd a2 06 10  |687158.B........|
000000a0  00 7a 00 8a 01 d1 01 0a  0e 6b 75 62 65 2d 73 63  |.z.......kube-sc|
000000b0  68 65 64 75 6c 65 72 12  06 55 70 64 61 74 65 1a  |heduler..Update.|
000000c0  10 65 76 65 6e 74 73 2e  6b 38 73 2e 69 6f 2f 76  |.events.k8s.io/v|
000000d0  31 22 08 08 a9 ed bd a2  06 10 00 32 08 46 69 65  |1".........2.Fie|
000000e0  6c 64 73 56 31 3a 8e 01  0a 8b 01 7b 22 66 3a 61  |ldsV1:.....{"f:a|
000000f0  63 74 69 6f 6e 22 3a 7b  7d 2c 22 66 3a 65 76 65  |ction":{},"f:eve|
00000100  6e 74 54 69 6d 65 22 3a  7b 7d 2c 22 66 3a 6e 6f  |ntTime":{},"f:no|
00000110  74 65 22 3a 7b 7d 2c 22  66 3a 72 65 61 73 6f 6e  |te":{},"f:reason|
00000120  22 3a 7b 7d 2c 22 66 3a  72 65 67 61 72 64 69 6e  |":{},"f:regardin|
00000130  67 22 3a 7b 7d 2c 22 66  3a 72 65 70 6f 72 74 69  |g":{},"f:reporti|
00000140  6e 67 43 6f 6e 74 72 6f  6c 6c 65 72 22 3a 7b 7d  |ngController":{}|
00000150  2c 22 66 3a 72 65 70 6f  72 74 69 6e 67 49 6e 73  |,"f:reportingIns|
00000160  74 61 6e 63 65 22 3a 7b  7d 2c 22 66 3a 74 79 70  |tance":{},"f:typ|
00000170  65 22 3a 7b 7d 7d 42 00  12 0c 08 a9 ed bd a2 06  |e":{}}B.........|
00000180  10 c9 ee af e5 02 22 11  64 65 66 61 75 6c 74 2d  |......".default-|
00000190  73 63 68 65 64 75 6c 65  72 2a 24 64 65 66 61 75  |scheduler*$defau|
000001a0  6c 74 2d 73 63 68 65 64  75 6c 65 72 2d 6b 69 6e  |lt-scheduler-kin|
000001b0  64 2d 63 6f 6e 74 72 6f  6c 2d 70 6c 61 6e 65 32  |d-control-plane2|
000001c0  07 42 69 6e 64 69 6e 67  3a 09 53 63 68 65 64 75  |.Binding:.Schedu|
000001d0  6c 65 64 42 66 0a 03 50  6f 64 12 07 64 65 66 61  |ledBf..Pod..defa|
000001e0  75 6c 74 1a 21 6e 67 69  6e 78 2d 64 65 70 6c 6f  |ult.!nginx-deplo|
000001f0  79 6d 65 6e 74 2d 36 36  66 35 38 62 66 66 37 63  |yment-66f58bff7c|
00000200  2d 6a 67 76 74 6b 22 24  37 64 65 38 38 37 31 64  |-jgvtk"$7de8871d|
00000210  2d 66 38 66 33 2d 34 37  30 61 2d 39 35 62 38 2d  |-f8f3-470a-95b8-|
00000220  32 62 35 66 63 30 36 63  35 34 31 66 2a 02 76 31  |2b5fc06c541f*.v1|
00000230  32 07 32 32 36 38 37 30  36 3a 00 52 4f 53 75 63  |2.2268706:.ROSuc|
