I0318 03:19:12.249706       1 flags.go:64] FLAG: --add-dir-header="false"
I0318 03:19:12.250058       1 flags.go:64] FLAG: --allow-metric-labels="[]"
I0318 03:19:12.250124       1 flags.go:64] FLAG: --alsologtostderr="false"
I0318 03:19:12.250155       1 flags.go:64] FLAG: --authentication-kubeconfig="/etc/kubernetes/scheduler.conf"
I0318 03:19:12.250193       1 flags.go:64] FLAG: --authentication-skip-lookup="false"
I0318 03:19:12.250256       1 flags.go:64] FLAG: --authentication-token-webhook-cache-ttl="10s"
I0318 03:19:12.250281       1 flags.go:64] FLAG: --authentication-tolerate-lookup-failure="true"
I0318 03:19:12.250301       1 flags.go:64] FLAG: --authorization-always-allow-paths="[/healthz,/readyz,/livez]"
I0318 03:19:12.250355       1 flags.go:64] FLAG: --authorization-kubeconfig="/etc/kubernetes/scheduler.conf"
I0318 03:19:12.250380       1 flags.go:64] FLAG: --authorization-webhook-cache-authorized-ttl="10s"
I0318 03:19:12.250401       1 flags.go:64] FLAG: --authorization-webhook-cache-unauthorized-ttl="10s"
I0318 03:19:12.250421       1 flags.go:64] FLAG: --bind-address="127.0.0.1"
I0318 03:19:12.250451       1 flags.go:64] FLAG: --cert-dir=""
I0318 03:19:12.250473       1 flags.go:64] FLAG: --client-ca-file=""
I0318 03:19:12.250492       1 flags.go:64] FLAG: --config=""
I0318 03:19:12.250511       1 flags.go:64] FLAG: --contention-profiling="true"
I0318 03:19:12.250532       1 flags.go:64] FLAG: --disabled-metrics="[]"
I0318 03:19:12.250569       1 flags.go:64] FLAG: --feature-gates=""
I0318 03:19:12.250608       1 flags.go:64] FLAG: --help="false"
I0318 03:19:12.250634       1 flags.go:64] FLAG: --http2-max-streams-per-connection="0"
I0318 03:19:12.250657       1 flags.go:64] FLAG: --kube-api-burst="100"
I0318 03:19:12.250682       1 flags.go:64] FLAG: --kube-api-content-type="application/vnd.kubernetes.protobuf"
I0318 03:19:12.250703       1 flags.go:64] FLAG: --kube-api-qps="50"
I0318 03:19:12.250727       1 flags.go:64] FLAG: --kubeconfig="/etc/kubernetes/scheduler.conf"
I0318 03:19:12.250749       1 flags.go:64] FLAG: --leader-elect="true"
I0318 03:19:12.250768       1 flags.go:64] FLAG: --leader-elect-lease-duration="15s"
I0318 03:19:12.250828       1 flags.go:64] FLAG: --leader-elect-renew-deadline="10s"
I0318 03:19:12.250858       1 flags.go:64] FLAG: --leader-elect-resource-lock="leases"
I0318 03:19:12.250872       1 flags.go:64] FLAG: --leader-elect-resource-name="kube-scheduler"
I0318 03:19:12.250882       1 flags.go:64] FLAG: --leader-elect-resource-namespace="kube-system"
I0318 03:19:12.250893       1 flags.go:64] FLAG: --leader-elect-retry-period="2s"
I0318 03:19:12.250917       1 flags.go:64] FLAG: --lock-object-name="kube-scheduler"
I0318 03:19:12.250933       1 flags.go:64] FLAG: --lock-object-namespace="kube-system"
I0318 03:19:12.250947       1 flags.go:64] FLAG: --log-backtrace-at=":0"
I0318 03:19:12.250978       1 flags.go:64] FLAG: --log-dir=""
I0318 03:19:12.250989       1 flags.go:64] FLAG: --log-file=""
I0318 03:19:12.250999       1 flags.go:64] FLAG: --log-file-max-size="1800"
I0318 03:19:12.251011       1 flags.go:64] FLAG: --log-flush-frequency="5s"
I0318 03:19:12.251022       1 flags.go:64] FLAG: --log-json-info-buffer-size="0"
I0318 03:19:12.251038       1 flags.go:64] FLAG: --log-json-split-stream="false"
I0318 03:19:12.251049       1 flags.go:64] FLAG: --logging-format="text"
I0318 03:19:12.251059       1 flags.go:64] FLAG: --logtostderr="true"
I0318 03:19:12.251069       1 flags.go:64] FLAG: --master=""
I0318 03:19:12.251079       1 flags.go:64] FLAG: --one-output="false"
I0318 03:19:12.251090       1 flags.go:64] FLAG: --permit-address-sharing="false"
I0318 03:19:12.251100       1 flags.go:64] FLAG: --permit-port-sharing="false"
I0318 03:19:12.251111       1 flags.go:64] FLAG: --pod-max-in-unschedulable-pods-duration="5m0s"
I0318 03:19:12.251194       1 flags.go:64] FLAG: --profiling="true"
I0318 03:19:12.251207       1 flags.go:64] FLAG: --requestheader-allowed-names="[]"
I0318 03:19:12.251232       1 flags.go:64] FLAG: --requestheader-client-ca-file=""
I0318 03:19:12.251243       1 flags.go:64] FLAG: --requestheader-extra-headers-prefix="[x-remote-extra-]"
I0318 03:19:12.251277       1 flags.go:64] FLAG: --requestheader-group-headers="[x-remote-group]"
I0318 03:19:12.251305       1 flags.go:64] FLAG: --requestheader-username-headers="[x-remote-user]"
I0318 03:19:12.251335       1 flags.go:64] FLAG: --secure-port="10259"
I0318 03:19:12.251351       1 flags.go:64] FLAG: --show-hidden-metrics-for-version=""
I0318 03:19:12.251364       1 flags.go:64] FLAG: --skip-headers="false"
I0318 03:19:12.251377       1 flags.go:64] FLAG: --skip-log-headers="false"
I0318 03:19:12.251390       1 flags.go:64] FLAG: --stderrthreshold="2"
I0318 03:19:12.251403       1 flags.go:64] FLAG: --tls-cert-file=""
I0318 03:19:12.251415       1 flags.go:64] FLAG: --tls-cipher-suites="[]"
I0318 03:19:12.251442       1 flags.go:64] FLAG: --tls-min-version=""
I0318 03:19:12.251456       1 flags.go:64] FLAG: --tls-private-key-file=""
I0318 03:19:12.251475       1 flags.go:64] FLAG: --tls-sni-cert-key="[]"
I0318 03:19:12.251494       1 flags.go:64] FLAG: --v="2"
I0318 03:19:12.251510       1 flags.go:64] FLAG: --version="false"
I0318 03:19:12.251527       1 flags.go:64] FLAG: --vmodule=""
I0318 03:19:12.251542       1 flags.go:64] FLAG: --write-config-to=""
I0318 03:19:13.938987       1 serving.go:348] Generated self-signed cert in-memory
I0318 03:19:14.305740       1 requestheader_controller.go:244] Loaded a new request header values for RequestHeaderAuthRequestController
I0318 03:19:14.334999       1 configfile.go:102] "Using component config" config=<
	apiVersion: kubescheduler.config.k8s.io/v1
	clientConnection:
	  acceptContentTypes: ""
	  burst: 100
	  contentType: application/vnd.kubernetes.protobuf
	  kubeconfig: /etc/kubernetes/scheduler.conf
	  qps: 50
	enableContentionProfiling: true
	enableProfiling: true
	kind: KubeSchedulerConfiguration
	leaderElection:
	  leaderElect: true
	  leaseDuration: 15s
	  renewDeadline: 10s
	  resourceLock: leases
	  resourceName: kube-scheduler
	  resourceNamespace: kube-system
	  retryPeriod: 2s
	parallelism: 16
	percentageOfNodesToScore: 0
	podInitialBackoffSeconds: 1
	podMaxBackoffSeconds: 10
	profiles:
	- pluginConfig:
	  - args:
	      apiVersion: kubescheduler.config.k8s.io/v1
	      kind: DefaultPreemptionArgs
	      minCandidateNodesAbsolute: 100
	      minCandidateNodesPercentage: 10
	    name: DefaultPreemption
	  - args:
	      apiVersion: kubescheduler.config.k8s.io/v1
	      hardPodAffinityWeight: 1
	      kind: InterPodAffinityArgs
	    name: InterPodAffinity
	  - args:
	      apiVersion: kubescheduler.config.k8s.io/v1
	      kind: NodeAffinityArgs
	    name: NodeAffinity
	  - args:
	      apiVersion: kubescheduler.config.k8s.io/v1
	      kind: NodeResourcesBalancedAllocationArgs
	      resources:
	      - name: cpu
	        weight: 1
	      - name: memory
	        weight: 1
	    name: NodeResourcesBalancedAllocation
	  - args:
	      apiVersion: kubescheduler.config.k8s.io/v1
	      kind: NodeResourcesFitArgs
	      scoringStrategy:
	        resources:
	        - name: cpu
	          weight: 1
	        - name: memory
	          weight: 1
	        type: LeastAllocated
	    name: NodeResourcesFit
	  - args:
	      apiVersion: kubescheduler.config.k8s.io/v1
	      defaultingType: System
	      kind: PodTopologySpreadArgs
	    name: PodTopologySpread
	  - args:
	      apiVersion: kubescheduler.config.k8s.io/v1
	      bindTimeoutSeconds: 600
	      kind: VolumeBindingArgs
	    name: VolumeBinding
	  plugins:
	    bind: {}
	    filter: {}
	    multiPoint:
	      enabled:
	      - name: PrioritySort
	        weight: 0
	      - name: NodeUnschedulable
	        weight: 0
	      - name: NodeName
	        weight: 0
	      - name: TaintToleration
	        weight: 3
	      - name: NodeAffinity
	        weight: 2
	      - name: NodePorts
	        weight: 0
	      - name: NodeResourcesFit
	        weight: 1
	      - name: VolumeRestrictions
	        weight: 0
	      - name: EBSLimits
	        weight: 0
	      - name: GCEPDLimits
	        weight: 0
	      - name: NodeVolumeLimits
	        weight: 0
	      - name: AzureDiskLimits
	        weight: 0
	      - name: VolumeBinding
	        weight: 0
	      - name: VolumeZone
	        weight: 0
	      - name: PodTopologySpread
	        weight: 2
	      - name: InterPodAffinity
	        weight: 2
	      - name: DefaultPreemption
	        weight: 0
	      - name: NodeResourcesBalancedAllocation
	        weight: 1
	      - name: ImageLocality
	        weight: 1
	      - name: DefaultBinder
	        weight: 0
	    permit: {}
	    postBind: {}
	    postFilter: {}
	    preBind: {}
	    preFilter: {}
	    preScore: {}
	    queueSort: {}
	    reserve: {}
	    score: {}
	  schedulerName: default-scheduler
 >
I0318 03:19:14.335201       1 server.go:148] "Starting Kubernetes Scheduler" version="v1.25.3"
I0318 03:19:14.335254       1 server.go:150] "Golang settings" GOGC="" GOMAXPROCS="" GOTRACEBACK=""
I0318 03:19:14.343382       1 requestheader_controller.go:169] Starting RequestHeaderAuthRequestController
I0318 03:19:14.343476       1 configmap_cafile_content.go:202] "Starting controller" name="client-ca::kube-system::extension-apiserver-authentication::client-ca-file"
I0318 03:19:14.343521       1 shared_informer.go:255] Waiting for caches to sync for client-ca::kube-system::extension-apiserver-authentication::client-ca-file
I0318 03:19:14.343652       1 configmap_cafile_content.go:202] "Starting controller" name="client-ca::kube-system::extension-apiserver-authentication::requestheader-client-ca-file"
I0318 03:19:14.343694       1 shared_informer.go:255] Waiting for caches to sync for client-ca::kube-system::extension-apiserver-authentication::requestheader-client-ca-file
I0318 03:19:14.343711       1 tlsconfig.go:200] "Loaded serving cert" certName="Generated self signed cert" certDetail="\"localhost@1679109553\" [serving] validServingFor=[127.0.0.1,127.0.0.1,localhost] issuer=\"localhost-ca@1679109552\" (2023-03-18 02:19:12 +0000 UTC to 2024-03-17 02:19:12 +0000 UTC (now=2023-03-18 03:19:14.343545428 +0000 UTC))"
I0318 03:19:14.343503       1 shared_informer.go:255] Waiting for caches to sync for RequestHeaderAuthRequestController
I0318 03:19:14.344254       1 named_certificates.go:53] "Loaded SNI cert" index=0 certName="self-signed loopback" certDetail="\"apiserver-loopback-client@1679109554\" [serving] validServingFor=[apiserver-loopback-client] issuer=\"apiserver-loopback-client-ca@1679109554\" (2023-03-18 02:19:13 +0000 UTC to 2024-03-17 02:19:13 +0000 UTC (now=2023-03-18 03:19:14.344130269 +0000 UTC))"
I0318 03:19:14.344324       1 secure_serving.go:210] Serving securely on 127.0.0.1:10259
I0318 03:19:14.344609       1 tlsconfig.go:240] "Starting DynamicServingCertificateController"
I0318 03:19:14.361919       1 node_tree.go:65] "Added node in listed group to NodeTree" node="three-worker-cluster-control-plane" zone=""
I0318 03:19:14.362028       1 node_tree.go:65] "Added node in listed group to NodeTree" node="three-worker-cluster-worker2" zone=""
I0318 03:19:14.362108       1 node_tree.go:65] "Added node in listed group to NodeTree" node="three-worker-cluster-worker3" zone=""
I0318 03:19:14.362178       1 node_tree.go:65] "Added node in listed group to NodeTree" node="three-worker-cluster-worker" zone=""
I0318 03:19:14.443838       1 shared_informer.go:262] Caches are synced for client-ca::kube-system::extension-apiserver-authentication::client-ca-file
I0318 03:19:14.444451       1 shared_informer.go:262] Caches are synced for RequestHeaderAuthRequestController
I0318 03:19:14.444493       1 shared_informer.go:262] Caches are synced for client-ca::kube-system::extension-apiserver-authentication::requestheader-client-ca-file
I0318 03:19:14.444798       1 leaderelection.go:248] attempting to acquire leader lease kube-system/kube-scheduler...
I0318 03:19:14.445088       1 tlsconfig.go:178] "Loaded client CA" index=0 certName="client-ca::kube-system::extension-apiserver-authentication::client-ca-file,client-ca::kube-system::extension-apiserver-authentication::requestheader-client-ca-file" certDetail="\"kubernetes\" [] validServingFor=[kubernetes] issuer=\"<self>\" (2023-03-14 00:47:38 +0000 UTC to 2033-03-11 00:47:38 +0000 UTC (now=2023-03-18 03:19:14.445018415 +0000 UTC))"
I0318 03:19:14.445936       1 tlsconfig.go:200] "Loaded serving cert" certName="Generated self signed cert" certDetail="\"localhost@1679109553\" [serving] validServingFor=[127.0.0.1,127.0.0.1,localhost] issuer=\"localhost-ca@1679109552\" (2023-03-18 02:19:12 +0000 UTC to 2024-03-17 02:19:12 +0000 UTC (now=2023-03-18 03:19:14.445888706 +0000 UTC))"
I0318 03:19:14.446446       1 named_certificates.go:53] "Loaded SNI cert" index=0 certName="self-signed loopback" certDetail="\"apiserver-loopback-client@1679109554\" [serving] validServingFor=[apiserver-loopback-client] issuer=\"apiserver-loopback-client-ca@1679109554\" (2023-03-18 02:19:13 +0000 UTC to 2024-03-17 02:19:13 +0000 UTC (now=2023-03-18 03:19:14.446372025 +0000 UTC))"
I0318 03:19:14.446764       1 tlsconfig.go:178] "Loaded client CA" index=0 certName="client-ca::kube-system::extension-apiserver-authentication::client-ca-file,client-ca::kube-system::extension-apiserver-authentication::requestheader-client-ca-file" certDetail="\"kubernetes\" [] validServingFor=[kubernetes] issuer=\"<self>\" (2023-03-14 00:47:38 +0000 UTC to 2033-03-11 00:47:38 +0000 UTC (now=2023-03-18 03:19:14.446720448 +0000 UTC))"
I0318 03:19:14.447005       1 tlsconfig.go:178] "Loaded client CA" index=1 certName="client-ca::kube-system::extension-apiserver-authentication::client-ca-file,client-ca::kube-system::extension-apiserver-authentication::requestheader-client-ca-file" certDetail="\"front-proxy-ca\" [] validServingFor=[front-proxy-ca] issuer=\"<self>\" (2023-03-14 00:47:41 +0000 UTC to 2033-03-11 00:47:41 +0000 UTC (now=2023-03-18 03:19:14.446952751 +0000 UTC))"
I0318 03:19:14.447485       1 tlsconfig.go:200] "Loaded serving cert" certName="Generated self signed cert" certDetail="\"localhost@1679109553\" [serving] validServingFor=[127.0.0.1,127.0.0.1,localhost] issuer=\"localhost-ca@1679109552\" (2023-03-18 02:19:12 +0000 UTC to 2024-03-17 02:19:12 +0000 UTC (now=2023-03-18 03:19:14.447451279 +0000 UTC))"
I0318 03:19:14.447785       1 named_certificates.go:53] "Loaded SNI cert" index=0 certName="self-signed loopback" certDetail="\"apiserver-loopback-client@1679109554\" [serving] validServingFor=[apiserver-loopback-client] issuer=\"apiserver-loopback-client-ca@1679109554\" (2023-03-18 02:19:13 +0000 UTC to 2024-03-17 02:19:13 +0000 UTC (now=2023-03-18 03:19:14.447757634 +0000 UTC))"
I0318 03:19:14.455624       1 leaderelection.go:258] successfully acquired lease kube-system/kube-scheduler
I0322 02:36:00.374740       1 schedule_one.go:266] "Successfully bound pod to node" pod="kube-system/my-release-descheduler-27990876-jk9fv" node="three-worker-cluster-worker2" evaluatedNodes=4 feasibleNodes=2
I0322 02:38:00.626716       1 schedule_one.go:266] "Successfully bound pod to node" pod="kube-system/my-release-descheduler-27990878-rdkmd" node="three-worker-cluster-worker2" evaluatedNodes=4 feasibleNodes=2
I0322 02:40:00.314379       1 schedule_one.go:266] "Successfully bound pod to node" pod="kube-system/my-release-descheduler-27990880-m9qdj" node="three-worker-cluster-worker2" evaluatedNodes=4 feasibleNodes=2
I0322 02:42:00.469282       1 schedule_one.go:266] "Successfully bound pod to node" pod="kube-system/my-release-descheduler-27990882-27px4" node="three-worker-cluster-worker2" evaluatedNodes=4 feasibleNodes=2
I0322 02:44:00.335842       1 schedule_one.go:266] "Successfully bound pod to node" pod="kube-system/my-release-descheduler-27990884-v848x" node="three-worker-cluster-worker2" evaluatedNodes=4 feasibleNodes=2
I0322 02:46:00.375052       1 schedule_one.go:266] "Successfully bound pod to node" pod="kube-system/my-release-descheduler-27990886-pjk75" node="three-worker-cluster-worker2" evaluatedNodes=4 feasibleNodes=2
I0322 02:48:00.330051       1 schedule_one.go:266] "Successfully bound pod to node" pod="kube-system/my-release-descheduler-27990888-m2djw" node="three-worker-cluster-worker2" evaluatedNodes=4 feasibleNodes=2
I0322 02:50:00.336136       1 schedule_one.go:266] "Successfully bound pod to node" pod="kube-system/my-release-descheduler-27990890-c8bq5" node="three-worker-cluster-worker2" evaluatedNodes=4 feasibleNodes=2
I0322 02:53:28.415972       1 schedule_one.go:266] "Successfully bound pod to node" pod="kube-system/descheduler-74b6dc9649-8bw22" node="three-worker-cluster-worker2" evaluatedNodes=4 feasibleNodes=2
I0322 04:45:10.977146       1 schedule_one.go:266] "Successfully bound pod to node" pod="kube-system/descheduler-74b6dc9649-ndkng" node="three-worker-cluster-worker3" evaluatedNodes=4 feasibleNodes=2
I0322 04:49:33.374828       1 schedule_one.go:266] "Successfully bound pod to node" pod="kube-system/descheduler-74b6dc9649-26qp6" node="three-worker-cluster-worker2" evaluatedNodes=4 feasibleNodes=2
I0322 04:49:37.291751       1 schedule_one.go:266] "Successfully bound pod to node" pod="local-path-storage/local-path-provisioner-684f458cdd-s7v6w" node="three-worker-cluster-worker3" evaluatedNodes=4 feasibleNodes=3
I0322 04:49:38.503238       1 schedule_one.go:266] "Successfully bound pod to node" pod="default/nginx-deployment-58df68d8db-r9vqx" node="three-worker-cluster-worker2" evaluatedNodes=4 feasibleNodes=2
I0322 04:49:38.805874       1 schedule_one.go:266] "Successfully bound pod to node" pod="default/nginx-deployment-58df68d8db-9bpnq" node="three-worker-cluster-worker3" evaluatedNodes=4 feasibleNodes=2
I0322 04:49:39.725260       1 schedule_one.go:266] "Successfully bound pod to node" pod="default/nginx-deployment-58df68d8db-s5h4b" node="three-worker-cluster-worker3" evaluatedNodes=4 feasibleNodes=2
I0322 05:04:37.709200       1 schedule_one.go:266] "Successfully bound pod to node" pod="default/nginx-deployment-58df68d8db-mhrjp" node="three-worker-cluster-worker2" evaluatedNodes=4 feasibleNodes=2
I0322 05:04:38.234462       1 schedule_one.go:266] "Successfully bound pod to node" pod="local-path-storage/local-path-provisioner-684f458cdd-wnd6c" node="three-worker-cluster-worker3" evaluatedNodes=4 feasibleNodes=3
I0322 05:04:38.724303       1 schedule_one.go:266] "Successfully bound pod to node" pod="default/nginx-deployment-58df68d8db-hv65p" node="three-worker-cluster-worker3" evaluatedNodes=4 feasibleNodes=2
I0322 05:04:39.776226       1 schedule_one.go:266] "Successfully bound pod to node" pod="default/nginx-deployment-58df68d8db-mpfhv" node="three-worker-cluster-worker3" evaluatedNodes=4 feasibleNodes=2
I0322 05:19:37.231952       1 schedule_one.go:266] "Successfully bound pod to node" pod="default/nginx-deployment-58df68d8db-gzs5t" node="three-worker-cluster-worker2" evaluatedNodes=4 feasibleNodes=2
I0322 05:19:38.333146       1 schedule_one.go:266] "Successfully bound pod to node" pod="local-path-storage/local-path-provisioner-684f458cdd-df4gf" node="three-worker-cluster-worker3" evaluatedNodes=4 feasibleNodes=3
I0322 05:19:38.596376       1 schedule_one.go:266] "Successfully bound pod to node" pod="default/nginx-deployment-58df68d8db-drlzs" node="three-worker-cluster-worker3" evaluatedNodes=4 feasibleNodes=2
I0322 05:19:41.005676       1 schedule_one.go:266] "Successfully bound pod to node" pod="default/nginx-deployment-58df68d8db-plq9l" node="three-worker-cluster-worker2" evaluatedNodes=4 feasibleNodes=2
I0322 05:34:37.653741       1 schedule_one.go:266] "Successfully bound pod to node" pod="default/nginx-deployment-58df68d8db-bc8cv" node="three-worker-cluster-worker3" evaluatedNodes=4 feasibleNodes=2
I0322 05:34:37.654902       1 schedule_one.go:266] "Successfully bound pod to node" pod="local-path-storage/local-path-provisioner-684f458cdd-fqtfh" node="three-worker-cluster-worker3" evaluatedNodes=4 feasibleNodes=3
I0322 05:34:38.957510       1 schedule_one.go:266] "Successfully bound pod to node" pod="default/nginx-deployment-58df68d8db-q8hfc" node="three-worker-cluster-worker2" evaluatedNodes=4 feasibleNodes=2
I0322 05:34:40.147414       1 schedule_one.go:266] "Successfully bound pod to node" pod="default/nginx-deployment-58df68d8db-qswbk" node="three-worker-cluster-worker3" evaluatedNodes=4 feasibleNodes=2
I0322 05:49:37.297239       1 schedule_one.go:266] "Successfully bound pod to node" pod="default/nginx-deployment-58df68d8db-rf8vd" node="three-worker-cluster-worker3" evaluatedNodes=4 feasibleNodes=2
I0322 05:49:37.838507       1 schedule_one.go:266] "Successfully bound pod to node" pod="local-path-storage/local-path-provisioner-684f458cdd-m2xbk" node="three-worker-cluster-worker2" evaluatedNodes=4 feasibleNodes=3
I0322 05:49:38.188906       1 schedule_one.go:266] "Successfully bound pod to node" pod="default/nginx-deployment-58df68d8db-zzbvx" node="three-worker-cluster-worker2" evaluatedNodes=4 feasibleNodes=2
I0322 05:49:38.888088       1 schedule_one.go:266] "Successfully bound pod to node" pod="default/nginx-deployment-58df68d8db-2cwk8" node="three-worker-cluster-worker3" evaluatedNodes=4 feasibleNodes=2
I0322 06:04:37.812101       1 schedule_one.go:266] "Successfully bound pod to node" pod="default/nginx-deployment-58df68d8db-plhlc" node="three-worker-cluster-worker2" evaluatedNodes=4 feasibleNodes=2
I0322 06:04:38.163880       1 schedule_one.go:266] "Successfully bound pod to node" pod="local-path-storage/local-path-provisioner-684f458cdd-452gd" node="three-worker-cluster-worker3" evaluatedNodes=4 feasibleNodes=3
I0322 06:04:38.420934       1 schedule_one.go:266] "Successfully bound pod to node" pod="default/nginx-deployment-58df68d8db-zm7qj" node="three-worker-cluster-worker3" evaluatedNodes=4 feasibleNodes=2
I0322 06:04:40.294371       1 schedule_one.go:266] "Successfully bound pod to node" pod="default/nginx-deployment-58df68d8db-bm85k" node="three-worker-cluster-worker3" evaluatedNodes=4 feasibleNodes=2
I0322 06:19:37.599755       1 schedule_one.go:266] "Successfully bound pod to node" pod="default/nginx-deployment-58df68d8db-8fh6j" node="three-worker-cluster-worker2" evaluatedNodes=4 feasibleNodes=2
I0322 06:19:38.089826       1 schedule_one.go:266] "Successfully bound pod to node" pod="local-path-storage/local-path-provisioner-684f458cdd-lrsjr" node="three-worker-cluster-worker3" evaluatedNodes=4 feasibleNodes=3
I0322 06:19:38.415152       1 schedule_one.go:266] "Successfully bound pod to node" pod="default/nginx-deployment-58df68d8db-qzgk5" node="three-worker-cluster-worker3" evaluatedNodes=4 feasibleNodes=2
I0322 06:19:40.335152       1 schedule_one.go:266] "Successfully bound pod to node" pod="default/nginx-deployment-58df68d8db-jmbs9" node="three-worker-cluster-worker3" evaluatedNodes=4 feasibleNodes=2
I0322 06:34:37.666507       1 schedule_one.go:266] "Successfully bound pod to node" pod="local-path-storage/local-path-provisioner-684f458cdd-z7557" node="three-worker-cluster-worker3" evaluatedNodes=4 feasibleNodes=3
I0322 06:34:37.666788       1 schedule_one.go:266] "Successfully bound pod to node" pod="default/nginx-deployment-58df68d8db-lgg9m" node="three-worker-cluster-worker2" evaluatedNodes=4 feasibleNodes=2
I0322 06:34:38.037858       1 schedule_one.go:266] "Successfully bound pod to node" pod="default/nginx-deployment-58df68d8db-lsn4b" node="three-worker-cluster-worker3" evaluatedNodes=4 feasibleNodes=2
I0322 06:34:39.483501       1 schedule_one.go:266] "Successfully bound pod to node" pod="default/nginx-deployment-58df68d8db-5xdrv" node="three-worker-cluster-worker3" evaluatedNodes=4 feasibleNodes=2
I0322 06:49:37.616094       1 schedule_one.go:266] "Successfully bound pod to node" pod="default/nginx-deployment-58df68d8db-dlmz6" node="three-worker-cluster-worker2" evaluatedNodes=4 feasibleNodes=2
I0322 06:49:38.049520       1 schedule_one.go:266] "Successfully bound pod to node" pod="local-path-storage/local-path-provisioner-684f458cdd-vfkkl" node="three-worker-cluster-worker3" evaluatedNodes=4 feasibleNodes=3
I0322 06:49:38.231871       1 schedule_one.go:266] "Successfully bound pod to node" pod="default/nginx-deployment-58df68d8db-wfnss" node="three-worker-cluster-worker3" evaluatedNodes=4 feasibleNodes=2
I0322 06:49:39.491674       1 schedule_one.go:266] "Successfully bound pod to node" pod="default/nginx-deployment-58df68d8db-x8kb9" node="three-worker-cluster-worker2" evaluatedNodes=4 feasibleNodes=2
I0322 07:04:37.264754       1 schedule_one.go:266] "Successfully bound pod to node" pod="default/nginx-deployment-58df68d8db-wwnxd" node="three-worker-cluster-worker3" evaluatedNodes=4 feasibleNodes=2
I0322 07:04:38.210012       1 schedule_one.go:266] "Successfully bound pod to node" pod="local-path-storage/local-path-provisioner-684f458cdd-5rk6k" node="three-worker-cluster-worker3" evaluatedNodes=4 feasibleNodes=3
I0322 07:04:38.218111       1 schedule_one.go:266] "Successfully bound pod to node" pod="default/nginx-deployment-58df68d8db-gq78p" node="three-worker-cluster-worker3" evaluatedNodes=4 feasibleNodes=2
I0322 07:04:39.680369       1 schedule_one.go:266] "Successfully bound pod to node" pod="default/nginx-deployment-58df68d8db-s44fm" node="three-worker-cluster-worker2" evaluatedNodes=4 feasibleNodes=2
I0322 07:04:41.006537       1 schedule_one.go:266] "Successfully bound pod to node" pod="default/nginx-deployment-58df68d8db-4chzw" node="three-worker-cluster-worker3" evaluatedNodes=4 feasibleNodes=2
I0322 07:19:37.232887       1 schedule_one.go:266] "Successfully bound pod to node" pod="default/nginx-deployment-58df68d8db-lh9vq" node="three-worker-cluster-worker3" evaluatedNodes=4 feasibleNodes=2
I0322 07:19:37.793285       1 schedule_one.go:266] "Successfully bound pod to node" pod="local-path-storage/local-path-provisioner-684f458cdd-dc96n" node="three-worker-cluster-worker2" evaluatedNodes=4 feasibleNodes=3
I0322 07:19:38.099758       1 schedule_one.go:266] "Successfully bound pod to node" pod="default/nginx-deployment-58df68d8db-hgm8f" node="three-worker-cluster-worker2" evaluatedNodes=4 feasibleNodes=2
I0322 07:19:39.330873       1 schedule_one.go:266] "Successfully bound pod to node" pod="default/nginx-deployment-58df68d8db-z85f8" node="three-worker-cluster-worker3" evaluatedNodes=4 feasibleNodes=2
I0322 07:34:37.999751       1 schedule_one.go:266] "Successfully bound pod to node" pod="default/nginx-deployment-58df68d8db-5jwpw" node="three-worker-cluster-worker2" evaluatedNodes=4 feasibleNodes=2
I0322 07:34:38.001869       1 schedule_one.go:266] "Successfully bound pod to node" pod="local-path-storage/local-path-provisioner-684f458cdd-hxfl4" node="three-worker-cluster-worker3" evaluatedNodes=4 feasibleNodes=3
I0322 07:34:38.220775       1 schedule_one.go:266] "Successfully bound pod to node" pod="default/nginx-deployment-58df68d8db-hqlzr" node="three-worker-cluster-worker3" evaluatedNodes=4 feasibleNodes=2
I0322 07:34:39.006330       1 schedule_one.go:266] "Successfully bound pod to node" pod="default/nginx-deployment-58df68d8db-9n4nx" node="three-worker-cluster-worker3" evaluatedNodes=4 feasibleNodes=2
I0322 07:49:37.523648       1 schedule_one.go:266] "Successfully bound pod to node" pod="default/nginx-deployment-58df68d8db-6vhmb" node="three-worker-cluster-worker2" evaluatedNodes=4 feasibleNodes=2
I0322 07:49:38.048842       1 schedule_one.go:266] "Successfully bound pod to node" pod="local-path-storage/local-path-provisioner-684f458cdd-mhdzn" node="three-worker-cluster-worker3" evaluatedNodes=4 feasibleNodes=3
I0322 07:49:39.249858       1 schedule_one.go:266] "Successfully bound pod to node" pod="default/nginx-deployment-58df68d8db-q4rm4" node="three-worker-cluster-worker3" evaluatedNodes=4 feasibleNodes=2
I0322 07:49:40.086264       1 schedule_one.go:266] "Successfully bound pod to node" pod="default/nginx-deployment-58df68d8db-22nsl" node="three-worker-cluster-worker3" evaluatedNodes=4 feasibleNodes=2
I0322 08:04:37.693614       1 schedule_one.go:266] "Successfully bound pod to node" pod="default/nginx-deployment-58df68d8db-ltnwl" node="three-worker-cluster-worker2" evaluatedNodes=4 feasibleNodes=2
I0322 08:04:38.448000       1 schedule_one.go:266] "Successfully bound pod to node" pod="local-path-storage/local-path-provisioner-684f458cdd-s5p4z" node="three-worker-cluster-worker3" evaluatedNodes=4 feasibleNodes=3
I0322 08:04:39.148185       1 schedule_one.go:266] "Successfully bound pod to node" pod="default/nginx-deployment-58df68d8db-mfq8z" node="three-worker-cluster-worker3" evaluatedNodes=4 feasibleNodes=2
I0322 08:04:39.204852       1 schedule_one.go:266] "Successfully bound pod to node" pod="default/nginx-deployment-58df68d8db-dr77b" node="three-worker-cluster-worker3" evaluatedNodes=4 feasibleNodes=2
I0322 08:19:37.678524       1 schedule_one.go:266] "Successfully bound pod to node" pod="default/nginx-deployment-58df68d8db-mm846" node="three-worker-cluster-worker2" evaluatedNodes=4 feasibleNodes=2
I0322 08:19:38.137722       1 schedule_one.go:266] "Successfully bound pod to node" pod="local-path-storage/local-path-provisioner-684f458cdd-zzhgk" node="three-worker-cluster-worker3" evaluatedNodes=4 feasibleNodes=3
I0322 08:19:38.965750       1 schedule_one.go:266] "Successfully bound pod to node" pod="default/nginx-deployment-58df68d8db-m2nsb" node="three-worker-cluster-worker3" evaluatedNodes=4 feasibleNodes=2
I0322 08:19:40.053409       1 schedule_one.go:266] "Successfully bound pod to node" pod="default/nginx-deployment-58df68d8db-94tds" node="three-worker-cluster-worker2" evaluatedNodes=4 feasibleNodes=2
I0322 08:34:38.034102       1 schedule_one.go:266] "Successfully bound pod to node" pod="local-path-storage/local-path-provisioner-684f458cdd-qmvm6" node="three-worker-cluster-worker3" evaluatedNodes=4 feasibleNodes=3
I0322 08:34:38.048536       1 schedule_one.go:266] "Successfully bound pod to node" pod="default/nginx-deployment-58df68d8db-x5vrt" node="three-worker-cluster-worker3" evaluatedNodes=4 feasibleNodes=2
I0322 08:34:38.350056       1 schedule_one.go:266] "Successfully bound pod to node" pod="default/nginx-deployment-58df68d8db-4mhbg" node="three-worker-cluster-worker3" evaluatedNodes=4 feasibleNodes=2
I0322 08:34:39.628643       1 schedule_one.go:266] "Successfully bound pod to node" pod="default/nginx-deployment-58df68d8db-h26mc" node="three-worker-cluster-worker2" evaluatedNodes=4 feasibleNodes=2
I0322 08:49:37.518972       1 schedule_one.go:266] "Successfully bound pod to node" pod="default/nginx-deployment-58df68d8db-c944h" node="three-worker-cluster-worker3" evaluatedNodes=4 feasibleNodes=2
I0322 08:49:37.759290       1 schedule_one.go:266] "Successfully bound pod to node" pod="local-path-storage/local-path-provisioner-684f458cdd-r9nnd" node="three-worker-cluster-worker2" evaluatedNodes=4 feasibleNodes=3
I0322 08:49:38.229630       1 schedule_one.go:266] "Successfully bound pod to node" pod="default/nginx-deployment-58df68d8db-w4mbh" node="three-worker-cluster-worker2" evaluatedNodes=4 feasibleNodes=2
I0322 08:49:39.584930       1 schedule_one.go:266] "Successfully bound pod to node" pod="default/nginx-deployment-58df68d8db-p7pnr" node="three-worker-cluster-worker3" evaluatedNodes=4 feasibleNodes=2
I0322 09:04:37.263781       1 schedule_one.go:266] "Successfully bound pod to node" pod="default/nginx-deployment-58df68d8db-jbwzn" node="three-worker-cluster-worker2" evaluatedNodes=4 feasibleNodes=2
I0322 09:04:37.872257       1 schedule_one.go:266] "Successfully bound pod to node" pod="local-path-storage/local-path-provisioner-684f458cdd-v4prm" node="three-worker-cluster-worker3" evaluatedNodes=4 feasibleNodes=3
I0322 09:04:38.598153       1 schedule_one.go:266] "Successfully bound pod to node" pod="default/nginx-deployment-58df68d8db-xnsll" node="three-worker-cluster-worker3" evaluatedNodes=4 feasibleNodes=2
I0322 09:04:39.802265       1 schedule_one.go:266] "Successfully bound pod to node" pod="default/nginx-deployment-58df68d8db-cgvkv" node="three-worker-cluster-worker3" evaluatedNodes=4 feasibleNodes=2
I0322 09:19:37.706486       1 schedule_one.go:266] "Successfully bound pod to node" pod="default/nginx-deployment-58df68d8db-tjmln" node="three-worker-cluster-worker2" evaluatedNodes=4 feasibleNodes=2
I0322 09:19:38.032742       1 schedule_one.go:266] "Successfully bound pod to node" pod="default/nginx-deployment-58df68d8db-khs8v" node="three-worker-cluster-worker3" evaluatedNodes=4 feasibleNodes=2
I0322 09:19:38.033252       1 schedule_one.go:266] "Successfully bound pod to node" pod="local-path-storage/local-path-provisioner-684f458cdd-jshll" node="three-worker-cluster-worker3" evaluatedNodes=4 feasibleNodes=3
I0322 09:19:38.942638       1 schedule_one.go:266] "Successfully bound pod to node" pod="default/nginx-deployment-58df68d8db-hh4tb" node="three-worker-cluster-worker3" evaluatedNodes=4 feasibleNodes=2
I0322 09:34:38.071348       1 schedule_one.go:266] "Successfully bound pod to node" pod="default/nginx-deployment-58df68d8db-bq4pg" node="three-worker-cluster-worker2" evaluatedNodes=4 feasibleNodes=2
I0322 09:34:38.072273       1 schedule_one.go:266] "Successfully bound pod to node" pod="local-path-storage/local-path-provisioner-684f458cdd-wgrk2" node="three-worker-cluster-worker3" evaluatedNodes=4 feasibleNodes=3
I0322 09:34:38.376729       1 schedule_one.go:266] "Successfully bound pod to node" pod="default/nginx-deployment-58df68d8db-p2zgl" node="three-worker-cluster-worker3" evaluatedNodes=4 feasibleNodes=2
I0322 09:34:39.699677       1 schedule_one.go:266] "Successfully bound pod to node" pod="default/nginx-deployment-58df68d8db-s6dxc" node="three-worker-cluster-worker3" evaluatedNodes=4 feasibleNodes=2
I0322 09:49:37.287276       1 schedule_one.go:266] "Successfully bound pod to node" pod="default/nginx-deployment-58df68d8db-rtxc5" node="three-worker-cluster-worker2" evaluatedNodes=4 feasibleNodes=2
I0322 09:49:37.938439       1 schedule_one.go:266] "Successfully bound pod to node" pod="local-path-storage/local-path-provisioner-684f458cdd-g8kdt" node="three-worker-cluster-worker3" evaluatedNodes=4 feasibleNodes=3
I0322 09:49:38.765365       1 schedule_one.go:266] "Successfully bound pod to node" pod="default/nginx-deployment-58df68d8db-tzt7b" node="three-worker-cluster-worker3" evaluatedNodes=4 feasibleNodes=2
I0322 09:49:40.106169       1 schedule_one.go:266] "Successfully bound pod to node" pod="default/nginx-deployment-58df68d8db-722x8" node="three-worker-cluster-worker2" evaluatedNodes=4 feasibleNodes=2
I0322 10:04:37.800708       1 schedule_one.go:266] "Successfully bound pod to node" pod="default/nginx-deployment-58df68d8db-8jt9n" node="three-worker-cluster-worker3" evaluatedNodes=4 feasibleNodes=2
I0322 10:04:38.327939       1 schedule_one.go:266] "Successfully bound pod to node" pod="local-path-storage/local-path-provisioner-684f458cdd-xf9hs" node="three-worker-cluster-worker3" evaluatedNodes=4 feasibleNodes=3
I0322 10:04:38.642556       1 schedule_one.go:266] "Successfully bound pod to node" pod="default/nginx-deployment-58df68d8db-m45wh" node="three-worker-cluster-worker3" evaluatedNodes=4 feasibleNodes=2
I0322 10:04:40.150074       1 schedule_one.go:266] "Successfully bound pod to node" pod="default/nginx-deployment-58df68d8db-hr9w5" node="three-worker-cluster-worker2" evaluatedNodes=4 feasibleNodes=2
I0322 10:19:37.602768       1 schedule_one.go:266] "Successfully bound pod to node" pod="default/nginx-deployment-58df68d8db-j68qt" node="three-worker-cluster-worker3" evaluatedNodes=4 feasibleNodes=2
I0322 10:19:38.392024       1 schedule_one.go:266] "Successfully bound pod to node" pod="default/nginx-deployment-58df68d8db-pw8lx" node="three-worker-cluster-worker3" evaluatedNodes=4 feasibleNodes=2
I0322 10:19:38.395437       1 schedule_one.go:266] "Successfully bound pod to node" pod="local-path-storage/local-path-provisioner-684f458cdd-tpxp2" node="three-worker-cluster-worker2" evaluatedNodes=4 feasibleNodes=3
I0322 10:19:39.719256       1 schedule_one.go:266] "Successfully bound pod to node" pod="default/nginx-deployment-58df68d8db-jtctx" node="three-worker-cluster-worker2" evaluatedNodes=4 feasibleNodes=2
I0322 10:19:41.053768       1 schedule_one.go:266] "Successfully bound pod to node" pod="default/nginx-deployment-58df68d8db-jdsf2" node="three-worker-cluster-worker3" evaluatedNodes=4 feasibleNodes=2
I0322 10:34:37.451711       1 schedule_one.go:266] "Successfully bound pod to node" pod="default/nginx-deployment-58df68d8db-cwjcz" node="three-worker-cluster-worker3" evaluatedNodes=4 feasibleNodes=2
I0322 10:34:37.722788       1 schedule_one.go:266] "Successfully bound pod to node" pod="local-path-storage/local-path-provisioner-684f458cdd-6nr7r" node="three-worker-cluster-worker3" evaluatedNodes=4 feasibleNodes=3
I0322 10:34:38.153801       1 schedule_one.go:266] "Successfully bound pod to node" pod="default/nginx-deployment-58df68d8db-x66d7" node="three-worker-cluster-worker2" evaluatedNodes=4 feasibleNodes=2
I0322 10:34:39.317843       1 schedule_one.go:266] "Successfully bound pod to node" pod="default/nginx-deployment-58df68d8db-hqgkd" node="three-worker-cluster-worker3" evaluatedNodes=4 feasibleNodes=2
I0322 10:49:37.285552       1 schedule_one.go:266] "Successfully bound pod to node" pod="default/nginx-deployment-58df68d8db-mblxr" node="three-worker-cluster-worker2" evaluatedNodes=4 feasibleNodes=2
I0322 10:49:38.392426       1 schedule_one.go:266] "Successfully bound pod to node" pod="local-path-storage/local-path-provisioner-684f458cdd-csmlk" node="three-worker-cluster-worker3" evaluatedNodes=4 feasibleNodes=3
I0322 10:49:38.941388       1 schedule_one.go:266] "Successfully bound pod to node" pod="default/nginx-deployment-58df68d8db-mtj68" node="three-worker-cluster-worker3" evaluatedNodes=4 feasibleNodes=2
I0322 10:49:40.207172       1 schedule_one.go:266] "Successfully bound pod to node" pod="default/nginx-deployment-58df68d8db-hh7hr" node="three-worker-cluster-worker2" evaluatedNodes=4 feasibleNodes=2
I0322 11:04:37.807576       1 schedule_one.go:266] "Successfully bound pod to node" pod="default/nginx-deployment-58df68d8db-66w5x" node="three-worker-cluster-worker3" evaluatedNodes=4 feasibleNodes=2
I0322 11:04:38.531647       1 schedule_one.go:266] "Successfully bound pod to node" pod="local-path-storage/local-path-provisioner-684f458cdd-kxl2h" node="three-worker-cluster-worker3" evaluatedNodes=4 feasibleNodes=3
I0322 11:04:38.735490       1 schedule_one.go:266] "Successfully bound pod to node" pod="default/nginx-deployment-58df68d8db-l2v2m" node="three-worker-cluster-worker3" evaluatedNodes=4 feasibleNodes=2
I0322 11:04:39.848634       1 schedule_one.go:266] "Successfully bound pod to node" pod="default/nginx-deployment-58df68d8db-5m9rt" node="three-worker-cluster-worker2" evaluatedNodes=4 feasibleNodes=2
I0322 11:04:40.418969       1 schedule_one.go:266] "Successfully bound pod to node" pod="default/nginx-deployment-58df68d8db-vzf6s" node="three-worker-cluster-worker3" evaluatedNodes=4 feasibleNodes=2
I0322 11:19:37.448237       1 schedule_one.go:266] "Successfully bound pod to node" pod="local-path-storage/local-path-provisioner-684f458cdd-4hqw7" node="three-worker-cluster-worker3" evaluatedNodes=4 feasibleNodes=3
I0322 11:19:38.161334       1 schedule_one.go:266] "Successfully bound pod to node" pod="default/nginx-deployment-58df68d8db-jkdl2" node="three-worker-cluster-worker2" evaluatedNodes=4 feasibleNodes=2
I0322 11:19:38.847884       1 schedule_one.go:266] "Successfully bound pod to node" pod="default/nginx-deployment-58df68d8db-vqhlz" node="three-worker-cluster-worker3" evaluatedNodes=4 feasibleNodes=2
I0322 11:19:39.772948       1 schedule_one.go:266] "Successfully bound pod to node" pod="default/nginx-deployment-58df68d8db-pk8v8" node="three-worker-cluster-worker3" evaluatedNodes=4 feasibleNodes=2
I0322 11:34:37.841404       1 schedule_one.go:266] "Successfully bound pod to node" pod="local-path-storage/local-path-provisioner-684f458cdd-42vhq" node="three-worker-cluster-worker3" evaluatedNodes=4 feasibleNodes=3
I0322 11:34:37.947286       1 schedule_one.go:266] "Successfully bound pod to node" pod="default/nginx-deployment-58df68d8db-wjdvf" node="three-worker-cluster-worker2" evaluatedNodes=4 feasibleNodes=2
I0322 11:34:38.407383       1 schedule_one.go:266] "Successfully bound pod to node" pod="default/nginx-deployment-58df68d8db-qg4p6" node="three-worker-cluster-worker3" evaluatedNodes=4 feasibleNodes=2
I0322 11:34:39.434747       1 schedule_one.go:266] "Successfully bound pod to node" pod="default/nginx-deployment-58df68d8db-qs5bd" node="three-worker-cluster-worker3" evaluatedNodes=4 feasibleNodes=2
I0322 11:49:37.833455       1 schedule_one.go:266] "Successfully bound pod to node" pod="default/nginx-deployment-58df68d8db-nckbx" node="three-worker-cluster-worker2" evaluatedNodes=4 feasibleNodes=2
I0322 11:49:38.301740       1 schedule_one.go:266] "Successfully bound pod to node" pod="local-path-storage/local-path-provisioner-684f458cdd-zcxf9" node="three-worker-cluster-worker3" evaluatedNodes=4 feasibleNodes=3
I0322 11:49:38.508893       1 schedule_one.go:266] "Successfully bound pod to node" pod="default/nginx-deployment-58df68d8db-pjc5s" node="three-worker-cluster-worker3" evaluatedNodes=4 feasibleNodes=2
I0322 11:49:39.469101       1 schedule_one.go:266] "Successfully bound pod to node" pod="default/nginx-deployment-58df68d8db-6j55d" node="three-worker-cluster-worker2" evaluatedNodes=4 feasibleNodes=2
I0322 12:04:37.329190       1 schedule_one.go:266] "Successfully bound pod to node" pod="default/nginx-deployment-58df68d8db-v8s7t" node="three-worker-cluster-worker3" evaluatedNodes=4 feasibleNodes=2
I0322 12:04:38.065044       1 schedule_one.go:266] "Successfully bound pod to node" pod="local-path-storage/local-path-provisioner-684f458cdd-dqqxn" node="three-worker-cluster-worker3" evaluatedNodes=4 feasibleNodes=3
I0322 12:04:38.670591       1 schedule_one.go:266] "Successfully bound pod to node" pod="default/nginx-deployment-58df68d8db-s8ql6" node="three-worker-cluster-worker3" evaluatedNodes=4 feasibleNodes=2
I0322 12:04:39.935690       1 schedule_one.go:266] "Successfully bound pod to node" pod="default/nginx-deployment-58df68d8db-wl64k" node="three-worker-cluster-worker2" evaluatedNodes=4 feasibleNodes=2
I0322 12:04:41.137225       1 schedule_one.go:266] "Successfully bound pod to node" pod="default/nginx-deployment-58df68d8db-nxmmn" node="three-worker-cluster-worker3" evaluatedNodes=4 feasibleNodes=2
I0322 12:19:37.344166       1 schedule_one.go:266] "Successfully bound pod to node" pod="default/nginx-deployment-58df68d8db-57wkg" node="three-worker-cluster-worker3" evaluatedNodes=4 feasibleNodes=2
I0322 12:19:37.953341       1 schedule_one.go:266] "Successfully bound pod to node" pod="local-path-storage/local-path-provisioner-684f458cdd-tpszw" node="three-worker-cluster-worker2" evaluatedNodes=4 feasibleNodes=3
I0322 12:19:38.545042       1 schedule_one.go:266] "Successfully bound pod to node" pod="default/nginx-deployment-58df68d8db-ltjjj" node="three-worker-cluster-worker2" evaluatedNodes=4 feasibleNodes=2
I0322 12:19:39.659341       1 schedule_one.go:266] "Successfully bound pod to node" pod="default/nginx-deployment-58df68d8db-5hbzz" node="three-worker-cluster-worker3" evaluatedNodes=4 feasibleNodes=2
I0322 12:34:38.175039       1 schedule_one.go:266] "Successfully bound pod to node" pod="local-path-storage/local-path-provisioner-684f458cdd-jq5gd" node="three-worker-cluster-worker3" evaluatedNodes=4 feasibleNodes=3
I0322 12:34:38.515375       1 schedule_one.go:266] "Successfully bound pod to node" pod="default/nginx-deployment-58df68d8db-rvn9h" node="three-worker-cluster-worker2" evaluatedNodes=4 feasibleNodes=2
I0322 12:34:38.743906       1 schedule_one.go:266] "Successfully bound pod to node" pod="default/nginx-deployment-58df68d8db-wqnl8" node="three-worker-cluster-worker3" evaluatedNodes=4 feasibleNodes=2
I0322 12:34:39.337500       1 schedule_one.go:266] "Successfully bound pod to node" pod="default/nginx-deployment-58df68d8db-shbkh" node="three-worker-cluster-worker3" evaluatedNodes=4 feasibleNodes=2
I0322 12:49:37.850523       1 schedule_one.go:266] "Successfully bound pod to node" pod="default/nginx-deployment-58df68d8db-nlrr2" node="three-worker-cluster-worker2" evaluatedNodes=4 feasibleNodes=2
I0322 12:49:38.733397       1 schedule_one.go:266] "Successfully bound pod to node" pod="local-path-storage/local-path-provisioner-684f458cdd-rsgnc" node="three-worker-cluster-worker3" evaluatedNodes=4 feasibleNodes=3
I0322 12:49:38.938807       1 schedule_one.go:266] "Successfully bound pod to node" pod="default/nginx-deployment-58df68d8db-8jn5t" node="three-worker-cluster-worker3" evaluatedNodes=4 feasibleNodes=2
I0322 12:49:39.898759       1 schedule_one.go:266] "Successfully bound pod to node" pod="default/nginx-deployment-58df68d8db-9bcsn" node="three-worker-cluster-worker2" evaluatedNodes=4 feasibleNodes=2
I0322 13:04:37.315066       1 schedule_one.go:266] "Successfully bound pod to node" pod="default/nginx-deployment-58df68d8db-rl7lv" node="three-worker-cluster-worker3" evaluatedNodes=4 feasibleNodes=2
I0322 13:04:37.911538       1 schedule_one.go:266] "Successfully bound pod to node" pod="local-path-storage/local-path-provisioner-684f458cdd-6tfvb" node="three-worker-cluster-worker3" evaluatedNodes=4 feasibleNodes=3
I0322 13:04:38.584820       1 schedule_one.go:266] "Successfully bound pod to node" pod="default/nginx-deployment-58df68d8db-z5njg" node="three-worker-cluster-worker3" evaluatedNodes=4 feasibleNodes=2
I0322 13:04:39.772275       1 schedule_one.go:266] "Successfully bound pod to node" pod="default/nginx-deployment-58df68d8db-dmpsp" node="three-worker-cluster-worker2" evaluatedNodes=4 feasibleNodes=2
I0322 13:19:37.498494       1 schedule_one.go:266] "Successfully bound pod to node" pod="local-path-storage/local-path-provisioner-684f458cdd-lvfd5" node="three-worker-cluster-worker3" evaluatedNodes=4 feasibleNodes=3
I0322 13:19:38.271291       1 schedule_one.go:266] "Successfully bound pod to node" pod="default/nginx-deployment-58df68d8db-q44pk" node="three-worker-cluster-worker3" evaluatedNodes=4 feasibleNodes=2
I0322 13:19:38.877570       1 schedule_one.go:266] "Successfully bound pod to node" pod="default/nginx-deployment-58df68d8db-4glw8" node="three-worker-cluster-worker2" evaluatedNodes=4 feasibleNodes=2
I0322 13:19:40.103539       1 schedule_one.go:266] "Successfully bound pod to node" pod="default/nginx-deployment-58df68d8db-b476c" node="three-worker-cluster-worker2" evaluatedNodes=4 feasibleNodes=2
I0322 13:34:37.881123       1 schedule_one.go:266] "Successfully bound pod to node" pod="local-path-storage/local-path-provisioner-684f458cdd-xlpjt" node="three-worker-cluster-worker3" evaluatedNodes=4 feasibleNodes=3
I0322 13:34:37.881824       1 schedule_one.go:266] "Successfully bound pod to node" pod="default/nginx-deployment-58df68d8db-k2zqs" node="three-worker-cluster-worker3" evaluatedNodes=4 feasibleNodes=2
I0322 13:34:38.341597       1 schedule_one.go:266] "Successfully bound pod to node" pod="default/nginx-deployment-58df68d8db-5p4d6" node="three-worker-cluster-worker3" evaluatedNodes=4 feasibleNodes=2
I0322 13:34:39.080102       1 schedule_one.go:266] "Successfully bound pod to node" pod="default/nginx-deployment-58df68d8db-f4kdz" node="three-worker-cluster-worker2" evaluatedNodes=4 feasibleNodes=2
I0322 13:34:40.795332       1 schedule_one.go:266] "Successfully bound pod to node" pod="default/nginx-deployment-58df68d8db-jbrkf" node="three-worker-cluster-worker3" evaluatedNodes=4 feasibleNodes=2
I0322 13:49:37.532354       1 schedule_one.go:266] "Successfully bound pod to node" pod="default/nginx-deployment-58df68d8db-9725m" node="three-worker-cluster-worker3" evaluatedNodes=4 feasibleNodes=2
I0322 13:49:37.790326       1 schedule_one.go:266] "Successfully bound pod to node" pod="local-path-storage/local-path-provisioner-684f458cdd-b4knf" node="three-worker-cluster-worker2" evaluatedNodes=4 feasibleNodes=3
I0322 13:49:38.743988       1 schedule_one.go:266] "Successfully bound pod to node" pod="default/nginx-deployment-58df68d8db-wfqfm" node="three-worker-cluster-worker2" evaluatedNodes=4 feasibleNodes=2
I0322 13:49:40.001392       1 schedule_one.go:266] "Successfully bound pod to node" pod="default/nginx-deployment-58df68d8db-nd2vq" node="three-worker-cluster-worker3" evaluatedNodes=4 feasibleNodes=2
I0322 14:04:37.449978       1 schedule_one.go:266] "Successfully bound pod to node" pod="local-path-storage/local-path-provisioner-684f458cdd-tdkjl" node="three-worker-cluster-worker3" evaluatedNodes=4 feasibleNodes=3
I0322 14:04:37.917865       1 schedule_one.go:266] "Successfully bound pod to node" pod="default/nginx-deployment-58df68d8db-j8qjz" node="three-worker-cluster-worker3" evaluatedNodes=4 feasibleNodes=2
I0322 14:04:38.648812       1 schedule_one.go:266] "Successfully bound pod to node" pod="default/nginx-deployment-58df68d8db-rbm8w" node="three-worker-cluster-worker2" evaluatedNodes=4 feasibleNodes=2
I0322 14:04:39.715698       1 schedule_one.go:266] "Successfully bound pod to node" pod="default/nginx-deployment-58df68d8db-xch6t" node="three-worker-cluster-worker3" evaluatedNodes=4 feasibleNodes=2
I0322 14:19:37.393394       1 schedule_one.go:266] "Successfully bound pod to node" pod="local-path-storage/local-path-provisioner-684f458cdd-cg9v8" node="three-worker-cluster-worker3" evaluatedNodes=4 feasibleNodes=3
I0322 14:19:38.287921       1 schedule_one.go:266] "Successfully bound pod to node" pod="default/nginx-deployment-58df68d8db-n2md9" node="three-worker-cluster-worker2" evaluatedNodes=4 feasibleNodes=2
I0322 14:19:38.922265       1 schedule_one.go:266] "Successfully bound pod to node" pod="default/nginx-deployment-58df68d8db-c2t58" node="three-worker-cluster-worker3" evaluatedNodes=4 feasibleNodes=2
I0322 14:19:40.276496       1 schedule_one.go:266] "Successfully bound pod to node" pod="default/nginx-deployment-58df68d8db-5fvgh" node="three-worker-cluster-worker3" evaluatedNodes=4 feasibleNodes=2
I0322 14:34:38.004251       1 schedule_one.go:266] "Successfully bound pod to node" pod="local-path-storage/local-path-provisioner-684f458cdd-vr7lj" node="three-worker-cluster-worker3" evaluatedNodes=4 feasibleNodes=3
I0322 14:34:38.004318       1 schedule_one.go:266] "Successfully bound pod to node" pod="default/nginx-deployment-58df68d8db-8qgtl" node="three-worker-cluster-worker2" evaluatedNodes=4 feasibleNodes=2
I0322 14:34:38.534034       1 schedule_one.go:266] "Successfully bound pod to node" pod="default/nginx-deployment-58df68d8db-4wjzb" node="three-worker-cluster-worker3" evaluatedNodes=4 feasibleNodes=2
I0322 14:34:39.574637       1 schedule_one.go:266] "Successfully bound pod to node" pod="default/nginx-deployment-58df68d8db-pvv99" node="three-worker-cluster-worker3" evaluatedNodes=4 feasibleNodes=2
I0322 14:49:37.734237       1 schedule_one.go:266] "Successfully bound pod to node" pod="default/nginx-deployment-58df68d8db-rcpbt" node="three-worker-cluster-worker2" evaluatedNodes=4 feasibleNodes=2
I0322 14:49:37.908960       1 schedule_one.go:266] "Successfully bound pod to node" pod="local-path-storage/local-path-provisioner-684f458cdd-twd7t" node="three-worker-cluster-worker3" evaluatedNodes=4 feasibleNodes=3
I0322 14:49:39.297887       1 schedule_one.go:266] "Successfully bound pod to node" pod="default/nginx-deployment-58df68d8db-rssk8" node="three-worker-cluster-worker3" evaluatedNodes=4 feasibleNodes=2
I0322 14:49:39.507876       1 schedule_one.go:266] "Successfully bound pod to node" pod="default/nginx-deployment-58df68d8db-zc6ms" node="three-worker-cluster-worker2" evaluatedNodes=4 feasibleNodes=2
I0322 15:04:37.579199       1 schedule_one.go:266] "Successfully bound pod to node" pod="default/nginx-deployment-58df68d8db-9hw6v" node="three-worker-cluster-worker3" evaluatedNodes=4 feasibleNodes=2
I0322 15:04:38.061183       1 schedule_one.go:266] "Successfully bound pod to node" pod="local-path-storage/local-path-provisioner-684f458cdd-dgjft" node="three-worker-cluster-worker3" evaluatedNodes=4 feasibleNodes=3
I0322 15:04:38.561550       1 schedule_one.go:266] "Successfully bound pod to node" pod="default/nginx-deployment-58df68d8db-lz5tl" node="three-worker-cluster-worker2" evaluatedNodes=4 feasibleNodes=2
I0322 15:04:39.606398       1 schedule_one.go:266] "Successfully bound pod to node" pod="default/nginx-deployment-58df68d8db-v6lz7" node="three-worker-cluster-worker3" evaluatedNodes=4 feasibleNodes=2
I0322 15:19:37.737105       1 schedule_one.go:266] "Successfully bound pod to node" pod="default/nginx-deployment-58df68d8db-d52lt" node="three-worker-cluster-worker3" evaluatedNodes=4 feasibleNodes=2
I0322 15:19:38.124561       1 schedule_one.go:266] "Successfully bound pod to node" pod="local-path-storage/local-path-provisioner-684f458cdd-rh6mw" node="three-worker-cluster-worker2" evaluatedNodes=4 feasibleNodes=3
I0322 15:19:38.850828       1 schedule_one.go:266] "Successfully bound pod to node" pod="default/nginx-deployment-58df68d8db-zcbbh" node="three-worker-cluster-worker2" evaluatedNodes=4 feasibleNodes=2
I0322 15:19:40.014644       1 schedule_one.go:266] "Successfully bound pod to node" pod="default/nginx-deployment-58df68d8db-nwcss" node="three-worker-cluster-worker3" evaluatedNodes=4 feasibleNodes=2
I0322 15:34:37.624628       1 schedule_one.go:266] "Successfully bound pod to node" pod="local-path-storage/local-path-provisioner-684f458cdd-fdb82" node="three-worker-cluster-worker3" evaluatedNodes=4 feasibleNodes=3
I0322 15:34:37.958223       1 schedule_one.go:266] "Successfully bound pod to node" pod="default/nginx-deployment-58df68d8db-dchpf" node="three-worker-cluster-worker2" evaluatedNodes=4 feasibleNodes=2
I0322 15:34:38.028898       1 schedule_one.go:266] "Successfully bound pod to node" pod="default/nginx-deployment-58df68d8db-z8jqb" node="three-worker-cluster-worker3" evaluatedNodes=4 feasibleNodes=2
I0322 15:34:39.608763       1 schedule_one.go:266] "Successfully bound pod to node" pod="default/nginx-deployment-58df68d8db-rfxv6" node="three-worker-cluster-worker3" evaluatedNodes=4 feasibleNodes=2
I0322 15:49:37.746880       1 schedule_one.go:266] "Successfully bound pod to node" pod="default/nginx-deployment-58df68d8db-gn7jc" node="three-worker-cluster-worker2" evaluatedNodes=4 feasibleNodes=2
I0322 15:49:38.320117       1 schedule_one.go:266] "Successfully bound pod to node" pod="local-path-storage/local-path-provisioner-684f458cdd-fnx66" node="three-worker-cluster-worker3" evaluatedNodes=4 feasibleNodes=3
I0322 15:49:38.680138       1 schedule_one.go:266] "Successfully bound pod to node" pod="default/nginx-deployment-58df68d8db-72kg8" node="three-worker-cluster-worker3" evaluatedNodes=4 feasibleNodes=2
I0322 15:49:39.549836       1 schedule_one.go:266] "Successfully bound pod to node" pod="default/nginx-deployment-58df68d8db-9xznh" node="three-worker-cluster-worker2" evaluatedNodes=4 feasibleNodes=2
I0322 16:04:37.866681       1 schedule_one.go:266] "Successfully bound pod to node" pod="default/nginx-deployment-58df68d8db-zccz6" node="three-worker-cluster-worker3" evaluatedNodes=4 feasibleNodes=2
I0322 16:04:38.279592       1 schedule_one.go:266] "Successfully bound pod to node" pod="local-path-storage/local-path-provisioner-684f458cdd-7kcxc" node="three-worker-cluster-worker3" evaluatedNodes=4 feasibleNodes=3
I0322 16:04:38.887378       1 schedule_one.go:266] "Successfully bound pod to node" pod="default/nginx-deployment-58df68d8db-fvqkp" node="three-worker-cluster-worker3" evaluatedNodes=4 feasibleNodes=2
I0322 16:04:40.263844       1 schedule_one.go:266] "Successfully bound pod to node" pod="default/nginx-deployment-58df68d8db-vk7jj" node="three-worker-cluster-worker2" evaluatedNodes=4 feasibleNodes=2
I0322 16:04:41.195851       1 schedule_one.go:266] "Successfully bound pod to node" pod="default/nginx-deployment-58df68d8db-4wlnk" node="three-worker-cluster-worker3" evaluatedNodes=4 feasibleNodes=2
I0322 16:19:37.766592       1 schedule_one.go:266] "Successfully bound pod to node" pod="local-path-storage/local-path-provisioner-684f458cdd-7xc5z" node="three-worker-cluster-worker3" evaluatedNodes=4 feasibleNodes=3
I0322 16:19:37.767864       1 schedule_one.go:266] "Successfully bound pod to node" pod="default/nginx-deployment-58df68d8db-8pcsz" node="three-worker-cluster-worker2" evaluatedNodes=4 feasibleNodes=2
I0322 16:19:39.149037       1 schedule_one.go:266] "Successfully bound pod to node" pod="default/nginx-deployment-58df68d8db-mqg7d" node="three-worker-cluster-worker3" evaluatedNodes=4 feasibleNodes=2
I0322 16:19:40.002641       1 schedule_one.go:266] "Successfully bound pod to node" pod="default/nginx-deployment-58df68d8db-pqnsm" node="three-worker-cluster-worker2" evaluatedNodes=4 feasibleNodes=2
I0322 16:34:37.729097       1 schedule_one.go:266] "Successfully bound pod to node" pod="default/nginx-deployment-58df68d8db-dbx66" node="three-worker-cluster-worker3" evaluatedNodes=4 feasibleNodes=2
I0322 16:34:37.887017       1 schedule_one.go:266] "Successfully bound pod to node" pod="local-path-storage/local-path-provisioner-684f458cdd-htcm4" node="three-worker-cluster-worker3" evaluatedNodes=4 feasibleNodes=3
I0322 16:34:38.519572       1 schedule_one.go:266] "Successfully bound pod to node" pod="default/nginx-deployment-58df68d8db-7trnh" node="three-worker-cluster-worker3" evaluatedNodes=4 feasibleNodes=2
I0322 16:34:39.922401       1 schedule_one.go:266] "Successfully bound pod to node" pod="default/nginx-deployment-58df68d8db-t459f" node="three-worker-cluster-worker2" evaluatedNodes=4 feasibleNodes=2
I0322 16:49:38.149142       1 schedule_one.go:266] "Successfully bound pod to node" pod="default/nginx-deployment-58df68d8db-xrc75" node="three-worker-cluster-worker3" evaluatedNodes=4 feasibleNodes=2
I0322 16:49:38.464332       1 schedule_one.go:266] "Successfully bound pod to node" pod="local-path-storage/local-path-provisioner-684f458cdd-xntsv" node="three-worker-cluster-worker2" evaluatedNodes=4 feasibleNodes=3
I0322 16:49:38.881930       1 schedule_one.go:266] "Successfully bound pod to node" pod="default/nginx-deployment-58df68d8db-pdnfb" node="three-worker-cluster-worker2" evaluatedNodes=4 feasibleNodes=2
I0322 16:49:40.173054       1 schedule_one.go:266] "Successfully bound pod to node" pod="default/nginx-deployment-58df68d8db-ldhfm" node="three-worker-cluster-worker3" evaluatedNodes=4 feasibleNodes=2
I0322 17:04:37.302287       1 schedule_one.go:266] "Successfully bound pod to node" pod="default/nginx-deployment-58df68d8db-m6j4d" node="three-worker-cluster-worker3" evaluatedNodes=4 feasibleNodes=2
I0322 17:04:38.011739       1 schedule_one.go:266] "Successfully bound pod to node" pod="local-path-storage/local-path-provisioner-684f458cdd-bszmb" node="three-worker-cluster-worker3" evaluatedNodes=4 feasibleNodes=3
I0322 17:04:38.642116       1 schedule_one.go:266] "Successfully bound pod to node" pod="default/nginx-deployment-58df68d8db-x42xj" node="three-worker-cluster-worker2" evaluatedNodes=4 feasibleNodes=2
I0322 17:04:40.436447       1 schedule_one.go:266] "Successfully bound pod to node" pod="default/nginx-deployment-58df68d8db-dxxpb" node="three-worker-cluster-worker3" evaluatedNodes=4 feasibleNodes=2
I0322 17:19:37.830981       1 schedule_one.go:266] "Successfully bound pod to node" pod="local-path-storage/local-path-provisioner-684f458cdd-s9lgv" node="three-worker-cluster-worker2" evaluatedNodes=4 feasibleNodes=3
I0322 17:19:37.831339       1 schedule_one.go:266] "Successfully bound pod to node" pod="default/nginx-deployment-58df68d8db-rg4gh" node="three-worker-cluster-worker3" evaluatedNodes=4 feasibleNodes=2
I0322 17:19:38.143778       1 schedule_one.go:266] "Successfully bound pod to node" pod="default/nginx-deployment-58df68d8db-jw7lc" node="three-worker-cluster-worker2" evaluatedNodes=4 feasibleNodes=2
I0322 17:19:38.758692       1 schedule_one.go:266] "Successfully bound pod to node" pod="default/nginx-deployment-58df68d8db-npwxh" node="three-worker-cluster-worker3" evaluatedNodes=4 feasibleNodes=2
I0322 17:34:37.516223       1 schedule_one.go:266] "Successfully bound pod to node" pod="local-path-storage/local-path-provisioner-684f458cdd-mwsr4" node="three-worker-cluster-worker3" evaluatedNodes=4 feasibleNodes=3
I0322 17:34:37.753848       1 schedule_one.go:266] "Successfully bound pod to node" pod="default/nginx-deployment-58df68d8db-hw6zm" node="three-worker-cluster-worker2" evaluatedNodes=4 feasibleNodes=2
I0322 17:34:38.025247       1 schedule_one.go:266] "Successfully bound pod to node" pod="default/nginx-deployment-58df68d8db-xmp88" node="three-worker-cluster-worker3" evaluatedNodes=4 feasibleNodes=2
I0322 17:34:38.866595       1 schedule_one.go:266] "Successfully bound pod to node" pod="default/nginx-deployment-58df68d8db-b86qm" node="three-worker-cluster-worker3" evaluatedNodes=4 feasibleNodes=2
I0322 17:49:37.669945       1 schedule_one.go:266] "Successfully bound pod to node" pod="default/nginx-deployment-58df68d8db-7wnnc" node="three-worker-cluster-worker2" evaluatedNodes=4 feasibleNodes=2
I0322 17:49:38.114094       1 schedule_one.go:266] "Successfully bound pod to node" pod="default/nginx-deployment-58df68d8db-lv596" node="three-worker-cluster-worker3" evaluatedNodes=4 feasibleNodes=2
I0322 17:49:39.320487       1 schedule_one.go:266] "Successfully bound pod to node" pod="local-path-storage/local-path-provisioner-684f458cdd-gk8sj" node="three-worker-cluster-worker3" evaluatedNodes=4 feasibleNodes=3
I0322 17:49:39.641237       1 schedule_one.go:266] "Successfully bound pod to node" pod="default/nginx-deployment-58df68d8db-mch88" node="three-worker-cluster-worker2" evaluatedNodes=4 feasibleNodes=2
I0322 18:04:37.561787       1 schedule_one.go:266] "Successfully bound pod to node" pod="default/nginx-deployment-58df68d8db-mpdbn" node="three-worker-cluster-worker3" evaluatedNodes=4 feasibleNodes=2
I0322 18:04:37.947749       1 schedule_one.go:266] "Successfully bound pod to node" pod="default/nginx-deployment-58df68d8db-nbl2m" node="three-worker-cluster-worker3" evaluatedNodes=4 feasibleNodes=2
I0322 18:04:38.966508       1 schedule_one.go:266] "Successfully bound pod to node" pod="default/nginx-deployment-58df68d8db-snbxt" node="three-worker-cluster-worker2" evaluatedNodes=4 feasibleNodes=2
I0322 18:04:40.086259       1 schedule_one.go:266] "Successfully bound pod to node" pod="local-path-storage/local-path-provisioner-684f458cdd-jtb8l" node="three-worker-cluster-worker3" evaluatedNodes=4 feasibleNodes=3
I0322 18:19:37.821886       1 schedule_one.go:266] "Successfully bound pod to node" pod="default/nginx-deployment-58df68d8db-zhbdc" node="three-worker-cluster-worker3" evaluatedNodes=4 feasibleNodes=2
I0322 18:19:38.043686       1 schedule_one.go:266] "Successfully bound pod to node" pod="default/nginx-deployment-58df68d8db-n85vx" node="three-worker-cluster-worker2" evaluatedNodes=4 feasibleNodes=2
I0322 18:19:39.178918       1 schedule_one.go:266] "Successfully bound pod to node" pod="default/nginx-deployment-58df68d8db-x94sn" node="three-worker-cluster-worker3" evaluatedNodes=4 feasibleNodes=2
I0322 18:19:40.649642       1 schedule_one.go:266] "Successfully bound pod to node" pod="local-path-storage/local-path-provisioner-684f458cdd-gdsm6" node="three-worker-cluster-worker3" evaluatedNodes=4 feasibleNodes=3
I0322 18:34:38.327453       1 schedule_one.go:266] "Successfully bound pod to node" pod="default/nginx-deployment-58df68d8db-t66xf" node="three-worker-cluster-worker3" evaluatedNodes=4 feasibleNodes=2
I0322 18:34:38.623382       1 schedule_one.go:266] "Successfully bound pod to node" pod="default/nginx-deployment-58df68d8db-92fvm" node="three-worker-cluster-worker2" evaluatedNodes=4 feasibleNodes=2
I0322 18:34:38.869401       1 schedule_one.go:266] "Successfully bound pod to node" pod="default/nginx-deployment-58df68d8db-vc82d" node="three-worker-cluster-worker3" evaluatedNodes=4 feasibleNodes=2
I0322 18:34:39.530974       1 schedule_one.go:266] "Successfully bound pod to node" pod="local-path-storage/local-path-provisioner-684f458cdd-wphqq" node="three-worker-cluster-worker2" evaluatedNodes=4 feasibleNodes=3
I0322 18:49:37.581466       1 schedule_one.go:266] "Successfully bound pod to node" pod="default/nginx-deployment-58df68d8db-69gcc" node="three-worker-cluster-worker2" evaluatedNodes=4 feasibleNodes=2
I0322 18:49:37.814418       1 schedule_one.go:266] "Successfully bound pod to node" pod="default/nginx-deployment-58df68d8db-lmhl7" node="three-worker-cluster-worker3" evaluatedNodes=4 feasibleNodes=2
I0322 18:49:38.836355       1 schedule_one.go:266] "Successfully bound pod to node" pod="default/nginx-deployment-58df68d8db-ttbc5" node="three-worker-cluster-worker3" evaluatedNodes=4 feasibleNodes=2
I0322 18:49:40.114233       1 schedule_one.go:266] "Successfully bound pod to node" pod="local-path-storage/local-path-provisioner-684f458cdd-8kl7h" node="three-worker-cluster-worker3" evaluatedNodes=4 feasibleNodes=3
I0322 19:04:37.348664       1 schedule_one.go:266] "Successfully bound pod to node" pod="default/nginx-deployment-58df68d8db-kqwbx" node="three-worker-cluster-worker2" evaluatedNodes=4 feasibleNodes=2
I0322 19:04:38.006115       1 schedule_one.go:266] "Successfully bound pod to node" pod="default/nginx-deployment-58df68d8db-thjtc" node="three-worker-cluster-worker3" evaluatedNodes=4 feasibleNodes=2
I0322 19:04:38.877605       1 schedule_one.go:266] "Successfully bound pod to node" pod="default/nginx-deployment-58df68d8db-mzvdm" node="three-worker-cluster-worker3" evaluatedNodes=4 feasibleNodes=2
I0322 19:04:39.962827       1 schedule_one.go:266] "Successfully bound pod to node" pod="local-path-storage/local-path-provisioner-684f458cdd-7jtjw" node="three-worker-cluster-worker2" evaluatedNodes=4 feasibleNodes=3
I0322 19:19:37.445661       1 schedule_one.go:266] "Successfully bound pod to node" pod="default/nginx-deployment-58df68d8db-grvcw" node="three-worker-cluster-worker2" evaluatedNodes=4 feasibleNodes=2
I0322 19:19:38.342627       1 schedule_one.go:266] "Successfully bound pod to node" pod="default/nginx-deployment-58df68d8db-rtwks" node="three-worker-cluster-worker3" evaluatedNodes=4 feasibleNodes=2
I0322 19:19:38.745478       1 schedule_one.go:266] "Successfully bound pod to node" pod="default/nginx-deployment-58df68d8db-ds8nh" node="three-worker-cluster-worker3" evaluatedNodes=4 feasibleNodes=2
I0322 19:19:39.606681       1 schedule_one.go:266] "Successfully bound pod to node" pod="local-path-storage/local-path-provisioner-684f458cdd-mxmxd" node="three-worker-cluster-worker3" evaluatedNodes=4 feasibleNodes=3
I0322 19:34:37.931707       1 schedule_one.go:266] "Successfully bound pod to node" pod="default/nginx-deployment-58df68d8db-2bnmx" node="three-worker-cluster-worker3" evaluatedNodes=4 feasibleNodes=2
I0322 19:34:38.403209       1 schedule_one.go:266] "Successfully bound pod to node" pod="default/nginx-deployment-58df68d8db-f975l" node="three-worker-cluster-worker2" evaluatedNodes=4 feasibleNodes=2
I0322 19:34:38.482439       1 schedule_one.go:266] "Successfully bound pod to node" pod="default/nginx-deployment-58df68d8db-dhglq" node="three-worker-cluster-worker3" evaluatedNodes=4 feasibleNodes=2
I0322 19:34:38.620013       1 schedule_one.go:266] "Successfully bound pod to node" pod="local-path-storage/local-path-provisioner-684f458cdd-ddkhv" node="three-worker-cluster-worker2" evaluatedNodes=4 feasibleNodes=3
I0322 19:49:37.487300       1 schedule_one.go:266] "Successfully bound pod to node" pod="local-path-storage/local-path-provisioner-684f458cdd-2jtbk" node="three-worker-cluster-worker3" evaluatedNodes=4 feasibleNodes=3
I0322 19:49:37.943555       1 schedule_one.go:266] "Successfully bound pod to node" pod="default/nginx-deployment-58df68d8db-f42zx" node="three-worker-cluster-worker2" evaluatedNodes=4 feasibleNodes=2
I0322 19:49:38.358635       1 schedule_one.go:266] "Successfully bound pod to node" pod="default/nginx-deployment-58df68d8db-qq5mf" node="three-worker-cluster-worker3" evaluatedNodes=4 feasibleNodes=2
I0322 19:49:39.805832       1 schedule_one.go:266] "Successfully bound pod to node" pod="default/nginx-deployment-58df68d8db-vr6xk" node="three-worker-cluster-worker3" evaluatedNodes=4 feasibleNodes=2
I0322 20:04:37.585373       1 schedule_one.go:266] "Successfully bound pod to node" pod="default/nginx-deployment-58df68d8db-kgqpx" node="three-worker-cluster-worker2" evaluatedNodes=4 feasibleNodes=2
I0322 20:04:38.115167       1 schedule_one.go:266] "Successfully bound pod to node" pod="local-path-storage/local-path-provisioner-684f458cdd-tm8s9" node="three-worker-cluster-worker3" evaluatedNodes=4 feasibleNodes=3
I0322 20:04:39.111281       1 schedule_one.go:266] "Successfully bound pod to node" pod="default/nginx-deployment-58df68d8db-qk2pd" node="three-worker-cluster-worker3" evaluatedNodes=4 feasibleNodes=2
I0322 20:04:40.600321       1 schedule_one.go:266] "Successfully bound pod to node" pod="default/nginx-deployment-58df68d8db-2rtwg" node="three-worker-cluster-worker2" evaluatedNodes=4 feasibleNodes=2
I0322 20:19:37.617217       1 schedule_one.go:266] "Successfully bound pod to node" pod="default/nginx-deployment-58df68d8db-vlnns" node="three-worker-cluster-worker3" evaluatedNodes=4 feasibleNodes=2
I0322 20:19:38.238166       1 schedule_one.go:266] "Successfully bound pod to node" pod="local-path-storage/local-path-provisioner-684f458cdd-gqpkl" node="three-worker-cluster-worker3" evaluatedNodes=4 feasibleNodes=3
I0322 20:19:38.679238       1 schedule_one.go:266] "Successfully bound pod to node" pod="default/nginx-deployment-58df68d8db-z9czw" node="three-worker-cluster-worker3" evaluatedNodes=4 feasibleNodes=2
I0322 20:19:40.409352       1 schedule_one.go:266] "Successfully bound pod to node" pod="default/nginx-deployment-58df68d8db-9hmpc" node="three-worker-cluster-worker2" evaluatedNodes=4 feasibleNodes=2
I0322 20:19:40.876867       1 schedule_one.go:266] "Successfully bound pod to node" pod="default/nginx-deployment-58df68d8db-czbvx" node="three-worker-cluster-worker3" evaluatedNodes=4 feasibleNodes=2
I0322 20:20:09.882573       1 schedule_one.go:266] "Successfully bound pod to node" pod="kube-system/descheduler-74b6dc9649-d7znz" node="three-worker-cluster-worker3" evaluatedNodes=4 feasibleNodes=2
I0322 20:55:14.057738       1 schedule_one.go:266] "Successfully bound pod to node" pod="default/nginx-deployment-58df68d8db-ng9pk" node="three-worker-cluster-worker" evaluatedNodes=4 feasibleNodes=3
I0322 21:21:31.566560       1 schedule_one.go:266] "Successfully bound pod to node" pod="default/nginx-deployment-58df68d8db-6wzkk" node="three-worker-cluster-worker" evaluatedNodes=4 feasibleNodes=3
I0322 23:49:38.281410       1 schedule_one.go:266] "Successfully bound pod to node" pod="default/pdc-pod" node="three-worker-cluster-worker3" evaluatedNodes=4 feasibleNodes=3
I0323 00:28:42.989945       1 schedule_one.go:266] "Successfully bound pod to node" pod="default/nginx-deployment-7c4cdc74b5-rpw56" node="three-worker-cluster-worker3" evaluatedNodes=4 feasibleNodes=3
I0323 00:28:43.587654       1 schedule_one.go:266] "Successfully bound pod to node" pod="default/nginx-deployment-7c4cdc74b5-rjjj2" node="three-worker-cluster-worker3" evaluatedNodes=4 feasibleNodes=3
I0323 00:28:46.428085       1 schedule_one.go:266] "Successfully bound pod to node" pod="default/nginx-deployment-7c4cdc74b5-g2x96" node="three-worker-cluster-worker3" evaluatedNodes=4 feasibleNodes=3
I0323 00:28:47.835960       1 schedule_one.go:266] "Successfully bound pod to node" pod="default/nginx-deployment-7c4cdc74b5-rv5gm" node="three-worker-cluster-worker3" evaluatedNodes=4 feasibleNodes=3
I0323 00:30:14.121609       1 schedule_one.go:266] "Successfully bound pod to node" pod="default/nginx-deployment-7c4cdc74b5-smswq" node="three-worker-cluster-worker3" evaluatedNodes=4 feasibleNodes=3
I0323 00:30:14.640300       1 schedule_one.go:266] "Successfully bound pod to node" pod="default/nginx-deployment-7c4cdc74b5-zmnf9" node="three-worker-cluster-worker3" evaluatedNodes=4 feasibleNodes=3
I0323 00:35:13.823399       1 schedule_one.go:266] "Successfully bound pod to node" pod="default/nginx-deployment-7c4cdc74b5-lch4d" node="three-worker-cluster-worker3" evaluatedNodes=4 feasibleNodes=3
I0323 00:35:13.933849       1 schedule_one.go:266] "Successfully bound pod to node" pod="default/nginx-deployment-7c4cdc74b5-2tk2r" node="three-worker-cluster-worker3" evaluatedNodes=4 feasibleNodes=3
I0323 00:40:13.933331       1 schedule_one.go:266] "Successfully bound pod to node" pod="default/nginx-deployment-7c4cdc74b5-dbbfp" node="three-worker-cluster-worker3" evaluatedNodes=4 feasibleNodes=3
I0323 00:40:14.214921       1 schedule_one.go:266] "Successfully bound pod to node" pod="default/nginx-deployment-7c4cdc74b5-72x7l" node="three-worker-cluster-worker3" evaluatedNodes=4 feasibleNodes=3
I0323 00:45:13.923711       1 schedule_one.go:266] "Successfully bound pod to node" pod="default/nginx-deployment-7c4cdc74b5-p2smb" node="three-worker-cluster-worker3" evaluatedNodes=4 feasibleNodes=3
I0323 00:45:14.837308       1 schedule_one.go:266] "Successfully bound pod to node" pod="default/nginx-deployment-7c4cdc74b5-r589b" node="three-worker-cluster-worker3" evaluatedNodes=4 feasibleNodes=3
I0323 00:50:13.917891       1 schedule_one.go:266] "Successfully bound pod to node" pod="default/nginx-deployment-7c4cdc74b5-xxhn2" node="three-worker-cluster-worker3" evaluatedNodes=4 feasibleNodes=3
I0323 00:50:14.341758       1 schedule_one.go:266] "Successfully bound pod to node" pod="default/nginx-deployment-7c4cdc74b5-ttxnt" node="three-worker-cluster-worker3" evaluatedNodes=4 feasibleNodes=3
I0323 00:55:13.830089       1 schedule_one.go:266] "Successfully bound pod to node" pod="default/nginx-deployment-7c4cdc74b5-ddpfm" node="three-worker-cluster-worker3" evaluatedNodes=4 feasibleNodes=3
I0323 00:55:14.489382       1 schedule_one.go:266] "Successfully bound pod to node" pod="default/nginx-deployment-7c4cdc74b5-g6gxg" node="three-worker-cluster-worker3" evaluatedNodes=4 feasibleNodes=3
I0323 00:56:21.944059       1 schedule_one.go:266] "Successfully bound pod to node" pod="default/nginx-deployment-57b4987665-w2xqb" node="three-worker-cluster-worker" evaluatedNodes=4 feasibleNodes=3
I0323 00:56:22.538592       1 schedule_one.go:266] "Successfully bound pod to node" pod="default/nginx-deployment-57b4987665-gg67z" node="three-worker-cluster-worker2" evaluatedNodes=4 feasibleNodes=3
I0323 00:56:25.301591       1 schedule_one.go:266] "Successfully bound pod to node" pod="default/nginx-deployment-57b4987665-kk699" node="three-worker-cluster-worker" evaluatedNodes=4 feasibleNodes=3
I0323 00:56:26.274815       1 schedule_one.go:266] "Successfully bound pod to node" pod="default/nginx-deployment-57b4987665-wfbnv" node="three-worker-cluster-worker2" evaluatedNodes=4 feasibleNodes=3
